Workbook

Sheet Index Composition
A1: Company | B1: ISIN Code | C1: MIC | D1: Number of Shares | E1: Free Float | F1: Capping Factor | G1: Effective Date of Review | H1: Currency
A2: ACCOR | B2: FR0000120404 | C2: XPAR | D2: 2637889 | E2: 1 | F2: 1 | G2: 23-Jun-25 | H2: EUR | I2: =D2=[1]selection!D2 -> TRUE
A3: ARCELORMITTAL SA | B3: LU1598757687 | C3: XAMS | D3: 4265861 | E3: 1 | F3: 1 | G3: 23-Jun-25 | H3: EUR | I3: =D3=[1]selection!D3 -> TRUE
A4: BOUYGUES | B4: FR0000120503 | C4: XPAR | D4: 3022362 | E4: 1 | F4: 1 | G4: 23-Jun-25 | H4: EUR | I4: =D4=[1]selection!D4 -> TRUE
A5: BUREAU VERITAS | B5: FR0006174348 | C5: XPAR | D5: 3911353 | E5: 1 | F5: 1 | G5: 23-Jun-25 | H5: EUR | I5: =D5=[1]selection!D5 -> TRUE
A6: CAPGEMINI | B6: FR0000125338 | C6: XPAR | D6: 755188 | E6: 1 | F6: 1 | G6: 23-Jun-25 | H6: EUR | I6: =D6=[1]selection!D6 -> TRUE
A7: CARREFOUR | B7: FR0000120172 | C7: XPAR | D7: 8847835 | E7: 1 | F7: 1 | G7: 23-Jun-25 | H7: EUR | I7: =D7=[1]selection!D7 -> TRUE
A8: CREDIT AGRICOLE | B8: FR0000045072 | C8: XPAR | D8: 7140651 | E8: 1 | F8: 1 | G8: 23-Jun-25 | H8: EUR | I8: =D8=[1]selection!D8 -> TRUE
A9: DASSAULT SYSTEMES | B9: FR0014003TT8 | C9: XPAR | D9: 3581599 | E9: 1 | F9: 1 | G9: 23-Jun-25 | H9: EUR | I9: =D9=[1]selection!D9 -> TRUE
A10: EDENRED | B10: FR0010908533 | C10: XPAR | D10: 4508317 | E10: 1 | F10: 1 | G10: 23-Jun-25 | H10: EUR | I10: =D10=[1]selection!D10 -> TRUE
A11: EUROFINS SCIENT. | B11: FR0014000MR3 | C11: XPAR | D11: 1870535 | E11: 1 | F11: 1 | G11: 23-Jun-25 | H11: EUR | I11: =D11=[1]selection!D11 -> TRUE
A12: KERING | B12: FR0000121485 | C12: XPAR | D12: 613131 | E12: 1 | F12: 1 | G12: 23-Jun-25 | H12: EUR | I12: =D12=[1]selection!D12 -> TRUE
A13: ORANGE | B13: FR0000133308 | C13: XPAR | D13: 8899902 | E13: 1 | F13: 1 | G13: 23-Jun-25 | H13: EUR | I13: =D13=[1]selection!D13 -> TRUE
... A21: VEOLIA ENVIRON. | B21: FR0000124141 | C21: XPAR | D21: 3792352 | E21: 1 | F21: 1 | G21: 23-Jun-25 | H21: EUR | I21: =D21=[1]selection!D21 -> TRUE

Sheet Inclusion
A1: Company | B1: ISIN code | C1: MIC
A2: AIR LIQUIDE | B2: FR0000120073 | C2: XPAR
A3: AIRBUS | B3: NL0000235190 | C3: XPAR
A4: AXA | B4: FR0000120628 | C4: XPAR
A5: BNP PARIBAS ACT.A | B5: FR0000131104 | C5: XPAR
A6: DANONE | B6: FR0000120644 | C6: XPAR
A7: DASSAULT SYSTEMES | B7: FR0014003TT8 | C7: XPAR
A8: ENGIE | B8: FR0010208488 | C8: XPAR
A9: ESSILORLUXOTTICA | B9: FR0000121667 | C9: XPAR
A10: HERMES INTL | B10: FR0000052292 | C10: XPAR
A11: L'OREAL | B11: FR0000120321 | C11: XPAR
A12: LEGRAND | B12: FR0010307819 | C12: XPAR
... A21: VINCI | B21: FR0000125486 | C21: XPAR

Sheet Exclusion
A1: Company | B1: ISIN code | C1: MIC

Sheet Full Universe
A1: Company | B1: ISIN code | C1: MIC | D1: Number of shares | E1: Free Float | F1: Capping | G1: #Symbol | H1: FX/Index Ccy | I1: Close Prc_EOD | J1: Close Prc_CO | K1: Number of issued shares | L1: Free Float Round: | M1: Capping Factor | N1: FFMC | O1: Unrounded NOSH | P1: Inclusion | Q1: x
A2: ACCOR | B2: FR0000120404 | C2: XPAR | D2: 243622860 | E2: 0.85 | F2: 1 | G2: FR0000120404 | H2: 1 | I2: 43 | J2: 46 | K2: 244966893 | L2: 0.85 | M2: 1 | N2: 9.5782055e+09 | O2: 2637889.4 | P2: FALSE | Q2: =ISNUMBER(MATCH(B2,'Index Composition'!$B$2:$B$21,0)) -> TRUE | R2: ='Index Market Cap'!$B$2/'Full Universe'!I2 -> 2637889.4
A3: AIR LIQUIDE | B3: FR0000120073 | C3: XPAR | D3: 578131063 | E3: 1 | F3: 1 | G3: FR0000120073 | H3: 1 | I3: 182.24 | J3: 183.92 | K3: 578439151 | L3: 1 | M3: 1 | N3: 1.0638653e+11 | O3: 622416.84 | P3: TRUE | Q3: =ISNUMBER(MATCH(B3,'Index Composition'!$B$2:$B$21,0)) -> FALSE
A4: AIRBUS | B4: NL0000235190 | C4: XPAR | D4: 792283683 | E4: 0.75 | F4: 1 | G4: NL0000235190 | H4: 1 | I4: 160.74 | J4: 157.3 | K4: 792283683 | L4: 0.75 | M4: 1 | N4: 9.3469668e+10 | O4: 705669.07 | P4: TRUE | Q4: =ISNUMBER(MATCH(B4,'Index Composition'!$B$2:$B$21,0)) -> FALSE
A5: ARCELORMITTAL SA | B5: LU1598757687 | C5: XAMS | D5: 852809772 | E5: 0.5 | F5: 1 | G5: NSCNL000AMT7 | H5: 1 | I5: 26.59 | J5: 26.45 | K5: 852809772 | L5: 0.5 | M5: 1 | N5: 1.1278409e+10 | O5: 4265861.1 | P5: FALSE | Q5: =ISNUMBER(MATCH(B5,'Index Composition'!$B$2:$B$21,0)) -> TRUE | R5: ='Index Market Cap'!$B$2/'Full Universe'!I5 -> 4265861.1
A6: AXA | B6: FR0000120628 | C6: XPAR | D6: 2200619258 | E6: 0.85 | F6: 1 | G6: FR0000120628 | H6: 1 | I6: 41.63 | J6: 40.97 | K6: 2215068307 | L6: 0.85 | M6: 1 | N6: 7.7138646e+10 | O6: 2724699.6 | P6: TRUE | Q6: =ISNUMBER(MATCH(B6,'Index Composition'!$B$2:$B$21,0)) -> FALSE
A7: BNP PARIBAS ACT.A | B7: FR0000131104 | C7: XPAR | D7: 1130810671 | E7: 0.95 | F7: 1 | G7: FR0000131104 | H7: 1 | I7: 75.97 | J7: 75.84 | K7: 1130810671 | L7: 0.95 | M7: 1 | N7: 8.1472647e+10 | O7: 1493079.4 | P7: TRUE | Q7: =ISNUMBER(MATCH(B7,'Index Composition'!$B$2:$B$21,0)) -> FALSE
A8: BOUYGUES | B8: FR0000120503 | C8: XPAR | D8: 379243267 | E8: 0.5 | F8: 1 | G8: FR0000120503 | H8: 1 | I8: 37.53 | J8: 39.59 | K8: 379208202 | L8: 0.5 | M8: 1 | N8: 7.5064264e+09 | O8: 3022362 | P8: FALSE | Q8: =ISNUMBER(MATCH(B8,'Index Composition'!$B$2:$B$21,0)) -> TRUE | R8: ='Index Market Cap'!$B$2/'Full Universe'!I8 -> 3022362
A9: BUREAU VERITAS | B9: FR0006174348 | C9: XPAR | D9: 453871520 | E9: 0.75 | F9: 1 | G9: FR0006174348 | H9: 1 | I9: 29 | J9: 29.92 | K9: 453871520 | L9: 0.75 | M9: 1 | N9: 1.0184877e+10 | O9: 3911353.3 | P9: FALSE | Q9: =ISNUMBER(MATCH(B9,'Index Composition'!$B$2:$B$21,0)) -> TRUE | R9: ='Index Market Cap'!$B$2/'Full Universe'!I9 -> 3911353.3
A10: CAPGEMINI | B10: FR0000125338 | C10: XPAR | D10: 172608113 | E10: 0.85 | F10: 1 | G10: FR0000125338 | H10: 1 | I10: 150.2 | J10: 146.9 | K10: 171347471 | L10: 0.85 | M10: 1 | N10: 2.1395302e+10 | O10: 755188.05 | P10: FALSE | Q10: =ISNUMBER(MATCH(B10,'Index Composition'!$B$2:$B$21,0)) -> TRUE | R10: ='Index Market Cap'!$B$2/'Full Universe'!I10 -> 755188.05
A11: CARREFOUR | B11: FR0000120172 | C11: XPAR | D11: 677969188 | E11: 0.85 | F11: 1 | G11: FR0000120172 | H11: 1 | I11: 12.82 | J11: 14.6 | K11: 677969188 | L11: 0.85 | M11: 1 | N11: 8.4135976e+09 | O11: 8847835.1 | P11: FALSE | Q11: =ISNUMBER(MATCH(B11,'Index Composition'!$B$2:$B$21,0)) -> TRUE | R11: ='Index Market Cap'!$B$2/'Full Universe'!I11 -> 8847835.1
A12: CREDIT AGRICOLE | B12: FR0000045072 | C12: XPAR | D12: 3025902350 | E12: 0.3 | F12: 1 | G12: FR0000045072 | H12: 1 | I12: 15.885 | J12: 17.23 | K12: 3025902350 | L12: 0.3 | M12: 1 | N12: 1.5640889e+10 | O12: 7140651.3 | P12: FALSE | Q12: =ISNUMBER(MATCH(B12,'Index Composition'!$B$2:$B$21,0)) -> TRUE | R12: ='Index Market Cap'!$B$2/'Full Universe'!I12 -> 7140651.3
A13: DANONE | B13: FR0000120644 | C13: XPAR | D13: 679553991 | E13: 0.95 | F13: 1 | G13: FR0000120644 | H13: 1 | I13: 71.66 | J13: 75.64 | K13: 679553991 | L13: 0.95 | M13: 1 | N13: 4.8831391e+10 | O13: 1582880.9 | P13: TRUE | Q13: =ISNUMBER(MATCH(B13,'Index Composition'!$B$2:$B$21,0)) -> FALSE
A14: DASSAULT SYSTEMES | B14: FR0014003TT8 | C14: XPAR | D14: 1338435363 | E14: 0.5 | F14: 1 | G14: FR0014003TT8 | H14: 1 | I14: 31.67 | J14: 33.59 | K14: 1340433125 | L14: 0.5 | M14: 1 | N14: 2.2512574e+10 | O14: 3581599.2 | P14: TRUE | Q14: =ISNUMBER(MATCH(B14,'Index Composition'!$B$2:$B$21,0)) -> TRUE | R14: ='Index Market Cap'!$B$2/'Full Universe'!I14 -> 3581599.2
A15: EDENRED | B15: FR0010908533 | C15: XPAR | D15: 249588059 | E15: 1 | F15: 1 | G15: FR0010908533 | H15: 1 | I15: 25.16 | J15: 27.12 | K15: 239891064 | L15: 1 | M15: 1 | N15: 6.5058457e+09 | O15: 4508316.6 | P15: FALSE | Q15: =ISNUMBER(MATCH(B15,'Index Composition'!$B$2:$B$21,0)) -> TRUE | R15: ='Index Market Cap'!$B$2/'Full Universe'!I15 -> 4508316.6
A16: ENGIE | B16: FR0010208488 | C16: XPAR | D16: 2435285011 | E16: 0.75 | F16: 1 | G16: FR0010208488 | H16: 1 | I16: 19.515 | J16: 18.97 | K16: 2435285011 | L16: 0.75 | M16: 1 | N16: 3.4648017e+10 | O16: 5812413.3 | P16: TRUE | Q16: =ISNUMBER(MATCH(B16,'Index Composition'!$B$2:$B$21,0)) -> FALSE
A17: ESSILORLUXOTTICA | B17: FR0000121667 | C17: XPAR | D17: 457318291 | E17: 0.7 | F17: 1 | G17: FR0000121667 | H17: 1 | I17: 240.5 | J17: 250 | K17: 457507201 | L17: 0.7 | M17: 1 | N17: 80063760175 | O17: 471639.27 | P17: TRUE | Q17: =ISNUMBER(MATCH(B17,'Index Composition'!$B$2:$B$21,0)) -> FALSE
A18: EUROFINS SCIENT. | B18: FR0014000MR3 | C18: XPAR | D18: 192981183 | E18: 0.65 | F18: 1 | G18: FR0014000MR3 | H18: 1 | I18: 60.64 | J18: 56.4 | K18: 182163000 | L18: 0.65 | M18: 1 | N18: 6678095580 | O18: 1870535.1 | P18: FALSE | Q18: =ISNUMBER(MATCH(B18,'Index Composition'!$B$2:$B$21,0)) -> TRUE | R18: ='Index Market Cap'!$B$2/'Full Universe'!I18 -> 1870535.1
A19: HERMES INTL | B19: FR0000052292 | C19: XPAR | D19: 105569412 | E19: 0.3 | F19: 1 | G19: FR0000052292 | H19: 1 | I19: 2294 | J19: 2373 | K19: 105569412 | L19: 0.3 | M19: 1 | N19: 7.5154864e+10 | O19: 49446.053 | P19: TRUE | Q19: =ISNUMBER(MATCH(B19,'Index Composition'!$B$2:$B$21,0)) -> FALSE
A20: KERING | B20: FR0000121485 | C20: XPAR | D20: 123420778 | E20: 0.6 | F20: 1 | G20: FR0000121485 | H20: 1 | I20: 185 | J20: 173.3 | K20: 123420778 | L20: 0.6 | M20: 1 | N20: 1.2833292e+10 | O20: 613131.06 | P20: FALSE | Q20: =ISNUMBER(MATCH(B20,'Index Composition'!$B$2:$B$21,0)) -> TRUE | R20: ='Index Market Cap'!$B$2/'Full Universe'!I20 -> 613131.06
A21: LEGRAND | B21: FR0010307819 | C21: XPAR | D21: 262245733 | E21: 1 | F21: 1 | G21: FR0010307819 | H21: 1 | I21: 111.15 | J21: 106.85 | K21: 262245733 | L21: 1 | M21: 1 | N21: 2.8020957e+10 | O21: 1020506 | P21: TRUE | Q21: =ISNUMBER(MATCH(B21,'Index Composition'!$B$2:$B$21,0)) -> FALSE
A22: L'OREAL | B22: FR0000120321 | C22: XPAR | D22: 534955898 | E22: 0.45 | F22: 1 | G22: FR0000120321 | H22: 1 | I22: 369 | J22: 372.95 | K22: 534315364 | L22: 0.45 | M22: 1 | N22: 8.9672812e+10 | O22: 307396.33 | P22: TRUE | Q22: =ISNUMBER(MATCH(B22,'Index Composition'!$B$2:$B$21,0)) -> FALSE
A23: LVMH | B23: FR0000121014 | C23: XPAR | D23: 500141700 | E23: 0.5 | F23: 1 | G23: FR0000121014 | H23: 1 | I23: 460.7 | J23: 479 | K23: 500141700 | L23: 0.5 | M23: 1 | N23: 119783937150 | O23: 246210.65 | P23: TRUE | Q23: =ISNUMBER(MATCH(B23,'Index Composition'!$B$2:$B$21,0)) -> FALSE
A24: MICHELIN | B24: FR001400AJ45 | C24: XPAR | D24: 714958226 | E24: 1 | F24: 1 | G24: FR001400AJ45 | H24: 1 | I24: 32.17 | J24: 33.32 | K24: 705747272 | L24: 1 | M24: 1 | N24: 2.3515499e+10 | O24: 3525932.4 | P24: FALSE | Q24: =ISNUMBER(MATCH(B24,'Index Composition'!$B$2:$B$21,0)) -> FALSE
A25: ORANGE | B25: FR0000133308 | C25: XPAR | D25: 2660056599 | E25: 0.65 | F25: 1 | G25: FR0000133308 | H25: 1 | I25: 12.745 | J25: 13.34 | K25: 2660056599 | L25: 0.65 | M25: 1 | N25: 2.3065351e+10 | O25: 8899901.6 | P25: FALSE | Q25: =ISNUMBER(MATCH(B25,'Index Composition'!$B$2:$B$21,0)) -> TRUE | R25: ='Index Market Cap'!$B$2/'Full Universe'!I25 -> 8899901.6
A26: PERNOD RICARD | B26: FR0000120693 | C26: XPAR | D26: 253328748 | E26: 0.8 | F26: 1 | G26: FR0000120693 | H26: 1 | I26: 88.5 | J26: 91.16 | K26: 252269195 | L26: 0.8 | M26: 1 | N26: 1.8397488e+10 | O26: 1281686.4 | P26: FALSE | Q26: =ISNUMBER(MATCH(B26,'Index Composition'!$B$2:$B$21,0)) -> TRUE | R26: ='Index Market Cap'!$B$2/'Full Universe'!I26 -> 1281686.4
A27: PUBLICIS GROUPE SA | B27: FR0000130577 | C27: XPAR | D27: 254311860 | E27: 0.95 | F27: 1 | G27: FR0000130577 | H27: 1 | I27: 95.74 | J27: 95.94 | K27: 254311860 | L27: 0.95 | M27: 1 | N27: 2.3178746e+10 | O27: 1184763.4 | P27: FALSE | Q27: =ISNUMBER(MATCH(B27,'Index Composition'!$B$2:$B$21,0)) -> TRUE | R27: ='Index Market Cap'!$B$2/'Full Universe'!I27 -> 1184763.4
A28: RENAULT | B28: FR0000131906 | C28: XPAR | D28: 295722284 | E28: 0.7 | F28: 1 | G28: FR0000131906 | H28: 1 | I28: 38.99 | J28: 47.56 | K28: 295722284 | L28: 0.7 | M28: 1 | N28: 9.8451863e+09 | O28: 2909188.1 | P28: FALSE | Q28: =ISNUMBER(MATCH(B28,'Index Composition'!$B$2:$B$21,0)) -> TRUE | R28: ='Index Market Cap'!$B$2/'Full Universe'!I28 -> 2909188.1
A29: SAFRAN | B29: FR0000073272 | C29: XPAR | D29: 427260541 | E29: 0.85 | F29: 1 | G29: FR0000073272 | H29: 1 | I29: 259.8 | J29: 254.8 | K29: 423632587 | L29: 0.85 | M29: 1 | N29: 9.1750346e+10 | O29: 436602.18 | P29: TRUE | Q29: =ISNUMBER(MATCH(B29,'Index Composition'!$B$2:$B$21,0)) -> FALSE
A30: SAINT GOBAIN | B30: FR0000125007 | C30: XPAR | D30: 504005802 | E30: 0.9 | F30: 1 | G30: FR0000125007 | H30: 1 | I30: 96.74 | J30: 97.6 | K30: 499054076 | L30: 0.9 | M30: 1 | N30: 4.383691e+10 | O30: 1172516.5 | P30: TRUE | Q30: =ISNUMBER(MATCH(B30,'Index Composition'!$B$2:$B$21,0)) -> FALSE
A31: SANOFI | B31: FR0000120578 | C31: XPAR | D31: 1268607152 | E31: 0.9 | F31: 1 | G31: FR0000120578 | H31: 1 | I31: 84.85 | J31: 92.14 | K31: 1227755441 | L31: 0.9 | M31: 1 | N31: 1.0181285e+11 | O31: 1336820.8 | P31: TRUE | Q31: =ISNUMBER(MATCH(B31,'Index Composition'!$B$2:$B$21,0)) -> FALSE
A32: SCHNEIDER ELECTRIC | B32: FR0000121972 | C32: XPAR | D32: 575627026 | E32: 1 | F32: 1 | G32: FR0000121972 | H32: 1 | I32: 221.9 | J32: 217.15 | K32: 575631676 | L32: 1 | M32: 1 | N32: 1.2499842e+11 | O32: 511172.81 | P32: TRUE | Q32: =ISNUMBER(MATCH(B32,'Index Composition'!$B$2:$B$21,0)) -> FALSE
A33: SOCIETE GENERALE | B33: FR0000130809 | C33: XPAR | D33: 812035548 | E33: 0.9 | F33: 1 | G33: FR0000130809 | H33: 1 | I33: 48.03 | J33: 47.97 | K33: 800316777 | L33: 0.9 | M33: 1 | N33: 3.4552076e+10 | O33: 2361633.3 | P33: TRUE | Q33: =ISNUMBER(MATCH(B33,'Index Composition'!$B$2:$B$21,0)) -> FALSE
A34: STELLANTIS NV | B34: NL00150001Q9 | C34: XPAR | D34: 3023129879 | E34: 0.7 | F34: 1 | G34: NL00150001Q9 | H34: 1 | I34: 8.408 | J34: 8.752 | K34: 2896073567 | L34: 0.7 | M34: 1 | N34: 1.7742505e+10 | O34: 13490633 | P34: TRUE | Q34: =ISNUMBER(MATCH(B34,'Index Composition'!$B$2:$B$21,0)) -> TRUE | R34: ='Index Market Cap'!$B$2/'Full Universe'!I34 -> 13490633
A35: STMICROELECTRONICS | B35: NL0000226223 | C35: XPAR | D35: 911281920 | E35: 0.7 | F35: 1 | G35: NL0000226223 | H35: 1 | I35: 25.245 | J35: 21.52 | K35: 911281920 | L35: 0.7 | M35: 1 | N35: 1.3727551e+10 | O35: 4493137.1 | P35: FALSE | Q35: =ISNUMBER(MATCH(B35,'Index Composition'!$B$2:$B$21,0)) -> TRUE | R35: ='Index Market Cap'!$B$2/'Full Universe'!I35 -> 4493137.1
A36: TELEPERFORMANCE | B36: FR0000051807 | C36: XPAR | D36: 60738823 | E36: 0.95 | F36: 1 | G36: FR0000051807 | H36: 1 | I36: 94.76 | J36: 91.5 | K36: 59874365 | L36: 0.95 | M36: 1 | N36: 5.2045792e+09 | O36: 1197016.1 | P36: FALSE | Q36: =ISNUMBER(MATCH(B36,'Index Composition'!$B$2:$B$21,0)) -> TRUE | R36: ='Index Market Cap'!$B$2/'Full Universe'!I36 -> 1197016.1
A37: THALES | B37: FR0000121329 | C37: XPAR | D37: 210210140 | E37: 0.45 | F37: 1 | G37: FR0000121329 | H37: 1 | I37: 248.2 | J37: 257 | K37: 205941913 | L37: 0.45 | M37: 1 | N37: 2.3817182e+10 | O37: 457007.44 | P37: FALSE | Q37: =ISNUMBER(MATCH(B37,'Index Composition'!$B$2:$B$21,0)) -> FALSE
A38: TOTALENERGIES | B38: FR0000120271 | C38: XPAR | D38: 2397679661 | E38: 0.9 | F38: 1 | G38: FR0000120271 | H38: 1 | I38: 55.51 | J38: 50.97 | K38: 2270057201 | L38: 0.9 | M38: 1 | N38: 1.0413433e+11 | O38: 2043402 | P38: TRUE | Q38: =ISNUMBER(MATCH(B38,'Index Composition'!$B$2:$B$21,0)) -> FALSE
A39: UNIBAIL-RODAMCO-WE | B39: FR0013326246 | C39: XPAR | D39: 139364104 | E39: 0.85 | F39: 1 | G39: FR0013326246 | H39: 1 | I39: 83.02 | J39: 78.74 | K39: 143188454 | L39: 0.85 | M39: 1 | N39: 9.58346e+09 | O39: 1366288.2 | P39: FALSE | Q39: =ISNUMBER(MATCH(B39,'Index Composition'!$B$2:$B$21,0)) -> TRUE | R39: ='Index Market Cap'!$B$2/'Full Universe'!I39 -> 1366288.2
A40: VEOLIA ENVIRON. | B40: FR0000124141 | C40: XPAR | D40: 726148514 | E40: 0.9 | F40: 1 | G40: FR0000124141 | H40: 1 | I40: 29.91 | J40: 30.37 | K40: 740652608 | L40: 0.9 | M40: 1 | N40: 2.0244258e+10 | O40: 3792351.9 | P40: FALSE | Q40: =ISNUMBER(MATCH(B40,'Index Composition'!$B$2:$B$21,0)) -> TRUE | R40: ='Index Market Cap'!$B$2/'Full Universe'!I40 -> 3792351.9
...

Sheet Index Market Cap
A1: Index Market Cap
A2: 2.2685849e+09 | B2: =A2/20 -> 1.1342925e+08
