Workbook

Sheet Sheet1
A1: Initalization
A2: 0. GAFI Black List | D2: exclude_gafi_black
A3: 1. GAFI Grey List | D3: exclude_gafi_grey
A4: 2. Countries non fiscally cooperative with EU | D4: exclude_non_fiscal_coop
A5: 3. Subsectors | D5: exclude_subsector
A6: 4. UNGC controversies | D6: exclude_nbr_red
A7: 5. Tobacco Production | D7: exclude_tobacco_prod
A8: 6. Tobacco Distribution | D8: exclude_tobacco_dist
A9: 7. Biological weapons | D9: exclude_biological_weapons
A10: 8. Chemical weapons | D10: exclude_chemical_weapons
A11: 9. Nuclear weapons | D11: exclude_nuclear_weapons_inside_npt
A12: 10. Nuclear non-NPT weapons | D12: exclude_nuclear_weapons_outside_npt
A13: 11. Cluster munitions | D13: exclude_cluster_munitions
... A32: 30. Worst 10% avg soc gov score | D32: exclude_sg_bottom_10
A33: 35. Final Selection
D34: Excluded
D35: Exclusion_Reason
D36: itr_scope123_target_filled
D37: itr_scope12_trend_filled
D38: cdp_temperature_score
D39: bonus_malus
D40: climate_score
A41: 31. Non EU Taxonomy pocket
A42: 32. Rank Non EU Taxonomy by supersector | D42: SG_Score
A43: 33. Non EU Taxonomy initial selection
A44: 34. Non EU Taxonomy final selection
A45: 36. Dummy FFMC Weight

Sheet Selected Companies
A1: Rank | B1: Ticker | C1: Company | D1: ISIN Code | E1: MIC | F1: Number of Shares | G1: Price (EUR) | H1: Currency | I1: Mcap in EUR | J1: index | K1: VOL_AV_3M | L1: Free Float | M1: FFMC_CO | N1: Close Prc | O1: FX/Index Ccy | P1: FFMC_WD | Q1: Price_WD | R1: Subsector Code | S1: Supersector Code | T1: itr_scope123_target | U1: itr_scope12_trend | V1: CDP_climate_score | W1: NBR Overall Flag | X1: Tobacco - Production Maximum Percentage of Revenues (%) | Y1: Tobacco - Distribution Maximum Percentage of Revenues (%) | Z1: Biological Weapons - Overall Flag | AA1: Chemical Weapons - Overall Flag | AB1: Nuclear Weapons Outside NPT - Overall Flag | AC1: Nuclear Weapons Inside NPT - Overall Flag | AD1: Cluster Munitions - Overall Flag | AE1: Depleted Uranium - Overall Flag | AF1: Anti-personnel Mines - Overall Flag | AG1: coal_mining_and_power_gen_maximum_percentage_of_revenues-values | AH1: Fossil Fuel - Total Maximum Percentage of Revenues (%) | AI1: power_generation_thermal_maximum_percentage_of_revenues-values | AJ1: shale_oil_and_or_gas_involvement_tie | AK1: arctic_drilling_share_max-values | AL1: deepwater_drilling_involvement | AM1: HydraulicFracturingInvolvement | AN1: CoalMiningExpInvolved | AO1: OilGasExtractExpInvolved | AP1: OtherFFInfraInvolved | AQ1: NuclearPowerInvolvement | AR1: NuclearPowerRevShareMax-values | AS1: NuclearPowerUraniumRevShareMax-values | AT1: CivFARevShareMax-values | AU1: MilitaryEqmtDistMaxRev-values | AV1: Social Rating (Num) | AW1: Governance Rating (Num) | AX1: NACE | AY1: High_Climate_Impact | AZ1: EU_Taxonomy | BA1: Country_Code | BB1: GAFI_Black_List | BC1: GAFI_Grey_List | BD1: Non_Fiscally_Cooperative | BE1: exclude_gafi_black | BF1: exclude_gafi_grey | BG1: exclude_non_fiscal_coop | BH1: exclude_subsector | BI1: exclude_nbr_red | BJ1: exclude_tobacco_prod | BK1: exclude_tobacco_dist | BL1: exclude_biological_weapons | BM1: exclude_chemical_weapons | BN1: exclude_nuclear_weapons_inside_npt | BO1: exclude_nuclear_weapons_outside_npt | BP1: exclude_cluster_munitions | BQ1: exclude_depleted_uranium | BR1: exclude_anti_personnel_mines | BS1: exclude_coal_mining | BT1: exclude_fossil_fuel | BU1: exclude_thermal_power | BV1: exclude_shale_oil_gas | BW1: exclude_arctic_drilling | BX1: exclude_deepwater_drilling | BY1: exclude_hydraulic_fracturing | BZ1: exclude_coal_mining_expansion | CA1: exclude_oil_gas_extraction_expansion | CB1: exclude_other_fossil_fuel_infra | CC1: exclude_nuclear_power | CD1: exclude_nuclear_power_revenue | CE1: exclude_nuclear_uranium | CF1: exclude_civilian_firearms | CG1: exclude_military_equipment | CH1: SG_Score | CI1: exclude_sg_bottom_10 | CJ1: Excluded | CK1: Exclusion_Reason | CL1: itr_scope123_target_filled | CM1: itr_scope12_trend_filled | CN1: cdp_temperature_score | CO1: bonus_malus | CP1: climate_score | CQ1: PAB_Flag | CR1: Liquidity_Cap | CS1: Liquidity_Floor
A2: 67 | B2: ALO-FR | C2: ALSTOM | D2: FR0010220475 | E2: XPAR | F2: 461510538 | G2: 20.09 | H2: EUR | I2: 9.2717467e+09 | J2: EU500;EZ300 | K2: 23095735 | L2: 0.75 | M2: 6.95381e+09 | N2: 19.87 | O2: 1 | P2: 6.8776608e+09 | Q2: 19.87 | R2: 50202010 | S2: 5020 | T2: 1.9980521 | U2: 3.1 | V2: A | W2: Green | X2: 0 | Y2: 0 | Z2: Green | AA2: Green | AB2: Green | AC2: Green | AD2: Green | AE2: Green | AF2: Green | AG2: 0 | AH2: 0 | AI2: 0 | AK2: 0 | AL2: F | AN2: F | AO2: F | AP2: F | AR2: 0 | AS2: 0 | AT2: 0 | AU2: 0 | AV2: 2.795 | AW2: 3.363 | AX2: C | AY2: 1 | AZ2: 1 | BA2: FR | BB2: 0 | BC2: 0 | BD2: 0 | CH2: 3.079 | CJ2: No | CL2: 1.9980521 | CM2: 3.1 | CN2: 2.5490261 | CO2: -0.3 | CP2: 2.2490261 | CQ2: 0 | CR2: 0.019975527 | CS2: 0
A3: 254 | B3: CAST-SE | C3: CASTELLUM AB | D3: SE0000379190 | E3: XSTO | F3: 492601440 | G3: 10.55657 | H3: SEK | I3: 5.2001816e+09 | J3: EU500 | K3: 15217501 | L3: 0.9 | M3: 4.6801634e+09 | N3: 111.95 | O3: 0.08996851 | P3: 4.4653223e+09 | Q3: 10.071975 | R3: 35101010 | S3: 3510 | T3: 1.9835888 | V3: A | W3: Green | X3: 0 | Y3: 0 | Z3: Green | AA3: Green | AB3: Green | AC3: Green | AD3: Green | AE3: Green | AF3: Green | AG3: 0 | AH3: 0 | AI3: 0 | AK3: 0 | AL3: F | AN3: F | AO3: F | AP3: F | AR3: 0 | AS3: 0 | AT3: 0 | AU3: 0 | AV3: 2.359 | AW3: 2.663 | AX3: L | AY3: 1 | AZ3: 1 | BA3: SE | BB3: 0 | BC3: 0 | BD3: 0 | CH3: 2.511 | CJ3: No | CL3: 1.9835888 | CM3: 3.1 | CN3: 2.5417944 | CO3: -0.3 | CP3: 2.2417944 | CQ3: 0 | CR3: 0.013136057 | CS3: 0
A4: 368 | B4: DSY-FR | C4: DASSAULT SYSTEMES | D4: FR0014003TT8 | E4: XPAR | F4: 1338435363 | G4: 39.72 | H4: EUR | I4: 5.3162653e+10 | J4: EU500;EZ300 | K4: 57311403 | L4: 0.5 | M4: 2.6581326e+10 | N4: 33.54 | O4: 1 | P4: 2.2445561e+10 | Q4: 33.54 | R4: 10101015 | S4: 1010 | T4: 1.9943237 | V4: B | W4: Green | X4: 0 | Y4: 0 | Z4: Green | AA4: Green | AB4: Green | AC4: Green | AD4: Green | AE4: Green | AF4: Green | AG4: 0 | AH4: 0 | AI4: 0 | AK4: 0 | AL4: F | AN4: F | AO4: F | AP4: F | AR4: 0 | AS4: 0 | AT4: 0 | AU4: 0 | AV4: 2.636 | AW4: 3.304 | AX4: J | AY4: 0 | AZ4: 1 | BA4: FR | BB4: 0 | BC4: 0 | BD4: 0 | CH4: 2.97 | CJ4: No | CL4: 1.9943237 | CM4: 3.1 | CN4: 2.5471619 | CO4: -0.18 | CP4: 2.3671619 | CQ4: 0 | CR4: 0.051644106 | CS4: 0
A5: 652 | B5: INPST-NL | C5: INPOST | D5: LU2290522684 | E5: XAMS | F5: 500000000 | G5: 17.46 | H5: EUR | I5: 8730000000 | J5: EU500;EZ300 | K5: 7745434.2 | L5: 0.4 | M5: 3492000000 | N5: 13.22 | O5: 1 | P5: 2644000000 | Q5: 13.22 | R5: 50206040 | S5: 5020 | T5: 3.3134401 | V5: A | W5: Green | X5: 0 | Y5: 0 | Z5: Green | AA5: Green | AB5: Green | AC5: Green | AD5: Green | AE5: Green | AF5: Green | AG5: 0 | AH5: 0 | AI5: 0 | AK5: 0 | AL5: F | AN5: F | AO5: F | AP5: F | AR5: 0 | AS5: 0 | AT5: 0 | AU5: 0 | AV5: 2.05 | AW5: 3.117 | AX5: H | AY5: 1 | AZ5: 1 | BA5: LU | BB5: 0 | BC5: 0 | BD5: 0 | CH5: 2.5835 | CJ5: No | CL5: 3.3134401 | CM5: 3.1 | CN5: 3.2067201 | CO5: -0.3 | CP5: 2.9067201 | CQ5: 0 | CR5: 0.0068292552 | CS5: 0
A6: 748 | B6: KRX-IE | C6: KINGSPAN GROUP PLC | D6: IE0004927939 | E6: XMSM | F6: 181964859 | G6: 75.5 | H6: EUR | I6: 1.3738347e+10 | J6: EU500;EZ300 | K6: 27712784 | L6: 0.85 | M6: 1.1677595e+10 | N6: 74.4 | O6: 1 | P6: 1.1507458e+10 | Q6: 74.4 | R6: 50101035 | S6: 5010 | T6: 1.9783312 | U6: 3.1 | V6: A | W6: Green | X6: 0 | Y6: 0 | Z6: Green | AA6: Green | AB6: Green | AC6: Green | AD6: Green | AE6: Green | AF6: Green | AG6: 0 | AH6: 0 | AI6: 0 | AK6: 0 | AL6: F | AN6: F | AO6: F | AP6: F | AR6: 0 | AS6: 0 | AT6: 0 | AU6: 0 | AV6: 2.108 | AW6: 2.617 | AX6: C | AY6: 1 | AZ6: 1 | BA6: IE | BB6: 0 | BC6: 0 | BD6: 0 | CH6: 2.3625 | CJ6: No | CL6: 1.9783312 | CM6: 3.1 | CN6: 2.5391656 | CO6: -0.3 | CP6: 2.2391656 | CQ6: 0 | CR6: 0.025224706 | CS6: 0
A7: 755 | B7: KBX-DE | C7: KNORR-BREMSE AG | D7: DE000KBX1006 | E7: XETR | F7: 161200000 | G7: 82.2 | H7: EUR | I7: 13250640000 | J7: EU500;EZ300 | K7: 9423306.8 | L7: 0.4 | M7: 5300256000 | N7: 81.25 | O7: 1 | P7: 5239000000 | Q7: 81.25 | R7: 50206025 | S7: 5020 | T7: 1.9989892 | V7: A- | W7: Green | X7: 0 | Y7: 0 | Z7: Green | AA7: Green | AB7: Green | AC7: Green | AD7: Green | AE7: Green | AF7: Green | AG7: 0 | AH7: 0 | AI7: 0 | AK7: 0 | AL7: F | AN7: F | AO7: F | AP7: F | AR7: 0 | AS7: 0 | AT7: 0 | AU7: 0 | AV7: 2.78 | AW7: 2.888 | AX7: C | AY7: 1 | AZ7: 1 | BA7: DE | BB7: 0 | BC7: 0 | BD7: 0 | CH7: 2.834 | CJ7: No | CL7: 1.9989892 | CM7: 3.1 | CN7: 2.5494946 | CO7: -0.24 | CP7: 2.3094946 | CQ7: 0 | CR7: 0.0090889328 | CS7: 0
A8: 865 | B8: METSO-FI | C8: METSO CORPORATION | D8: FI0009014575 | E8: XHEL | F8: 828972400 | G8: 10.98 | H8: EUR | I8: 9102116952 | J8: EU500;EZ300 | K8: 13202646 | L8: 0.85 | M8: 7.7367994e+09 | N8: 8.644 | O8: 1 | P8: 6.0907918e+09 | Q8: 8.644 | R8: 50204020 | S8: 5020 | T8: 1.9935451 | V8: B | W8: Green | X8: 0 | Y8: 0 | Z8: Green | AA8: Green | AB8: Green | AC8: Green | AD8: Green | AE8: Green | AF8: Green | AG8: 0 | AH8: 0 | AI8: 0 | AK8: 0 | AL8: F | AN8: F | AO8: F | AP8: F | AR8: 0 | AS8: 0 | AT8: 0 | AU8: 0 | AV8: 2.559 | AW8: 2.673 | AX8: C | AY8: 1 | AZ8: 1 | BA8: FI | BB8: 0 | BC8: 0 | BD8: 0 | CH8: 2.616 | CJ8: No | CL8: 1.9935451 | CM8: 3.1 | CN8: 2.5467726 | CO8: -0.18 | CP8: 2.3667726 | CQ8: 0 | CR8: 0.012252098 | CS8: 0
A9: 970 | B9: NHY-NO | C9: NORSK HYDRO | D9: NO0005052605 | E9: XOSL | F9: 2009015998 | G9: 5.713564 | H9: NOK | I9: 1.1478641e+10 | J9: EU500 | K9: 22699024 | L9: 0.65 | M9: 7.461117e+09 | N9: 54 | O9: 0.08336807 | P9: 5.8788213e+09 | Q9: 4.5018758 | R9: 55102035 | S9: 5510 | T9: 2.728329 | U9: 1.5 | V9: C | W9: Green | X9: 0 | Y9: 0 | Z9: Green | AA9: Green | AB9: Green | AC9: Green | AD9: Green | AE9: Green | AF9: Green | AG9: 0 | AH9: 0 | AI9: 0 | AK9: 0 | AL9: F | AN9: F | AO9: F | AP9: F | AR9: 0 | AS9: 0 | AT9: 0 | AU9: 0 | AV9: 2.861 | AW9: 3.723 | AX9: C | AY9: 1 | AZ9: 1 | BA9: NO | BB9: 0 | BC9: 0 | BD9: 0 | CH9: 3.292 | CJ9: No | CL9: 2.728329 | CM9: 1.5 | CN9: 2.1141645 | CO9: 0 | CP9: 2.1141645 | CQ9: 0 | CR9: 0.019292594 | CS9: 0
A10: 1092 | B10: RED-ES | C10: REDEIA CORP | D10: ES0173093024 | E10: XMAD | F10: 541080000 | G10: 16.83 | H10: EUR | I10: 9106376400 | J10: EU500;EZ300 | K10: 15311685 | L10: 0.75 | M10: 6829782300 | N10: 19.08 | O10: 1 | P10: 7742854800 | Q10: 19.08 | R10: 65101015 | S10: 6510 | T10: 1.5959603 | V10: A | W10: Green | X10: 0 | Y10: 0 | Z10: Green | AA10: Green | AB10: Green | AC10: Green | AD10: Green | AE10: Green | AF10: Green | AG10: 0 | AH10: 0 | AI10: 0 | AK10: 0 | AL10: F | AN10: F | AO10: F | AP10: F | AR10: 0 | AS10: 0 | AT10: 0 | AU10: 0 | AV10: 2.938 | AW10: 2.874 | AX10: D | AY10: 1 | AZ10: 1 | BA10: ES | BB10: 0 | BC10: 0 | BD10: 0 | CH10: 2.906 | CJ10: No | CL10: 1.5959603 | CM10: 3.1 | CN10: 2.3479802 | CO10: -0.3 | CP10: 2.0479802 | CQ10: 0 | CR10: 0.014471321 | CS10: 0
A11: 1119 | B11: ROCK.B-DK | C11: ROCKWOOL B | D11: DK0063855168 | E11: XCSE | F11: 117541060 | G11: 37.53242 | H11: DKK | I11: 4.4116004e+09 | J11: EU500 | K11: 13834313 | L11: 0.85 | M11: 3.7498604e+09 | N11: 282.2 | O11: 0.13395578 | P11: 3.7768262e+09 | Q11: 37.802321 | R11: 50101035 | S11: 5010 | T11: 1.8363484 | U11: 3.1 | V11: B | W11: Green | X11: 0 | Y11: 0 | Z11: Green | AA11: Green | AB11: Green | AC11: Green | AD11: Green | AE11: Green | AF11: Green | AG11: 0 | AH11: 0 | AI11: 0 | AK11: 0 | AL11: F | AN11: F | AO11: F | AP11: F | AR11: 0 | AS11: 0 | AT11: 0 | AU11: 0 | AV11: 2.152 | AW11: 2.604 | AX11: C | AY11: 1 | AZ11: 1 | BA11: DK | BB11: 0 | BC11: 0 | BD11: 0 | CH11: 2.378 | CJ11: No | CL11: 1.8363484 | CM11: 3.1 | CN11: 2.4681742 | CO11: -0.18 | CP11: 2.2881742 | CQ11: 0 | CR11: 0.011833012 | CS11: 0
A12: 1192 | B12: SVT-GB | C12: SEVERN TRENT | D12: GB00B1FH8J72 | E12: XLON | F12: 300209100 | G12: 29.42568 | H12: GBX | I12: 8.8338569e+09 | J12: EU500 | K12: 14800849 | L12: 0.9 | M12: 7.9504712e+09 | N12: 2699 | O12: 0.01169249 | P12: 8.5266071e+09 | Q12: 31.558031 | R12: 65102030 | S12: 6510 | T12: 1.7824348 | U12: 1.5 | V12: A- | W12: Green | X12: 0 | Y12: 0 | Z12: Green | AA12: Green | AB12: Green | AC12: Green | AD12: Green | AE12: Green | AF12: Green | AG12: 0 | AH12: 0 | AI12: 0 | AK12: 0 | AL12: F | AN12: F | AO12: F | AP12: F | AR12: 0 | AS12: 0 | AT12: 0 | AU12: 0 | AV12: 2.826 | AW12: 3.137 | AX12: E | AY12: 1 | AZ12: 1 | BA12: GB | BB12: 0 | BC12: 0 | BD12: 0 | CH12: 2.9815 | CJ12: No | CL12: 1.7824348 | CM12: 1.5 | CN12: 1.6412174 | CO12: -0.24 | CP12: 1.4012174 | CQ12: 1 | CR12: 0.014390603 | CS12: 0
A13: 1359 | B13: TRN-IT | C13: TERNA | D13: IT0003242622 | E13: MTAA | F13: 2009992000 | G13: 7.826 | H13: EUR | I13: 15730197392 | J13: EU500;EZ300 | K13: 30108575 | L13: 0.7 | M13: 1.1011138e+10 | N13: 8.336 | O13: 1 | P13: 1.1728705e+10 | Q13: 8.336 | R13: 65101015 | S13: 6510 | T13: 1.7449211 | V13: A- | W13: Green | X13: 0 | Y13: 0 | Z13: Green | AA13: Green | AB13: Green | AC13: Green | AD13: Green | AE13: Green | AF13: Green | AG13: 0 | AH13: 0 | AI13: 0 | AK13: 0 | AL13: F | AN13: F | AO13: F | AP13: F | AR13: 0 | AS13: 0 | AT13: 0 | AU13: 0 | AV13: 2.853 | AW13: 3.169 | AX13: D | AY13: 1 | AZ13: 1 | BA13: IT | BB13: 0 | BC13: 0 | BD13: 0 | CH13: 3.011 | CJ13: No | CL13: 1.7449211 | CM13: 3.1 | CN13: 2.4224605 | CO13: -0.24 | CP13: 2.1824605 | CQ13: 0 | CR13: 0.027106918 | CS13: 0
A14: 1462 | B14: VWS-DK | C14: VESTAS WIND SYSTEMS | D14: DK0061539921 | E14: XCSE | F14: 1009867250 | G14: 13.13903 | H14: DKK | I14: 1.3268676e+10 | J14: EU500 | K14: 50667588 | L14: 1 | M14: 1.3268676e+10 | N14: 90.6 | O14: 0.13395578 | P14: 1.2256146e+10 | Q14: 12.136394 | R14: 60102020 | S14: 6010 | T14: 1.9940728 | U14: 3.1 | V14: D | W14: Green | X14: 0 | Y14: 0 | Z14: Green | AA14: Green | AB14: Green | AC14: Green | AD14: Green | AE14: Green | AF14: Green | AG14: 0 | AH14: 0 | AI14: 0 | AK14: 0 | AL14: F | AN14: F | AO14: F | AP14: F | AR14: 0 | AS14: 0 | AT14: 0 | AU14: 0 | AV14: 2.304 | AW14: 3.223 | AX14: C | AY14: 1 | AZ14: 1 | BA14: DK | BB14: 0 | BC14: 0 | BD14: 0 | CH14: 2.7635 | CJ14: No | CL14: 1.9940728 | CM14: 3.1 | CN14: 2.5470364 | CO14: 0.18 | CP14: 2.7270364 | CQ14: 0 | CR14: 0.042729689 | CS14: 0
A15: 1505 | B15: WIE-AT | C15: WIENERBERGER AG | D15: AT0000831706 | E15: WBAH | F15: 111732346 | G15: 29.66 | H15: EUR | I15: 3.3139814e+09 | J15: EU500;EZ300 | K15: 6821360.8 | L15: 1 | M15: 3.3139814e+09 | N15: 30.3 | O15: 1 | P15: 3.3854901e+09 | Q15: 30.3 | R15: 50101035 | S15: 5010 | V15: B | W15: Green | X15: 0 | Y15: 0 | Z15: Green | AA15: Green | AB15: Green | AC15: Green | AD15: Green | AE15: Green | AF15: Green | AG15: 0 | AH15: 0 | AI15: 0 | AK15: 0 | AL15: F | AN15: F | AO15: F | AP15: F | AR15: 0 | AS15: 0 | AT15: 0 | AU15: 0 | AV15: 2.441 | AW15: 3.471 | AX15: C | AY15: 1 | AZ15: 1 | BA15: AT | BB15: 0 | BC15: 0 | BD15: 0 | CH15: 2.956 | CJ15: No | CL15: 3.4 | CM15: 3.1 | CN15: 3.25 | CO15: -0.18 | CP15: 3.07 | CQ15: 0 | CR15: 0.006422302 | CS15: 0
A16: 1139 | B16: SGE-GB | C16: SAGE GROUP PLC/THE | D16: GB00B8C3BL03 | E16: XLON | F16: 995756840 | G16: 15.69208 | H16: GBX | I16: 1.5625496e+10 | J16: EU500 | K16: 29289351 | L16: 1 | M16: 1.5625496e+10 | N16: 1180.5 | O16: 0.01169249 | P16: 1.3744416e+10 | Q16: 13.802984 | R16: 10101015 | S16: 1010 | T16: 1.7465783 | U16: 1.5 | V16: A | W16: Green | X16: 0 | Y16: 0 | Z16: Green | AA16: Green | AB16: Green | AC16: Green | AD16: Green | AE16: Green | AF16: Green | AG16: 0 | AH16: 0 | AI16: 0 | AK16: 0 | AL16: F | AN16: F | AO16: F | AP16: F | AR16: 0 | AS16: 0 | AT16: 0 | AU16: 0 | AV16: 2.41 | AW16: 3.306 | AX16: J | AY16: 0 | AZ16: 0 | BA16: GB | BB16: 0 | BC16: 0 | BD16: 0 | CH16: 2.858 | CJ16: No | CL16: 1.7465783 | CM16: 1.5 | CN16: 1.6232892 | CO16: -0.3 | CP16: 1.3232892 | CQ16: 1 | CR16: 0.014090048 | CS16: 0
A17: 1098 | B17: REN-NL | C17: RELX | D17: GB00B2B0DG97 | E17: XAMS | F17: 1907070957 | G17: 47.26 | H17: EUR | I17: 9.0128173e+10 | J17: EU500;EZ300 | K17: 34161920 | L17: 1 | M17: 9.0128173e+10 | N17: 45.6 | O17: 1 | P17: 8.6962436e+10 | Q17: 45.6 | R17: 10101010 | S17: 1010 | T17: 1.9831747 | U17: 1.5 | V17: B | W17: Green | X17: 0 | Y17: 0 | Z17: Green | AA17: Green | AB17: Green | AC17: Green | AD17: Green | AE17: Green | AF17: Green | AG17: 0 | AH17: 0 | AI17: 0 | AK17: 0 | AL17: F | AN17: F | AO17: F | AP17: F | AR17: 0 | AS17: 0 | AT17: 0 | AU17: 0 | AV17: 2.474 | AW17: 3.295 | AX17: M | AY17: 0 | AZ17: 0 | BA17: GB | BB17: 0 | BC17: 0 | BD17: 0 | CH17: 2.8845 | CJ17: No | CL17: 1.9831747 | CM17: 1.5 | CN17: 1.7415873 | CO17: -0.18 | CP17: 1.5615873 | CQ17: 1 | CR17: 0.043802775 | CS17: 0.023305623
A18: 119 | B18: ASM-NL | C18: ASM INTERNATIONAL | D18: NL0000334118 | E18: XAMS | F18: 49328548 | G18: 569.8 | H18: EUR | I18: 2.8107407e+10 | J18: EU500;EZ300 | K18: 78679459 | L18: 0.95 | M18: 2.6702036e+10 | N18: 408 | O18: 1 | P18: 1.9119745e+10 | Q18: 408 | R18: 10102020 | S18: 1010 | T18: 1.7486641 | U18: 3.1 | V18: A | W18: Green | X18: 0 | Y18: 0 | Z18: Green | AA18: Green | AB18: Green | AC18: Green | AD18: Green | AE18: Green | AF18: Green | AG18: 0 | AH18: 0 | AI18: 0 | AK18: 0 | AL18: F | AN18: F | AO18: F | AP18: F | AR18: 0 | AS18: 0 | AT18: 0 | AU18: 0 | AV18: 2.446 | AW18: 3.219 | AX18: C | AY18: 1 | AZ18: 0 | BA18: NL | BB18: 0 | BC18: 0 | BD18: 0 | CH18: 2.8325 | CJ18: No | CL18: 1.7486641 | CM18: 3.1 | CN18: 2.4243321 | CO18: -0.3 | CP18: 2.1243321 | CQ18: 0 | CR18: 0.030981135 | CS18: 0
A19: 805 | B19: LOGN-CH | C19: LOGITECH INTL SA | D19: CH0025751329 | E19: XSWX | F19: 168994140 | G19: 99.48116 | H19: CHF | I19: 1.6811733e+10 | J19: EU500 | K19: 53427463 | L19: 0.9 | M19: 1.513056e+10 | N19: 59.66 | O19: 1.079797 | P19: 9.798047e+09 | Q19: 64.420689 | R19: 10102030 | S19: 1010 | T19: 1.7497523 | V19: A | W19: Green | X19: 0 | Y19: 0 | Z19: Green | AA19: Green | AB19: Green | AC19: Green | AD19: Green | AE19: Green | AF19: Green | AG19: 0 | AH19: 0 | AI19: 0 | AK19: 0 | AL19: F | AN19: F | AO19: F | AP19: F | AR19: 0 | AS19: 0 | AT19: 0 | AU19: 0 | AV19: 2.565 | AW19: 3.4 | AX19: C | AY19: 1 | AZ19: 0 | BA19: CH | BB19: 0 | BC19: 0 | BD19: 0 | CH19: 2.9825 | CJ19: No | CL19: 1.7497523 | CM19: 3.1 | CN19: 2.4248762 | CO19: -0.3 | CP19: 2.1248762 | CQ19: 0 | CR19: 0.019808786 | CS19: 0
A20: 1348 | B20: TEF-ES | C20: TELEFONICA | D20: ES0178430E18 | E20: XMAD | F20: 5670161600 | G20: 4.174 | H20: EUR | I20: 2.3667255e+10 | J20: EU500;EZ300 | K20: 53268601 | L20: 0.7 | M20: 1.6567078e+10 | N20: 4.166 | O20: 1 | P20: 1.6535325e+10 | Q20: 4.166 | R20: 15102015 | S20: 1510 | T20: 1.7233601 | U20: 1.5 | V20: A | W20: Green | X20: 0 | Y20: 0 | Z20: Green | AA20: Green | AB20: Green | AC20: Green | AD20: Green | AE20: Green | AF20: Green | AG20: 0 | AH20: 0 | AI20: 0 | AK20: 0 | AL20: F | AN20: F | AO20: F | AP20: F | AR20: 0 | AS20: 0 | AT20: 0 | AU20: 0 | AV20: 3.103 | AW20: 2.885 | AX20: J | AY20: 0 | AZ20: 0 | BA20: ES | BB20: 0 | BC20: 0 | BD20: 0 | CH20: 2.994 | CJ20: No | CL20: 1.7233601 | CM20: 1.5 | CN20: 1.61168 | CO20: -0.3 | CP20: 1.31168 | CQ20: 1 | CR20: 0.022360687 | CS20: 0
A21: 1471 | B21: VOD-GB | C21: VODAFONE GROUP | D21: GB00BH4HKS39 | E21: XLON | F21: 25081295000 | G21: 0.8003203 | H21: GBX | I21: 2.007307e+10 | J21: EU500 | K21: 51438057 | L21: 0.8 | M21: 1.6058456e+10 | N21: 69.26 | O21: 0.01169249 | P21: 1.6249105e+10 | Q21: 0.80982186 | R21: 15102015 | S21: 1510 | T21: 1.7280905 | U21: 1.5 | V21: A | W21: Green | X21: 0 | Y21: 0 | Z21: Green | AA21: Green | AB21: Green | AC21: Green | AD21: Green | AE21: Green | AF21: Green | AG21: 0 | AH21: 0 | AI21: 0 | AK21: 0 | AL21: F | AN21: F | AO21: F | AP21: F | AR21: 0 | AS21: 0 | AT21: 0 | AU21: 0 | AV21: 2.765 | AW21: 3.141 | AX21: J | AY21: 0 | AZ21: 0 | BA21: GB | BB21: 0 | BC21: 0 | BD21: 0 | CH21: 2.953 | CJ21: No | CL21: 1.7280905 | CM21: 1.5 | CN21: 1.6140453 | CO21: -0.3 | CP21: 1.3140453 | CQ21: 1 | CR21: 0.021701086 | CS21: 0
A22: 1002 | B22: ORA-FR | C22: ORANGE | D22: FR0000133308 | E22: XPAR | F22: 2660056599 | G22: 11.075 | H22: EUR | I22: 2.9460127e+10 | J22: EU500;EZ300 | K22: 71522746 | L22: 0.65 | M22: 1.9149082e+10 | N22: 12.39 | O22: 1 | P22: 2.1422766e+10 | Q22: 12.39 | R22: 15102015 | S22: 1510 | T22: 1.7104133 | U22: 2.39 | V22: B | W22: Green | X22: 0 | Y22: 0 | Z22: Green | AA22: Green | AB22: Green | AC22: Green | AD22: Green | AE22: Green | AF22: Green | AG22: 0 | AH22: 0 | AI22: 0 | AK22: 0 | AL22: F | AN22: F | AO22: F | AP22: F | AR22: 0 | AS22: 0 | AT22: 0 | AU22: 0 | AV22: 2.716 | AW22: 2.747 | AX22: J | AY22: 0 | AZ22: 0 | BA22: FR | BB22: 0 | BC22: 0 | BD22: 0 | CH22: 2.7315 | CJ22: No | CL22: 1.7104133 | CM22: 2.39 | CN22: 2.0502067 | CO22: -0.18 | CP22: 1.8702067 | CQ22: 0 | CR22: 0.029722735 | CS22: 0
A23: 1350 | B23: TEL-NO | C23: TELENOR | D23: NO0010063308 | E23: XOSL | F23: 1368349989 | G23: 12.14261 | H23: NOK | I23: 1.661534e+10 | J23: EU500 | K23: 14604406 | L23: 0.45 | M23: 7.4769031e+09 | N23: 146.7 | O23: 0.08336807 | P23: 7.5307732e+09 | Q23: 12.230096 | R23: 15102015 | S23: 1510 | T23: 1.6924228 | U23: 2.7 | V23: A- | W23: Green | X23: 0 | Y23: 0 | Z23: Green | AA23: Green | AB23: Green | AC23: Green | AD23: Green | AE23: Green | AF23: Green | AG23: 0 | AH23: 0 | AI23: 0 | AK23: 0 | AL23: F | AN23: F | AO23: F | AP23: F | AR23: 0 | AS23: 0 | AT23: 0 | AU23: 0 | AV23: 2.337 | AW23: 2.934 | AX23: J | AY23: 0 | AZ23: 0 | BA23: NO | BB23: 0 | BC23: 0 | BD23: 0 | CH23: 2.6355 | CJ23: No | CL23: 1.6924228 | CM23: 2.7 | CN23: 2.1962114 | CO23: -0.24 | CP23: 1.9562114 | CQ23: 0 | CR23: 0.0072870485 | CS23: 0
A24: 976 | B24: NSIS.B-DK | C24: NOVONESIS | D24: DK0060336014 | E24: XCSE | F24: 414555050 | G24: 53.64455 | H24: DKK | I24: 2.2238619e+10 | J24: EU500 | K24: 28551145 | L24: 0.85 | M24: 1.8902826e+10 | N24: 410 | O24: 0.13395578 | P24: 1.9352918e+10 | Q24: 54.92187 | R24: 20103010 | S24: 2010 | T24: 1.704606 | U24: 1.5 | V24: A | W24: Green | X24: 0 | Y24: 0 | Z24: Green | AA24: Green | AB24: Green | AC24: Green | AD24: Green | AE24: Green | AF24: Green | AG24: 0 | AH24: 0 | AI24: 0 | AK24: 0 | AL24: F | AN24: F | AO24: F | AP24: F | AR24: 0 | AS24: 0 | AT24: 0 | AU24: 0 | AV24: 2.575 | AW24: 2.876 | AX24: C | AY24: 1 | AZ24: 0 | BA24: DK | BB24: 0 | BC24: 0 | BD24: 0 | CH24: 2.7255 | CJ24: No | CL24: 1.704606 | CM24: 1.5 | CN24: 1.602303 | CO24: -0.3 | CP24: 1.302303 | CQ24: 1 | CR24: 0.01603261 | CS24: 0
A25: 566 | B25: GSK-GB | C25: GSK PLC | D25: GB00BN7SWP63 | E25: XLON | F25: 4145945300 | G25: 17.2758 | H25: GBX | I25: 7.1624522e+10 | J25: EU500 | K25: 94231735 | L25: 1 | M25: 7.1624522e+10 | N25: 1346 | O25: 0.01169249 | P25: 6.5249267e+10 | Q25: 15.738092 | R25: 20103015 | S25: 2010 | T25: 1.7306923 | U25: 1.5 | V25: A | W25: Green | X25: 0 | Y25: 0 | Z25: Green | AA25: Green | AB25: Green | AC25: Green | AD25: Green | AE25: Green | AF25: Green | AG25: 0 | AH25: 0 | AI25: 0 | AK25: 0 | AL25: F | AN25: F | AO25: F | AP25: F | AR25: 0 | AS25: 0 | AT25: 0 | AU25: 0 | AV25: 3.198 | AW25: 2.788 | AX25: C | AY25: 1 | AZ25: 0 | BA25: GB | BB25: 0 | BC25: 0 | BD25: 0 | CH25: 2.993 | CJ25: No | CL25: 1.7306923 | CM25: 1.5 | CN25: 1.6153462 | CO25: -0.3 | CP25: 1.3153462 | CQ25: 1 | CR25: 0.053445758 | CS25: 0
A26: 974 | B26: NOVN-CH | C26: NOVARTIS | D26: CH0012005267 | E26: XSWX | F26: 2189930400 | G26: 104.3617 | H26: CHF | I26: 2.2854486e+11 | J26: EU500 | K26: 3.4805244e+08 | L26: 0.95 | M26: 2.1711762e+11 | N26: 90.2 | O26: 1.079797 | P26: 2.0262945e+11 | Q26: 97.397689 | R26: 20103015 | S26: 2010 | T26: 1.7351436 | U26: 1.5 | V26: A | W26: Green | X26: 0 | Y26: 0 | Z26: Green | AA26: Green | AB26: Green | AC26: Green | AD26: Green | AE26: Green | AF26: Green | AG26: 0 | AH26: 0 | AI26: 0 | AK26: 0 | AL26: F | AN26: F | AO26: F | AP26: F | AR26: 0 | AS26: 0 | AT26: 0 | AU26: 0 | AV26: 2.978 | AW26: 2.973 | AX26: C | AY26: 1 | AZ26: 0 | BA26: CH | BB26: 0 | BC26: 0 | BD26: 0 | CH26: 2.9755 | CJ26: No | CL26: 1.7351436 | CM26: 1.5 | CN26: 1.6175718 | CO26: -0.3 | CP26: 1.3175718 | CQ26: 1 | CR26: 0.1 | CS26: 0
A27: 126 | B27: AZN-GB | C27: ASTRAZENECA | D27: GB0009895292 | E27: XLON | F27: 1550581200 | G27: 141.5431 | H27: GBX | I27: 2.1947407e+11 | J27: EU500 | K27: 1.7576966e+08 | L27: 1 | M27: 2.1947407e+11 | N27: 10280 | O27: 0.01169249 | P27: 1.86378e+11 | Q27: 120.1988 | R27: 20103015 | S27: 2010 | T27: 1.7400925 | U27: 1.5 | V27: A | W27: Green | X27: 0 | Y27: 0 | Z27: Green | AA27: Green | AB27: Green | AC27: Green | AD27: Green | AE27: Green | AF27: Green | AG27: 0 | AH27: 0 | AI27: 0 | AK27: 0 | AL27: F | AN27: F | AO27: F | AP27: F | AR27: 0 | AS27: 0 | AT27: 0 | AU27: 0 | AV27: 2.777 | AW27: 2.399 | AX27: C | AY27: 1 | AZ27: 0 | BA27: GB | BB27: 0 | BC27: 0 | BD27: 0 | CH27: 2.588 | CJ27: No | CL27: 1.7400925 | CM27: 1.5 | CN27: 1.6200463 | CO27: -0.3 | CP27: 1.3200463 | CQ27: 1 | CR27: 0.1 | CS27: 0.019182503
A28: 1151 | B28: SAN-FR | C28: SANOFI | D28: FR0000120578 | E28: XPAR | F28: 1263122721 | G28: 104.12 | H28: EUR | I28: 1.3151634e+11 | J28: EU500;EZ300 | K28: 1.5479623e+08 | L28: 0.95 | M28: 1.2494052e+11 | N28: 91.62 | O28: 1 | P28: 1.0994094e+11 | Q28: 91.62 | R28: 20103015 | S28: 2010 | T28: 1.7231997 | U28: 1.5 | V28: A- | W28: Green | X28: 0 | Y28: 0 | Z28: Green | AA28: Green | AB28: Green | AC28: Green | AD28: Green | AE28: Green | AF28: Green | AG28: 0 | AH28: 0 | AI28: 0 | AK28: 0 | AL28: F | AN28: F | AO28: F | AP28: F | AR28: 0 | AS28: 0 | AT28: 0 | AU28: 0 | AV28: 2.98 | AW28: 2.774 | AX28: C | AY28: 1 | AZ28: 0 | BA28: FR | BB28: 0 | BC28: 0 | BD28: 0 | CH28: 2.877 | CJ28: No | CL28: 1.7231997 | CM28: 1.5 | CN28: 1.6115998 | CO28: -0.24 | CP28: 1.3715998 | CQ28: 1 | CR28: 0.088859254 | CS28: 0
A29: 1426 | B29: UCB-BE | C29: UCB | D29: BE0003739530 | E29: XBRU | F29: 194505658 | G29: 181.8 | H29: EUR | I29: 3.5361129e+10 | J29: EU500;EZ300 | K29: 36834331 | L29: 0.65 | M29: 2.2984734e+10 | N29: 142.5 | O29: 1 | P29: 1.8016087e+10 | Q29: 142.5 | R29: 20103015 | S29: 2010 | T29: 1.7415642 | U29: 1.77 | V29: A- | W29: Green | X29: 0 | Y29: 0 | Z29: Green | AA29: Green | AB29: Green | AC29: Green | AD29: Green | AE29: Green | AF29: Green | AG29: 0 | AH29: 0 | AI29: 0 | AK29: 0 | AL29: F | AN29: F | AO29: F | AP29: F | AR29: 0 | AS29: 0 | AT29: 0 | AU29: 0 | AV29: 2.661 | AW29: 2.861 | AX29: M | AY29: 0 | AZ29: 0 | BA29: BE | BB29: 0 | BC29: 0 | BD29: 0 | CH29: 2.761 | CJ29: No | CL29: 1.7415642 | CM29: 1.77 | CN29: 1.7557821 | CO29: -0.24 | CP29: 1.5157821 | CQ29: 1 | CR29: 0.018001753 | CS29: 0
A30: 322 | B30: CTEC-GB | C30: CONVATEC GROUP PLC | D30: GB00BD3VFW73 | E30: XLON | F30: 2049789600 | G30: 2.990925 | H30: GBX | I30: 6.130767e+09 | J30: EU500 | K30: 9155054.9 | L30: 0.8 | M30: 4.9046136e+09 | N30: 259 | O30: 0.01169249 | P30: 4.9659923e+09 | Q30: 3.0283549 | R30: 20102015 | S30: 2010 | T30: 1.9742318 | U30: 1.5 | V30: B | W30: Green | X30: 0 | Y30: 0 | Z30: Green | AA30: Green | AB30: Green | AC30: Green | AD30: Green | AE30: Green | AF30: Green | AG30: 0 | AH30: 0 | AI30: 0 | AK30: 0 | AL30: F | AN30: F | AO30: F | AP30: F | AR30: 0 | AS30: 0 | AT30: 0 | AU30: 0 | AV30: 2.786 | AW30: 3.001 | AX30: C | AY30: 1 | AZ30: 0 | BA30: GB | BB30: 0 | BC30: 0 | BD30: 0 | CH30: 2.8935 | CJ30: No | CL30: 1.9742318 | CM30: 1.5 | CN30: 1.7371159 | CO30: -0.18 | CP30: 1.5571159 | CQ30: 1 | CR30: 0.00466263 | CS30: 0
A31: 73 | B31: AMBU.B-DK | C31: AMBU A/S CLASS B | D31: DK0060946788 | E31: XCSE | F31: 234974400 | G31: 18.71929 | H31: DKK | I31: 4.3985539e+09 | J31: EU500 | K31: 7606684.2 | L31: 0.85 | M31: 3.7387708e+09 | N31: 117.9 | O31: 0.13395578 | P31: 3.1543853e+09 | Q31: 15.793386 | R31: 20102010 | S31: 2010 | T31: 1.9159909 | U31: 1.5 | V31: D | W31: Green | X31: 0 | Y31: 0 | Z31: Green | AA31: Green | AB31: Green | AC31: Green | AD31: Green | AE31: Green | AF31: Green | AG31: 0 | AH31: 0 | AI31: 0 | AK31: 0 | AL31: F | AN31: F | AO31: F | AP31: F | AR31: 0 | AS31: 0 | AT31: 0 | AU31: 0 | AV31: 2.627 | AW31: 2.753 | AX31: C | AY31: 1 | AZ31: 0 | BA31: DK | BB31: 0 | BC31: 0 | BD31: 0 | CH31: 2.69 | CJ31: No | CL31: 1.9159909 | CM31: 1.5 | CN31: 1.7079955 | CO31: 0.18 | CP31: 1.8879955 | CQ31: 1 | CR31: 0.0034991155 | CS31: 0
... A44: 1431 | B44: UCG-IT | C44: UNICREDIT | D44: IT0005239360 | E44: MTAA | F44: 1557675176 | G44: 47.785 | H44: EUR | I44: 7.4433508e+10 | J44: EU500;EZ300 | K44: 3.2895438e+08 | L44: 1 | M44: 7.4433508e+10 | N44: 49.65 | O44: 1 | P44: 7.7338572e+10 | Q44: 49.65 | R44: 30101010 | S44: 3010 | T44: 3.4 | U44: 1.5 | V44: B | W44: Green | X44: 0 | Y44: 0 | Z44: Green | AA44: Green | AB44: Green | AC44: Green | AD44: Green | AE44: Green | AF44: Green | AG44: 0 | AH44: 0 | AI44: 0 | AK44: 0 | AL44: F | AN44: F | AO44: F | AP44: F | AR44: 0 | AS44: 0 | AT44: 0 | AU44: 0 | AV44: 2.355 | AW44: 3.066 | AX44: K | AY44: 0 | AZ44: 0 | BA44: IT | BB44: 0 | BC44: 0 | BD44: 0 | CH44: 2.7105 | CJ44: No | CL44: 3.4 | CM44: 1.5 | CN44: 2.45 | CO44: -0.18 | CP44: 2.27 | CQ44: 0 | CR44: 0.1 | CS44: 0
A45: 919 | B45: NWG-GB | C45: NATWEST GROUP | D45: GB00BM8PJY71 | E45: XLON | F45: 8058562000 | G45: 5.462005 | H45: GBX | I45: 4.4015906e+10 | J45: EU500 | K45: 81343299 | L45: 0.9 | M45: 3.9614315e+10 | N45: 456.9 | O45: 0.01169249 | P45: 3.8746121e+10 | Q45: 5.3422987 | R45: 30101010 | S45: 3010 | T45: 1.9993422 | V45: A- | W45: Green | X45: 0 | Y45: 0 | Z45: Green | AA45: Green | AB45: Green | AC45: Green | AD45: Green | AE45: Green | AF45: Green | AG45: 0 | AH45: 0 | AI45: 0 | AK45: 0 | AL45: F | AN45: F | AO45: F | AP45: F | AR45: 0 | AS45: 0 | AT45: 0 | AU45: 0 | AV45: 2.414 | AW45: 2.734 | AX45: K | AY45: 0 | AZ45: 0 | BA45: GB | BB45: 0 | BC45: 0 | BD45: 0 | CH45: 2.574 | CJ45: No | CL45: 1.9993422 | CM45: 3.1 | CN45: 2.5496711 | CO45: -0.24 | CP45: 2.3096711 | CQ45: 0 | CR45: 0.039353066 | CS45: 0
A46: 165 | B46: BIRG-IE | C46: BANK OF IRELAND GP | D46: IE00BD1RP616 | E46: XMSM | F46: 1003409101 | G46: 10.44 | H46: EUR | I46: 1.0475591e+10 | J46: EU500;EZ300 | K46: 17800026 | L46: 1 | M46: 1.0475591e+10 | N46: 10.49 | O46: 1 | P46: 1.0525761e+10 | Q46: 10.49 | R46: 30101010 | S46: 3010 | T46: 1.9796332 | V46: C | W46: Green | X46: 0 | Y46: 0 | Z46: Green | AA46: Green | AB46: Green | AC46: Green | AD46: Green | AE46: Green | AF46: Green | AG46: 0 | AH46: 0 | AI46: 0 | AK46: 0 | AL46: F | AN46: F | AO46: F | AP46: F | AR46: 0 | AS46: 0 | AT46: 0 | AU46: 0 | AV46: 2.317 | AW46: 2.543 | AX46: K | AY46: 0 | AZ46: 0 | BA46: IE | BB46: 0 | BC46: 0 | BD46: 0 | CH46: 2.43 | CJ46: No | CL46: 1.9796332 | CM46: 3.1 | CN46: 2.5398166 | CO46: 0 | CP46: 2.5398166 | CQ46: 0 | CR46: 0.0094013419 | CS46: 0
A47: 712 | B47: BAER-CH | C47: JULIUS BAER GRUPPE | D47: CH0102484968 | E47: XSWX | F47: 206001790 | G47: 62.62763 | H47: CHF | I47: 1.2901404e+10 | J47: EU500 | K47: 34741509 | L47: 1 | M47: 1.2901404e+10 | N47: 49.83 | O47: 1.079797 | P47: 1.1084191e+10 | Q47: 53.806285 | R47: 30202010 | S47: 3020 | T47: 1.9981675 | U47: 2.7 | V47: B | W47: Green | X47: 0 | Y47: 0 | Z47: Green | AA47: Green | AB47: Green | AC47: Green | AD47: Green | AE47: Green | AF47: Green | AG47: 0 | AH47: 0 | AI47: 0 | AK47: 0 | AL47: F | AN47: F | AO47: F | AP47: F | AR47: 0 | AS47: 0 | AT47: 0 | AU47: 0 | AV47: 2.184 | AW47: 2.667 | AX47: K | AY47: 0 | AZ47: 0 | BA47: CH | BB47: 0 | BC47: 0 | BD47: 0 | CH47: 2.4255 | CJ47: No | CL47: 1.9981675 | CM47: 2.7 | CN47: 2.3490837 | CO47: -0.18 | CP47: 2.1690837 | CQ47: 0 | CR47: 0.014699255 | CS47: 0
A48: 533 | B48: GBLB-BE | C48: GBL | D48: BE0003797140 | E48: XBRU | F48: 138400000 | G48: 68.55 | H48: EUR | I48: 9487320000 | J48: EU500;EZ300 | K48: 6900889.3 | L48: 0.55 | M48: 5218026000 | N48: 68.6 | O48: 1 | P48: 5221832000 | Q48: 68.6 | R48: 30202000 | S48: 3020 | T48: 1.8920545 | V48: A | W48: Green | X48: 0 | Y48: 0 | Z48: Green | AA48: Green | AB48: Green | AC48: Green | AD48: Green | AE48: Green | AF48: Green | AG48: 0 | AH48: 0 | AI48: 0 | AK48: 0 | AL48: F | AN48: F | AO48: F | AP48: F | AR48: 0 | AS48: 0 | AT48: 0 | AU48: 0 | AV48: 2.205 | AW48: 2.864 | AX48: K | AY48: 0 | AZ48: 0 | BA48: BE | BB48: 0 | BC48: 0 | BD48: 0 | CH48: 2.5345 | CJ48: No | CL48: 1.8920545 | CM48: 3.1 | CN48: 2.4960272 | CO48: -0.3 | CP48: 2.1960272 | CQ48: 0 | CR48: 0.0040850953 | CS48: 0
A49: 384 | B49: DB1-DE | C49: DEUTSCHE BOERSE AG | D49: DE0005810055 | E49: XETR | F49: 188300000 | G49: 246.4 | H49: EUR | I49: 46397120000 | J49: EU500;EZ300 | K49: 64953417 | L49: 1 | M49: 46397120000 | N49: 271.1 | O49: 1 | P49: 5.104813e+10 | Q49: 271.1 | R49: 30202015 | S49: 3020 | T49: 1.7390817 | V49: B | W49: Green | X49: 0 | Y49: 0 | Z49: Green | AA49: Green | AB49: Green | AC49: Green | AD49: Green | AE49: Green | AF49: Green | AG49: 0 | AH49: 0 | AI49: 0 | AK49: 0 | AL49: F | AN49: F | AO49: F | AP49: F | AR49: 0 | AS49: 0 | AT49: 0 | AU49: 0 | AV49: 2.382 | AW49: 3.231 | AX49: K | AY49: 0 | AZ49: 0 | BA49: DE | BB49: 0 | BC49: 0 | BD49: 0 | CH49: 2.8065 | CJ49: No | CL49: 1.7390817 | CM49: 3.1 | CN49: 2.4195408 | CO49: -0.18 | CP49: 2.2395408 | CQ49: 0 | CR49: 0.039182796 | CS49: 0.00021074519
A50: 806 | B50: LSEG-GB | C50: LONDON STOCK EXCHANG | D50: GB00B0SWJX34 | E50: XLON | F50: 531451840 | G50: 140.0561 | H50: GBX | I50: 7.4433072e+10 | J50: EU500 | K50: 76651155 | L50: 0.95 | M50: 7.0711418e+10 | N50: 11390 | O50: 0.01169249 | P50: 6.7238536e+10 | Q50: 133.17746 | R50: 30201030 | S50: 3020 | T50: 1.9964408 | V50: A- | W50: Green | X50: 0 | Y50: 0 | Z50: Green | AA50: Green | AB50: Green | AC50: Green | AD50: Green | AE50: Green | AF50: Green | AG50: 0 | AH50: 0 | AI50: 0 | AK50: 0 | AL50: F | AN50: F | AO50: F | AP50: F | AR50: 0 | AS50: 0 | AT50: 0 | AU50: 0 | AV50: 2.301 | AW50: 3.03 | AX50: K | AY50: 0 | AZ50: 0 | BA50: GB | BB50: 0 | BC50: 0 | BD50: 0 | CH50: 2.6655 | CJ50: No | CL50: 1.9964408 | CM50: 3.1 | CN50: 2.5482204 | CO50: -0.24 | CP50: 2.3082204 | CQ50: 0 | CR50: 0.048939138 | CS50: 0.0029484444
A51: 660 | B51: ICG-GB | C51: INTERMEDIATE CAPITAL | D51: GB00BYT1DJ19 | E51: XLON | F51: 290636470 | G51: 28.9421 | H51: GBX | I51: 8.4116298e+09 | J51: EU500 | K51: 15022769 | L51: 1 | M51: 8.4116298e+09 | N51: 1816 | O51: 0.01169249 | P51: 6.1712475e+09 | Q51: 21.233562 | R51: 30202010 | S51: 3020 | T51: 1.9965142 | V51: A- | W51: Green | X51: 0 | Y51: 0 | Z51: Green | AA51: Green | AB51: Green | AC51: Green | AD51: Green | AE51: Green | AF51: Green | AG51: 0 | AH51: 0 | AI51: 0 | AK51: 0 | AL51: F | AN51: F | AO51: F | AP51: F | AR51: 0 | AS51: 0 | AT51: 0 | AU51: 0 | AV51: 2.117 | AW51: 2.916 | AX51: K | AY51: 0 | AZ51: 0 | BA51: GB | BB51: 0 | BC51: 0 | BD51: 0 | CH51: 2.5165 | CJ51: No | CL51: 1.9965142 | CM51: 3.1 | CN51: 2.5482571 | CO51: -0.24 | CP51: 2.3082571 | CQ51: 0 | CR51: 0.0068879882 | CS51: 0
A52: 470 | B52: ENX-FR | C52: EURONEXT | D52: NL0006294274 | E52: XPAR | F52: 104235507 | G52: 119 | H52: EUR | I52: 12404025333 | J52: EU500;EZ300 | K52: 23304183 | L52: 0.75 | M52: 9.303019e+09 | N52: 138 | O52: 1 | P52: 1.0788375e+10 | Q52: 138 | R52: 30202015 | S52: 3020 | T52: 1.9783808 | U52: 3.1 | V52: B | W52: Green | X52: 0 | Y52: 0 | Z52: Green | AA52: Green | AB52: Green | AC52: Green | AD52: Green | AE52: Green | AF52: Green | AG52: 0 | AH52: 0 | AI52: 0 | AK52: 0 | AL52: F | AN52: F | AO52: F | AP52: F | AR52: 0 | AS52: 0 | AT52: 0 | AU52: 0 | AV52: 2.37 | AW52: 3.108 | AX52: K | AY52: 0 | AZ52: 0 | BA52: NL | BB52: 0 | BC52: 0 | BD52: 0 | CH52: 2.739 | CJ52: No | CL52: 1.9783808 | CM52: 3.1 | CN52: 2.5391904 | CO52: -0.18 | CP52: 2.3591904 | CQ52: 0 | CR52: 0.011153918 | CS52: 0
...

Sheet Sheet2
A1: Date | B1: Name | C1: ISIN Code | D1: MIC | E1: Weight Initial universe | F1: Weight Index | G1: Subsector Code | H1: GAFI Black List | I1: GAFI Grey List | J1: Countries non fiscally cooperative with EU | K1: Subsectors | L1: UNGC controversies | M1: Tobacco Production | N1: Tobacco Distribution | O1: Biological weapons | P1: Chemical weapons | Q1: Nuclear weapons | R1: Nuclear non-NPT weapons | S1: Cluster munitions | T1: Depleted uranium | U1: AP mines | V1: Coal mining | W1: Fossil fuel | X1: Power generation | Y1: Shale oil gas involvement | Z1: Arctic drilling involvement | AA1: Deepwater drilling involvement | AB1: Hydraulic Fracturing involvement | AC1: Coal mining expansion involvement | AD1: Oil gas extraction involvement | AE1: Other fossil fuel involvement | AF1: Nuclear power involvement | AG1: Nuclear power revenue | AH1: Nuclear power uranium | AI1: Civilian firearms | AJ1: Military equipment | AK1: EU Taxonomy pocket | AL1: Worst 10% avg soc gov score | AM1: Climate Score | AN1: Final Selection | AO1: Carbon Intensity (ISS) | AP1: Temperate score from ISS
A2: 45709 | B2: ALSTOM | C2: FR0010220475 | D2: XPAR | E2: =_xlfn.XLOOKUP(C2,[2]generation_steps!$I$2:$I$500,[2]generation_steps!$L$2:$L$500) -> 0.00066478048 | F2: =_xlfn.XLOOKUP(C2,[2]full_dataframe_final!$C$2:$C$101,[2]full_dataframe_final!$H$2:$H$101,"") -> 0.013739746 | G2: 50202010 | H2: =ISBLANK('Full Universe'!BE36) -> TRUE | I2: =ISBLANK('Full Universe'!BF36) -> TRUE | J2: =ISBLANK('Full Universe'!BG36) -> TRUE | K2: =ISBLANK('Full Universe'!BH36) -> TRUE | L2: =ISBLANK('Full Universe'!BI36) -> TRUE | M2: =ISBLANK('Full Universe'!BJ36) -> TRUE | N2: =ISBLANK('Full Universe'!BK36) -> TRUE | O2: =ISBLANK('Full Universe'!BL36) -> TRUE | ... AJ2: =ISBLANK('Full Universe'!CG36) -> TRUE | AK2: =ISNUMBER(MATCH(C2,[1]Europe!$B$2:$B$15,0)) -> TRUE | AL2: =ISBLANK('Full Universe'!CJ36) -> TRUE | AM2: Green - not applicable | AN2: =ISNUMBER(MATCH(C2,'Selected Companies'!$D$2:$D$101,0)) -> TRUE | AO2: =_xlfn.XLOOKUP(C2,[2]generation_steps!$C$2:$C$18963,[2]generation_steps!$CM$2:$CM$18963) -> 3285.23 | AP2: =_xlfn.XLOOKUP(C2,[2]generation_steps!$C$2:$C$18963,[2]generation_steps!$CN$2:$CN$18963) -> 1.6
A3: 45709 | B3: CASTELLUM AB | C3: SE0000379190 | D3: XSTO | E3: =_xlfn.XLOOKUP(C3,[2]generation_steps!$I$2:$I$500,[2]generation_steps!$L$2:$L$500) -> 0.00043160883 | F3: =_xlfn.XLOOKUP(C3,[2]full_dataframe_final!$C$2:$C$101,[2]full_dataframe_final!$H$2:$H$101,"") -> 0.0035714286 | G3: 35101010 | H3: =ISBLANK('Full Universe'!BE118) -> TRUE | I3: =ISBLANK('Full Universe'!BF118) -> TRUE | J3: =ISBLANK('Full Universe'!BG118) -> TRUE | K3: =ISBLANK('Full Universe'!BH118) -> TRUE | L3: =ISBLANK('Full Universe'!BI118) -> TRUE | M3: =ISBLANK('Full Universe'!BJ118) -> TRUE | N3: =ISBLANK('Full Universe'!BK118) -> TRUE | O3: =ISBLANK('Full Universe'!BL118) -> TRUE | ... AJ3: =ISBLANK('Full Universe'!CG118) -> TRUE | AK3: =ISNUMBER(MATCH(C3,[1]Europe!$B$2:$B$15,0)) -> TRUE | AL3: =ISBLANK('Full Universe'!CJ118) -> TRUE | AM3: Green - not applicable | AN3: =ISNUMBER(MATCH(C3,'Selected Companies'!$D$2:$D$101,0)) -> TRUE | AO3: =_xlfn.XLOOKUP(C3,[2]generation_steps!$C$2:$C$18963,[2]generation_steps!$CM$2:$CM$18963) -> 6.9595815 | AP3: =_xlfn.XLOOKUP(C3,[2]generation_steps!$C$2:$C$18963,[2]generation_steps!$CN$2:$CN$18963) -> 1.4333333
A4: 45709 | B4: DASSAULT SYSTEMES | C4: FR0014003TT8 | D4: XPAR | E4: =_xlfn.XLOOKUP(C4,[2]generation_steps!$I$2:$I$500,[2]generation_steps!$L$2:$L$500) -> 0.0021695415 | F4: =_xlfn.XLOOKUP(C4,[2]full_dataframe_final!$C$2:$C$101,[2]full_dataframe_final!$H$2:$H$101,"") -> 0.0035714286 | G4: 10101015 | H4: =ISBLANK('Full Universe'!BE139) -> TRUE | I4: =ISBLANK('Full Universe'!BF139) -> TRUE | J4: =ISBLANK('Full Universe'!BG139) -> TRUE | K4: =ISBLANK('Full Universe'!BH139) -> TRUE | L4: =ISBLANK('Full Universe'!BI139) -> TRUE | M4: =ISBLANK('Full Universe'!BJ139) -> TRUE | N4: =ISBLANK('Full Universe'!BK139) -> TRUE | O4: =ISBLANK('Full Universe'!BL139) -> TRUE | ... AJ4: =ISBLANK('Full Universe'!CG139) -> TRUE | AK4: =ISNUMBER(MATCH(C4,[1]Europe!$B$2:$B$15,0)) -> TRUE | AL4: =ISBLANK('Full Universe'!CJ139) -> TRUE | AM4: Green - not applicable | AN4: =ISNUMBER(MATCH(C4,'Selected Companies'!$D$2:$D$101,0)) -> TRUE | AO4: =_xlfn.XLOOKUP(C4,[2]generation_steps!$C$2:$C$18963,[2]generation_steps!$CM$2:$CM$18963) -> 10.868427 | AP4: =_xlfn.XLOOKUP(C4,[2]generation_steps!$C$2:$C$18963,[2]generation_steps!$CN$2:$CN$18963) -> 1.4666667
A5: 45709 | B5: INPOST | C5: LU2290522684 | D5: XAMS | E5: =_xlfn.XLOOKUP(C5,[2]generation_steps!$I$2:$I$500,[2]generation_steps!$L$2:$L$500) -> 0.00025556358 | F5: =_xlfn.XLOOKUP(C5,[2]full_dataframe_final!$C$2:$C$101,[2]full_dataframe_final!$H$2:$H$101,"") -> 0.0068292552 | G5: 50206040 | H5: =ISBLANK('Full Universe'!BE243) -> TRUE | I5: =ISBLANK('Full Universe'!BF243) -> TRUE | J5: =ISBLANK('Full Universe'!BG243) -> TRUE | K5: =ISBLANK('Full Universe'!BH243) -> TRUE | L5: =ISBLANK('Full Universe'!BI243) -> TRUE | M5: =ISBLANK('Full Universe'!BJ243) -> TRUE | N5: =ISBLANK('Full Universe'!BK243) -> TRUE | O5: =ISBLANK('Full Universe'!BL243) -> TRUE | ... AJ5: =ISBLANK('Full Universe'!CG243) -> TRUE | AK5: =ISNUMBER(MATCH(C5,[1]Europe!$B$2:$B$15,0)) -> TRUE | AL5: =ISBLANK('Full Universe'!CJ243) -> TRUE | AM5: Green - not applicable | AN5: =ISNUMBER(MATCH(C5,'Selected Companies'!$D$2:$D$101,0)) -> TRUE | AO5: =_xlfn.XLOOKUP(C5,[2]generation_steps!$C$2:$C$18963,[2]generation_steps!$CM$2:$CM$18963) -> 65.872922 | AP5: =_xlfn.XLOOKUP(C5,[2]generation_steps!$C$2:$C$18963,[2]generation_steps!$CN$2:$CN$18963) -> 1.7
A6: 45709 | B6: KINGSPAN GROUP PLC | C6: IE0004927939 | D6: XMSM | E6: =_xlfn.XLOOKUP(C6,[2]generation_steps!$I$2:$I$500,[2]generation_steps!$L$2:$L$500) -> 0.0011122871 | F6: =_xlfn.XLOOKUP(C6,[2]full_dataframe_final!$C$2:$C$101,[2]full_dataframe_final!$H$2:$H$101,"") -> 0.0035714286 | G6: 50101035 | H6: =ISBLANK('Full Universe'!BE267) -> TRUE | I6: =ISBLANK('Full Universe'!BF267) -> TRUE | J6: =ISBLANK('Full Universe'!BG267) -> TRUE | K6: =ISBLANK('Full Universe'!BH267) -> TRUE | L6: =ISBLANK('Full Universe'!BI267) -> TRUE | M6: =ISBLANK('Full Universe'!BJ267) -> TRUE | N6: =ISBLANK('Full Universe'!BK267) -> TRUE | O6: =ISBLANK('Full Universe'!BL267) -> TRUE | ... AJ6: =ISBLANK('Full Universe'!CG267) -> TRUE | AK6: =ISNUMBER(MATCH(C6,[1]Europe!$B$2:$B$15,0)) -> TRUE | AL6: =ISBLANK('Full Universe'!CJ267) -> TRUE | AM6: Green - not applicable | AN6: =ISNUMBER(MATCH(C6,'Selected Companies'!$D$2:$D$101,0)) -> TRUE | AO6: =_xlfn.XLOOKUP(C6,[2]generation_steps!$C$2:$C$18963,[2]generation_steps!$CM$2:$CM$18963) -> 429.69418 | AP6: =_xlfn.XLOOKUP(C6,[2]generation_steps!$C$2:$C$18963,[2]generation_steps!$CN$2:$CN$18963) -> 1.5666667
A7: 45709 | B7: KNORR-BREMSE AG | C7: DE000KBX1006 | D7: XETR | E7: =_xlfn.XLOOKUP(C7,[2]generation_steps!$I$2:$I$500,[2]generation_steps!$L$2:$L$500) -> 0.00050639091 | F7: =_xlfn.XLOOKUP(C7,[2]full_dataframe_final!$C$2:$C$101,[2]full_dataframe_final!$H$2:$H$101,"") -> 0.0035714286 | G7: 50206025 | H7: =ISBLANK('Full Universe'!BE269) -> TRUE | I7: =ISBLANK('Full Universe'!BF269) -> TRUE | J7: =ISBLANK('Full Universe'!BG269) -> TRUE | K7: =ISBLANK('Full Universe'!BH269) -> TRUE | L7: =ISBLANK('Full Universe'!BI269) -> TRUE | M7: =ISBLANK('Full Universe'!BJ269) -> TRUE | N7: =ISBLANK('Full Universe'!BK269) -> TRUE | O7: =ISBLANK('Full Universe'!BL269) -> TRUE | ... AJ7: =ISBLANK('Full Universe'!CG269) -> TRUE | AK7: =ISNUMBER(MATCH(C7,[1]Europe!$B$2:$B$15,0)) -> TRUE | AL7: =ISBLANK('Full Universe'!CJ269) -> TRUE | AM7: Green - not applicable | AN7: =ISNUMBER(MATCH(C7,'Selected Companies'!$D$2:$D$101,0)) -> TRUE | AO7: =_xlfn.XLOOKUP(C7,[2]generation_steps!$C$2:$C$18963,[2]generation_steps!$CM$2:$CM$18963) -> 3428.5625 | AP7: =_xlfn.XLOOKUP(C7,[2]generation_steps!$C$2:$C$18963,[2]generation_steps!$CN$2:$CN$18963) -> 3.0333333
A8: 45709 | B8: METSO CORPORATION | C8: FI0009014575 | D8: XHEL | E8: =_xlfn.XLOOKUP(C8,[2]generation_steps!$I$2:$I$500,[2]generation_steps!$L$2:$L$500) -> 0.00058872335 | F8: =_xlfn.XLOOKUP(C8,[2]full_dataframe_final!$C$2:$C$101,[2]full_dataframe_final!$H$2:$H$101,"") -> 0.012252098 | G8: 50204020 | H8: =ISBLANK('Full Universe'!BE302) -> TRUE | I8: =ISBLANK('Full Universe'!BF302) -> TRUE | J8: =ISBLANK('Full Universe'!BG302) -> TRUE | K8: =ISBLANK('Full Universe'!BH302) -> TRUE | L8: =ISBLANK('Full Universe'!BI302) -> TRUE | M8: =ISBLANK('Full Universe'!BJ302) -> TRUE | N8: =ISBLANK('Full Universe'!BK302) -> TRUE | O8: =ISBLANK('Full Universe'!BL302) -> TRUE | ... AJ8: =ISBLANK('Full Universe'!CG302) -> TRUE | AK8: =ISNUMBER(MATCH(C8,[1]Europe!$B$2:$B$15,0)) -> TRUE | AL8: =ISBLANK('Full Universe'!CJ302) -> TRUE | AM8: Green - not applicable | AN8: =ISNUMBER(MATCH(C8,'Selected Companies'!$D$2:$D$101,0)) -> TRUE | AO8: =_xlfn.XLOOKUP(C8,[2]generation_steps!$C$2:$C$18963,[2]generation_steps!$CM$2:$CM$18963) -> 447.68354 | AP8: =_xlfn.XLOOKUP(C8,[2]generation_steps!$C$2:$C$18963,[2]generation_steps!$CN$2:$CN$18963) -> 1.5333333
A9: 45709 | B9: NORSK HYDRO | C9: NO0005052605 | D9: XOSL | E9: =_xlfn.XLOOKUP(C9,[2]generation_steps!$I$2:$I$500,[2]generation_steps!$L$2:$L$500) -> 0.00056823472 | F9: =_xlfn.XLOOKUP(C9,[2]full_dataframe_final!$C$2:$C$101,[2]full_dataframe_final!$H$2:$H$101,"") -> 0.0035714286 | G9: 55102035 | H9: =ISBLANK('Full Universe'!BE324) -> TRUE | I9: =ISBLANK('Full Universe'!BF324) -> TRUE | J9: =ISBLANK('Full Universe'!BG324) -> TRUE | K9: =ISBLANK('Full Universe'!BH324) -> TRUE | L9: =ISBLANK('Full Universe'!BI324) -> TRUE | M9: =ISBLANK('Full Universe'!BJ324) -> TRUE | N9: =ISBLANK('Full Universe'!BK324) -> TRUE | O9: =ISBLANK('Full Universe'!BL324) -> TRUE | ... AJ9: =ISBLANK('Full Universe'!CG324) -> TRUE | AK9: =ISNUMBER(MATCH(C9,[1]Europe!$B$2:$B$15,0)) -> TRUE | AL9: =ISBLANK('Full Universe'!CJ324) -> TRUE | AM9: Green - not applicable | AN9: =ISNUMBER(MATCH(C9,'Selected Companies'!$D$2:$D$101,0)) -> TRUE | AO9: =_xlfn.XLOOKUP(C9,[2]generation_steps!$C$2:$C$18963,[2]generation_steps!$CM$2:$CM$18963) -> 1406.9401 | AP9: =_xlfn.XLOOKUP(C9,[2]generation_steps!$C$2:$C$18963,[2]generation_steps!$CN$2:$CN$18963) -> 1.5
A10: 45709 | B10: REDEIA CORP | C10: ES0173093024 | D10: XMAD | E10: =_xlfn.XLOOKUP(C10,[2]generation_steps!$I$2:$I$500,[2]generation_steps!$L$2:$L$500) -> 0.00074840834 | F10: =_xlfn.XLOOKUP(C10,[2]full_dataframe_final!$C$2:$C$101,[2]full_dataframe_final!$H$2:$H$101,"") -> 0.010036043 | G10: 65101015 | H10: =ISBLANK('Full Universe'!BE355) -> TRUE | I10: =ISBLANK('Full Universe'!BF355) -> TRUE | J10: =ISBLANK('Full Universe'!BG355) -> TRUE | K10: =ISBLANK('Full Universe'!BH355) -> TRUE | L10: =ISBLANK('Full Universe'!BI355) -> TRUE | M10: =ISBLANK('Full Universe'!BJ355) -> TRUE | N10: =ISBLANK('Full Universe'!BK355) -> TRUE | O10: =ISBLANK('Full Universe'!BL355) -> TRUE | ... AJ10: =ISBLANK('Full Universe'!CG355) -> TRUE | AK10: =ISNUMBER(MATCH(C10,[1]Europe!$B$2:$B$15,0)) -> TRUE | AL10: =ISBLANK('Full Universe'!CJ355) -> TRUE | AM10: Green - not applicable | AN10: =ISNUMBER(MATCH(C10,'Selected Companies'!$D$2:$D$101,0)) -> TRUE | AO10: =_xlfn.XLOOKUP(C10,[2]generation_steps!$C$2:$C$18963,[2]generation_steps!$CM$2:$CM$18963) -> 95.988242 | AP10: =_xlfn.XLOOKUP(C10,[2]generation_steps!$C$2:$C$18963,[2]generation_steps!$CN$2:$CN$18963) -> 1.6333333
A11: 45709 | B11: ROCKWOOL B | C11: DK0063855168 | D11: XCSE | E11: =_xlfn.XLOOKUP(C11,[2]generation_steps!$I$2:$I$500,[2]generation_steps!$L$2:$L$500) -> 0.00036506021 | F11: =_xlfn.XLOOKUP(C11,[2]full_dataframe_final!$C$2:$C$101,[2]full_dataframe_final!$H$2:$H$101,"") -> 0.0035714286 | G11: 50101035 | H11: =ISBLANK('Full Universe'!BE367) -> TRUE | I11: =ISBLANK('Full Universe'!BF367) -> TRUE | J11: =ISBLANK('Full Universe'!BG367) -> TRUE | K11: =ISBLANK('Full Universe'!BH367) -> TRUE | L11: =ISBLANK('Full Universe'!BI367) -> TRUE | M11: =ISBLANK('Full Universe'!BJ367) -> TRUE | N11: =ISBLANK('Full Universe'!BK367) -> TRUE | O11: =ISBLANK('Full Universe'!BL367) -> TRUE | ... AJ11: =ISBLANK('Full Universe'!CG367) -> TRUE | AK11: =ISNUMBER(MATCH(C11,[1]Europe!$B$2:$B$15,0)) -> TRUE | AL11: =ISBLANK('Full Universe'!CJ367) -> TRUE | AM11: Green - not applicable | AN11: =ISNUMBER(MATCH(C11,'Selected Companies'!$D$2:$D$101,0)) -> TRUE | AO11: =_xlfn.XLOOKUP(C11,[2]generation_steps!$C$2:$C$18963,[2]generation_steps!$CM$2:$CM$18963) -> 46.694402 | AP11: =_xlfn.XLOOKUP(C11,[2]generation_steps!$C$2:$C$18963,[2]generation_steps!$CN$2:$CN$18963) -> 1.5
A12: 45709 | B12: SEVERN TRENT | C12: GB00B1FH8J72 | D12: XLON | E12: =_xlfn.XLOOKUP(C12,[2]generation_steps!$I$2:$I$500,[2]generation_steps!$L$2:$L$500) -> 0.00082416423 | F12: =_xlfn.XLOOKUP(C12,[2]full_dataframe_final!$C$2:$C$101,[2]full_dataframe_final!$H$2:$H$101,"") -> 0.014285714 | G12: 65102030 | H12: =ISBLANK('Full Universe'!BE396) -> TRUE | I12: =ISBLANK('Full Universe'!BF396) -> TRUE | J12: =ISBLANK('Full Universe'!BG396) -> TRUE | K12: =ISBLANK('Full Universe'!BH396) -> TRUE | L12: =ISBLANK('Full Universe'!BI396) -> TRUE | M12: =ISBLANK('Full Universe'!BJ396) -> TRUE | N12: =ISBLANK('Full Universe'!BK396) -> TRUE | O12: =ISBLANK('Full Universe'!BL396) -> TRUE | ... AJ12: =ISBLANK('Full Universe'!CG396) -> TRUE | AK12: =ISNUMBER(MATCH(C12,[1]Europe!$B$2:$B$15,0)) -> TRUE | AL12: =ISBLANK('Full Universe'!CJ396) -> TRUE | AM12: Green - not applicable | AN12: =ISNUMBER(MATCH(C12,'Selected Companies'!$D$2:$D$101,0)) -> TRUE | AO12: =_xlfn.XLOOKUP(C12,[2]generation_steps!$C$2:$C$18963,[2]generation_steps!$CM$2:$CM$18963) -> 59.179045 | AP12: =_xlfn.XLOOKUP(C12,[2]generation_steps!$C$2:$C$18963,[2]generation_steps!$CN$2:$CN$18963) -> 1.5
A13: 45709 | B13: TERNA | C13: IT0003242622 | D13: MTAA | E13: =_xlfn.XLOOKUP(C13,[2]generation_steps!$I$2:$I$500,[2]generation_steps!$L$2:$L$500) -> 0.0011336724 | F13: =_xlfn.XLOOKUP(C13,[2]full_dataframe_final!$C$2:$C$101,[2]full_dataframe_final!$H$2:$H$101,"") -> 0.0035714286 | G13: 65101015 | H13: =ISBLANK('Full Universe'!BE457) -> TRUE | I13: =ISBLANK('Full Universe'!BF457) -> TRUE | J13: =ISBLANK('Full Universe'!BG457) -> TRUE | K13: =ISBLANK('Full Universe'!BH457) -> TRUE | L13: =ISBLANK('Full Universe'!BI457) -> TRUE | M13: =ISBLANK('Full Universe'!BJ457) -> TRUE | N13: =ISBLANK('Full Universe'!BK457) -> TRUE | O13: =ISBLANK('Full Universe'!BL457) -> TRUE | ... AJ13: =ISBLANK('Full Universe'!CG457) -> TRUE | AK13: =ISNUMBER(MATCH(C13,[1]Europe!$B$2:$B$15,0)) -> TRUE | AL13: =ISBLANK('Full Universe'!CJ457) -> TRUE | AM13: Green - not applicable | AN13: =ISNUMBER(MATCH(C13,'Selected Companies'!$D$2:$D$101,0)) -> TRUE | AO13: =_xlfn.XLOOKUP(C13,[2]generation_steps!$C$2:$C$18963,[2]generation_steps!$CM$2:$CM$18963) -> 134.74022 | AP13: =_xlfn.XLOOKUP(C13,[2]generation_steps!$C$2:$C$18963,[2]generation_steps!$CN$2:$CN$18963) -> 1.5
A14: 45709 | B14: VESTAS WIND SYSTEMS | C14: DK0061539921 | D14: XCSE | E14: =_xlfn.XLOOKUP(C14,[2]generation_steps!$I$2:$I$500,[2]generation_steps!$L$2:$L$500) -> 0.0011846538 | F14: =_xlfn.XLOOKUP(C14,[2]full_dataframe_final!$C$2:$C$101,[2]full_dataframe_final!$H$2:$H$101,"") -> 0.014285714 | G14: 60102020 | H14: =ISBLANK('Full Universe'!BE483) -> TRUE | I14: =ISBLANK('Full Universe'!BF483) -> TRUE | J14: =ISBLANK('Full Universe'!BG483) -> TRUE | K14: =ISBLANK('Full Universe'!BH483) -> TRUE | L14: =ISBLANK('Full Universe'!BI483) -> TRUE | M14: =ISBLANK('Full Universe'!BJ483) -> TRUE | N14: =ISBLANK('Full Universe'!BK483) -> TRUE | O14: =ISBLANK('Full Universe'!BL483) -> TRUE | ... AJ14: =ISBLANK('Full Universe'!CG483) -> TRUE | AK14: =ISNUMBER(MATCH(C14,[1]Europe!$B$2:$B$15,0)) -> TRUE | AL14: =ISBLANK('Full Universe'!CJ483) -> TRUE | AM14: Green - not applicable | AN14: =ISNUMBER(MATCH(C14,'Selected Companies'!$D$2:$D$101,0)) -> TRUE | AO14: =_xlfn.XLOOKUP(C14,[2]generation_steps!$C$2:$C$18963,[2]generation_steps!$CM$2:$CM$18963) -> 239.55135 | AP14: =_xlfn.XLOOKUP(C14,[2]generation_steps!$C$2:$C$18963,[2]generation_steps!$CN$2:$CN$18963) -> 1.4666667
A15: 45709 | B15: WIENERBERGER AG | C15: AT0000831706 | D15: WBAH | E15: =_xlfn.XLOOKUP(C15,[2]generation_steps!$I$2:$I$500,[2]generation_steps!$L$2:$L$500) -> 0.00032723448 | F15: =_xlfn.XLOOKUP(C15,[2]full_dataframe_final!$C$2:$C$101,[2]full_dataframe_final!$H$2:$H$101,"") -> 0.0035714286 | G15: 50101035 | H15: =ISBLANK('Full Universe'!BE493) -> TRUE | I15: =ISBLANK('Full Universe'!BF493) -> TRUE | J15: =ISBLANK('Full Universe'!BG493) -> TRUE | K15: =ISBLANK('Full Universe'!BH493) -> TRUE | L15: =ISBLANK('Full Universe'!BI493) -> TRUE | M15: =ISBLANK('Full Universe'!BJ493) -> TRUE | N15: =ISBLANK('Full Universe'!BK493) -> TRUE | O15: =ISBLANK('Full Universe'!BL493) -> TRUE | ... AJ15: =ISBLANK('Full Universe'!CG493) -> TRUE | AK15: =ISNUMBER(MATCH(C15,[1]Europe!$B$2:$B$15,0)) -> TRUE | AL15: =ISBLANK('Full Universe'!CJ493) -> TRUE | AM15: Green - not applicable | AN15: =ISNUMBER(MATCH(C15,'Selected Companies'!$D$2:$D$101,0)) -> TRUE | AO15: =_xlfn.XLOOKUP(C15,[2]generation_steps!$C$2:$C$18963,[2]generation_steps!$CM$2:$CM$18963) -> 1738.1272 | AP15: =_xlfn.XLOOKUP(C15,[2]generation_steps!$C$2:$C$18963,[2]generation_steps!$CN$2:$CN$18963) -> 1.5333333
A16: 45709 | B16: 3I GROUP PLC | C16: GB00B1YW4409 | D16: XLON | E16: =_xlfn.XLOOKUP(C16,[2]generation_steps!$I$2:$I$500,[2]generation_steps!$L$2:$L$500) -> 0.0045434353 | F16: =_xlfn.XLOOKUP(C16,[2]full_dataframe_final!$C$2:$C$101,[2]full_dataframe_final!$H$2:$H$101,"") | G16: 30202010 | H16: =ISBLANK('Full Universe'!BE2) -> TRUE | I16: =ISBLANK('Full Universe'!BF2) -> TRUE | J16: =ISBLANK('Full Universe'!BG2) -> TRUE | K16: =ISBLANK('Full Universe'!BH2) -> TRUE | L16: =ISBLANK('Full Universe'!BI2) -> TRUE | M16: =ISBLANK('Full Universe'!BJ2) -> TRUE | N16: =ISBLANK('Full Universe'!BK2) -> TRUE | O16: =ISBLANK('Full Universe'!BL2) -> TRUE | ... AJ16: =ISBLANK('Full Universe'!CG2) -> TRUE | AK16: =ISNUMBER(MATCH(C16,[1]Europe!$B$2:$B$15,0)) -> FALSE | AL16: =ISBLANK('Full Universe'!CJ2) -> TRUE | AM16: 1.9270395 | AN16: =ISNUMBER(MATCH(C16,'Selected Companies'!$D$2:$D$101,0)) -> FALSE | AO16: =_xlfn.XLOOKUP(C16,[2]generation_steps!$C$2:$C$18963,[2]generation_steps!$CM$2:$CM$18963) -> 13.164173 | AP16: =_xlfn.XLOOKUP(C16,[2]generation_steps!$C$2:$C$18963,[2]generation_steps!$CN$2:$CN$18963) -> 1.5333333
A17: 45709 | B17: A2A | C17: IT0001233417 | D17: MTAA | E17: =_xlfn.XLOOKUP(C17,[2]generation_steps!$I$2:$I$500,[2]generation_steps!$L$2:$L$500) -> 0.00031493296 | F17: =_xlfn.XLOOKUP(C17,[2]full_dataframe_final!$C$2:$C$101,[2]full_dataframe_final!$H$2:$H$101,"") | G17: 65101015 | H17: =ISBLANK('Full Universe'!BE3) -> TRUE | I17: =ISBLANK('Full Universe'!BF3) -> TRUE | J17: =ISBLANK('Full Universe'!BG3) -> TRUE | K17: =ISBLANK('Full Universe'!BH3) -> TRUE | L17: =ISBLANK('Full Universe'!BI3) -> TRUE | M17: =ISBLANK('Full Universe'!BJ3) -> TRUE | N17: =ISBLANK('Full Universe'!BK3) -> TRUE | O17: =ISBLANK('Full Universe'!BL3) -> TRUE | ... AJ17: =ISBLANK('Full Universe'!CG3) -> TRUE | AK17: =ISNUMBER(MATCH(C17,[1]Europe!$B$2:$B$15,0)) -> FALSE | AL17: =ISBLANK('Full Universe'!CJ3) -> TRUE | AM17: 2.225 | AN17: =ISNUMBER(MATCH(C17,'Selected Companies'!$D$2:$D$101,0)) -> FALSE | AO17: =_xlfn.XLOOKUP(C17,[2]generation_steps!$C$2:$C$18963,[2]generation_steps!$CM$2:$CM$18963) -> 1181.0697 | AP17: =_xlfn.XLOOKUP(C17,[2]generation_steps!$C$2:$C$18963,[2]generation_steps!$CN$2:$CN$18963) -> 1.5
A18: 45709 | B18: AAK AB | C18: SE0011337708 | D18: XSTO | E18: =_xlfn.XLOOKUP(C18,[2]generation_steps!$I$2:$I$500,[2]generation_steps!$L$2:$L$500) -> 0.00043166138 | F18: =_xlfn.XLOOKUP(C18,[2]full_dataframe_final!$C$2:$C$101,[2]full_dataframe_final!$H$2:$H$101,"") | G18: 45102020 | H18: =ISBLANK('Full Universe'!BE4) -> TRUE | I18: =ISBLANK('Full Universe'!BF4) -> TRUE | J18: =ISBLANK('Full Universe'!BG4) -> TRUE | K18: =ISBLANK('Full Universe'!BH4) -> TRUE | L18: =ISBLANK('Full Universe'!BI4) -> TRUE | M18: =ISBLANK('Full Universe'!BJ4) -> TRUE | N18: =ISBLANK('Full Universe'!BK4) -> TRUE | O18: =ISBLANK('Full Universe'!BL4) -> TRUE | ... AJ18: =ISBLANK('Full Universe'!CG4) -> TRUE | AK18: =ISNUMBER(MATCH(C18,[1]Europe!$B$2:$B$15,0)) -> FALSE | AL18: =ISBLANK('Full Universe'!CJ4) -> TRUE | AM18: 2.5321528 | AN18: =ISNUMBER(MATCH(C18,'Selected Companies'!$D$2:$D$101,0)) -> FALSE | AO18: =_xlfn.XLOOKUP(C18,[2]generation_steps!$C$2:$C$18963,[2]generation_steps!$CM$2:$CM$18963) -> 1223.803 | AP18: =_xlfn.XLOOKUP(C18,[2]generation_steps!$C$2:$C$18963,[2]generation_steps!$CN$2:$CN$18963) -> 1.5
A19: 45709 | B19: AALBERTS NV | C19: NL0000852564 | D19: XAMS | E19: =_xlfn.XLOOKUP(C19,[2]generation_steps!$I$2:$I$500,[2]generation_steps!$L$2:$L$500) -> 0.0002618455 | F19: =_xlfn.XLOOKUP(C19,[2]full_dataframe_final!$C$2:$C$101,[2]full_dataframe_final!$H$2:$H$101,"") | G19: 50202020 | H19: =ISBLANK('Full Universe'!BE5) -> TRUE | I19: =ISBLANK('Full Universe'!BF5) -> TRUE | J19: =ISBLANK('Full Universe'!BG5) -> TRUE | K19: =ISBLANK('Full Universe'!BH5) -> TRUE | L19: =ISBLANK('Full Universe'!BI5) -> TRUE | M19: =ISBLANK('Full Universe'!BJ5) -> TRUE | N19: =ISBLANK('Full Universe'!BK5) -> TRUE | O19: =ISBLANK('Full Universe'!BL5) -> TRUE | ... AJ19: =ISBLANK('Full Universe'!CG5) -> TRUE | AK19: =ISNUMBER(MATCH(C19,[1]Europe!$B$2:$B$15,0)) -> FALSE | AL19: =ISBLANK('Full Universe'!CJ5) -> TRUE | AM19: 3.25 | AN19: =ISNUMBER(MATCH(C19,'Selected Companies'!$D$2:$D$101,0)) -> FALSE | AO19: =_xlfn.XLOOKUP(C19,[2]generation_steps!$C$2:$C$18963,[2]generation_steps!$CM$2:$CM$18963) -> 1619.7555 | AP19: =_xlfn.XLOOKUP(C19,[2]generation_steps!$C$2:$C$18963,[2]generation_steps!$CN$2:$CN$18963) -> 1.5
A20: 45709 | B20: AB INBEV | C20: BE0974293251 | D20: XBRU | E20: =_xlfn.XLOOKUP(C20,[2]generation_steps!$I$2:$I$500,[2]generation_steps!$L$2:$L$500) -> 0.0053561082 | F20: =_xlfn.XLOOKUP(C20,[2]full_dataframe_final!$C$2:$C$101,[2]full_dataframe_final!$H$2:$H$101,"") | G20: 45101010 | H20: =ISBLANK('Full Universe'!BE6) -> TRUE | I20: =ISBLANK('Full Universe'!BF6) -> TRUE | J20: =ISBLANK('Full Universe'!BG6) -> TRUE | K20: =ISBLANK('Full Universe'!BH6) -> TRUE | L20: =ISBLANK('Full Universe'!BI6) -> TRUE | M20: =ISBLANK('Full Universe'!BJ6) -> TRUE | N20: =ISBLANK('Full Universe'!BK6) -> TRUE | O20: =ISBLANK('Full Universe'!BL6) -> TRUE | ... AJ20: =ISBLANK('Full Universe'!CG6) -> TRUE | AK20: =ISNUMBER(MATCH(C20,[1]Europe!$B$2:$B$15,0)) -> FALSE | AL20: =ISBLANK('Full Universe'!CJ6) -> FALSE | AM20: 2.7005395 | AN20: =ISNUMBER(MATCH(C20,'Selected Companies'!$D$2:$D$101,0)) -> FALSE | AO20: =_xlfn.XLOOKUP(C20,[2]generation_steps!$C$2:$C$18963,[2]generation_steps!$CM$2:$CM$18963) -> 128.46807 | AP20: =_xlfn.XLOOKUP(C20,[2]generation_steps!$C$2:$C$18963,[2]generation_steps!$CN$2:$CN$18963) -> 1.5
A21: 45709 | B21: AB SAGAX CLASS B | C21: SE0005127818 | D21: XSTO | E21: =_xlfn.XLOOKUP(C21,[2]generation_steps!$I$2:$I$500,[2]generation_steps!$L$2:$L$500) -> 0.00040208942 | F21: =_xlfn.XLOOKUP(C21,[2]full_dataframe_final!$C$2:$C$101,[2]full_dataframe_final!$H$2:$H$101,"") | G21: 35101010 | H21: =ISBLANK('Full Universe'!BE7) -> TRUE | I21: =ISBLANK('Full Universe'!BF7) -> TRUE | J21: =ISBLANK('Full Universe'!BG7) -> TRUE | K21: =ISBLANK('Full Universe'!BH7) -> TRUE | L21: =ISBLANK('Full Universe'!BI7) -> TRUE | M21: =ISBLANK('Full Universe'!BJ7) -> TRUE | N21: =ISBLANK('Full Universe'!BK7) -> TRUE | O21: =ISBLANK('Full Universe'!BL7) -> TRUE | ... AJ21: =ISBLANK('Full Universe'!CG7) -> TRUE | AK21: =ISNUMBER(MATCH(C21,[1]Europe!$B$2:$B$15,0)) -> FALSE | AL21: =ISBLANK('Full Universe'!CJ7) -> FALSE | AM21: 3.4860513 | AN21: =ISNUMBER(MATCH(C21,'Selected Companies'!$D$2:$D$101,0)) -> FALSE | AO21: =_xlfn.XLOOKUP(C21,[2]generation_steps!$C$2:$C$18963,[2]generation_steps!$CM$2:$CM$18963) -> 3.5372492 | AP21: =_xlfn.XLOOKUP(C21,[2]generation_steps!$C$2:$C$18963,[2]generation_steps!$CN$2:$CN$18963) -> 1.4
