Workbook

Sheet Sheet1
A1: Where to find the details file:
A2: (4) Folder | Dataiku (Automation)
A3: App | Dataiku (Automation)
B4: Mnemo | C4: Name | D4: Universe | E4: Weighting Method | F4: Capping | G4: Data vendor(s) | H4: Method 2 | I4: Review Aligned on June
B5: AEXEW | C5: AEX Equal Weight | D5: AEX | E5: Equal Weight | F5: 0 | G5: 0 | H5: New Sheet | I5: 1
B6: CACEW | C6: CAC 40 Equal Weight | D6: PX1 | E6: Equal Weight | F6: 0 | G6: 0 | H6: New Sheet | I6: 1
B7: CLEW | C7: CAC Large 60 Equal Weight | D7: CACLG | E7: Equal Weight | F7: 0 | G7: 0 | H7: New Sheet | I7: 1
B8: BNEW | C8: Euronext BeNe 40 Equal Weight | D8: AEX;BEL20 | E8: Equal Weight | F8: 0 | G8: 0 | H8: New Sheet | I8: 1
B9: SBF80 | C9: SBF Top 80 EW | D9: PX4 | E9: Equal Weight | F9: 0 | G9: 0 | H9: New Sheet | I9: Lex
B10: EC1EW | C10: Euronext Core Europe 100 EW | D10: Main Markets France, Germany, Netherland, Belgium, Luxembourg | E10: Equal Weight | F10: 0 | G10: 0 | H10: New Sheet | I10: Wait for Amanda/Edwin
B11: COR3P | C11: Euronext Core Europe 30 EW | D11: Main Markets France, Germany, Netherland, Belgium, Luxembourg | E11: Equal Weight | F11: 0 | G11: 0 | H11: New Sheet | I11: Wait for Amanda/Edwin
B12: EZ40P | C12: Euronext Eurozone 40 EW | D12: EZ300 | E12: Equal Weight | F12: 0 | G12: 0 | H12: New Sheet | I12: 1
B13: EFMEP | C13: Euronext Founding Members Europe 50 EW | D13: EZ300 | E13: Equal Weight | F13: 0 | G13: 0 | H13: New Sheet | I13: 1
B14: FGINP | C14: Euronext Top 30 France Germany Industrials EW | D14: CACT | E14: Equal Weight | F14: 0 | G14: 0 | H14: New Sheet
B15: EZ15P | C15: Euronext Eurozone 150 EW | D15: EZ300 | E15: Equal Weight | F15: 0 | G15: 0 | H15: New Sheet | I15: 1
B16: EZN1P | C16: Euronext Eurozone Next 100 EW | D16: EZ300 | E16: Equal Weight | F16: 0 | G16: 0 | H16: New Sheet | I16: 1
B17: FRECP | C17: Euronext France 20-40 Challengers EW | D17: PX1 | E17: Equal Weight | F17: 0 | G17: 0 | H17: New Sheet | I17: 1
B18: FRN4P | C18: Euronext France Next 40 EW | D18: PX4 | E18: Equal Weight | F18: 0 | G18: 0 | H18: New Sheet | I18: 1
B19: FR20P | C19: Euronext France 20 EW | D19: PX1 | E19: Equal Weight | F19: 0 | G19: 0 | H19: New Sheet | I19: 1
B20: EUS5P | C20: Euronext Transatlantic 50 EW | D20: EZ300;NA500 | E20: Equal Weight | F20: 0 | G20: 0 | H20: New Sheet | I20: 1
B21: ERI5P | C21: Euronext Responsible Investment Euro 50 EW | D21: EZ300 | E21: Equal Weight | F21: 0 | G21: 0 | H21: New Sheet | I21: 1
B22: ELUXP | C22: Euronext Europe Luxury | D22: Fixed Basket | E22: Equal Weight | F22: 0 | G22: 0 | H22: New Sheet | I22: 1
B23: ESVEP | C23: Euronext Souveraineté Européenne | D23: Fixed Basket | E23: Equal Weight | F23: 0 | G23: 0 | H23: New Sheet | I23: 1
B24: BE1P | C24: Euronext Banks Eurozone Select 10 EW | D24: EZ300 | E24: Equal Weight | F24: 0 | G24: 0 | H24: New Sheet | I24: 1
B25: EIAPR | C25: EN Intelligence Artificielle PR | D25: DEUPT;EUSPT | E25: Equal Weight | F25: 0 | G25: 0 | H25: New Sheet
B26: GSFBP | C26: EN Germany Selection Fixed Basket PR | D26: Fixed Basket | E26: Equal Weight | F26: 0 | G26: 0 | H26: New Sheet | I26: Practice Index
B27: EDEFP | C27: Euronext Europe Defense Fixed Basket PR | D27: AS500;EU500;NA500;EZ300 | E27: Equal Weight | F27: 0 | G27: 0 | H27: New Sheet | I27: 1
B28: EZ60P | C28: Euronext Eurozone 60 EW | D28: EZ300 | E28: Equal Weight | F28: 0 | G28: 0 | H28: New Sheet | I28: 1
B29: ETPFB | C29: Euronext Transatlantic Pharmaceuticals Selection Fixed Basket | D29: Fixed Basket | E29: Equal Weight | F29: 0 | G29: 0 | H29: 0 | I29: 1
B30: EES2 | C30: Euronext European Sovereignty 20 EW | D30: Fixed Basket | E30: Equal Weight | F30: 0 | G30: 0 | H30: 0 | I30: Practice Index
B31: ETSEP | C31: Euronext Transatlantic Selection Fixed Basket | D31: Fixed Basket | E31: Equal Weight | F31: 0 | G31: 0 | H31: 0 | I31: Practice Index

Sheet To automate
F1: Total Indices | G1: =COUNTA($A$8:$A$300) -> 187
F2: Done | G2: =COUNTIF($F$8:$F$301,"Done") -> 36
F3: To do: | G3: =COUNTIF($F$8:$F$194,"") -> 90
F4: Moodys: | G4: =COUNTIF($F$8:$F$301,"Moodys") -> 38
F5: Other | G5: =COUNTA($A$8:$A$301)-G1 -> 0
B7: Index | C7: ISIN | D7: Name | E7: Group | F7: Done | G7: Coding Notes | H7: Significant | I7: First Review Effective Date (after close of the ... ) | J7: Cut off Date(s) (after close of the ... ) | K7: Used the following datasets
A8: 21 | B8: AEXEW | C8: QS0011159744 | D8: AEX Equal Weight | E8: CAC/AEX Equal Weight | F8: Done | H8: =ISNUMBER(MATCH(B8,'Old Sheet'!$B$2:$B$305,0)) -> TRUE | I8: Third Friday of March, June, September, December | J8: Penultimate Friday of February, May, August, November | K8: =ISNUMBER(MATCH(B8,$O$9:$O$27,0)) -> FALSE
A9: 21 | B9: CACEW | C9: QS0011159777 | D9: CAC 40 Equal Weight | E9: CAC/AEX Equal Weight | F9: Done | H9: =ISNUMBER(MATCH(B9,'Old Sheet'!$B$2:$B$305,0)) -> TRUE | I9: Third Friday of March, June, September, December | J9: Penultimate Friday of February, May, August, November | K9: =ISNUMBER(MATCH(B9,$O$9:$O$27,0)) -> FALSE
A10: 21 | B10: CLEW | C10: FR0012663292 | D10: CAC Large 60 Equal Weight | E10: CAC/AEX Equal Weight | F10: Done | H10: =ISNUMBER(MATCH(B10,'Old Sheet'!$B$2:$B$305,0)) -> TRUE | I10: Third Friday of March, June, September, December | J10: Penultimate Friday of February, May, August, November | K10: =ISNUMBER(MATCH(B10,$O$9:$O$27,0)) -> FALSE
A11: 28 | B11: BNEW | C11: NL0011376116 | D11: Euronext BeNe 40 Equal Weight | E11: Bene40 Equal Weight | F11: Done | H11: =ISNUMBER(MATCH(B11,'Old Sheet'!$B$2:$B$305,0)) -> TRUE | I11: Third Friday of March, June, September, December | J11: Penultimate Friday of February, May, August, November | K11: =ISNUMBER(MATCH(B11,$O$9:$O$27,0)) -> FALSE
A12: 29 | B12: SBF80 | C12: FR0013017936 | D12: SBF Top 80 EW | E12: SBF 80 | F12: Done | H12: =ISNUMBER(MATCH(B12,'Old Sheet'!$B$2:$B$305,0)) -> TRUE | I12: Third Friday of March, June, September, December | J12: Penultimate Friday of February, May, August, November | K12: =ISNUMBER(MATCH(B12,$O$9:$O$27,0)) -> FALSE
A13: 32 | B13: CAGOV | C13: FR0013232188 | D13: CAC 40 Governance | E13: Cac 40 Governance | F13: Moodys | H13: =ISNUMBER(MATCH(B13,'Old Sheet'!$B$2:$B$305,0)) -> TRUE | I13: Third Friday of March, June, September, December | J13: Penultimate Friday of February, May, August, November | K13: =ISNUMBER(MATCH(B13,$O$9:$O$27,0)) -> FALSE
A14: 33 | B14: EC1EW | C14: NL0012254635 | D14: Euronext Core Europe 100 EW | E14: Core Europe | H14: =ISNUMBER(MATCH(B14,'Old Sheet'!$B$2:$B$305,0)) -> TRUE | I14: Third Friday of March, June, September, December | J14: Penultimate Friday of February, May, August, November | K14: =ISNUMBER(MATCH(B14,$O$9:$O$27,0)) -> FALSE
A15: 33 | B15: COR3P | C15: NL0012483903 | D15: Euronext Core Europe 30 EW | E15: Core Europe | H15: =ISNUMBER(MATCH(B15,'Old Sheet'!$B$2:$B$305,0)) -> TRUE | I15: Third Friday of March, June, September, December | J15: Penultimate Friday of February, May, August, November | K15: =ISNUMBER(MATCH(B15,$O$9:$O$27,0)) -> FALSE
A16: 33 | B16: CEE3P | C16: NL0013026917 | D16: Euronext Core Europe 30 ESG EW | E16: Core Europe | F16: Moodys | H16: =ISNUMBER(MATCH(B16,'Old Sheet'!$B$2:$B$305,0)) -> TRUE | I16: Third Friday of March, June, September, December | J16: Penultimate Friday of February, May, August, November | K16: =ISNUMBER(MATCH(B16,$O$9:$O$27,0)) -> FALSE
A17: 38 | B17: EFGEW | C17: NL0012365035 | D17: Euronext France Germany Leaders 50 EW | E17: France German Leaders 50 EW | H17: =ISNUMBER(MATCH(B17,'Old Sheet'!$B$2:$B$305,0)) -> FALSE | I17: Third Friday of March, June, September, December | J17: Penultimate Friday of February, May, August, November | K17: =ISNUMBER(MATCH(B17,$O$9:$O$27,0)) -> FALSE
A18: 40 | B18: EFGP | C18: NL0012658769 | D18: Euronext France Germany Leaders 50 | E18: France German Leaders 50 | H18: =ISNUMBER(MATCH(B18,'Old Sheet'!$B$2:$B$305,0)) -> TRUE | I18: Third Friday of March, June, September, December | J18: Penultimate Friday of February, May, August, November | K18: =ISNUMBER(MATCH(B18,$O$9:$O$27,0)) -> FALSE
A19: 41 | B19: EZ40P | C19: NL0012731871 | D19: Euronext Eurozone 40 EW | E19: Eurozone 40 EW | H19: =ISNUMBER(MATCH(B19,'Old Sheet'!$B$2:$B$305,0)) -> TRUE | I19: Third Friday of March, June, September, December | J19: Penultimate Friday of February, May, August, November | K19: =ISNUMBER(MATCH(B19,$O$9:$O$27,0)) -> FALSE
A20: 43 | B20: EFMEP | C20: NL0012730451 | D20: Euronext Founding Members Europe 50 EW | E20: Founding Members | H20: =ISNUMBER(MATCH(B20,'Old Sheet'!$B$2:$B$305,0)) -> FALSE | I20: Third Friday of March, June, September, December | J20: Penultimate Friday of February, May, August, November | K20: =ISNUMBER(MATCH(B20,$O$9:$O$27,0)) -> FALSE
A21: 47 | B21: ES1EP | C21: NL0012758627 | D21: Euronext® Europe Sustainable 100 EW | E21: Europe Sustainable 100 | F21: Moodys | H21: =ISNUMBER(MATCH(B21,'Old Sheet'!$B$2:$B$305,0)) -> TRUE | I21: Third Friday of March, June, September, December | J21: Penultimate Friday of February, May, August, November | K21: =ISNUMBER(MATCH(B21,$O$9:$O$27,0)) -> FALSE
A22: 48 | B22: CLE5P | C22: NL0012758585 | D22: Euronext® Eurozone Energy Transition Leaders 50 EW | E22: Eurozone Energy Transition Leaders 50 | F22: Moodys | H22: =ISNUMBER(MATCH(B22,'Old Sheet'!$B$2:$B$305,0)) -> FALSE | I22: Second Friday of January, April, July, October | J22: Penultimate Friday of February, May, August, November | K22: =ISNUMBER(MATCH(B22,$O$9:$O$27,0)) -> FALSE
A23: 49 | B23: ESE4P | C23: NL0012758544 | D23: Euronext® Eurozone ESG Leaders 40 EW | E23: Eurozone ESG Leaders 40 | F23: Moodys | H23: =ISNUMBER(MATCH(B23,'Old Sheet'!$B$2:$B$305,0)) -> TRUE | I23: Third Friday of March, June, September, December | J23: Penultimate Friday of February, May, August, November | K23: =ISNUMBER(MATCH(B23,$O$9:$O$27,0)) -> FALSE
A24: 50 | B24: CLF4P | C24: FR0013317773 | D24: Euronext France Energy Transition Leaders 40 EW | E24: France Energy Transition Leaders 40 | F24: Moodys | H24: =ISNUMBER(MATCH(B24,'Old Sheet'!$B$2:$B$305,0)) -> FALSE | I24: Third Friday of March, June, September, December | J24: Penultimate Friday of February, May, August, November | K24: =ISNUMBER(MATCH(B24,$O$9:$O$27,0)) -> FALSE
A25: 51 | B25: ESF4P | C25: FR0013317732 | D25: Euronext® France ESG Leaders 40 EW | E25: France ESG Leaders 40 | F25: Moodys | H25: =ISNUMBER(MATCH(B25,'Old Sheet'!$B$2:$B$305,0)) -> TRUE | I25: Third Friday of March, June, September, December | J25: Penultimate Friday of February, May, August, November | K25: =ISNUMBER(MATCH(B25,$O$9:$O$27,0)) -> FALSE
A26: 52 | B26: ESG50 | C26: NL0012481741 | D26: Euronext Euro 50 ESG EW | E26: Euronext ESG Euro 50 | F26: Moodys | H26: =ISNUMBER(MATCH(B26,'Old Sheet'!$B$2:$B$305,0)) -> TRUE | I26: Third Friday of March, June, September, December | J26: Penultimate Friday of February, May, August, November | K26: =ISNUMBER(MATCH(B26,$O$9:$O$27,0)) -> FALSE
A27: 56 | B27: EZ15P | C27: NL0012949101 | D27: Euronext Eurozone 150 EW | E27: Eurozone | H27: =ISNUMBER(MATCH(B27,'Old Sheet'!$B$2:$B$305,0)) -> TRUE | I27: Third Friday of March, June, September, December | J27: Penultimate Friday of February, May, August, November | K27: =ISNUMBER(MATCH(B27,$O$9:$O$27,0)) -> FALSE
A28: 56 | B28: EZN1P | C28: NL0012949143 | D28: Euronext Eurozone Next 100 EW | E28: Eurozone | H28: =ISNUMBER(MATCH(B28,'Old Sheet'!$B$2:$B$305,0)) -> TRUE | I28: Third Friday of March, June, September, December | J28: Penultimate Friday of February, May, August, November | K28: =ISNUMBER(MATCH(B28,$O$9:$O$27,0)) -> FALSE
A29: 58 | B29: FRENP | C29: NL0013025471 | D29: Euronext CDP Environment France EW | E29: CDP Environment France | H29: =ISNUMBER(MATCH(B29,'Old Sheet'!$B$2:$B$305,0)) -> TRUE | I29: Third Friday of March, June, September, December | J29: Penultimate Friday of February, May, August, November | K29: =ISNUMBER(MATCH(B29,$O$9:$O$27,0)) -> FALSE
A30: 59 | B30: ESG1P | C30: NL0013025596 | D30: Euronext Eurozone 100 ESG | E30: Eurozone 100 ESG | F30: Moodys | H30: =ISNUMBER(MATCH(B30,'Old Sheet'!$B$2:$B$305,0)) -> TRUE | I30: Third Friday of March, June, September, December | J30: Penultimate Friday of February, May, August, November | K30: =ISNUMBER(MATCH(B30,$O$9:$O$27,0)) -> FALSE
A31: 62 | B31: FRECP | C31: FR0013349057 | D31: Euronext France 20-40 Challengers EW | E31: Euronext France 20-40 Challengers | H31: =ISNUMBER(MATCH(B31,'Old Sheet'!$B$2:$B$305,0)) -> TRUE | I31: Third Friday of March, June, September, December | J31: Penultimate Friday of February, May, August, November | K31: =ISNUMBER(MATCH(B31,$O$9:$O$27,0)) -> FALSE
A32: 63 | B32: FRN4P | C32: FR0013354156 | D32: Euronext France Next 40 EW | E32: France Next 40 | H32: =ISNUMBER(MATCH(B32,'Old Sheet'!$B$2:$B$305,0)) -> TRUE | I32: Third Friday of March, June, September, December | J32: Penultimate Friday of February, May, August, November | K32: =ISNUMBER(MATCH(B32,$O$9:$O$27,0)) -> FALSE
A33: 64 | B33: FR20P | C33: FR0013355948 | D33: Euronext France 20 EW | E33: France 20 | H33: =ISNUMBER(MATCH(B33,'Old Sheet'!$B$2:$B$305,0)) -> TRUE | I33: Third Friday of March, June, September, December | J33: Penultimate Friday of February, May, August, November | K33: =ISNUMBER(MATCH(B33,$O$9:$O$27,0)) -> FALSE
A34: 65 | B34: FREEP | C34: NL0013039258 | D34: Euronext CDP Environment France Ex Oil & Gas EW | E34: CDP Environ. France ex Oil & Gas | H34: =ISNUMBER(MATCH(B34,'Old Sheet'!$B$2:$B$305,0)) -> TRUE | I34: Third Friday of March, June, September, December | J34: Penultimate Friday of February, May, August, November | K34: =ISNUMBER(MATCH(B34,$O$9:$O$27,0)) -> FALSE
A35: 66 | B35: ESF5P | C35: FR0013371416 | D35: SBF Top 50 ESG EW | E35: SBF Top 50 ESG | F35: Moodys | H35: =ISNUMBER(MATCH(B35,'Old Sheet'!$B$2:$B$305,0)) -> TRUE | I35: Third Friday of March, June, September, December | J35: Penultimate Friday of February, May, August, November | K35: =ISNUMBER(MATCH(B35,$O$9:$O$27,0)) -> FALSE
A36: 67 | B36: C6RIP | C36: FR0013376258 | D36: CAC Large 60 Responsible Investment SW | E36: Responsible Investment CAC Large 60 | H36: =ISNUMBER(MATCH(B36,'Old Sheet'!$B$2:$B$305,0)) -> TRUE | I36: Third Friday of March, June, September, December | J36: Penultimate Friday of February, May, August, November | K36: =ISNUMBER(MATCH(B36,$O$9:$O$27,0)) -> FALSE
A37: 68 | B37: F4RIP | C37: FR0013376209 | D37: Euronext France 40 Responsible Investment | E37: Responsible Investment Euronext France 40 | F37: Done | H37: =ISNUMBER(MATCH(B37,'Old Sheet'!$B$2:$B$305,0)) -> TRUE | I37: Third Friday of March, June, September, December | J37: Penultimate Friday of February, May, August, November | K37: =ISNUMBER(MATCH(B37,$O$9:$O$27,0)) -> FALSE
A38: 69 | B38: EUS5P | C38: NL0013216468 | D38: Euronext Transatlantic 50 EW | E38: Transatlantic 50 EW | H38: =ISNUMBER(MATCH(B38,'Old Sheet'!$B$2:$B$305,0)) -> TRUE | I38: Third Friday of March, June, September, December | J38: Penultimate Friday of February, May, August, November | K38: =ISNUMBER(MATCH(B38,$O$9:$O$27,0)) -> FALSE
A39: 70 | B39: ERI5P | C39: NL0013217730 | D39: Euronext Responsible Investment Euro 50 EW | E39: Responsible Investment Euro 50 | H39: =ISNUMBER(MATCH(B39,'Old Sheet'!$B$2:$B$305,0)) -> TRUE | I39: Third Friday of March, June, September, December | J39: Penultimate Friday of February, May, August, November | K39: =ISNUMBER(MATCH(B39,$O$9:$O$27,0)) -> FALSE
A40: 75 | B40: EZENP | C40: NL0013352560 | D40: Euronext CDP Environment Eurozone EW | E40: CDP Environment Eurozone | H40: =ISNUMBER(MATCH(B40,'Old Sheet'!$B$2:$B$305,0)) -> TRUE | I40: Third Friday of March, June, September, December | J40: Penultimate Friday of February, May, August, November | K40: =ISNUMBER(MATCH(B40,$O$9:$O$27,0)) -> FALSE
A41: 76 | B41: WLENP | C41: NL0013352602 | D41: Euronext CDP Environment World EW | E41: CDP Environment World | H41: =ISNUMBER(MATCH(B41,'Old Sheet'!$B$2:$B$305,0)) -> TRUE | I41: Third Friday of March, June, September, December | J41: Penultimate Friday of February, May, August, November | K41: =ISNUMBER(MATCH(B41,$O$9:$O$27,0)) -> FALSE
...

Sheet Full sheet Francesco
B3: Index Type | C3: SuperGroup | D3: Group | E3: Inception Date | F3: Delisting Date | G3: Number of effective dates per review | H3: First Review Effective Date (after close of the ... ) | I3: Cut off Date(s) (after close of the ... ) | J3: Review Announcement Date (n. days before eff date) | K3: Review Composition Date (n. days before eff date) | L3: Review Weighting Date (n. days before eff date) | M3: Free float start date (n. days before cutoff) | N3: Universe | O3: Data vendor(s) | P3: Packages | Q3: Comments | R3: Responsible 1 | S3: Method 1 | T3: Responsible 2 | U3: Method 2 | V3: Will be in Agenda Review? | W3: Mnemos in group (price only) | X3: Effective String 1 | Y3: Effective String 2 | Z3: Effective String 3 | AA3: Effective String 4 | AB3: Effective String 5 | AC3: Effective String 6 | AD3: Effective String 7 | AE3: Effective String 8 | AF3: Effective String 9 | AG3: Effective String 10 | AH3: Effective String 11 | AI3: Effective String 12 | AJ3: Effective Date 1 | AK3: Effective Date 2 | AL3: Effective Date 3 | AM3: Effective Date 4 | AN3: Effective Date 5 | AO3: Effective Date 6 | AP3: Effective Date 7 | AQ3: Effective Date 8 | AR3: Effective Date 9 | AS3: Effective Date 10 | AT3: Effective Date 11 | AU3: Effective Date 12 | AV3: Effective Date 13 | AW3: Effective Date 14 | AX3: Effective Date 15 | AY3: Effective Date 16 | AZ3: Effective Date 17 | BA3: Effective Date 18 | BB3: Effective Date 19 | BC3: Effective Date 20 | BD3: Cutoff String 1 | BE3: Cutoff String 2 | BF3: Cutoff String 3 | BG3: Cutoff String 4 | BH3: Cutoff String 5 | BI3: Cutoff String 6 | BJ3: Cutoff String 7 | BK3: Cutoff String 8 | BL3: Cutoff String 9 | BM3: Cutoff String 10 | BN3: Cutoff String 11 | BO3: Cutoff String 12 | BP3: Cutoff Date 1 | BQ3: Cutoff Date 2 | BR3: Cutoff Date 3 | BS3: Cutoff Date 4 | BT3: Cutoff Date 5 | BU3: Cutoff Date 6 | BV3: Cutoff Date 7 | BW3: Cutoff Date 8 | BX3: Cutoff Date 9 | BY3: Cutoff Date 10 | BZ3: Cutoff Date 11 | CA3: Cutoff Date 12 | CB3: Announcement date 1 | CC3: Announcement date 2 | CD3: Announcement date 3 | CE3: Announcement date 4 | CF3: Announcement date 5 | CG3: Announcement date 6 | CH3: Announcement date 7 | CI3: Announcement date 8 | CJ3: Announcement date 9 | CK3: Announcement date 10 | CL3: Announcement date 11 | CM3: Announcement date 12 | CN3: Composition date 1 | CO3: Composition date 2 | CP3: Composition date 3 | CQ3: Composition date 4 | CR3: Composition date 5 | CS3: Composition date 6 | CT3: Composition date 7 | CU3: Composition date 8 | CV3: Composition date 9 | CW3: Composition date 10 | CX3: Composition date 11 | CY3: Composition date 12 | CZ3: Free float date 1 | DA3: Free float date 2 | DB3: Free float date 3 | DC3: Free float date 4 | DD3: Free float date 5 | DE3: Free float date 6 | DF3: Free float date 7 | DG3: Free float date 8 | DH3: Free float date 9 | DI3: Free float date 10 | DJ3: Free float date 11 | DK3: Free float date 12 | DL3: Effective dates in a year | DM3: Cutoff dates in year | DN3: Announcements in year | DO3: Composition dates in year | DP3: Free float start dates | DQ3: Total Dates counter | DR3: Id | DS3: Id stop | DU3: Reason why it's not in dataiku yet | DV3: Dataiku first release | DW3: Year | DX3: Month
B4: Price | C4: 1.5 AEX/CAC | D4: CAC/AEX Equal Weight | E4: 39986 | G4: 1 | H4: Third Friday of March, June, September, December | I4: Penultimate Friday of February, May, August, November | K4: 2 | L4: 3 | P4: NXTG | R4: Lex | S4: New Sheet | T4: Automatic | U4: Dataiku | V4: Yes | W4: AEXEW CACEW CLEW | X4: Third Friday of March | Y4: Third Friday of June | Z4: Third Friday of September | AA4: Third Friday of December | AJ4: 45740 | AK4: 45831 | AL4: 45922 | AM4: 46013 | BD4: Penultimate Friday of February | BE4: Penultimate Friday of May | BF4: Penultimate Friday of August | BG4: Penultimate Friday of November | BP4: 45712 | BQ4: 45803 | BR4: 45894 | BS4: 45985 | CN4: 45736 | CO4: 45827 | CP4: 45918 | CQ4: 46009 | DL4: 4 | DM4: 4 | DN4: 0 | DO4: 4 | DP4: 0 | DQ4: 12 | DR4: 112 | DV4: 44483.638 | DW4: 2021 | DX4: 10
B5: Price | C5: 1.5 AEX/CAC | D5: CAC/AEX Equal Weight | E5: 39986 | G5: 1 | H5: Third Friday of March, June, September, December | I5: Penultimate Friday of February, May, August, November | K5: 2 | L5: 3 | P5: NXTG | R5: Lex | S5: New Sheet | T5: Automatic | U5: Dataiku | V5: No | DL5: 0 | DM5: 0 | DN5: 0 | DO5: 0 | DP5: 0 | DQ5: 0 | DV5: 44483.75 | DW5: 2021 | DX5: 10
B6: Price | C6: 1.5 AEX/CAC | D6: CAC/AEX Equal Weight | E6: 42118 | G6: 1 | H6: Third Friday of March, June, September, December | I6: Penultimate Friday of February, May, August, November | K6: 2 | L6: 3 | P6: NXTG | R6: Lex | S6: New Sheet | T6: Automatic | U6: Dataiku | V6: No | DL6: 0 | DM6: 0 | DN6: 0 | DO6: 0 | DP6: 0 | DQ6: 0 | DV6: 44483.75 | DW6: 2021 | DX6: 10
B7: Price | C7: 1.5 AEX/CAC | D7: Bene40 Equal Weight | E7: 42268 | G7: 1 | H7: Third Friday of March, June, September, December | I7: Penultimate Friday of February, May, August, November | K7: 2 | L7: 3 | P7: NXTG | R7: Lex | S7: New Sheet | T7: Automatic | U7: Dataiku | V7: Yes | W7: BNEW | X7: Third Friday of March | Y7: Third Friday of June | Z7: Third Friday of September | AA7: Third Friday of December | AJ7: 45740 | AK7: 45831 | AL7: 45922 | AM7: 46013 | BD7: Penultimate Friday of February | BE7: Penultimate Friday of May | BF7: Penultimate Friday of August | BG7: Penultimate Friday of November | BP7: 45712 | BQ7: 45803 | BR7: 45894 | BS7: 45985 | CN7: 45736 | CO7: 45827 | CP7: 45918 | CQ7: 46009 | DL7: 4 | DM7: 4 | DN7: 0 | DO7: 4 | DP7: 0 | DQ7: 12 | DR7: 174 | DV7: 45520 | DW7: 2024 | DX7: 8
B8: Price | C8: 2.6 Normal index | D8: SBF 80 | E8: 42345 | G8: 1 | H8: Third Friday of March, June, September, December | I8: Penultimate Friday of February, May, August, November | K8: 2 | L8: 3 | P8: PAR | R8: Lex | S8: New Sheet | T8: Automatic | U8: Dataiku | V8: Yes | W8: SBF80 | X8: Third Friday of March | Y8: Third Friday of June | Z8: Third Friday of September | AA8: Third Friday of December | AJ8: 45740 | AK8: 45831 | AL8: 45922 | AM8: 46013 | BD8: Penultimate Friday of February | BE8: Penultimate Friday of May | BF8: Penultimate Friday of August | BG8: Penultimate Friday of November | BP8: 45712 | BQ8: 45803 | BR8: 45894 | BS8: 45985 | CN8: 45736 | CO8: 45827 | CP8: 45918 | CQ8: 46009 | DL8: 4 | DM8: 4 | DN8: 0 | DO8: 4 | DP8: 0 | DQ8: 12 | DR8: 186 | DV8: 44483.753 | DW8: 2021 | DX8: 10
B9: Price | C9: 2.6 Normal index | D9: Cac 40 Governance | E9: 42787 | G9: 1 | H9: Third Friday of March, June, September, December | I9: Penultimate Friday of February, May, August, November | K9: 2 | L9: 3 | O9: Moody's | P9: NXTG | Q9: Query rates from Vigeo Eiris rates on cut-off date | R9: Lex | S9: New Sheet | T9: Automatic | U9: Dataiku | V9: Yes | W9: CAGOV | X9: Third Friday of March | Y9: Third Friday of June | Z9: Third Friday of September | AA9: Third Friday of December | AJ9: 45740 | AK9: 45831 | AL9: 45922 | AM9: 46013 | BD9: Penultimate Friday of February | BE9: Penultimate Friday of May | BF9: Penultimate Friday of August | BG9: Penultimate Friday of November | BP9: 45712 | BQ9: 45803 | BR9: 45894 | BS9: 45985 | CN9: 45736 | CO9: 45827 | CP9: 45918 | CQ9: 46009 | DL9: 4 | DM9: 4 | DN9: 0 | DO9: 4 | DP9: 0 | DQ9: 12 | DR9: 207 | DV9: 44627.477 | DW9: 2022 | DX9: 3
B10: Price | C10: 1.6 Core | D10: Core Europe | E10: 42831 | G10: 1 | H10: Third Friday of March, June, September, December | I10: Penultimate Friday of February, May, August, November | J10: 6 | K10: 2 | L10: 3 | M10: 20 | P10: NXTG | Q10: Mother index Eurozone 300 can be used as underlying universe (not in rulebook) | R10: Amanda | S10: New Sheet | T10: Edwin | U10: Dataiku | V10: Yes | W10: EC1EW COR3P CEE3P CEE1P | X10: Third Friday of March | Y10: Third Friday of June | Z10: Third Friday of September | AA10: Third Friday of December | AJ10: 45740 | AK10: 45831 | AL10: 45922 | AM10: 46013 | BD10: Penultimate Friday of February | BE10: Penultimate Friday of May | BF10: Penultimate Friday of August | BG10: Penultimate Friday of November | BP10: 45712 | BQ10: 45803 | BR10: 45894 | BS10: 45985 | CB10: 45730 | CC10: 45821 | CD10: 45912 | CE10: 46003 | CN10: 45736 | CO10: 45827 | CP10: 45918 | CQ10: 46009 | CZ10: 45685 | DA10: 45776 | DB10: 45867 | DC10: 45958 | DL10: 4 | DM10: 4 | DN10: 4 | DO10: 4 | DP10: 4 | DQ10: 20 | DR10: 219 | DV10: 44992.583 | DW10: 2023 | DX10: 3
B11: Price | C11: 1.6 Core | D11: Core Europe | E11: 42977 | G11: 1 | H11: Third Friday of March, June, September, December | I11: Penultimate Friday of February, May, August, November | J11: 6 | K11: 2 | L11: 3 | M11: 20 | P11: NXTG | Q11: Mother index Eurozone 300 can be used as underlying universe (not in rulebook) | R11: Amanda | S11: New Sheet | T11: Edwin | U11: Dataiku | V11: No | DL11: 0 | DM11: 0 | DN11: 0 | DO11: 0 | DP11: 0 | DQ11: 0 | DV11: 44992.607 | DW11: 2023 | DX11: 3
B12: Price | C12: 1.6 Core | D12: Core Europe | E12: 43299 | G12: 1 | H12: Third Friday of March, June, September, December | I12: Penultimate Friday of February, May, August, November | J12: 6 | K12: 2 | L12: 3 | M12: 20 | O12: Moody's | P12: NXTG | Q12: Mother index Eurozone 300 can be used as underlying universe (not in rulebook) | R12: Amanda | S12: New Sheet | T12: Edwin | U12: Dataiku | V12: No | DL12: 0 | DM12: 0 | DN12: 0 | DO12: 0 | DP12: 0 | DQ12: 0 | DV12: 45084.603 | DW12: 2023 | DX12: 6
B13: Price | C13: 2.6 Normal index | D13: France German Leaders 50 EW | E13: 42909 | G13: 2 | H13: Third Friday of March, June, September, December | I13: Penultimate Friday of February, May, August, November | K13: 2 | L13: 3 | P13: NXTG | Q13: Mother index Eurozone 300 can be used as underlying (not in rulebook). Review spread over 2 days. | R13: Amanda | S13: New Sheet | T13: Automatic | U13: Dataiku | V13: Yes | W13: EFGEW | X13: Third Friday of March | Y13: Third Friday of June | Z13: Third Friday of September | AA13: Third Friday of December | AJ13: 45740 | AK13: 45741 | AL13: 45831 | AM13: 45832 | AN13: 45922 | AO13: 45923 | AP13: 46013 | AQ13: 46014 | BD13: Penultimate Friday of February | BE13: Penultimate Friday of May | BF13: Penultimate Friday of August | BG13: Penultimate Friday of November | BP13: 45712 | BQ13: 45803 | BR13: 45894 | BS13: 45985 | CN13: 45736 | CO13: 45827 | CP13: 45918 | CQ13: 46009 | DL13: 8 | DM13: 4 | DN13: 0 | DO13: 4 | DP13: 0 | DQ13: 16 | DR13: 255 | DV13: 44483.753 | DW13: 2021 | DX13: 10
B14: Price | C14: 2.6 Normal index | D14: France German Leaders 50 | E14: 43049 | G14: 1 | H14: Third Friday of March, June, September, December | I14: Penultimate Friday of February, May, August, November | K14: 2 | L14: 2 | P14: NXTG | Q14: Mother index Eurozone 300 can be used as underlying (not in rulebook). Review spread over 2 days. | R14: Amanda | S14: New Sheet | T14: Automatic | U14: Dataiku | V14: Yes | W14: EFGP | X14: Third Friday of March | Y14: Third Friday of June | Z14: Third Friday of September | AA14: Third Friday of December | AJ14: 45740 | AK14: 45831 | AL14: 45922 | AM14: 46013 | BD14: Penultimate Friday of February | BE14: Penultimate Friday of May | BF14: Penultimate Friday of August | BG14: Penultimate Friday of November | BP14: 45712 | BQ14: 45803 | BR14: 45894 | BS14: 45985 | CN14: 45736 | CO14: 45827 | CP14: 45918 | CQ14: 46009 | DL14: 4 | DM14: 4 | DN14: 0 | DO14: 4 | DP14: 0 | DQ14: 12 | DR14: 307 | DV14: 44627.447 | DW14: 2022 | DX14: 3
B15: Price | C15: 1.8 Eurozone | D15: Eurozone 40 EW | E15: 43115 | G15: 1 | H15: Third Friday of March, June, September, December | I15: Penultimate Friday of February, May, August, November | K15: 2 | L15: 3 | P15: NXTG | Q15: Underlying universe is mother index Eurozone 300 | R15: Anna | S15: New Sheet | T15: Automatic | U15: Dataiku | V15: Yes | W15: EZ40P | X15: Third Friday of March | Y15: Third Friday of June | Z15: Third Friday of September | AA15: Third Friday of December | AJ15: 45740 | AK15: 45831 | AL15: 45922 | AM15: 46013 | BD15: Penultimate Friday of February | BE15: Penultimate Friday of May | BF15: Penultimate Friday of August | BG15: Penultimate Friday of November | BP15: 45712 | BQ15: 45803 | BR15: 45894 | BS15: 45985 | CN15: 45736 | CO15: 45827 | CP15: 45918 | CQ15: 46009 | DL15: 4 | DM15: 4 | DN15: 0 | DO15: 4 | DP15: 0 | DQ15: 12 | DR15: 319 | DV15: 44483.751 | DW15: 2021 | DX15: 10
B16: Price | C16: 1.8 Eurozone | D16: Eurozone 2 | E16: 43217 | F16: 45699 | G16: 1 | H16: Third Friday of March, June, September, December | I16: Penultimate Friday of February, May, August, November | K16: 2 | L16: 3 | P16: NXTG | Q16: Underlying universe is mother index Eurozone 300 | R16: Anna | S16: New Sheet | T16: Automatic | U16: Dataiku | V16: No | DL16: 0 | DM16: 0 | DN16: 0 | DO16: 0 | DP16: 0 | DQ16: 0 | DV16: 44483.751 | DW16: 2021 | DX16: 10
B17: Price | C17: 2.6 Normal index | D17: Founding Members | E17: 43115 | G17: 1 | H17: Third Friday of March, June, September, December | I17: Penultimate Friday of February, May, August, November | K17: 2 | L17: 3 | P17: NXTG | Q17: Mother index Eurozone 300 can be used as underlying (not in rulebook) | R17: Ginevra | S17: New Sheet | T17: Automatic | U17: Dataiku | V17: Yes | W17: EFMEP | X17: Third Friday of March | Y17: Third Friday of June | Z17: Third Friday of September | AA17: Third Friday of December | AJ17: 45740 | AK17: 45831 | AL17: 45922 | AM17: 46013 | BD17: Penultimate Friday of February | BE17: Penultimate Friday of May | BF17: Penultimate Friday of August | BG17: Penultimate Friday of November | BP17: 45712 | BQ17: 45803 | BR17: 45894 | BS17: 45985 | CN17: 45736 | CO17: 45827 | CP17: 45918 | CQ17: 46009 | DL17: 4 | DM17: 4 | DN17: 0 | DO17: 4 | DP17: 0 | DQ17: 12 | DR17: 331 | DV17: 44483.752 | DW17: 2021 | DX17: 10
B18: Price | C18: 2.6 Normal index | D18: Europe Sustainable 100 | E18: 43154 | G18: 1 | H18: Third Friday of March, June, September, December | I18: Penultimate Friday of February, May, August, November | K18: 2 | L18: 3 | O18: Moody's | P18: NXTG | Q18: Underlying is mother index Europe 500 | R18: Ken | S18: New Sheet | T18: Automatic | U18: Dataiku | V18: Yes | W18: ES1EP | X18: Third Friday of March | Y18: Third Friday of June | Z18: Third Friday of September | AA18: Third Friday of December | AJ18: 45740 | AK18: 45831 | AL18: 45922 | AM18: 46013 | BD18: Penultimate Friday of February | BE18: Penultimate Friday of May | BF18: Penultimate Friday of August | BG18: Penultimate Friday of November | BP18: 45712 | BQ18: 45803 | BR18: 45894 | BS18: 45985 | CN18: 45736 | CO18: 45827 | CP18: 45918 | CQ18: 46009 | DL18: 4 | DM18: 4 | DN18: 0 | DO18: 4 | DP18: 0 | DQ18: 12 | DR18: 355 | DV18: 45061.624 | DW18: 2023 | DX18: 5
B19: Price | C19: 2.6 Normal index | D19: Eurozone Energy Transition Leaders 50 | E19: 43154 | G19: 1 | H19: Second Friday of January, April, July, October | I19: Penultimate Friday of February, May, August, November | K19: 2 | L19: 3 | O19: Moody's | P19: NXTG | Q19: Underlying universe is mother index Eurozone 300 | R19: Anna | S19: New Sheet | T19: Automatic | U19: Dataiku | V19: Yes | W19: CLE5P | X19: Second Friday of January | Y19: Second Friday of April | Z19: Second Friday of July | AA19: Second Friday of October | AJ19: 45670 | AK19: 45761 | AL19: 45852 | AM19: 45943 | BD19: Penultimate Friday of February | BE19: Penultimate Friday of May | BF19: Penultimate Friday of August | BG19: Penultimate Friday of November | BP19: 45712 | BQ19: 45803 | BR19: 45894 | BS19: 45985 | CN19: 45666 | CO19: 45757 | CP19: 45848 | CQ19: 45939 | DL19: 4 | DM19: 4 | DN19: 0 | DO19: 4 | DP19: 0 | DQ19: 12 | DR19: 367 | DV19: 44483.752 | DW19: 2021 | DX19: 10
B20: Price | C20: 2.5 ESG Leaders | D20: Eurozone ESG Leaders 40 | E20: 43154 | G20: 2 | H20: Third Friday of March, June, September, December | I20: Penultimate Friday of February, May, August, November | K20: 2 | L20: 3 | O20: Moody's | P20: NXTG | Q20: Underlying universe is mother index Eurozone 300. Review spread over 2 days. | R20: Lex | S20: New Sheet | T20: Automatic | U20: Dataiku | V20: Yes | W20: ESE4P | X20: Third Friday of March | Y20: Third Friday of June | Z20: Third Friday of September | AA20: Third Friday of December | AJ20: 45740 | AK20: 45741 | AL20: 45831 | AM20: 45832 | AN20: 45922 | AO20: 45923 | AP20: 46013 | AQ20: 46014 | BD20: Penultimate Friday of February | BE20: Penultimate Friday of May | BF20: Penultimate Friday of August | BG20: Penultimate Friday of November | BP20: 45712 | BQ20: 45803 | BR20: 45894 | BS20: 45985 | CN20: 45736 | CO20: 45827 | CP20: 45918 | CQ20: 46009 | DL20: 8 | DM20: 4 | DN20: 0 | DO20: 4 | DP20: 0 | DQ20: 16 | DR20: 379 | DV20: 44483.752 | DW20: 2021 | DX20: 10
B21: Price | C21: 2.6 Normal index | D21: France Energy Transition Leaders 40 | E21: 43154 | G21: 1 | H21: Third Friday of March, June, September, December | I21: Penultimate Friday of February, May, August, November | K21: 2 | L21: 3 | O21: Moody's | P21: NXTG | R21: Anna | S21: New Sheet | T21: Automatic | U21: Dataiku | V21: Yes | W21: CLF4P | X21: Third Friday of March | Y21: Third Friday of June | Z21: Third Friday of September | AA21: Third Friday of December | AJ21: 45740 | AK21: 45831 | AL21: 45922 | AM21: 46013 | BD21: Penultimate Friday of February | BE21: Penultimate Friday of May | BF21: Penultimate Friday of August | BG21: Penultimate Friday of November | BP21: 45712 | BQ21: 45803 | BR21: 45894 | BS21: 45985 | CN21: 45736 | CO21: 45827 | CP21: 45918 | CQ21: 46009 | DL21: 4 | DM21: 4 | DN21: 0 | DO21: 4 | DP21: 0 | DQ21: 12 | DR21: 395 | DV21: 44483.752 | DW21: 2021 | DX21: 10
B22: Price | C22: 2.5 ESG Leaders | D22: France ESG Leaders 40 | E22: 43154 | G22: 1 | H22: Third Friday of March, June, September, December | I22: Penultimate Friday of February, May, August, November | K22: 2 | L22: 3 | O22: Moody's | P22: NXTG | R22: Lex | S22: New Sheet | T22: Automatic | U22: Dataiku | V22: Yes | W22: ESF4P | X22: Third Friday of March | Y22: Third Friday of June | Z22: Third Friday of September | AA22: Third Friday of December | AJ22: 45740 | AK22: 45831 | AL22: 45922 | AM22: 46013 | BD22: Penultimate Friday of February | BE22: Penultimate Friday of May | BF22: Penultimate Friday of August | BG22: Penultimate Friday of November | BP22: 45712 | BQ22: 45803 | BR22: 45894 | BS22: 45985 | CN22: 45736 | CO22: 45827 | CP22: 45918 | CQ22: 46009 | DL22: 4 | DM22: 4 | DN22: 0 | DO22: 4 | DP22: 0 | DQ22: 12 | DR22: 407 | DV22: 44483.752 | DW22: 2021 | DX22: 10
B23: Price | C23: 2.6 Normal index | D23: Euronext ESG Euro 50 | E23: 43193 | G23: 1 | H23: Third Friday of March, June, September, December | I23: Penultimate Friday of February, May, August, November | K23: 2 | L23: 3 | O23: Moody's | P23: NXTG | Q23: Underlying universe is mother index Eurozone 300, Vigeo Eiris is providing the ESG scores | R23: Anna | S23: New Sheet | T23: Automatic | U23: Dataiku | V23: Yes | W23: ESG50 | X23: Third Friday of March | Y23: Third Friday of June | Z23: Third Friday of September | AA23: Third Friday of December | AJ23: 45740 | AK23: 45831 | AL23: 45922 | AM23: 46013 | BD23: Penultimate Friday of February | BE23: Penultimate Friday of May | BF23: Penultimate Friday of August | BG23: Penultimate Friday of November | BP23: 45712 | BQ23: 45803 | BR23: 45894 | BS23: 45985 | CN23: 45736 | CO23: 45827 | CP23: 45918 | CQ23: 46009 | DL23: 4 | DM23: 4 | DN23: 0 | DO23: 4 | DP23: 0 | DQ23: 12 | DR23: 419 | DV23: 44483.75 | DW23: 2021 | DX23: 10
B24: Price | C24: 2.6 Normal index | D24: France Eurozone 60 | E24: 43217 | F24: 45699 | G24: 1 | H24: Third Friday of March, June, September, December | I24: Penultimate Friday of February, May, August, November | K24: 2 | L24: 3 | P24: NXTG | Q24: Underlying universe is mother index Eurozone 300 | R24: Lex | S24: New Sheet | T24: Automatic | U24: Dataiku | V24: No | DL24: 0 | DM24: 0 | DN24: 0 | DO24: 0 | DP24: 0 | DQ24: 0 | DV24: 44483.752 | DW24: 2021 | DX24: 10
B25: Price | C25: 1.8 Eurozone | D25: Eurozone | E25: 43257 | G25: 1 | H25: Third Friday of March, June, September, December | I25: Penultimate Friday of February, May, August, November | K25: 2 | L25: 3 | P25: NXTG | Q25: Underlying universe is mother index Eurozone 300 | R25: Anna | S25: New Sheet | T25: Automatic | U25: Dataiku | V25: Yes | W25: EZ15P EZN1P | X25: Third Friday of March | Y25: Third Friday of June | Z25: Third Friday of September | AA25: Third Friday of December | AJ25: 45740 | AK25: 45831 | AL25: 45922 | AM25: 46013 | BD25: Penultimate Friday of February | BE25: Penultimate Friday of May | BF25: Penultimate Friday of August | BG25: Penultimate Friday of November | BP25: 45712 | BQ25: 45803 | BR25: 45894 | BS25: 45985 | CN25: 45736 | CO25: 45827 | CP25: 45918 | CQ25: 46009 | DL25: 4 | DM25: 4 | DN25: 0 | DO25: 4 | DP25: 0 | DQ25: 12 | DR25: 431 | DV25: 44483.751 | DW25: 2021 | DX25: 10
B26: Price | C26: 1.8 Eurozone | D26: Eurozone | E26: 43257 | G26: 1 | H26: Third Friday of March, June, September, December | I26: Penultimate Friday of February, May, August, November | K26: 2 | L26: 3 | P26: NXTG | Q26: Underlying universe is mother index Eurozone 300 | R26: Anna | S26: New Sheet | T26: Automatic | U26: Dataiku | V26: No | DL26: 0 | DM26: 0 | DN26: 0 | DO26: 0 | DP26: 0 | DQ26: 0 | DV26: 44483.752 | DW26: 2021 | DX26: 10
B27: Price | C27: 1.8 Eurozone | D27: Eurozone | E27: 43264 | F27: 45520 | G27: 1 | H27: Third Friday of March, June, September, December | I27: Penultimate Friday of February, May, August, November | K27: 2 | L27: 3 | P27: NXTG | Q27: Underlying universe is mother index Eurozone 300 | R27: Anna | S27: New Sheet | T27: Automatic | U27: Dataiku | V27: No | DL27: 0 | DM27: 0 | DN27: 0 | DO27: 0 | DP27: 0 | DQ27: 0 | DV27: #N/A | DW27: #N/A | DX27: #N/A
B28: Price | C28: 1.8 Eurozone | D28: Eurozone | E28: 43285 | F28: 45520 | G28: 1 | H28: Third Friday of March, June, September, December | I28: Penultimate Friday of February, May, August, November | K28: 2 | L28: 3 | P28: NXTG | Q28: Underlying universe is mother index Eurozone 300 | R28: Anna | S28: New Sheet | T28: Automatic | U28: Dataiku | V28: No | DL28: 0 | DM28: 0 | DN28: 0 | DO28: 0 | DP28: 0 | DQ28: 0 | DV28: #N/A | DW28: #N/A | DX28: #N/A
B29: Price | C29: 1.8 Eurozone | D29: Eurozone | E29: 43292 | F29: 45699 | G29: 1 | H29: Third Friday of March, June, September, December | I29: Penultimate Friday of February, May, August, November | K29: 2 | L29: 3 | P29: NXTG | Q29: Underlying universe is mother index Eurozone 300 | R29: Anna | S29: New Sheet | T29: Automatic | U29: Dataiku | V29: No | DL29: 0 | DM29: 0 | DN29: 0 | DO29: 0 | DP29: 0 | DQ29: 0 | DV29: 44483.752 | DW29: 2021 | DX29: 10
B30: Price | C30: 2.0 CDP | D30: CDP Environment France | E30: 43271 | G30: 5 | H30: Third Friday of March, June, September, December | I30: Penultimate Friday of February, May, August, November | J30: 6 | K30: 2 | L30: 3 | O30: CDP | P30: NXTG | Q30: CDP provides CDP score; annual review in March. Only Review Announcement at Annual. | R30: Ken | S30: New Sheet | T30: Automatic | U30: Dataiku | V30: Yes | W30: FRENP | X30: Third Friday of March | Y30: Third Friday of June | Z30: Third Friday of September | AA30: Third Friday of December | AJ30: 45740 | AK30: 45741 | AL30: 45742 | AM30: 45743 | AN30: 45744 | AO30: 45831 | AP30: 45832 | AQ30: 45833 | AR30: 45834 | AS30: 45835 | AT30: 45922 | AU30: 45923 | AV30: 45924 | AW30: 45925 | AX30: 45926 | AY30: 46013 | AZ30: 46014 | BA30: 46015 | BB30: 46017 | BC30: 46020 | BD30: Penultimate Friday of February | BE30: Penultimate Friday of May | BF30: Penultimate Friday of August | BG30: Penultimate Friday of November | BP30: 45712 | BQ30: 45803 | BR30: 45894 | BS30: 45985 | CB30: 45730 | CC30: 45821 | CD30: 45912 | CE30: 46003 | CN30: 45736 | CO30: 45827 | CP30: 45918 | CQ30: 46009 | DL30: 20 | DM30: 4 | DN30: 4 | DO30: 4 | DP30: 0 | DQ30: 32 | DR30: 455 | DV30: 44610.309 | DW30: 2022 | DX30: 2
B31: Price | C31: 2.6 Normal index | D31: Eurozone 100 ESG | E31: 43278 | G31: 1 | H31: Third Friday of March, June, September, December | I31: Penultimate Friday of February, May, August, November | K31: 2 | L31: 3 | O31: Moody's | P31: NXTG | Q31: Underlying universe is mother index Eurozone 300, ESG scores provided | R31: Ken | S31: New Sheet | T31: Automatic | U31: Dataiku | V31: Yes | W31: ESG1P | X31: Third Friday of March | Y31: Third Friday of June | Z31: Third Friday of September | AA31: Third Friday of December | AJ31: 45740 | AK31: 45831 | AL31: 45922 | AM31: 46013 | BD31: Penultimate Friday of February | BE31: Penultimate Friday of May | BF31: Penultimate Friday of August | BG31: Penultimate Friday of November | BP31: 45712 | BQ31: 45803 | BR31: 45894 | BS31: 45985 | CN31: 45736 | CO31: 45827 | CP31: 45918 | CQ31: 46009 | DL31: 4 | DM31: 4 | DN31: 0 | DO31: 4 | DP31: 0 | DQ31: 12 | DR31: 487 | DV31: 44687 | DW31: 2022 | DX31: 5
B32: Price | C32: 2.6 Normal index | D32: Euronext France 20-40 Challengers | E32: 43299 | G32: 1 | H32: Third Friday of March, June, September, December | I32: Penultimate Friday of February, May, August, November | K32: 2 | L32: 3 | P32: NXTG | R32: Lex | S32: New Sheet | T32: Automatic | U32: Dataiku | V32: Yes | W32: FRECP | X32: Third Friday of March | Y32: Third Friday of June | Z32: Third Friday of September | AA32: Third Friday of December | AJ32: 45740 | AK32: 45831 | AL32: 45922 | AM32: 46013 | BD32: Penultimate Friday of February | BE32: Penultimate Friday of May | BF32: Penultimate Friday of August | BG32: Penultimate Friday of November | BP32: 45712 | BQ32: 45803 | BR32: 45894 | BS32: 45985 | CN32: 45736 | CO32: 45827 | CP32: 45918 | CQ32: 46009 | DL32: 4 | DM32: 4 | DN32: 0 | DO32: 4 | DP32: 0 | DQ32: 12 | DR32: 515 | DV32: 44483.752 | DW32: 2021 | DX32: 10
B33: Price | C33: 2.6 Normal index | D33: France Next 40 | E33: 43327 | G33: 1 | H33: Third Friday of March, June, September, December | I33: Penultimate Friday of February, May, August, November | K33: 2 | L33: 3 | P33: NXTG | Q33: Selection out of SBF120 | R33: Lex | S33: New Sheet | T33: Automatic | U33: Dataiku | V33: Yes | W33: FRN4P | X33: Third Friday of March | Y33: Third Friday of June | Z33: Third Friday of September | AA33: Third Friday of December | AJ33: 45740 | AK33: 45831 | AL33: 45922 | AM33: 46013 | BD33: Penultimate Friday of February | BE33: Penultimate Friday of May | BF33: Penultimate Friday of August | BG33: Penultimate Friday of November | BP33: 45712 | BQ33: 45803 | BR33: 45894 | BS33: 45985 | CN33: 45736 | CO33: 45827 | CP33: 45918 | CQ33: 46009 | DL33: 4 | DM33: 4 | DN33: 0 | DO33: 4 | DP33: 0 | DQ33: 12 | DR33: 527 | DV33: 44483.753 | DW33: 2021 | DX33: 10
B34: Price | C34: 2.6 Normal index | D34: France 20 | E34: 43334 | G34: 1 | H34: Third Friday of March, June, September, December | I34: Penultimate Friday of February, May, August, November | K34: 2 | L34: 3 | P34: NXTG | Q34: Selection out of CAC40 | R34: Lex | S34: New Sheet | T34: Automatic | U34: Dataiku | V34: Yes | W34: FR20P | X34: Third Friday of March | Y34: Third Friday of June | Z34: Third Friday of September | AA34: Third Friday of December | AJ34: 45740 | AK34: 45831 | AL34: 45922 | AM34: 46013 | BD34: Penultimate Friday of February | BE34: Penultimate Friday of May | BF34: Penultimate Friday of August | BG34: Penultimate Friday of November | BP34: 45712 | BQ34: 45803 | BR34: 45894 | BS34: 45985 | CN34: 45736 | CO34: 45827 | CP34: 45918 | CQ34: 46009 | DL34: 4 | DM34: 4 | DN34: 0 | DO34: 4 | DP34: 0 | DQ34: 12 | DR34: 539 | DV34: 44483.752 | DW34: 2021 | DX34: 10
B35: Price | C35: 2.0 CDP | D35: CDP Environ. France ex Oil & Gas | E35: 43341 | G35: 1 | H35: Third Friday of March, June, September, December | I35: Penultimate Friday of February, May, August, November | J35: 6 | K35: 2 | L35: 3 | O35: CDP | P35: NXTG | Q35: CDP provides CDP score; annual review in March. Only Review Announcement at Annual. | R35: Ken | S35: New Sheet | T35: Automatic | U35: Dataiku | V35: Yes | W35: FREEP | X35: Third Friday of March | Y35: Third Friday of June | Z35: Third Friday of September | AA35: Third Friday of December | AJ35: 45740 | AK35: 45831 | AL35: 45922 | AM35: 46013 | BD35: Penultimate Friday of February | BE35: Penultimate Friday of May | BF35: Penultimate Friday of August | BG35: Penultimate Friday of November | BP35: 45712 | BQ35: 45803 | BR35: 45894 | BS35: 45985 | CB35: 45730 | CC35: 45821 | CD35: 45912 | CE35: 46003 | CN35: 45736 | CO35: 45827 | CP35: 45918 | CQ35: 46009 | DL35: 4 | DM35: 4 | DN35: 4 | DO35: 4 | DP35: 0 | DQ35: 16 | DR35: 551 | DV35: 44610.311 | DW35: 2022 | DX35: 2
B36: Price | C36: 2.6 Normal index | D36: SBF Top 50 ESG | E36: 43390 | G36: 1 | H36: Third Friday of March, June, September, December | I36: Penultimate Friday of February, May, August, November | K36: 2 | L36: 3 | O36: Moody's | P36: NXTG | Q36: Underlying is the SBF120 | R36: Lex | S36: New Sheet | T36: Automatic | U36: Dataiku | V36: Yes | W36: ESF5P | X36: Third Friday of March | Y36: Third Friday of June | Z36: Third Friday of September | AA36: Third Friday of December | AJ36: 45740 | AK36: 45831 | AL36: 45922 | AM36: 46013 | BD36: Penultimate Friday of February | BE36: Penultimate Friday of May | BF36: Penultimate Friday of August | BG36: Penultimate Friday of November | BP36: 45712 | BQ36: 45803 | BR36: 45894 | BS36: 45985 | CN36: 45736 | CO36: 45827 | CP36: 45918 | CQ36: 46009 | DL36: 4 | DM36: 4 | DN36: 0 | DO36: 4 | DP36: 0 | DQ36: 12 | DR36: 567 | DV36: 44483.753 | DW36: 2021 | DX36: 10
B37: Price | C37: 2.2 Responsible Investment | D37: Responsible Investment CAC Large 60 | E37: 43411 | G37: 1 | H37: Third Friday of March, June, September, December | I37: Penultimate Friday of February, May, August, November | K37: 2 | L37: 3 | O37: ISS ESG | P37: NXTG | Q37: Underlying is CAC40 and Large 60 | R37: Anna | S37: New Sheet | T37: Automatic | U37: Dataiku | V37: Yes | W37: C6RIP | X37: Third Friday of March | Y37: Third Friday of June | Z37: Third Friday of September | AA37: Third Friday of December | AJ37: 45740 | AK37: 45831 | AL37: 45922 | AM37: 46013 | BD37: Penultimate Friday of February | BE37: Penultimate Friday of May | BF37: Penultimate Friday of August | BG37: Penultimate Friday of November | BP37: 45712 | BQ37: 45803 | BR37: 45894 | BS37: 45985 | CN37: 45736 | CO37: 45827 | CP37: 45918 | CQ37: 46009 | DL37: 4 | DM37: 4 | DN37: 0 | DO37: 4 | DP37: 0 | DQ37: 12 | DR37: 579 | DV37: 44483.75 | DW37: 2021 | DX37: 10
B38: Price | C38: 2.2 Responsible Investment | D38: Responsible Investment Euronext France 40 | E38: 43411 | G38: 1 | H38: Third Friday of March, June, September, December | I38: Penultimate Friday of February, May, August, November | K38: 2 | L38: 3 | O38: ISS ESG | P38: NXTG | Q38: Underlying is CAC40 and Large 60 | R38: Anna | S38: New Sheet | T38: Automatic | U38: Dataiku | V38: Yes | W38: F4RIP | X38: Third Friday of March | Y38: Third Friday of June | Z38: Third Friday of September | AA38: Third Friday of December | AJ38: 45740 | AK38: 45831 | AL38: 45922 | AM38: 46013 | BD38: Penultimate Friday of February | BE38: Penultimate Friday of May | BF38: Penultimate Friday of August | BG38: Penultimate Friday of November | BP38: 45712 | BQ38: 45803 | BR38: 45894 | BS38: 45985 | CN38: 45736 | CO38: 45827 | CP38: 45918 | CQ38: 46009 | DL38: 4 | DM38: 4 | DN38: 0 | DO38: 4 | DP38: 0 | DQ38: 12 | DR38: 591 | DV38: 44483.75 | DW38: 2021 | DX38: 10
B39: Price | C39: 2.6 Normal index | D39: Transatlantic 50 EW | E39: 43418 | G39: 1 | H39: Third Friday of March, June, September, December | I39: Penultimate Friday of February, May, August, November | K39: 2 | L39: 3 | P39: EUS5P | Q39: Underlying universe is mother index Eurozone 300 + 50 largest FF Mcap US; Composition to be announced on Wednesday on base of Tuesday close | R39: Amanda | S39: New Sheet | T39: Automatic | U39: Dataiku | V39: Yes | W39: EUS5P | X39: Third Friday of March | Y39: Third Friday of June | Z39: Third Friday of September | AA39: Third Friday of December | AJ39: 45740 | AK39: 45831 | AL39: 45922 | AM39: 46013 | BD39: Penultimate Friday of February | BE39: Penultimate Friday of May | BF39: Penultimate Friday of August | BG39: Penultimate Friday of November | BP39: 45712 | BQ39: 45803 | BR39: 45894 | BS39: 45985 | CN39: 45736 | CO39: 45827 | CP39: 45918 | CQ39: 46009 | DL39: 4 | DM39: 4 | DN39: 0 | DO39: 4 | DP39: 0 | DQ39: 12 | DR39: 603 | DV39: 44483.753 | DW39: 2021 | DX39: 10
B40: Price | C40: 2.2 Responsible Investment | D40: Responsible Investment Euro 50 | E40: 43439 | G40: 1 | H40: Third Friday of March, June, September, December | I40: Penultimate Friday of February, May, August, November | K40: 2 | L40: 3 | O40: ISS ESG | P40: NXTG | Q40: Underlying universe is mother index Eurozone 300 | R40: Anna | S40: New Sheet | T40: Automatic | U40: Dataiku | V40: Yes | W40: ERI5P | X40: Third Friday of March | Y40: Third Friday of June | Z40: Third Friday of September | AA40: Third Friday of December | AJ40: 45740 | AK40: 45831 | AL40: 45922 | AM40: 46013 | BD40: Penultimate Friday of February | BE40: Penultimate Friday of May | BF40: Penultimate Friday of August | BG40: Penultimate Friday of November | BP40: 45712 | BQ40: 45803 | BR40: 45894 | BS40: 45985 | CN40: 45736 | CO40: 45827 | CP40: 45918 | CQ40: 46009 | DL40: 4 | DM40: 4 | DN40: 0 | DO40: 4 | DP40: 0 | DQ40: 12 | DR40: 615 | DV40: 44610.31 | DW40: 2022 | DX40: 2
B41: Price | C41: 2.0 CDP | D41: CDP Environment Eurozone | E41: 43518 | G41: 1 | H41: Third Friday of March, June, September, December | I41: Penultimate Friday of February, May, August, November | J41: 6 | K41: 2 | L41: 3 | O41: CDP | P41: NXTG | Q41: Underlying Universe in Mother index Eurozone 300; CDP provides CDP score; annual review in March. Only Review Announcement at Annual. | R41: Ken | S41: New Sheet | T41: Automatic | U41: Dataiku | V41: Yes | W41: EZENP | X41: Third Friday of March | Y41: Third Friday of June | Z41: Third Friday of September | AA41: Third Friday of December | AJ41: 45740 | AK41: 45831 | AL41: 45922 | AM41: 46013 | BD41: Penultimate Friday of February | BE41: Penultimate Friday of May | BF41: Penultimate Friday of August | BG41: Penultimate Friday of November | BP41: 45712 | BQ41: 45803 | BR41: 45894 | BS41: 45985 | CB41: 45730 | CC41: 45821 | CD41: 45912 | CE41: 46003 | CN41: 45736 | CO41: 45827 | CP41: 45918 | CQ41: 46009 | DL41: 4 | DM41: 4 | DN41: 4 | DO41: 4 | DP41: 0 | DQ41: 16 | DR41: 691 | DV41: 44610.311 | DW41: 2022 | DX41: 2
B42: Price | C42: 2.0 CDP | D42: CDP Environment World | E42: 43518 | G42: 1 | H42: Third Friday of March, June, September, December | I42: Penultimate Friday of February, May, August, November | J42: 6 | K42: 2 | L42: 3 | O42: CDP | P42: CUSTOM | Q42: CDP provides CDP score; annual review in March. US index, review composition sent out +1 (Thursday morning instead of Wednesday night). Only Review Announcement at Annual. | R42: Ken | S42: New Sheet | T42: Automatic | U42: Dataiku | V42: Yes | W42: WLENP | X42: Third Friday of March | Y42: Third Friday of June | Z42: Third Friday of September | AA42: Third Friday of December | AJ42: 45740 | AK42: 45831 | AL42: 45922 | AM42: 46013 | BD42: Penultimate Friday of February | BE42: Penultimate Friday of May | BF42: Penultimate Friday of August | BG42: Penultimate Friday of November | BP42: 45712 | BQ42: 45803 | BR42: 45894 | BS42: 45985 | CB42: 45730 | CC42: 45821 | CD42: 45912 | CE42: 46003 | CN42: 45736 | CO42: 45827 | CP42: 45918 | CQ42: 46009 | DL42: 4 | DM42: 4 | DN42: 4 | DO42: 4 | DP42: 0 | DQ42: 16 | DR42: 707 | DV42: 44761.329 | DW42: 2022 | DX42: 7
...

Sheet AUM
AA2: 9.9652665e+09 | AB2: 3.0051983e+10 | AC2: 1.5548497e+10 | AD2: 6.3977345e+10 | AE2: 2.8613287e+11 | AF2: 2.7967554e+10 | AG2: 4.0807806e+11
C3: ESG Yes/No | D3: (Multiple Items) | G3: ESG Yes/No | H3: (Multiple Items) | K3: ESG Yes/No | L3: Yes | Q3: Blue-Chip | R3: Yes | T3: Blue-Chip | U3: Yes | AA3: TRUE | AB3: TRUE | AC3: TRUE | AD3: TRUE | AE3: TRUE | AF3: TRUE | AG3: TRUE
C5: Indices | D5: Total AUM per Index | E5: Classification | G5: Family Index | H5: Total AUM per Family Index | I5: Classification | K5: Row Labels | L5: Sum of Total | Q5: Family Index | R5: Total AUM per Family Index | T5: Family Index | U5: Total AUM per Family Index
C6: CAC 40 | D6: 1.789033e+11 | E6: =IF(D6>=500000000000,"Critical",IF(AND(D6>=50000000000,D6<500000000000),"Significant",IF(AND(D6>=45000000000,D6<50000000000),"Almost Significant",IF(D6<45000000000,"Non Significant",0)))) -> Significant | G6: CAC | H6: 2.1352225e+11 | I6: =IF(H6>=500000000000,"Critical",IF(AND(H6>=50000000000,H6<500000000000),"Significant",IF(AND(H6>=45000000000,H6<50000000000),"Almost Significant",IF(H6<45000000000,"Non Significant",0)))) -> Significant | K6: CTB | L6: 5262516339 | N6: ESG | O6: Sum of Total | Q6: CAC | R6: 1.9661952e+11 | T6: CAC 40 | U6: 1.789033e+11
C7: AEX-Index | D7: 1.3539561e+11 | E7: =IF(D7>=500000000000,"Critical",IF(AND(D7>=50000000000,D7<500000000000),"Significant",IF(AND(D7>=45000000000,D7<50000000000),"Almost Significant",IF(D7<45000000000,"Non Significant",0)))) -> Significant | G7: AEX | H7: 1.3664278e+11 | I7: =IF(H7>=500000000000,"Critical",IF(AND(H7>=50000000000,H7<500000000000),"Significant",IF(AND(H7>=45000000000,H7<50000000000),"Almost Significant",IF(H7<45000000000,"Non Significant",0)))) -> Significant | K7: ESG Other | L7: 1.2799828e+10 | N7: No | O7: 3.8825257e+11 | Q7: AEX | R7: 1.3607295e+11 | T7: AEX-Index | U7: 1.3539561e+11
C8: CAC 40 NR | D8: 1.3337071e+10 | E8: =IF(D8>=500000000000,"Critical",IF(AND(D8>=50000000000,D8<500000000000),"Significant",IF(AND(D8>=45000000000,D8<50000000000),"Almost Significant",IF(D8<45000000000,"Non Significant",0)))) -> Non Significant | G8: Oslo Børs Benchmark and Mutual Fund | H8: 2.1312566e+10 | I8: =IF(H8>=500000000000,"Critical",IF(AND(H8>=50000000000,H8<500000000000),"Significant",IF(AND(H8>=45000000000,H8<50000000000),"Almost Significant",IF(H8<45000000000,"Non Significant",0)))) -> Non Significant | K8: PAB | L8: 1.7631462e+09 | N8: Yes | O8: 1.9825491e+10 | Q8: CAC 40 ESG | R8: 1781588879 | T8: CAC 40 NR | U8: 1.3337071e+10
C9: Oslo Børs Mutual Fund Index_GI | D9: 1.2522008e+10 | E9: =IF(D9>=500000000000,"Critical",IF(AND(D9>=50000000000,D9<500000000000),"Significant",IF(AND(D9>=45000000000,D9<50000000000),"Almost Significant",IF(D9<45000000000,"Non Significant",0)))) -> Non Significant | G9: Euronext V.E ESG World-Select 75 Bund SV | H9: 5262516339 | I9: =IF(H9>=500000000000,"Critical",IF(AND(H9>=50000000000,H9<500000000000),"Significant",IF(AND(H9>=45000000000,H9<50000000000),"Almost Significant",IF(H9<45000000000,"Non Significant",0)))) -> Non Significant | K9: (blank) | L9: 0 | N9: (blank) | O9: 0 | Q9: PSI | R9: 6.0827938e+08 | T9: CAC 40 GR | U9: 4.379145e+09
C10: Oslo Børs Benchmark Index_GI | D10: 8.7905575e+09 | E10: =IF(D10>=500000000000,"Critical",IF(AND(D10>=50000000000,D10<500000000000),"Significant",IF(AND(D10>=45000000000,D10<50000000000),"Almost Significant",IF(D10<45000000000,"Non Significant",0)))) -> Non Significant | G10: Euronext Single Stock Decrement | H10: 4.9314225e+09 | I10: =IF(H10>=500000000000,"Critical",IF(AND(H10>=50000000000,H10<500000000000),"Significant",IF(AND(H10>=45000000000,H10<50000000000),"Almost Significant",IF(H10<45000000000,"Non Significant",0)))) -> Non Significant | K10: Grand Total | L10: 1.9825491e+10 | N10: Grand Total | O10: 4.0807806e+11 | Q10: OBX | R10: 5.9796738e+08 | T10: CAC 40 ESG NR | U10: 1114756668
C11: CAC All-Tradable NR | D11: 6.0207381e+09 | E11: =IF(D11>=500000000000,"Critical",IF(AND(D11>=50000000000,D11<500000000000),"Significant",IF(AND(D11>=45000000000,D11<50000000000),"Almost Significant",IF(D11<45000000000,"Non Significant",0)))) -> Non Significant | G11: CAC-EWE | H11: 4.1987155e+09 | I11: =IF(H11>=500000000000,"Critical",IF(AND(H11>=50000000000,H11<500000000000),"Significant",IF(AND(H11>=45000000000,H11<50000000000),"Almost Significant",IF(H11<45000000000,"Non Significant",0)))) -> Non Significant | Q11: BEL | R11: 3.6912727e+08 | T11: AEX NR | U11: 6.7734585e+08
C12: SBF 120 NR | D12: 5.9485787e+09 | E12: =IF(D12>=500000000000,"Critical",IF(AND(D12>=50000000000,D12<500000000000),"Significant",IF(AND(D12>=45000000000,D12<50000000000),"Almost Significant",IF(D12<45000000000,"Non Significant",0)))) -> Non Significant | G12: SBF TOP 80 EW | H12: 2738000000 | I12: =IF(H12>=500000000000,"Critical",IF(AND(H12>=50000000000,H12<500000000000),"Significant",IF(AND(H12>=45000000000,H12<50000000000),"Almost Significant",IF(H12<45000000000,"Non Significant",0)))) -> Non Significant | Q12: MIB ESG | R12: 72633454 | T12: OBX Total Return Index | U12: 5.9796738e+08
C13: Euronext V.E ESG World-Select 75 Bund/SV | D13: 5262516339 | E13: =IF(D13>=500000000000,"Critical",IF(AND(D13>=50000000000,D13<500000000000),"Significant",IF(AND(D13>=45000000000,D13<50000000000),"Almost Significant",IF(D13<45000000000,"Non Significant",0)))) -> Non Significant | G13: Euronext Climate Objective 50 Euro EW | H13: 1.7950542e+09 | I13: =IF(H13>=500000000000,"Critical",IF(AND(H13>=50000000000,H13<500000000000),"Significant",IF(AND(H13>=45000000000,H13<50000000000),"Almost Significant",IF(H13<45000000000,"Non Significant",0)))) -> Non Significant | Q13: Total | R13: 3.3612206e+11 | T13: CAC 40 ESG GR | U13: 329732605
C14: CAC 40 GR | D14: 4.379145e+09 | E14: =IF(D14>=500000000000,"Critical",IF(AND(D14>=50000000000,D14<500000000000),"Significant",IF(AND(D14>=45000000000,D14<50000000000),"Almost Significant",IF(D14<45000000000,"Non Significant",0)))) -> Non Significant | G14: CAC 40 ESG | H14: 1781588879 | I14: =IF(H14>=500000000000,"Critical",IF(AND(H14>=50000000000,H14<500000000000),"Significant",IF(AND(H14>=45000000000,H14<50000000000),"Almost Significant",IF(H14<45000000000,"Non Significant",0)))) -> Non Significant | T14: PSI | U14: 3.0632123e+08
C15: CAC Large 60 EW ER | D15: 2.9146715e+09 | E15: =IF(D15>=500000000000,"Critical",IF(AND(D15>=50000000000,D15<500000000000),"Significant",IF(AND(D15>=45000000000,D15<50000000000),"Almost Significant",IF(D15<45000000000,"Non Significant",0)))) -> Non Significant | G15: SBF Top 50 ESG EW | H15: 1.4316726e+09 | I15: =IF(H15>=500000000000,"Critical",IF(AND(H15>=50000000000,H15<500000000000),"Significant",IF(AND(H15>=45000000000,H15<50000000000),"Almost Significant",IF(H15<45000000000,"Non Significant",0)))) -> Non Significant | T15: PSI GR | U15: 3.0195814e+08
C16: SBF Top 80 EW Decrement 50 Points | D16: 2738000000 | E16: =IF(D16>=500000000000,"Critical",IF(AND(D16>=50000000000,D16<500000000000),"Significant",IF(AND(D16>=45000000000,D16<50000000000),"Almost Significant",IF(D16<45000000000,"Non Significant",0)))) -> Non Significant | G16: Low Carbon 100 Europe PAB | H16: 1386268710 | I16: =IF(H16>=500000000000,"Critical",IF(AND(H16>=50000000000,H16<500000000000),"Significant",IF(AND(H16>=45000000000,H16<50000000000),"Almost Significant",IF(H16<45000000000,"Non Significant",0)))) -> Non Significant | T16: BEL 20 NR | U16: 254158873
C17: CAC Mid & Small NR | D17: 2.0033838e+09 | E17: =IF(D17>=500000000000,"Critical",IF(AND(D17>=50000000000,D17<500000000000),"Significant",IF(AND(D17>=45000000000,D17<50000000000),"Almost Significant",IF(D17<45000000000,"Non Significant",0)))) -> Non Significant | G17: Euronext Euro 50 ESG EW | H17: 9.659314e+08 | I17: =IF(H17>=500000000000,"Critical",IF(AND(H17>=50000000000,H17<500000000000),"Significant",IF(AND(H17>=45000000000,H17<50000000000),"Almost Significant",IF(H17<45000000000,"Non Significant",0)))) -> Non Significant | T17: CAC 40 ESG Decrement 5% | U17: 200000000
