Workbook

Sheet Index Composition
A1: Company | B1: ISIN Code | C1: MIC | D1: Number of Shares | E1: Free Float | F1: Capping Factor | G1: Effective Date of Review | H1: Currency
A2: ADIDAS AG | B2: DE000A1EWWW0 | C2: XETR | D2: 383320 | E2: 1 | F2: 1 | G2: 22-Dec-25 | H2: EUR | I2: =ISNUMBER(MATCH(B2,[1]selection!$B$2:$B$41,0)) -> TRUE
A3: AIR LIQUIDE | B3: FR0000120073 | C3: XPAR | D3: 405324 | E3: 1 | F3: 1 | G3: 22-Dec-25 | H3: EUR | I3: =ISNUMBER(MATCH(B3,[1]selection!$B$2:$B$41,0)) -> TRUE
A4: ALLIANZ SE | B4: DE0008404005 | C4: XETR | D4: 168559 | E4: 1 | F4: 1 | G4: 22-Dec-25 | H4: EUR | I4: =ISNUMBER(MATCH(B4,[1]selection!$B$2:$B$41,0)) -> TRUE
A5: AMADEUS IT GROUP | B5: ES0109067019 | C5: XMAD | D5: 1038724 | E5: 1 | F5: 1 | G5: 22-Dec-25 | H5: EUR | I5: =ISNUMBER(MATCH(B5,[1]selection!$B$2:$B$41,0)) -> TRUE
A6: ASML HOLDING | B6: NL0010273215 | C6: XAMS | D6: 71108 | E6: 1 | F6: 1 | G6: 22-Dec-25 | H6: EUR | I6: =ISNUMBER(MATCH(B6,[1]selection!$B$2:$B$41,0)) -> TRUE
A7: AXA | B7: FR0000120628 | C7: XPAR | D7: 1593308 | E7: 1 | F7: 1 | G7: 22-Dec-25 | H7: EUR | I7: =ISNUMBER(MATCH(B7,[1]selection!$B$2:$B$41,0)) -> TRUE
A8: BANCO SANTANDER CENT | B8: ES0113900J37 | C8: XMAD | D8: 6581301 | E8: 1 | F8: 1 | G8: 22-Dec-25 | H8: EUR | I8: =ISNUMBER(MATCH(B8,[1]selection!$B$2:$B$41,0)) -> TRUE
A9: BBVA | B9: ES0113211835 | C9: XMAD | D9: 3346731 | E9: 1 | F9: 1 | G9: 22-Dec-25 | H9: EUR | I9: =ISNUMBER(MATCH(B9,[1]selection!$B$2:$B$41,0)) -> TRUE
A10: BNP PARIBAS ACT.A | B10: FR0000131104 | C10: XPAR | D10: 819283 | E10: 1 | F10: 1 | G10: 22-Dec-25 | H10: EUR | I10: =ISNUMBER(MATCH(B10,[1]selection!$B$2:$B$41,0)) -> TRUE
A11: CAIXABANK | B11: ES0140609019 | C11: XMAD | D11: 6359117 | E11: 1 | F11: 1 | G11: 22-Dec-25 | H11: EUR | I11: =ISNUMBER(MATCH(B11,[1]selection!$B$2:$B$41,0)) -> TRUE
A12: DANONE | B12: FR0000120644 | C12: XPAR | D12: 839291 | E12: 1 | F12: 1 | G12: 22-Dec-25 | H12: EUR | I12: =ISNUMBER(MATCH(B12,[1]selection!$B$2:$B$41,0)) -> TRUE
A13: DEUTSCHE BANK | B13: DE0005140008 | C13: XETR | D13: 2031079 | E13: 1 | F13: 1 | G13: 22-Dec-25 | H13: EUR | I13: =ISNUMBER(MATCH(B13,[1]selection!$B$2:$B$41,0)) -> TRUE
... A41: UNILEVER | B41: GB00BVZK7T90 | C41: XAMS | D41: 1180713 | E41: 1 | F41: 1 | G41: 22-Dec-25 | H41: EUR | I41: =ISNUMBER(MATCH(B41,[1]selection!$B$2:$B$41,0)) -> TRUE

Sheet Inclusion
A1: Company | B1: ISIN code | C1: MIC
A2: DEUTSCHE BANK | B2: DE0005140008 | C2: XETR
A3: DEUTSCHE TELEKOM AG | B3: DE0005557508 | C3: XETR
A4: MERCEDES-BENZ GROUP | B4: DE0007100000 | C4: XETR
A5: NOKIA | B5: FI0009000681 | C5: XHEL
A6: SANOFI | B6: FR0000120578 | C6: XPAR
A7: UNILEVER | B7: GB00BVZK7T90 | C7: XAMS

Sheet Exclusion
A1: Company | B1: ISIN code | C1: MIC
A2: COMMERZBANK AG | B2: DE000CBK1001 | C2: XETR
A3: DEUTSCHE POST | B3: DE0005552004 | C3: XETR
A4: FERROVIAL | B4: NL0015001FS8 | C4: XMAD
A5: L'OREAL | B5: FR0000120321 | C5: XPAR
A6: MICHELIN | B6: FR001400AJ45 | C6: XPAR
A7: WOLTERS KLUWER | B7: NL0000395903 | C7: XAMS

Sheet Top 40 Selection
A1: Rank | B1: Ticker | C1: Company | D1: ISIN code | E1: MIC | F1: Number of Shares | G1: Price | H1: Currency | I1: 12 month aver. turnover EUR | J1: 20 days aver. turn EUR | K1: 10 days aver. turn EUR | L1: 5 days aver. turn EUR | M1: 6 month aver. turnover EUR | N1: 126 days volatility | O1: 100 days volatility | P1: 100 days aver. turn EUR | Q1: 180 days volatility | R1: 3 months aver. Turnover EUR | S1: 3 months aver. Turnover USD | T1: Effective Date of Review | U1: #Symbol | V1: FX/Index Ccy | W1: Close Prc_EOD | X1: Close Prc_CO | Y1: Free Float Round: | Z1: FFMC_CO | AA1: 171613102999 - Controversial Weapons Non tailor-made or non essential-Category of Involvement Id | AB1: 171611102999 - Controversial Weapons Tailor-made and essential-Category of Involvement Id | AC1: 181110112399 - ESG Risk Score | AD1: 121010112599 - Highest Controversy Level-Answer Category | AE1: 172113112999 - Military Contracting Weapon-related products and/or services-Level of Involvement Id | AF1: 172111112999 - Military Contracting Weapons-Level of Involvement Id | AG1: 173011102999 - Oil Sands Extraction-Category of Involvement Id | AH1: 173211102999 - Shale Energy Extraction-Category of Involvement Id | AI1: 171711112999 - Small Arms Civilian customers (Assault weapons)-Level of Involvement Id | AJ1: 171721112999 - Small Arms Civilian customers (Non-assault weapons)-Level of Involvement Id | AK1: 171025111199 - Thermal Coal Extraction-Revenue Percentage | AL1: 172813112999 - Thermal Coal Power Generation-Level of Involvement Id | AM1: 172911112999 - Tobacco Products Production-Level of Involvement Id | AN1: 172915112999 - Tobacco Products Retail-Level of Involvement Id | AO1: excl_controversy | AP1: excl_tobacco_production | AQ1: excl_tobacco_retail | AR1: excl_military_weapons | AS1: excl_military_related | AT1: excl_controv_weapons_essential | AU1: excl_controv_weapons_non_essential | AV1: excl_small_arms_assault | AW1: excl_small_arms_non_assault | AX1: excl_oil_sands | AY1: excl_shale_energy | AZ1: excl_thermal_coal_extraction | BA1: excl_thermal_coal_power | BB1: excluded | BC1: FFMC_Rank | BD1: ESG_Risk_Score | BE1: ESG_Risk_Rank | BF1: Unrounded NOSH | BG1: Rounded NOSH | BH1: Free Float | BI1: Capping Factor
A2: 245 | B2: SU-FR | C2: SCHNEIDER ELECTRIC | D2: FR0000121972 | E2: XPAR | F2: 577122512 | G2: 222.3 | H2: EUR | I2: 2.2594707e+08 | J2: 2.0740473e+08 | M2: 1.9984495e+08 | N2: 29.388895 | O2: 29.79526 | P2: 2.0034853e+08 | Q2: 33.028824 | R2: 2.0033574e+08 | S2: 2.3358204e+08 | T2: 22-Dec-25 | U2: SCHN.PA | V2: 1 | W2: 239.25 | X2: 222.3 | Y2: 1 | Z2: 1.2829433e+11 | AA2: 0 | AB2: 0 | AC2: 7.1448088 | AD2: 2 | AE2: 1 | AF2: 0 | AG2: 0 | AH2: 0 | AI2: 0 | AJ2: 0 | AK2: 0 | AL2: 0 | AM2: 0 | AN2: 0 | AO2: FALSE | AP2: FALSE | AQ2: FALSE | AR2: FALSE | AS2: FALSE | AT2: FALSE | AU2: FALSE | AV2: FALSE | AW2: FALSE | AX2: FALSE | AY2: FALSE | AZ2: FALSE | BA2: FALSE | BB2: FALSE | BC2: 8 | BD2: 7.1448088 | BE2: 1 | BF2: 270046.53 | BG2: 270047 | BH2: 1 | BI2: 1
A3: 158 | B3: ISP-IT | C3: INTESA SANPAOLO | D3: IT0000072618 | E3: MTAA | F3: 17413389613 | G3: 5.619 | H3: EUR | I3: 2.9376709e+08 | J3: 3.2506638e+08 | M3: 2.681535e+08 | N3: 23.324429 | O3: 24.010738 | P3: 2.6892967e+08 | Q3: 28.28163 | R3: 2.8286848e+08 | S3: 3.2952365e+08 | T3: 22-Dec-25 | U3: ISP.MI | V3: 1 | W3: 5.783 | X3: 5.619 | Y3: 0.8 | Z3: 7.8276669e+10 | AA3: 0 | AB3: 0 | AC3: 8.09 | AD3: 2 | AE3: 0 | AF3: 0 | AG3: 0 | AH3: 0 | AI3: 0 | AJ3: 0 | AK3: 0 | AL3: 0 | AM3: 0 | AN3: 0 | AO3: FALSE | AP3: FALSE | AQ3: FALSE | AR3: FALSE | AS3: FALSE | AT3: FALSE | AU3: FALSE | AV3: FALSE | AW3: FALSE | AX3: FALSE | AY3: FALSE | AZ3: FALSE | BA3: FALSE | BB3: FALSE | BC3: 18 | BD3: 8.09 | BE3: 2 | BF3: 11172166 | BG3: 11172166 | BH3: 1 | BI3: 1
A4: 225 | B4: REN-NL | C4: RELX | D4: GB00B2B0DG97 | E4: XAMS | F4: 1907070957 | G4: 35.28 | H4: EUR | I4: 35151618 | J4: 38042579 | M4: 29814886 | N4: 20.830658 | O4: 22.413506 | P4: 31979317 | Q4: 23.983385 | R4: 32638215 | S4: 38012065 | T4: 22-Dec-25 | U4: REL.AS | V4: 1 | W4: 34.66 | X4: 35.28 | Y4: 1 | Z4: 6.7281463e+10 | AA4: 0 | AB4: 0 | AC4: 8.1090937 | AD4: 2 | AE4: 0 | AF4: 0 | AG4: 0 | AH4: 0 | AI4: 0 | AJ4: 0 | AK4: 0 | AL4: 0 | AM4: 0 | AN4: 0 | AO4: FALSE | AP4: FALSE | AQ4: FALSE | AR4: FALSE | AS4: FALSE | AT4: FALSE | AU4: FALSE | AV4: FALSE | AW4: FALSE | AX4: FALSE | AY4: FALSE | AZ4: FALSE | BA4: FALSE | BB4: FALSE | BC4: 23 | BD4: 8.1090937 | BE4: 3 | BF4: 1864069.1 | BG4: 1864069 | BH4: 1 | BI4: 1
A5: 36 | B5: ASML-NL | C5: ASML HOLDING | D5: NL0010273215 | E5: XAMS | F5: 388147674 | G5: 834 | H5: EUR | I5: 5.0748503e+08 | J5: 5.1907545e+08 | M5: 4.7687009e+08 | N5: 35.69043 | O5: 37.997826 | P5: 4.9820659e+08 | Q5: 36.628567 | R5: 5.3938184e+08 | S5: 6.2879074e+08 | T5: 22-Dec-25 | U5: ASML.AS | V5: 1 | W5: 908.6 | X5: 834 | Y5: 1 | Z5: 323715160116 | AA5: 0 | AB5: 0 | AC5: 8.928945 | AD5: 2 | AE5: 0 | AF5: 0 | AG5: 0 | AH5: 0 | AI5: 0 | AJ5: 0 | AK5: 0 | AL5: 0 | AM5: 0 | AN5: 0 | AO5: FALSE | AP5: FALSE | AQ5: FALSE | AR5: FALSE | AS5: FALSE | AT5: FALSE | AU5: FALSE | AV5: FALSE | AW5: FALSE | AX5: FALSE | AY5: FALSE | AZ5: FALSE | BA5: FALSE | BB5: FALSE | BC5: 1 | BD5: 8.928945 | BE5: 4 | BF5: 71107.895 | BG5: 71108 | BH5: 1 | BI5: 1
A6: 92 | B6: DBK-DE | C6: DEUTSCHE BANK | D6: DE0005140008 | E6: XETR | F6: 1948252900 | G6: 29.385 | H6: EUR | I6: 1.7015314e+08 | J6: 1.6283173e+08 | M6: 1.6847277e+08 | N6: 30.730797 | O6: 30.842863 | P6: 1.7071545e+08 | Q6: 36.20055 | R6: 1.7798169e+08 | S6: 2.0768553e+08 | T6: 22-Dec-25 | U6: DBKGn.DE | V6: 1 | W6: 31.81 | X6: 29.385 | Y6: 1 | Z6: 5.7249411e+10 | AA6: 0 | AB6: 0 | AC6: 8.9654925 | AD6: 3 | AE6: 0 | AF6: 0 | AG6: 0 | AH6: 0 | AI6: 0 | AJ6: 0 | AK6: 0 | AL6: 0 | AM6: 0 | AN6: 0 | AO6: FALSE | AP6: FALSE | AQ6: FALSE | AR6: FALSE | AS6: FALSE | AT6: FALSE | AU6: FALSE | AV6: FALSE | AW6: FALSE | AX6: FALSE | AY6: FALSE | AZ6: FALSE | BA6: FALSE | BB6: FALSE | BC6: 27 | BD6: 8.9654925 | BE6: 5 | BF6: 2031079.3 | BG6: 2031079 | BH6: 1 | BI6: 1
A7: 72 | B7: CABK-ES | C7: CAIXABANK | D7: ES0140609019 | E7: XMAD | F7: 7085565400 | G7: 9.254 | H7: EUR | I7: 62448678 | J7: 1.3507376e+08 | M7: 58951377 | N7: 22.261782 | O7: 21.86623 | P7: 59991050 | Q7: 29.400314 | R7: 67273797 | S7: 78123008 | T7: 22-Dec-25 | U7: CABK.MC | V7: 1 | W7: 10.16 | X7: 9.254 | Y7: 0.5 | Z7: 3.2784911e+10 | AA7: 0 | AB7: 0 | AC7: 9.509 | AD7: 2 | AE7: 0 | AF7: 0 | AG7: 0 | AH7: 0 | AI7: 0 | AJ7: 0 | AK7: 0 | AL7: 0 | AM7: 0 | AN7: 0 | AO7: FALSE | AP7: FALSE | AQ7: FALSE | AR7: FALSE | AS7: FALSE | AT7: FALSE | AU7: FALSE | AV7: FALSE | AW7: FALSE | AX7: FALSE | AY7: FALSE | AZ7: FALSE | BA7: FALSE | BB7: FALSE | BC7: 45 | BD7: 9.509 | BE7: 6 | BF7: 6359117.5 | BG7: 6359117 | BH7: 1 | BI7: 1
A8: 57 | B8: BBVA-ES | C8: BBVA | D8: ES0113211835 | E8: XMAD | F8: 5763285600 | G8: 17.705 | H8: EUR | I8: 1.3566252e+08 | J8: 3.6713379e+08 | M8: 1.4393072e+08 | N8: 27.777552 | O8: 28.950481 | P8: 1.5470505e+08 | Q8: 31.000454 | R8: 1.7807689e+08 | S8: 2.0687009e+08 | T8: 22-Dec-25 | U8: BBVA.MC | V8: 1 | W8: 19.305 | X8: 17.705 | Y8: 1 | Z8: 102038971548 | AA8: 0 | AB8: 0 | AC8: 9.56425 | AD8: 2 | AE8: 0 | AF8: 0 | AG8: 0 | AH8: 0 | AI8: 0 | AJ8: 0 | AK8: 0 | AL8: 0 | AM8: 0 | AN8: 0 | AO8: FALSE | AP8: FALSE | AQ8: FALSE | AR8: FALSE | AS8: FALSE | AT8: FALSE | AU8: FALSE | AV8: FALSE | AW8: FALSE | AX8: FALSE | AY8: FALSE | AZ8: FALSE | BA8: FALSE | BB8: FALSE | BC8: 11 | BD8: 9.56425 | BE8: 7 | BF8: 3346730.6 | BG8: 3346731 | BH8: 1 | BI8: 1
A9: 203 | B9: NOKIA-FI | C9: NOKIA | D9: FI0009000681 | E9: XHEL | F9: 5742239700 | G9: 5.13 | H9: EUR | I9: 57797346 | J9: 77090097 | M9: 60440865 | N9: 44.634285 | O9: 48.75582 | P9: 67323848 | Q9: 42.79206 | R9: 83697742 | S9: 97482565 | T9: 22-Dec-25 | U9: NOKIA.HE | V9: 1 | W9: 5.278 | X9: 5.13 | Y9: 0.95 | Z9: 2.7984805e+10 | AA9: 0 | AB9: 0 | AC9: 9.6503238 | AD9: 2 | AE9: 0 | AF9: 0 | AG9: 0 | AH9: 0 | AI9: 0 | AJ9: 0 | AK9: 0 | AL9: 0 | AM9: 0 | AN9: 0 | AO9: FALSE | AP9: FALSE | AQ9: FALSE | AR9: FALSE | AS9: FALSE | AT9: FALSE | AU9: FALSE | AV9: FALSE | AW9: FALSE | AX9: FALSE | AY9: FALSE | AZ9: FALSE | BA9: FALSE | BB9: FALSE | BC9: 49 | BD9: 9.6503238 | BE9: 8 | BF9: 12241120 | BG9: 12241120 | BH9: 1 | BI9: 1
A10: 279 | B10: UMG-NL | C10: UMG | D10: NL0015000IY2 | E10: XAMS | F10: 1834181554 | G10: 22.61 | H10: EUR | I10: 46598461 | J10: 39786466 | M10: 47611055 | N10: 25.067509 | O10: 25.950218 | P10: 39603260 | Q10: 26.64878 | R10: 39325563 | S10: 45813287 | T10: 22-Dec-25 | U10: UMG.AS | V10: 1 | W10: 21.72 | X10: 22.61 | Y10: 0.6 | Z10: 2.4882507e+10 | AA10: 0 | AB10: 0 | AC10: 9.7401696 | AD10: 1 | AE10: 0 | AF10: 0 | AG10: 0 | AH10: 0 | AI10: 0 | AJ10: 0 | AK10: 0 | AL10: 0 | AM10: 0 | AN10: 0 | AO10: FALSE | AP10: FALSE | AQ10: FALSE | AR10: FALSE | AS10: FALSE | AT10: FALSE | AU10: FALSE | AV10: FALSE | AW10: FALSE | AX10: FALSE | AY10: FALSE | AZ10: FALSE | BA10: FALSE | BB10: FALSE | BC10: 56 | BD10: 9.7401696 | BE10: 9 | BF10: 2974614.8 | BG10: 2974615 | BH10: 1 | BI10: 1
A11: 51 | B11: SAN-ES | C11: BANCO SANTANDER CENT | D11: ES0113900J37 | E11: XMAD | F11: 14885325000 | G11: 8.805 | H11: EUR | I11: 1.9934083e+08 | J11: 2.4831944e+08 | M11: 1.936803e+08 | N11: 26.54015 | O11: 26.308455 | P11: 1.9984515e+08 | Q11: 31.74772 | R11: 2.1740067e+08 | S11: 2.5332558e+08 | T11: 22-Dec-25 | U11: SAN.MC | V11: 1 | W11: 9.817 | X11: 8.805 | Y11: 1 | Z11: 131065286625 | AA11: 0 | AB11: 0 | AC11: 9.8890125 | AD11: 2 | AE11: 0 | AF11: 0 | AG11: 0 | AH11: 0 | AI11: 0 | AJ11: 0 | AK11: 0 | AL11: 0 | AM11: 0 | AN11: 0 | AO11: FALSE | AP11: FALSE | AQ11: FALSE | AR11: FALSE | AS11: FALSE | AT11: FALSE | AU11: FALSE | AV11: FALSE | AW11: FALSE | AX11: FALSE | AY11: FALSE | AZ11: FALSE | BA11: FALSE | BB11: FALSE | BC11: 7 | BD11: 9.8890125 | BE11: 10 | BF11: 6581301.1 | BG11: 6581301 | BH11: 1 | BI11: 1
A12: 165 | B12: KBC-BE | C12: KBC | D12: BE0003565737 | E12: XBRU | F12: 417544151 | G12: 105.35 | H12: EUR | I12: 39495466 | J12: 40066030 | M12: 36083656 | N12: 19.155403 | O12: 19.713436 | P12: 36288231 | Q12: 24.682182 | R12: 37189985 | S12: 43359474 | T12: 22-Dec-25 | U12: KBC.BR | V12: 1 | W12: 110.5 | X12: 105.35 | Y12: 0.55 | Z12: 2.4193552e+10 | AA12: 0 | AB12: 0 | AC12: 10.209262 | AD12: 1 | AE12: 0 | AF12: 0 | AG12: 0 | AH12: 0 | AI12: 0 | AJ12: 0 | AK12: 0 | AL12: 0 | AM12: 0 | AN12: 0 | AO12: FALSE | AP12: FALSE | AQ12: FALSE | AR12: FALSE | AS12: FALSE | AT12: FALSE | AU12: FALSE | AV12: FALSE | AW12: FALSE | AX12: FALSE | AY12: FALSE | AZ12: FALSE | BA12: FALSE | BB12: FALSE | BC12: 57 | BD12: 10.209262 | BE12: 11 | BF12: 584693.51 | BG12: 584694 | BH12: 1 | BI12: 1
A13: 282 | B13: UCG-IT | C13: UNICREDIT | D13: IT0005239360 | E13: MTAA | F13: 1557675176 | G13: 62.85 | H13: EUR | I13: 3.5910484e+08 | J13: 3.333183e+08 | M13: 3.1436746e+08 | N13: 26.839243 | O13: 26.80322 | P13: 3.2010403e+08 | Q13: 33.4783 | R13: 3.2023355e+08 | S13: 3.7337577e+08 | T13: 22-Dec-25 | U13: CRDI.MI | V13: 1 | W13: 69.5 | X13: 62.85 | Y13: 1 | Z13: 9.7899885e+10 | AA13: 0 | AB13: 0 | AC13: 10.553088 | AD13: 2 | AE13: 0 | AF13: 0 | AG13: 0 | AH13: 0 | AI13: 0 | AJ13: 0 | AK13: 0 | AL13: 0 | AM13: 0 | AN13: 0 | AO13: FALSE | AP13: FALSE | AQ13: FALSE | AR13: FALSE | AS13: FALSE | AT13: FALSE | AU13: FALSE | AV13: FALSE | AW13: FALSE | AX13: FALSE | AY13: FALSE | AZ13: FALSE | BA13: FALSE | BB13: FALSE | BC13: 14 | BD13: 10.553088 | BE13: 12 | BF13: 929620.62 | BG13: 929621 | BH13: 1 | BI13: 1
... A41: 154 | B41: IFX-DE | C41: INFINEON TECHNOLOGIE | D41: DE0006231004 | E41: XETR | F41: 1305921100 | G41: 31.695 | H41: EUR | I41: 1.4281894e+08 | J41: 1.5472296e+08 | M41: 1.30403e+08 | N41: 32.71463 | O41: 34.11599 | P41: 1.2661168e+08 | Q41: 38.33349 | R41: 1.2563083e+08 | S41: 1.463514e+08 | T41: 22-Dec-25 | U41: IFXGn.DE | V41: 1 | W41: 36 | X41: 31.695 | Y41: 1 | Z41: 4.1391169e+10 | AA41: 0 | AB41: 0 | AC41: 16.601476 | AD41: 1 | AE41: 1 | AF41: 0 | AG41: 0 | AH41: 0 | AI41: 0 | AJ41: 0 | AK41: 0 | AL41: 0 | AM41: 0 | AN41: 0 | AO41: FALSE | AP41: FALSE | AQ41: FALSE | AR41: FALSE | AS41: FALSE | AT41: FALSE | AU41: FALSE | AV41: FALSE | AW41: FALSE | AX41: FALSE | AY41: FALSE | AZ41: FALSE | BA41: FALSE | BB41: FALSE | BC41: 34 | BD41: 16.601476 | BE41: 40 | BF41: 1794684.3 | BG41: 1794684 | BH41: 1 | BI41: 1

Sheet Sheet1
B2: 1 | C2: ASML HOLDING | D2: NL0010273215 | E2: =ISNUMBER(MATCH(D2,$H$2:$H$62,0)) -> TRUE | F2: 1 | G2: ASML HOLDING | H2: NL0010273215 | I2: =ISNUMBER(MATCH(H2,$D$2:$D$181,0)) -> TRUE
B3: 1 | C3: ASML HOLDING | D3: NL0010273215 | E3: =ISNUMBER(MATCH(D3,$H$2:$H$62,0)) -> TRUE | F3: 2 | G3: SAP | H3: DE0007164600 | I3: =ISNUMBER(MATCH(H3,$D$2:$D$181,0)) -> TRUE
B4: 1 | C4: ASML HOLDING | D4: NL0010273215 | E4: =ISNUMBER(MATCH(D4,$H$2:$H$62,0)) -> TRUE | F4: 3 | G4: SIEMENS AG | H4: DE0007236101 | I4: =ISNUMBER(MATCH(H4,$D$2:$D$181,0)) -> TRUE
B5: 2 | C5: SAP | D5: DE0007164600 | E5: =ISNUMBER(MATCH(D5,$H$2:$H$62,0)) -> TRUE | F5: 4 | G5: LVMH | H5: FR0000121014 | I5: =ISNUMBER(MATCH(H5,$D$2:$D$181,0)) -> TRUE
B6: 2 | C6: SAP | D6: DE0007164600 | E6: =ISNUMBER(MATCH(D6,$H$2:$H$62,0)) -> TRUE | F6: 5 | G6: ALLIANZ SE | H6: DE0008404005 | I6: =ISNUMBER(MATCH(H6,$D$2:$D$181,0)) -> TRUE
B7: 2 | C7: SAP | D7: DE0007164600 | E7: =ISNUMBER(MATCH(D7,$H$2:$H$62,0)) -> TRUE | F7: 6 | G7: UNILEVER | H7: GB00BVZK7T90 | I7: =ISNUMBER(MATCH(H7,$D$2:$D$181,0)) -> TRUE
B8: 3 | C8: SIEMENS AG | D8: DE0007236101 | E8: =ISNUMBER(MATCH(D8,$H$2:$H$62,0)) -> TRUE | F8: 7 | G8: BANCO SANTANDER CENT | H8: ES0113900J37 | I8: =ISNUMBER(MATCH(H8,$D$2:$D$181,0)) -> TRUE
B9: 3 | C9: SIEMENS AG | D9: DE0007236101 | E9: =ISNUMBER(MATCH(D9,$H$2:$H$62,0)) -> TRUE | F9: 8 | G9: SCHNEIDER ELECTRIC | H9: FR0000121972 | I9: =ISNUMBER(MATCH(H9,$D$2:$D$181,0)) -> TRUE
B10: 3 | C10: SIEMENS AG | D10: DE0007236101 | E10: =ISNUMBER(MATCH(D10,$H$2:$H$62,0)) -> TRUE | F10: 9 | G10: TOTALENERGIES | H10: FR0000120271 | I10: =ISNUMBER(MATCH(H10,$D$2:$D$181,0)) -> FALSE
B11: 4 | C11: LVMH | D11: FR0000121014 | E11: =ISNUMBER(MATCH(D11,$H$2:$H$62,0)) -> TRUE | F11: 10 | G11: IBERDROLA | H11: ES0144580Y14 | I11: =ISNUMBER(MATCH(H11,$D$2:$D$181,0)) -> TRUE
B12: 4 | C12: LVMH | D12: FR0000121014 | E12: =ISNUMBER(MATCH(D12,$H$2:$H$62,0)) -> TRUE | F12: 11 | G12: BBVA | H12: ES0113211835 | I12: =ISNUMBER(MATCH(H12,$D$2:$D$181,0)) -> TRUE
B13: 4 | C13: LVMH | D13: FR0000121014 | E13: =ISNUMBER(MATCH(D13,$H$2:$H$62,0)) -> TRUE | F13: 12 | G13: SANOFI | H13: FR0000120578 | I13: =ISNUMBER(MATCH(H13,$D$2:$D$181,0)) -> TRUE
... B62: 21 | C62: PROSUS | D62: NL0013654783 | E62: =ISNUMBER(MATCH(D62,$H$2:$H$62,0)) -> TRUE | F62: 61 | G62: ASM INTERNATIONAL | H62: NL0000334118 | I62: =ISNUMBER(MATCH(H62,$D$2:$D$181,0)) -> TRUE
B63: 21 | C63: PROSUS | D63: NL0013654783 | E63: =ISNUMBER(MATCH(D63,$H$2:$H$62,0)) -> TRUE | F63: 62
B64: 21 | C64: PROSUS | D64: NL0013654783 | E64: =ISNUMBER(MATCH(D64,$H$2:$H$62,0)) -> TRUE | F64: 63
B65: 22 | C65: RELX | D65: GB00B2B0DG97 | E65: =ISNUMBER(MATCH(D65,$H$2:$H$62,0)) -> TRUE | F65: 64
B66: 22 | C66: RELX | D66: GB00B2B0DG97 | E66: =ISNUMBER(MATCH(D66,$H$2:$H$62,0)) -> TRUE | F66: 65
B67: 22 | C67: RELX | D67: GB00B2B0DG97 | E67: =ISNUMBER(MATCH(D67,$H$2:$H$62,0)) -> TRUE | F67: 66
B68: 23 | C68: HERMES INTL | D68: FR0000052292 | E68: =ISNUMBER(MATCH(D68,$H$2:$H$62,0)) -> TRUE | F68: 67
B69: 23 | C69: HERMES INTL | D69: FR0000052292 | E69: =ISNUMBER(MATCH(D69,$H$2:$H$62,0)) -> TRUE | F69: 68
B70: 23 | C70: HERMES INTL | D70: FR0000052292 | E70: =ISNUMBER(MATCH(D70,$H$2:$H$62,0)) -> TRUE | F70: 69
B71: 24 | C71: ING GROEP N.V. | D71: NL0011821202 | E71: =ISNUMBER(MATCH(D71,$H$2:$H$62,0)) -> TRUE | F71: 70
B72: 24 | C72: ING GROEP N.V. | D72: NL0011821202 | E72: =ISNUMBER(MATCH(D72,$H$2:$H$62,0)) -> TRUE | F72: 71
B73: 24 | C73: ING GROEP N.V. | D73: NL0011821202 | E73: =ISNUMBER(MATCH(D73,$H$2:$H$62,0)) -> TRUE | F73: 72
B74: 25 | C74: VINCI | D74: FR0000125486 | E74: =ISNUMBER(MATCH(D74,$H$2:$H$62,0)) -> TRUE | F74: 73
... B181: 60 | C181: ASM INTERNATIONAL | D181: NL0000334118 | E181: =ISNUMBER(MATCH(D181,$H$2:$H$62,0)) -> TRUE | F181: 180

Sheet ESG Ranked Eligible 60
A1: Rank | B1: Ticker | C1: Company | D1: ISIN code | E1: MIC | F1: Number of Shares | G1: Price | H1: Currency | I1: 12 month aver. turnover EUR | J1: 20 days aver. turn EUR | K1: 10 days aver. turn EUR | L1: 5 days aver. turn EUR | M1: 6 month aver. turnover EUR | N1: 126 days volatility | O1: 100 days volatility | P1: 100 days aver. turn EUR | Q1: 180 days volatility | R1: 3 months aver. Turnover EUR | S1: 3 months aver. Turnover USD | T1: Effective Date of Review | U1: #Symbol | V1: FX/Index Ccy | W1: Close Prc_EOD | X1: Close Prc_CO | Y1: Free Float Round: | Z1: FFMC_CO | AA1: 171613102999 - Controversial Weapons Non tailor-made or non essential-Category of Involvement Id | AB1: 171611102999 - Controversial Weapons Tailor-made and essential-Category of Involvement Id | AC1: 181110112399 - ESG Risk Score | AD1: 121010112599 - Highest Controversy Level-Answer Category | AE1: 172113112999 - Military Contracting Weapon-related products and/or services-Level of Involvement Id | AF1: 172111112999 - Military Contracting Weapons-Level of Involvement Id | AG1: 173011102999 - Oil Sands Extraction-Category of Involvement Id | AH1: 173211102999 - Shale Energy Extraction-Category of Involvement Id | AI1: 171711112999 - Small Arms Civilian customers (Assault weapons)-Level of Involvement Id | AJ1: 171721112999 - Small Arms Civilian customers (Non-assault weapons)-Level of Involvement Id | AK1: 171025111199 - Thermal Coal Extraction-Revenue Percentage | AL1: 172813112999 - Thermal Coal Power Generation-Level of Involvement Id | AM1: 172911112999 - Tobacco Products Production-Level of Involvement Id | AN1: 172915112999 - Tobacco Products Retail-Level of Involvement Id | AO1: excl_controversy | AP1: excl_tobacco_production | AQ1: excl_tobacco_retail | AR1: excl_military_weapons | AS1: excl_military_related | AT1: excl_controv_weapons_essential | AU1: excl_controv_weapons_non_essential | AV1: excl_small_arms_assault | AW1: excl_small_arms_non_assault | AX1: excl_oil_sands | AY1: excl_shale_energy | AZ1: excl_thermal_coal_extraction | BA1: excl_thermal_coal_power | BB1: excluded | BC1: FFMC_Rank | BD1: ESG_Risk_Score | BE1: ESG_Risk_Rank
A2: 245 | B2: SU-FR | C2: SCHNEIDER ELECTRIC | D2: FR0000121972 | E2: XPAR | F2: 577122512 | G2: 222.3 | H2: EUR | I2: 2.2594707e+08 | J2: 2.0740473e+08 | M2: 1.9984495e+08 | N2: 29.388895 | O2: 29.79526 | P2: 2.0034853e+08 | Q2: 33.028824 | R2: 2.0033574e+08 | S2: 2.3358204e+08 | T2: 22-Dec-25 | U2: SCHN.PA | V2: 1 | W2: 239.25 | X2: 222.3 | Y2: 1 | Z2: 1.2829433e+11 | AA2: 0 | AB2: 0 | AC2: 7.1448088 | AD2: 2 | AE2: 1 | AF2: 0 | AG2: 0 | AH2: 0 | AI2: 0 | AJ2: 0 | AK2: 0 | AL2: 0 | AM2: 0 | AN2: 0 | AO2: FALSE | AP2: FALSE | AQ2: FALSE | AR2: FALSE | AS2: FALSE | AT2: FALSE | AU2: FALSE | AV2: FALSE | AW2: FALSE | AX2: FALSE | AY2: FALSE | AZ2: FALSE | BA2: FALSE | BB2: FALSE | BC2: 8 | BD2: 7.1448088 | BE2: 1
A3: 158 | B3: ISP-IT | C3: INTESA SANPAOLO | D3: IT0000072618 | E3: MTAA | F3: 17413389613 | G3: 5.619 | H3: EUR | I3: 2.9376709e+08 | J3: 3.2506638e+08 | M3: 2.681535e+08 | N3: 23.324429 | O3: 24.010738 | P3: 2.6892967e+08 | Q3: 28.28163 | R3: 2.8286848e+08 | S3: 3.2952365e+08 | T3: 22-Dec-25 | U3: ISP.MI | V3: 1 | W3: 5.783 | X3: 5.619 | Y3: 0.8 | Z3: 7.8276669e+10 | AA3: 0 | AB3: 0 | AC3: 8.09 | AD3: 2 | AE3: 0 | AF3: 0 | AG3: 0 | AH3: 0 | AI3: 0 | AJ3: 0 | AK3: 0 | AL3: 0 | AM3: 0 | AN3: 0 | AO3: FALSE | AP3: FALSE | AQ3: FALSE | AR3: FALSE | AS3: FALSE | AT3: FALSE | AU3: FALSE | AV3: FALSE | AW3: FALSE | AX3: FALSE | AY3: FALSE | AZ3: FALSE | BA3: FALSE | BB3: FALSE | BC3: 18 | BD3: 8.09 | BE3: 2
A4: 225 | B4: REN-NL | C4: RELX | D4: GB00B2B0DG97 | E4: XAMS | F4: 1907070957 | G4: 35.28 | H4: EUR | I4: 35151618 | J4: 38042579 | M4: 29814886 | N4: 20.830658 | O4: 22.413506 | P4: 31979317 | Q4: 23.983385 | R4: 32638215 | S4: 38012065 | T4: 22-Dec-25 | U4: REL.AS | V4: 1 | W4: 34.66 | X4: 35.28 | Y4: 1 | Z4: 6.7281463e+10 | AA4: 0 | AB4: 0 | AC4: 8.1090937 | AD4: 2 | AE4: 0 | AF4: 0 | AG4: 0 | AH4: 0 | AI4: 0 | AJ4: 0 | AK4: 0 | AL4: 0 | AM4: 0 | AN4: 0 | AO4: FALSE | AP4: FALSE | AQ4: FALSE | AR4: FALSE | AS4: FALSE | AT4: FALSE | AU4: FALSE | AV4: FALSE | AW4: FALSE | AX4: FALSE | AY4: FALSE | AZ4: FALSE | BA4: FALSE | BB4: FALSE | BC4: 23 | BD4: 8.1090937 | BE4: 3
A5: 36 | B5: ASML-NL | C5: ASML HOLDING | D5: NL0010273215 | E5: XAMS | F5: 388147674 | G5: 834 | H5: EUR | I5: 5.0748503e+08 | J5: 5.1907545e+08 | M5: 4.7687009e+08 | N5: 35.69043 | O5: 37.997826 | P5: 4.9820659e+08 | Q5: 36.628567 | R5: 5.3938184e+08 | S5: 6.2879074e+08 | T5: 22-Dec-25 | U5: ASML.AS | V5: 1 | W5: 908.6 | X5: 834 | Y5: 1 | Z5: 323715160116 | AA5: 0 | AB5: 0 | AC5: 8.928945 | AD5: 2 | AE5: 0 | AF5: 0 | AG5: 0 | AH5: 0 | AI5: 0 | AJ5: 0 | AK5: 0 | AL5: 0 | AM5: 0 | AN5: 0 | AO5: FALSE | AP5: FALSE | AQ5: FALSE | AR5: FALSE | AS5: FALSE | AT5: FALSE | AU5: FALSE | AV5: FALSE | AW5: FALSE | AX5: FALSE | AY5: FALSE | AZ5: FALSE | BA5: FALSE | BB5: FALSE | BC5: 1 | BD5: 8.928945 | BE5: 4
A6: 92 | B6: DBK-DE | C6: DEUTSCHE BANK | D6: DE0005140008 | E6: XETR | F6: 1948252900 | G6: 29.385 | H6: EUR | I6: 1.7015314e+08 | J6: 1.6283173e+08 | M6: 1.6847277e+08 | N6: 30.730797 | O6: 30.842863 | P6: 1.7071545e+08 | Q6: 36.20055 | R6: 1.7798169e+08 | S6: 2.0768553e+08 | T6: 22-Dec-25 | U6: DBKGn.DE | V6: 1 | W6: 31.81 | X6: 29.385 | Y6: 1 | Z6: 5.7249411e+10 | AA6: 0 | AB6: 0 | AC6: 8.9654925 | AD6: 3 | AE6: 0 | AF6: 0 | AG6: 0 | AH6: 0 | AI6: 0 | AJ6: 0 | AK6: 0 | AL6: 0 | AM6: 0 | AN6: 0 | AO6: FALSE | AP6: FALSE | AQ6: FALSE | AR6: FALSE | AS6: FALSE | AT6: FALSE | AU6: FALSE | AV6: FALSE | AW6: FALSE | AX6: FALSE | AY6: FALSE | AZ6: FALSE | BA6: FALSE | BB6: FALSE | BC6: 27 | BD6: 8.9654925 | BE6: 5
A7: 72 | B7: CABK-ES | C7: CAIXABANK | D7: ES0140609019 | E7: XMAD | F7: 7085565400 | G7: 9.254 | H7: EUR | I7: 62448678 | J7: 1.3507376e+08 | M7: 58951377 | N7: 22.261782 | O7: 21.86623 | P7: 59991050 | Q7: 29.400314 | R7: 67273797 | S7: 78123008 | T7: 22-Dec-25 | U7: CABK.MC | V7: 1 | W7: 10.16 | X7: 9.254 | Y7: 0.5 | Z7: 3.2784911e+10 | AA7: 0 | AB7: 0 | AC7: 9.509 | AD7: 2 | AE7: 0 | AF7: 0 | AG7: 0 | AH7: 0 | AI7: 0 | AJ7: 0 | AK7: 0 | AL7: 0 | AM7: 0 | AN7: 0 | AO7: FALSE | AP7: FALSE | AQ7: FALSE | AR7: FALSE | AS7: FALSE | AT7: FALSE | AU7: FALSE | AV7: FALSE | AW7: FALSE | AX7: FALSE | AY7: FALSE | AZ7: FALSE | BA7: FALSE | BB7: FALSE | BC7: 45 | BD7: 9.509 | BE7: 6
A8: 57 | B8: BBVA-ES | C8: BBVA | D8: ES0113211835 | E8: XMAD | F8: 5763285600 | G8: 17.705 | H8: EUR | I8: 1.3566252e+08 | J8: 3.6713379e+08 | M8: 1.4393072e+08 | N8: 27.777552 | O8: 28.950481 | P8: 1.5470505e+08 | Q8: 31.000454 | R8: 1.7807689e+08 | S8: 2.0687009e+08 | T8: 22-Dec-25 | U8: BBVA.MC | V8: 1 | W8: 19.305 | X8: 17.705 | Y8: 1 | Z8: 102038971548 | AA8: 0 | AB8: 0 | AC8: 9.56425 | AD8: 2 | AE8: 0 | AF8: 0 | AG8: 0 | AH8: 0 | AI8: 0 | AJ8: 0 | AK8: 0 | AL8: 0 | AM8: 0 | AN8: 0 | AO8: FALSE | AP8: FALSE | AQ8: FALSE | AR8: FALSE | AS8: FALSE | AT8: FALSE | AU8: FALSE | AV8: FALSE | AW8: FALSE | AX8: FALSE | AY8: FALSE | AZ8: FALSE | BA8: FALSE | BB8: FALSE | BC8: 11 | BD8: 9.56425 | BE8: 7
A9: 203 | B9: NOKIA-FI | C9: NOKIA | D9: FI0009000681 | E9: XHEL | F9: 5742239700 | G9: 5.13 | H9: EUR | I9: 57797346 | J9: 77090097 | M9: 60440865 | N9: 44.634285 | O9: 48.75582 | P9: 67323848 | Q9: 42.79206 | R9: 83697742 | S9: 97482565 | T9: 22-Dec-25 | U9: NOKIA.HE | V9: 1 | W9: 5.278 | X9: 5.13 | Y9: 0.95 | Z9: 2.7984805e+10 | AA9: 0 | AB9: 0 | AC9: 9.6503238 | AD9: 2 | AE9: 0 | AF9: 0 | AG9: 0 | AH9: 0 | AI9: 0 | AJ9: 0 | AK9: 0 | AL9: 0 | AM9: 0 | AN9: 0 | AO9: FALSE | AP9: FALSE | AQ9: FALSE | AR9: FALSE | AS9: FALSE | AT9: FALSE | AU9: FALSE | AV9: FALSE | AW9: FALSE | AX9: FALSE | AY9: FALSE | AZ9: FALSE | BA9: FALSE | BB9: FALSE | BC9: 49 | BD9: 9.6503238 | BE9: 8
A10: 279 | B10: UMG-NL | C10: UMG | D10: NL0015000IY2 | E10: XAMS | F10: 1834181554 | G10: 22.61 | H10: EUR | I10: 46598461 | J10: 39786466 | M10: 47611055 | N10: 25.067509 | O10: 25.950218 | P10: 39603260 | Q10: 26.64878 | R10: 39325563 | S10: 45813287 | T10: 22-Dec-25 | U10: UMG.AS | V10: 1 | W10: 21.72 | X10: 22.61 | Y10: 0.6 | Z10: 2.4882507e+10 | AA10: 0 | AB10: 0 | AC10: 9.7401696 | AD10: 1 | AE10: 0 | AF10: 0 | AG10: 0 | AH10: 0 | AI10: 0 | AJ10: 0 | AK10: 0 | AL10: 0 | AM10: 0 | AN10: 0 | AO10: FALSE | AP10: FALSE | AQ10: FALSE | AR10: FALSE | AS10: FALSE | AT10: FALSE | AU10: FALSE | AV10: FALSE | AW10: FALSE | AX10: FALSE | AY10: FALSE | AZ10: FALSE | BA10: FALSE | BB10: FALSE | BC10: 56 | BD10: 9.7401696 | BE10: 9
A11: 51 | B11: SAN-ES | C11: BANCO SANTANDER CENT | D11: ES0113900J37 | E11: XMAD | F11: 14885325000 | G11: 8.805 | H11: EUR | I11: 1.9934083e+08 | J11: 2.4831944e+08 | M11: 1.936803e+08 | N11: 26.54015 | O11: 26.308455 | P11: 1.9984515e+08 | Q11: 31.74772 | R11: 2.1740067e+08 | S11: 2.5332558e+08 | T11: 22-Dec-25 | U11: SAN.MC | V11: 1 | W11: 9.817 | X11: 8.805 | Y11: 1 | Z11: 131065286625 | AA11: 0 | AB11: 0 | AC11: 9.8890125 | AD11: 2 | AE11: 0 | AF11: 0 | AG11: 0 | AH11: 0 | AI11: 0 | AJ11: 0 | AK11: 0 | AL11: 0 | AM11: 0 | AN11: 0 | AO11: FALSE | AP11: FALSE | AQ11: FALSE | AR11: FALSE | AS11: FALSE | AT11: FALSE | AU11: FALSE | AV11: FALSE | AW11: FALSE | AX11: FALSE | AY11: FALSE | AZ11: FALSE | BA11: FALSE | BB11: FALSE | BC11: 7 | BD11: 9.8890125 | BE11: 10
A12: 165 | B12: KBC-BE | C12: KBC | D12: BE0003565737 | E12: XBRU | F12: 417544151 | G12: 105.35 | H12: EUR | I12: 39495466 | J12: 40066030 | M12: 36083656 | N12: 19.155403 | O12: 19.713436 | P12: 36288231 | Q12: 24.682182 | R12: 37189985 | S12: 43359474 | T12: 22-Dec-25 | U12: KBC.BR | V12: 1 | W12: 110.5 | X12: 105.35 | Y12: 0.55 | Z12: 2.4193552e+10 | AA12: 0 | AB12: 0 | AC12: 10.209262 | AD12: 1 | AE12: 0 | AF12: 0 | AG12: 0 | AH12: 0 | AI12: 0 | AJ12: 0 | AK12: 0 | AL12: 0 | AM12: 0 | AN12: 0 | AO12: FALSE | AP12: FALSE | AQ12: FALSE | AR12: FALSE | AS12: FALSE | AT12: FALSE | AU12: FALSE | AV12: FALSE | AW12: FALSE | AX12: FALSE | AY12: FALSE | AZ12: FALSE | BA12: FALSE | BB12: FALSE | BC12: 57 | BD12: 10.209262 | BE12: 11
A13: 282 | B13: UCG-IT | C13: UNICREDIT | D13: IT0005239360 | E13: MTAA | F13: 1557675176 | G13: 62.85 | H13: EUR | I13: 3.5910484e+08 | J13: 3.333183e+08 | M13: 3.1436746e+08 | N13: 26.839243 | O13: 26.80322 | P13: 3.2010403e+08 | Q13: 33.4783 | R13: 3.2023355e+08 | S13: 3.7337577e+08 | T13: 22-Dec-25 | U13: CRDI.MI | V13: 1 | W13: 69.5 | X13: 62.85 | Y13: 1 | Z13: 9.7899885e+10 | AA13: 0 | AB13: 0 | AC13: 10.553088 | AD13: 2 | AE13: 0 | AF13: 0 | AG13: 0 | AH13: 0 | AI13: 0 | AJ13: 0 | AK13: 0 | AL13: 0 | AM13: 0 | AN13: 0 | AO13: FALSE | AP13: FALSE | AQ13: FALSE | AR13: FALSE | AS13: FALSE | AT13: FALSE | AU13: FALSE | AV13: FALSE | AW13: FALSE | AX13: FALSE | AY13: FALSE | AZ13: FALSE | BA13: FALSE | BB13: FALSE | BC13: 14 | BD13: 10.553088 | BE13: 12
... A57: 291 | B57: DG-FR | C57: VINCI | D57: FR0000125486 | E57: XPAR | F57: 586933775 | G57: 119.2 | H57: EUR | I57: 1.1354378e+08 | J57: 82508689 | M57: 1.0548036e+08 | N57: 19.922636 | O57: 21.265522 | P57: 1.0062867e+08 | Q57: 20.998957 | R57: 1.0287758e+08 | S57: 1.1992691e+08 | T57: 22-Dec-25 | U57: SGEF.PA | V57: 1 | W57: 120.45 | X57: 119.2 | Y57: 0.9 | Z57: 62966255382 | AA57: 0 | AB57: 0 | AC57: 23.816012 | AD57: 2 | AE57: 0 | AF57: 0 | AG57: 0 | AH57: 0 | AI57: 0 | AJ57: 0 | AK57: 0 | AL57: 0 | AM57: 0 | AN57: 0 | AO57: FALSE | AP57: FALSE | AQ57: FALSE | AR57: FALSE | AS57: FALSE | AT57: FALSE | AU57: FALSE | AV57: FALSE | AW57: FALSE | AX57: FALSE | AY57: FALSE | AZ57: FALSE | BA57: FALSE | BB57: FALSE | BC57: 26 | BD57: 23.816012 | BE57: 56
A58: 275 | B58: TTE-FR | C58: TOTALENERGIES | D58: FR0000120271 | E58: XPAR | F58: 2206585543 | G58: 55.97 | H58: EUR | I58: 2.3762657e+08 | J58: 1.8371428e+08 | M58: 2.1268388e+08 | N58: 18.864147 | O58: 18.458822 | P58: 1.9268064e+08 | Q58: 22.570004 | R58: 2.0409281e+08 | S58: 2.3806623e+08 | T58: 22-Dec-25 | U58: TTEF.PA | V58: 1 | W58: 54.5 | X58: 55.97 | Y58: 0.9 | Z58: 1.1115233e+11 | AA58: 0 | AB58: 0 | AC58: 24.461063 | AD58: 3 | AE58: 1 | AF58: 0 | AG58: 0 | AH58: SE1 | AI58: 0 | AJ58: 0 | AK58: 0 | AL58: 0 | AM58: 0 | AN58: 1 | AO58: FALSE | AP58: FALSE | AQ58: FALSE | AR58: FALSE | AS58: FALSE | AT58: FALSE | AU58: FALSE | AV58: FALSE | AW58: FALSE | AX58: FALSE | AY58: FALSE | AZ58: FALSE | BA58: FALSE | BB58: FALSE | BC58: 9 | BD58: 24.461063 | BE58: 57
A59: 32 | B59: ARGX-BE | C59: ARGENX SE | D59: NL0010832176 | E59: XBRU | F59: 61568926 | G59: 800.4 | H59: EUR | I59: 49963237 | J59: 55411929 | M59: 56477556 | N59: 32.719334 | O59: 33.88742 | P59: 62904880 | Q59: 36.607117 | R59: 71799660 | S59: 83818951 | T59: 22-Dec-25 | U59: ARGX.BR | V59: 1 | W59: 726.6 | X59: 800.4 | Y59: 1 | Z59: 4.9279768e+10 | AA59: 0 | AB59: 0 | AC59: 24.860811 | AD59: 0 | AE59: 0 | AF59: 0 | AG59: 0 | AH59: 0 | AI59: 0 | AJ59: 0 | AK59: 0 | AL59: 0 | AM59: 0 | AN59: 0 | AO59: FALSE | AP59: FALSE | AQ59: FALSE | AR59: FALSE | AS59: FALSE | AT59: FALSE | AU59: FALSE | AV59: FALSE | AW59: FALSE | AX59: FALSE | AY59: FALSE | AZ59: FALSE | BA59: FALSE | BB59: FALSE | BC59: 31 | BD59: 24.860811 | BE59: 58
A60: 110 | B60: ENI-IT | C60: ENI | D60: IT0003132476 | E60: MTAA | F60: 3146765114 | G60: 16.096 | H60: EUR | I60: 1.6676166e+08 | J60: 1.4251562e+08 | M60: 1.5546809e+08 | N60: 14.851142 | O60: 14.622597 | P60: 1.5158101e+08 | Q60: 21.121368 | R60: 1.6105516e+08 | S60: 1.8767732e+08 | T60: 22-Dec-25 | U60: ENI.MI | V60: 1 | W60: 15.6 | X60: 16.096 | Y60: 0.65 | Z60: 3.2922715e+10 | AA60: 0 | AB60: 0 | AC60: 24.906737 | AD60: 2 | AE60: 0 | AF60: 0 | AG60: 0 | AH60: 0 | AI60: 0 | AJ60: 0 | AK60: 0 | AL60: 0 | AM60: 0 | AN60: 1 | AO60: FALSE | AP60: FALSE | AQ60: FALSE | AR60: FALSE | AS60: FALSE | AT60: FALSE | AU60: FALSE | AV60: FALSE | AW60: FALSE | AX60: FALSE | AY60: FALSE | AZ60: FALSE | BA60: FALSE | BB60: FALSE | BC60: 44 | BD60: 24.906737 | BE60: 59
A61: 54 | B61: BAS-DE | C61: BASF | D61: DE000BASF111 | E61: XETR | F61: 893854900 | G61: 43.79 | H61: EUR | I61: 1.2288008e+08 | J61: 99043942 | M61: 1.0294899e+08 | N61: 24.3595 | O61: 24.48902 | P61: 1.0218357e+08 | Q61: 26.716286 | R61: 92868303 | S61: 1.0819193e+08 | T61: 22-Dec-25 | U61: BASFn.DE | V61: 1 | W61: 44.52 | X61: 43.79 | Y61: 1 | Z61: 39141906071 | AA61: 0 | AB61: 0 | AC61: 25.368255 | AD61: 3 | AE61: 0 | AF61: 0 | AG61: 0 | AH61: 0 | AI61: 0 | AJ61: 0 | AK61: 0 | AL61: 0 | AM61: 0 | AN61: 0 | AO61: FALSE | AP61: FALSE | AQ61: FALSE | AR61: FALSE | AS61: FALSE | AT61: FALSE | AU61: FALSE | AV61: FALSE | AW61: FALSE | AX61: FALSE | AY61: FALSE | AZ61: FALSE | BA61: FALSE | BB61: FALSE | BC61: 39 | BD61: 25.368255 | BE61: 60

Sheet FFMC Eligible 60
A1: Rank | B1: Ticker | C1: Company | D1: ISIN code | E1: MIC | F1: Number of Shares | G1: Price | H1: Currency | I1: 12 month aver. turnover EUR | J1: 20 days aver. turn EUR | K1: 10 days aver. turn EUR | L1: 5 days aver. turn EUR | M1: 6 month aver. turnover EUR | N1: 126 days volatility | O1: 100 days volatility | P1: 100 days aver. turn EUR | Q1: 180 days volatility | R1: 3 months aver. Turnover EUR | S1: 3 months aver. Turnover USD | T1: Effective Date of Review | U1: #Symbol | V1: FX/Index Ccy | W1: Close Prc_EOD | X1: Close Prc_CO | Y1: Free Float Round: | Z1: FFMC_CO | AA1: 171613102999 - Controversial Weapons Non tailor-made or non essential-Category of Involvement Id | AB1: 171611102999 - Controversial Weapons Tailor-made and essential-Category of Involvement Id | AC1: 181110112399 - ESG Risk Score | AD1: 121010112599 - Highest Controversy Level-Answer Category | AE1: 172113112999 - Military Contracting Weapon-related products and/or services-Level of Involvement Id | AF1: 172111112999 - Military Contracting Weapons-Level of Involvement Id | AG1: 173011102999 - Oil Sands Extraction-Category of Involvement Id | AH1: 173211102999 - Shale Energy Extraction-Category of Involvement Id | AI1: 171711112999 - Small Arms Civilian customers (Assault weapons)-Level of Involvement Id | AJ1: 171721112999 - Small Arms Civilian customers (Non-assault weapons)-Level of Involvement Id | AK1: 171025111199 - Thermal Coal Extraction-Revenue Percentage | AL1: 172813112999 - Thermal Coal Power Generation-Level of Involvement Id | AM1: 172911112999 - Tobacco Products Production-Level of Involvement Id | AN1: 172915112999 - Tobacco Products Retail-Level of Involvement Id | AO1: excl_controversy | AP1: excl_tobacco_production | AQ1: excl_tobacco_retail | AR1: excl_military_weapons | AS1: excl_military_related | AT1: excl_controv_weapons_essential | AU1: excl_controv_weapons_non_essential | AV1: excl_small_arms_assault | AW1: excl_small_arms_non_assault | AX1: excl_oil_sands | AY1: excl_shale_energy | AZ1: excl_thermal_coal_extraction | BA1: excl_thermal_coal_power | BB1: excluded | BC1: FFMC_Rank | BD1: ESG_Risk_Score
A2: 36 | B2: ASML-NL | C2: ASML HOLDING | D2: NL0010273215 | E2: XAMS | F2: 388147674 | G2: 834 | H2: EUR | I2: 5.0748503e+08 | J2: 5.1907545e+08 | M2: 4.7687009e+08 | N2: 35.69043 | O2: 37.997826 | P2: 4.9820659e+08 | Q2: 36.628567 | R2: 5.3938184e+08 | S2: 6.2879074e+08 | T2: 22-Dec-25 | U2: ASML.AS | V2: 1 | W2: 908.6 | X2: 834 | Y2: 1 | Z2: 323715160116 | AA2: 0 | AB2: 0 | AC2: 8.928945 | AD2: 2 | AE2: 0 | AF2: 0 | AG2: 0 | AH2: 0 | AI2: 0 | AJ2: 0 | AK2: 0 | AL2: 0 | AM2: 0 | AN2: 0 | AO2: FALSE | AP2: FALSE | AQ2: FALSE | AR2: FALSE | AS2: FALSE | AT2: FALSE | AU2: FALSE | AV2: FALSE | AW2: FALSE | AX2: FALSE | AY2: FALSE | AZ2: FALSE | BA2: FALSE | BB2: FALSE | BC2: 1 | BD2: 8.928945
A3: 240 | B3: SAP-DE | C3: SAP | D3: DE0007164600 | E3: XETR | F3: 1228504300 | G3: 205 | H3: EUR | I3: 3.958539e+08 | J3: 2.6802564e+08 | M3: 3.4841661e+08 | N3: 27.421091 | O3: 28.854689 | P3: 3.2556895e+08 | Q3: 31.971903 | R3: 3.2230969e+08 | S3: 3.7602994e+08 | T3: 22-Dec-25 | U3: SAPG.DE | V3: 1 | W3: 206.65 | X3: 205 | Y3: 0.9 | Z3: 226659043350 | AA3: 0 | AB3: 0 | AC3: 11.22554 | AD3: 2 | AE3: 0 | AF3: 0 | AG3: 0 | AH3: 0 | AI3: 0 | AJ3: 0 | AK3: 0 | AL3: 0 | AM3: 0 | AN3: 0 | AO3: FALSE | AP3: FALSE | AQ3: FALSE | AR3: FALSE | AS3: FALSE | AT3: FALSE | AU3: FALSE | AV3: FALSE | AW3: FALSE | AX3: FALSE | AY3: FALSE | AZ3: FALSE | BA3: FALSE | BB3: FALSE | BC3: 2 | BD3: 11.22554
A4: 250 | B4: SIE-DE | C4: SIEMENS AG | D4: DE0007236101 | E4: XETR | F4: 800000000 | G4: 219.15 | H4: EUR | I4: 2.6484863e+08 | J4: 2.6831397e+08 | M4: 2.1893284e+08 | N4: 28.99122 | O4: 30.5399 | P4: 2.1063116e+08 | Q4: 32.5281 | R4: 2.1377388e+08 | S4: 2.4915543e+08 | T4: 22-Dec-25 | U4: SIEGn.DE | V4: 1 | W4: 237.5 | X4: 219.15 | Y4: 0.95 | Z4: 166554000000 | AA4: 0 | AB4: 0 | AC4: 22.967218 | AD4: 2 | AE4: 0 | AF4: 0 | AG4: 0 | AH4: 0 | AI4: 0 | AJ4: 0 | AK4: 0 | AL4: 0 | AM4: 0 | AN4: 0 | AO4: FALSE | AP4: FALSE | AQ4: FALSE | AR4: FALSE | AS4: FALSE | AT4: FALSE | AU4: FALSE | AV4: FALSE | AW4: FALSE | AX4: FALSE | AY4: FALSE | AZ4: FALSE | BA4: FALSE | BB4: FALSE | BC4: 3 | BD4: 22.967218
A5: 184 | B5: MC-FR | C5: LVMH | D5: FR0000121014 | E5: XPAR | F5: 497686940 | G5: 623 | H5: EUR | I5: 2.9617958e+08 | J5: 2.3267182e+08 | M5: 2.555721e+08 | N5: 32.682705 | O5: 33.556435 | P5: 2.5173734e+08 | Q5: 34.11415 | R5: 2.690273e+08 | S5: 3.1355595e+08 | T5: 22-Dec-25 | U5: LVMH.PA | V5: 1 | W5: 636.5 | X5: 623 | Y5: 0.5 | Z5: 155029481810 | AA5: 0 | AB5: 0 | AC5: 13.552071 | AD5: 2 | AE5: 0 | AF5: 0 | AG5: 0 | AH5: 0 | AI5: 0 | AJ5: 0 | AK5: 0 | AL5: 0 | AM5: 0 | AN5: 1 | AO5: FALSE | AP5: FALSE | AQ5: FALSE | AR5: FALSE | AS5: FALSE | AT5: FALSE | AU5: FALSE | AV5: FALSE | AW5: FALSE | AX5: FALSE | AY5: FALSE | AZ5: FALSE | BA5: FALSE | BB5: FALSE | BC5: 4 | BD5: 13.552071
A6: 24 | B6: ALV-DE | C6: ALLIANZ SE | D6: DE0008404005 | E6: XETR | F6: 386166700 | G6: 363.1 | H6: EUR | I6: 2.3615602e+08 | J6: 1.7284928e+08 | M6: 1.9210522e+08 | N6: 18.476725 | O6: 19.508808 | P6: 1.7809613e+08 | Q6: 21.759954 | R6: 1.6830398e+08 | S6: 1.9617526e+08 | T6: 22-Dec-25 | U6: ALVG.DE | V6: 1 | W6: 383.3 | X6: 363.1 | Y6: 1 | Z6: 140217128770 | AA6: 0 | AB6: 0 | AC6: 13.1641 | AD6: 2 | AE6: 0 | AF6: 0 | AG6: 0 | AH6: 0 | AI6: 0 | AJ6: 0 | AK6: 0 | AL6: 0 | AM6: 0 | AN6: 0 | AO6: FALSE | AP6: FALSE | AQ6: FALSE | AR6: FALSE | AS6: FALSE | AT6: FALSE | AU6: FALSE | AV6: FALSE | AW6: FALSE | AX6: FALSE | AY6: FALSE | AZ6: FALSE | BA6: FALSE | BB6: FALSE | BC6: 5 | BD6: 13.1641
A7: 283 | B7: UNA-NL | C7: UNILEVER | D7: GB00BVZK7T90 | E7: XAMS | F7: 2637743772 | G7: 49.238591 | H7: EUR | I7: 57583134 | J7: 50496488 | M7: 46827108 | N7: 12.712624 | O7: 13.10243 | P7: 48659108 | Q7: 15.492692 | R7: 50959180 | S7: 0 | T7: 22-Dec-25 | U7: ULVR.AS | V7: 1 | W7: 54.72 | X7: 52.36 | Y7: 1 | Z7: 1.3811226e+11 | AA7: 0 | AB7: 0 | AC7: 16.078095 | AD7: 2 | AE7: 0 | AF7: 0 | AG7: 0 | AH7: 0 | AI7: 0 | AJ7: 0 | AK7: 0 | AL7: 0 | AM7: 0 | AN7: 0 | AO7: FALSE | AP7: FALSE | AQ7: FALSE | AR7: FALSE | AS7: FALSE | AT7: FALSE | AU7: FALSE | AV7: FALSE | AW7: FALSE | AX7: FALSE | AY7: FALSE | AZ7: FALSE | BA7: FALSE | BB7: FALSE | BC7: 6 | BD7: 16.078095
A8: 51 | B8: SAN-ES | C8: BANCO SANTANDER CENT | D8: ES0113900J37 | E8: XMAD | F8: 14885325000 | G8: 8.805 | H8: EUR | I8: 1.9934083e+08 | J8: 2.4831944e+08 | M8: 1.936803e+08 | N8: 26.54015 | O8: 26.308455 | P8: 1.9984515e+08 | Q8: 31.74772 | R8: 2.1740067e+08 | S8: 2.5332558e+08 | T8: 22-Dec-25 | U8: SAN.MC | V8: 1 | W8: 9.817 | X8: 8.805 | Y8: 1 | Z8: 131065286625 | AA8: 0 | AB8: 0 | AC8: 9.8890125 | AD8: 2 | AE8: 0 | AF8: 0 | AG8: 0 | AH8: 0 | AI8: 0 | AJ8: 0 | AK8: 0 | AL8: 0 | AM8: 0 | AN8: 0 | AO8: FALSE | AP8: FALSE | AQ8: FALSE | AR8: FALSE | AS8: FALSE | AT8: FALSE | AU8: FALSE | AV8: FALSE | AW8: FALSE | AX8: FALSE | AY8: FALSE | AZ8: FALSE | BA8: FALSE | BB8: FALSE | BC8: 7 | BD8: 9.8890125
A9: 245 | B9: SU-FR | C9: SCHNEIDER ELECTRIC | D9: FR0000121972 | E9: XPAR | F9: 577122512 | G9: 222.3 | H9: EUR | I9: 2.2594707e+08 | J9: 2.0740473e+08 | M9: 1.9984495e+08 | N9: 29.388895 | O9: 29.79526 | P9: 2.0034853e+08 | Q9: 33.028824 | R9: 2.0033574e+08 | S9: 2.3358204e+08 | T9: 22-Dec-25 | U9: SCHN.PA | V9: 1 | W9: 239.25 | X9: 222.3 | Y9: 1 | Z9: 1.2829433e+11 | AA9: 0 | AB9: 0 | AC9: 7.1448088 | AD9: 2 | AE9: 1 | AF9: 0 | AG9: 0 | AH9: 0 | AI9: 0 | AJ9: 0 | AK9: 0 | AL9: 0 | AM9: 0 | AN9: 0 | AO9: FALSE | AP9: FALSE | AQ9: FALSE | AR9: FALSE | AS9: FALSE | AT9: FALSE | AU9: FALSE | AV9: FALSE | AW9: FALSE | AX9: FALSE | AY9: FALSE | AZ9: FALSE | BA9: FALSE | BB9: FALSE | BC9: 8 | BD9: 7.1448088
A10: 275 | B10: TTE-FR | C10: TOTALENERGIES | D10: FR0000120271 | E10: XPAR | F10: 2206585543 | G10: 55.97 | H10: EUR | I10: 2.3762657e+08 | J10: 1.8371428e+08 | M10: 2.1268388e+08 | N10: 18.864147 | O10: 18.458822 | P10: 1.9268064e+08 | Q10: 22.570004 | R10: 2.0409281e+08 | S10: 2.3806623e+08 | T10: 22-Dec-25 | U10: TTEF.PA | V10: 1 | W10: 54.5 | X10: 55.97 | Y10: 0.9 | Z10: 1.1115233e+11 | AA10: 0 | AB10: 0 | AC10: 24.461063 | AD10: 3 | AE10: 1 | AF10: 0 | AG10: 0 | AH10: SE1 | AI10: 0 | AJ10: 0 | AK10: 0 | AL10: 0 | AM10: 0 | AN10: 1 | AO10: FALSE | AP10: FALSE | AQ10: FALSE | AR10: FALSE | AS10: FALSE | AT10: FALSE | AU10: FALSE | AV10: FALSE | AW10: FALSE | AX10: FALSE | AY10: FALSE | AZ10: FALSE | BA10: FALSE | BB10: FALSE | BC10: 9 | BD10: 24.461063
A11: 150 | B11: IBE-ES | C11: IBERDROLA | D11: ES0144580Y14 | E11: XMAD | F11: 6681227500 | G11: 17.935 | H11: EUR | I11: 1.550091e+08 | J11: 1.3705291e+08 | M11: 1.4579592e+08 | N11: 14.332403 | O11: 14.399873 | P11: 1.4353444e+08 | Q11: 17.798939 | R11: 1.3876985e+08 | S11: 1.6181232e+08 | T11: 22-Dec-25 | U11: IBE.MC | V11: 1 | W11: 17.975 | X11: 17.935 | Y11: 0.9 | Z11: 1.0784503e+11 | AA11: 0 | AB11: 0 | AC11: 20.991966 | AD11: 2 | AE11: 0 | AF11: 0 | AG11: 0 | AH11: 0 | AI11: 0 | AJ11: 0 | AK11: 0 | AL11: 0 | AM11: 0 | AN11: 0 | AO11: FALSE | AP11: FALSE | AQ11: FALSE | AR11: FALSE | AS11: FALSE | AT11: FALSE | AU11: FALSE | AV11: FALSE | AW11: FALSE | AX11: FALSE | AY11: FALSE | AZ11: FALSE | BA11: FALSE | BB11: FALSE | BC11: 10 | BD11: 20.991966
A12: 57 | B12: BBVA-ES | C12: BBVA | D12: ES0113211835 | E12: XMAD | F12: 5763285600 | G12: 17.705 | H12: EUR | I12: 1.3566252e+08 | J12: 3.6713379e+08 | M12: 1.4393072e+08 | N12: 27.777552 | O12: 28.950481 | P12: 1.5470505e+08 | Q12: 31.000454 | R12: 1.7807689e+08 | S12: 2.0687009e+08 | T12: 22-Dec-25 | U12: BBVA.MC | V12: 1 | W12: 19.305 | X12: 17.705 | Y12: 1 | Z12: 102038971548 | AA12: 0 | AB12: 0 | AC12: 9.56425 | AD12: 2 | AE12: 0 | AF12: 0 | AG12: 0 | AH12: 0 | AI12: 0 | AJ12: 0 | AK12: 0 | AL12: 0 | AM12: 0 | AN12: 0 | AO12: FALSE | AP12: FALSE | AQ12: FALSE | AR12: FALSE | AS12: FALSE | AT12: FALSE | AU12: FALSE | AV12: FALSE | AW12: FALSE | AX12: FALSE | AY12: FALSE | AZ12: FALSE | BA12: FALSE | BB12: FALSE | BC12: 11 | BD12: 9.56425
A13: 239 | B13: SAN-FR | C13: SANOFI | D13: FR0000120578 | E13: XPAR | F13: 1227468973 | G13: 86.32 | H13: EUR | I13: 1.7813017e+08 | J13: 1.4714786e+08 | M13: 1.6111507e+08 | N13: 27.717335 | O13: 28.988537 | P13: 1.556939e+08 | Q13: 28.241545 | R13: 1.6255782e+08 | S13: 1.8952858e+08 | T13: 22-Dec-25 | U13: SASY.PA | V13: 1 | W13: 80.94 | X13: 86.32 | Y13: 0.95 | Z13: 1.0065737e+11 | AA13: 0 | AB13: 0 | AC13: 13.170217 | AD13: 3 | AE13: 0 | AF13: 0 | AG13: 0 | AH13: 0 | AI13: 0 | AJ13: 0 | AK13: 0 | AL13: 0 | AM13: 0 | AN13: 0 | AO13: FALSE | AP13: FALSE | AQ13: FALSE | AR13: FALSE | AS13: FALSE | AT13: FALSE | AU13: FALSE | AV13: FALSE | AW13: FALSE | AX13: FALSE | AY13: FALSE | AZ13: FALSE | BA13: FALSE | BB13: FALSE | BC13: 12 | BD13: 13.170217
A14: 112 | B14: EL-FR | C14: ESSILORLUXOTTICA | D14: FR0000121667 | E14: XPAR | F14: 463145529 | G14: 306 | H14: EUR | I14: 1.3693304e+08 | J14: 1.1182662e+08 | M14: 1.1914464e+08 | N14: 28.494783 | O14: 30.682514 | P14: 1.0759697e+08 | Q14: 30.26312 | R14: 1.1001145e+08 | S14: 1.2824073e+08 | T14: 22-Dec-25 | U14: ESLX.PA | V14: 1 | W14: 278.2 | X14: 306 | Y14: 0.7 | Z14: 9.9205772e+10 | AA14: 0 | AB14: 0 | AC14: 12.911463 | AD14: 2 | AE14: 0 | AF14: 0 | AG14: 0 | AH14: 0 | AI14: 0 | AJ14: 0 | AK14: 0 | AL14: 0 | AM14: 0 | AN14: 0 | AO14: FALSE | AP14: FALSE | AQ14: FALSE | AR14: FALSE | AS14: FALSE | AT14: FALSE | AU14: FALSE | AV14: FALSE | AW14: FALSE | AX14: FALSE | AY14: FALSE | AZ14: FALSE | BA14: FALSE | BB14: FALSE | BC14: 13 | BD14: 12.911463
A15: 282 | B15: UCG-IT | C15: UNICREDIT | D15: IT0005239360 | E15: MTAA | F15: 1557675176 | G15: 62.85 | H15: EUR | I15: 3.5910484e+08 | J15: 3.333183e+08 | M15: 3.1436746e+08 | N15: 26.839243 | O15: 26.80322 | P15: 3.2010403e+08 | Q15: 33.4783 | R15: 3.2023355e+08 | S15: 3.7337577e+08 | T15: 22-Dec-25 | U15: CRDI.MI | V15: 1 | W15: 69.5 | X15: 62.85 | Y15: 1 | Z15: 9.7899885e+10 | AA15: 0 | AB15: 0 | AC15: 10.553088 | AD15: 2 | AE15: 0 | AF15: 0 | AG15: 0 | AH15: 0 | AI15: 0 | AJ15: 0 | AK15: 0 | AL15: 0 | AM15: 0 | AN15: 0 | AO15: FALSE | AP15: FALSE | AQ15: FALSE | AR15: FALSE | AS15: FALSE | AT15: FALSE | AU15: FALSE | AV15: FALSE | AW15: FALSE | AX15: FALSE | AY15: FALSE | AZ15: FALSE | BA15: FALSE | BB15: FALSE | BC15: 14 | BD15: 10.553088
A16: 20 | B16: AI-FR | C16: AIR LIQUIDE | D16: FR0000120073 | E16: XPAR | F16: 578534275 | G16: 165.94 | H16: EUR | I16: 1.1950551e+08 | J16: 92896515 | M16: 1.0300352e+08 | N16: 14.12708 | O16: 14.407667 | P16: 96960052 | Q16: 18.233885 | R16: 98286987 | S16: 1.1455434e+08 | T16: 22-Dec-25 | U16: AIRP.PA | V16: 1 | W16: 159.4 | X16: 165.94 | Y16: 1 | Z16: 9.6001978e+10 | AA16: 0 | AB16: 0 | AC16: 13.379856 | AD16: 2 | AE16: 1 | AF16: 0 | AG16: 0 | AH16: 0 | AI16: 0 | AJ16: 0 | AK16: 0 | AL16: 0 | AM16: 0 | AN16: 0 | AO16: FALSE | AP16: FALSE | AQ16: FALSE | AR16: FALSE | AS16: FALSE | AT16: FALSE | AU16: FALSE | AV16: FALSE | AW16: FALSE | AX16: FALSE | AY16: FALSE | AZ16: FALSE | BA16: FALSE | BB16: FALSE | BC16: 15 | BD16: 13.379856
A17: 95 | B17: DTE-DE | C17: DEUTSCHE TELEKOM AG | D17: DE0005557508 | E17: XETR | F17: 4905190400 | G17: 27.62 | H17: EUR | I17: 2.1313939e+08 | J17: 1.7461593e+08 | M17: 1.7785968e+08 | N17: 20.588774 | O17: 20.002012 | P17: 1.6875682e+08 | Q17: 22.332178 | R17: 1.6757909e+08 | S17: 1.9533953e+08 | T17: 22-Dec-25 | U17: DTEGn.DE | V17: 1 | W17: 26.74 | X17: 27.62 | Y17: 0.7 | Z17: 9.4836951e+10 | AA17: 0 | AB17: 0 | AC17: 16.2697 | AD17: 2 | AE17: 0 | AF17: 0 | AG17: 0 | AH17: 0 | AI17: 0 | AJ17: 0 | AK17: 0 | AL17: 0 | AM17: 0 | AN17: 0 | AO17: FALSE | AP17: FALSE | AQ17: FALSE | AR17: FALSE | AS17: FALSE | AT17: FALSE | AU17: FALSE | AV17: FALSE | AW17: FALSE | AX17: FALSE | AY17: FALSE | AZ17: FALSE | BA17: FALSE | BB17: FALSE | BC17: 16 | BD17: 16.2697
A18: 180 | B18: OR-FR | C18: L'OREAL | D18: FR0000120321 | E18: XPAR | F18: 533783024 | G18: 361.5 | H18: EUR | I18: 1.3997562e+08 | J18: 1.0567946e+08 | M18: 1.1566859e+08 | N18: 23.4039 | O18: 23.904568 | P18: 1.1234032e+08 | Q18: 25.882713 | R18: 1.2014462e+08 | S18: 1.4013649e+08 | T18: 22-Dec-25 | U18: OREP.PA | V18: 1 | W18: 373.7 | X18: 361.5 | Y18: 0.45 | Z18: 8.6833153e+10 | AA18: 0 | AB18: 0 | AC18: 16.898519 | AD18: 3 | AE18: 0 | AF18: 0 | AG18: 0 | AH18: 0 | AI18: 0 | AJ18: 0 | AK18: 0 | AL18: 0 | AM18: 0 | AN18: 0 | AO18: FALSE | AP18: FALSE | AQ18: FALSE | AR18: FALSE | AS18: FALSE | AT18: FALSE | AU18: FALSE | AV18: FALSE | AW18: FALSE | AX18: FALSE | AY18: FALSE | AZ18: FALSE | BA18: FALSE | BB18: FALSE | BC18: 17 | BD18: 16.898519
A19: 158 | B19: ISP-IT | C19: INTESA SANPAOLO | D19: IT0000072618 | E19: MTAA | F19: 17413389613 | G19: 5.619 | H19: EUR | I19: 2.9376709e+08 | J19: 3.2506638e+08 | M19: 2.681535e+08 | N19: 23.324429 | O19: 24.010738 | P19: 2.6892967e+08 | Q19: 28.28163 | R19: 2.8286848e+08 | S19: 3.2952365e+08 | T19: 22-Dec-25 | U19: ISP.MI | V19: 1 | W19: 5.783 | X19: 5.619 | Y19: 0.8 | Z19: 7.8276669e+10 | AA19: 0 | AB19: 0 | AC19: 8.09 | AD19: 2 | AE19: 0 | AF19: 0 | AG19: 0 | AH19: 0 | AI19: 0 | AJ19: 0 | AK19: 0 | AL19: 0 | AM19: 0 | AN19: 0 | AO19: FALSE | AP19: FALSE | AQ19: FALSE | AR19: FALSE | AS19: FALSE | AT19: FALSE | AU19: FALSE | AV19: FALSE | AW19: FALSE | AX19: FALSE | AY19: FALSE | AZ19: FALSE | BA19: FALSE | BB19: FALSE | BC19: 18 | BD19: 8.09
A20: 64 | B20: BNP-FR | C20: BNP PARIBAS ACT.A | D20: FR0000131104 | E20: XPAR | F20: 1116784757 | G20: 70.47 | H20: EUR | I20: 2.1291789e+08 | J20: 1.9340635e+08 | M20: 1.9621499e+08 | N20: 26.853807 | O20: 27.375444 | P20: 1.929767e+08 | Q20: 30.01338 | R20: 2.0862623e+08 | S20: 2.4301411e+08 | T20: 22-Dec-25 | U20: BNPP.PA | V20: 1 | W20: 78.86 | X20: 70.47 | Y20: 0.95 | Z20: 7.4764831e+10 | AA20: 0 | AB20: 0 | AC20: 12.271731 | AD20: 2 | AE20: 0 | AF20: 0 | AG20: 0 | AH20: 0 | AI20: 0 | AJ20: 0 | AK20: 0 | AL20: 0 | AM20: 0 | AN20: 0 | AO20: FALSE | AP20: FALSE | AQ20: FALSE | AR20: FALSE | AS20: FALSE | AT20: FALSE | AU20: FALSE | AV20: FALSE | AW20: FALSE | AX20: FALSE | AY20: FALSE | AZ20: FALSE | BA20: FALSE | BB20: FALSE | BC20: 19 | BD20: 12.271731
A21: 196 | B21: MUV2-DE | C21: MUNICH RE | D21: DE0008430026 | E21: XETR | F21: 130645070 | G21: 532.4 | H21: EUR | I21: 1.426145e+08 | J21: 1.2494389e+08 | M21: 1.3028414e+08 | N21: 21.03891 | O21: 21.719397 | P21: 1.250673e+08 | Q21: 25.573225 | R21: 1.2641745e+08 | S21: 1.4746131e+08 | T21: 22-Dec-25 | U21: MUVGn.DE | V21: 1 | W21: 557.8 | X21: 532.4 | Y21: 1 | Z21: 69555435268 | AA21: 0 | AB21: 0 | AC21: 11.755625 | AD21: 2 | AE21: 0 | AF21: 0 | AG21: 0 | AH21: 0 | AI21: 0 | AJ21: 0 | AK21: 0 | AL21: 0 | AM21: 0 | AN21: 0 | AO21: FALSE | AP21: FALSE | AQ21: FALSE | AR21: FALSE | AS21: FALSE | AT21: FALSE | AU21: FALSE | AV21: FALSE | AW21: FALSE | AX21: FALSE | AY21: FALSE | AZ21: FALSE | BA21: FALSE | BB21: FALSE | BC21: 20 | BD21: 11.755625
A22: 41 | B22: CS-FR | C22: AXA | D22: FR0000120628 | E22: XPAR | F22: 2123594281 | G22: 38.14 | H22: EUR | I22: 1.5993902e+08 | J22: 1.6239349e+08 | M22: 1.5156317e+08 | N22: 20.694818 | O22: 21.842218 | P22: 1.4429684e+08 | Q22: 23.645367 | R22: 1.5184721e+08 | S22: 1.7691325e+08 | T22: 22-Dec-25 | U22: AXAF.PA | V22: 1 | W22: 40.55 | X22: 38.14 | Y22: 0.85 | Z22: 6.8844803e+10 | AA22: 0 | AB22: 0 | AC22: 13.927437 | AD22: 2 | AE22: 0 | AF22: 0 | AG22: 0 | AH22: 0 | AI22: 0 | AJ22: 0 | AK22: 0 | AL22: 0 | AM22: 0 | AN22: 0 | AO22: FALSE | AP22: FALSE | AQ22: FALSE | AR22: FALSE | AS22: FALSE | AT22: FALSE | AU22: FALSE | AV22: FALSE | AW22: FALSE | AX22: FALSE | AY22: FALSE | AZ22: FALSE | BA22: FALSE | BB22: FALSE | BC22: 21 | BD22: 13.927437
... A61: 63 | B61: BMW-DE | C61: BMW | D61: DE0005190003 | E61: XETR | F61: 561134950 | G61: 85.08 | H61: EUR | I61: 96091437 | J61: 70224767 | M61: 83732698 | N61: 28.764463 | O61: 28.80359 | P61: 86135291 | Q61: 31.023952 | R61: 83149016 | S61: 96887741 | T61: 22-Dec-25 | U61: BMWG.DE | V61: 1 | W61: 94.26 | X61: 85.08 | Y61: 0.5 | Z61: 23870680773 | AA61: 0 | AB61: 0 | AC61: 19.4944 | AD61: 2 | AE61: 0 | AF61: 0 | AG61: 0 | AH61: 0 | AI61: 0 | AJ61: 0 | AK61: 0 | AL61: 0 | AM61: 0 | AN61: 0 | AO61: FALSE | AP61: FALSE | AQ61: FALSE | AR61: FALSE | AS61: FALSE | AT61: FALSE | AU61: FALSE | AV61: FALSE | AW61: FALSE | AX61: FALSE | AY61: FALSE | AZ61: FALSE | BA61: FALSE | BB61: FALSE | BC61: 60 | BD61: 19.4944

Sheet Excluded Companies
A1: Rank | B1: Ticker | C1: Company | D1: ISIN code | E1: MIC | F1: Number of Shares | G1: Price | H1: Currency | I1: 12 month aver. turnover EUR | J1: 20 days aver. turn EUR | K1: 10 days aver. turn EUR | L1: 5 days aver. turn EUR | M1: 6 month aver. turnover EUR | N1: 126 days volatility | O1: 100 days volatility | P1: 100 days aver. turn EUR | Q1: 180 days volatility | R1: 3 months aver. Turnover EUR | S1: 3 months aver. Turnover USD | T1: Effective Date of Review | U1: #Symbol | V1: FX/Index Ccy | W1: Close Prc_EOD | X1: Close Prc_CO | Y1: Free Float Round: | Z1: FFMC_CO | AA1: 171613102999 - Controversial Weapons Non tailor-made or non essential-Category of Involvement Id | AB1: 171611102999 - Controversial Weapons Tailor-made and essential-Category of Involvement Id | AC1: 181110112399 - ESG Risk Score | AD1: 121010112599 - Highest Controversy Level-Answer Category | AE1: 172113112999 - Military Contracting Weapon-related products and/or services-Level of Involvement Id | AF1: 172111112999 - Military Contracting Weapons-Level of Involvement Id | AG1: 173011102999 - Oil Sands Extraction-Category of Involvement Id | AH1: 173211102999 - Shale Energy Extraction-Category of Involvement Id | AI1: 171711112999 - Small Arms Civilian customers (Assault weapons)-Level of Involvement Id | AJ1: 171721112999 - Small Arms Civilian customers (Non-assault weapons)-Level of Involvement Id | AK1: 171025111199 - Thermal Coal Extraction-Revenue Percentage | AL1: 172813112999 - Thermal Coal Power Generation-Level of Involvement Id | AM1: 172911112999 - Tobacco Products Production-Level of Involvement Id | AN1: 172915112999 - Tobacco Products Retail-Level of Involvement Id | AO1: excl_controversy | AP1: excl_tobacco_production | AQ1: excl_tobacco_retail | AR1: excl_military_weapons | AS1: excl_military_related | AT1: excl_controv_weapons_essential | AU1: excl_controv_weapons_non_essential | AV1: excl_small_arms_assault | AW1: excl_small_arms_non_assault | AX1: excl_oil_sands | AY1: excl_shale_energy | AZ1: excl_thermal_coal_extraction | BA1: excl_thermal_coal_power | BB1: excluded
A2: 1 | B2: A2A-IT | C2: A2A | D2: IT0001233417 | E2: MTAA | F2: 3132905277 | G2: 2.357 | H2: EUR | I2: 21356336 | J2: 38747531 | M2: 20226624 | N2: 22.946901 | O2: 24.391619 | P2: 20378072 | Q2: 27.23011 | R2: 22744138 | S2: 26464460 | T2: 22-Dec-25 | U2: A2.MI | V2: 1 | W2: 2.26 | X2: 2.357 | Y2: 0.5 | Z2: 3.6921289e+09 | AA2: 0 | AB2: 0 | AC2: 28.479181 | AD2: 2 | AE2: 0 | AF2: 0 | AG2: 0 | AH2: 0 | AI2: 0 | AJ2: 0 | AK2: 0 | AL2: 1 | AM2: 0 | AN2: 0 | AO2: FALSE | AP2: FALSE | AQ2: FALSE | AR2: FALSE | AS2: FALSE | AT2: FALSE | AU2: FALSE | AV2: FALSE | AW2: FALSE | AX2: FALSE | AY2: FALSE | AZ2: FALSE | BA2: TRUE | BB2: TRUE
A3: 21 | B3: AIR-FR | C3: AIRBUS | D3: NL0000235190 | E3: XPAR | F3: 792283683 | G3: 202.75 | H3: EUR | I3: 1.8871926e+08 | J3: 1.6729117e+08 | M3: 1.7095168e+08 | N3: 21.41899 | O3: 20.605274 | P3: 1.6736631e+08 | Q3: 28.784521 | R3: 1.6885063e+08 | S3: 1.9690221e+08 | T3: 22-Dec-25 | U3: AIR.PA | V3: 1 | W3: 192.96 | X3: 202.75 | Y3: 0.75 | Z3: 1.2047664e+11 | AA3: 0 | AB3: CW1 | AC3: 20.333018 | AD3: 2 | AE3: 0 | AF3: 3 | AG3: 0 | AH3: 0 | AI3: 0 | AJ3: 0 | AK3: 0 | AL3: 0 | AM3: 0 | AN3: 0 | AO3: FALSE | AP3: FALSE | AQ3: FALSE | AR3: TRUE | AS3: FALSE | AT3: FALSE | AU3: FALSE | AV3: FALSE | AW3: FALSE | AX3: FALSE | AY3: FALSE | AZ3: FALSE | BA3: FALSE | BB3: TRUE
A4: 56 | B4: BAYN-DE | C4: BAYER AG | D4: DE000BAY0017 | E4: XETR | F4: 982424100 | G4: 27.585 | H4: EUR | I4: 80528977 | J4: 64711634 | M4: 70798654 | N4: 32.553543 | O4: 32.91984 | P4: 65891736 | Q4: 36.567383 | R4: 59831212 | S4: 69761048 | T4: 22-Dec-25 | U4: BAYGn.DE | V4: 1 | W4: 35.055 | X4: 27.585 | Y4: 1 | Z4: 2.7100169e+10 | AA4: 0 | AB4: 0 | AC4: 22.227213 | AD4: 5 | AE4: 0 | AF4: 0 | AG4: 0 | AH4: 0 | AI4: 0 | AJ4: 0 | AK4: 0 | AL4: 0 | AM4: 0 | AN4: 0 | AO4: TRUE | AP4: FALSE | AQ4: FALSE | AR4: FALSE | AS4: FALSE | AT4: FALSE | AU4: FALSE | AV4: FALSE | AW4: FALSE | AX4: FALSE | AY4: FALSE | AZ4: FALSE | BA4: FALSE | BB4: TRUE
A5: 88 | B5: AM-FR | C5: DASSAULT AVIATION | D5: FR0014004L86 | E5: XPAR | F5: 78397034 | G5: 265.8 | H5: EUR | I5: 16921318 | J5: 13580972 | M5: 16106851 | N5: 28.252726 | O5: 29.07985 | P5: 15322628 | Q5: 31.66167 | R5: 15257593 | S5: 17801641 | T5: 22-Dec-25 | U5: AM.PA | V5: 1 | W5: 268.6 | X5: 265.8 | Y5: 0.25 | Z5: 5.2094829e+09 | AA5: 0 | AB5: 0 | AC5: 31.245791 | AD5: 2 | AE5: 0 | AF5: 5 | AG5: 0 | AH5: 0 | AI5: 0 | AJ5: 0 | AK5: 0 | AL5: 0 | AM5: 0 | AN5: 0 | AO5: FALSE | AP5: FALSE | AQ5: FALSE | AR5: TRUE | AS5: FALSE | AT5: FALSE | AU5: FALSE | AV5: FALSE | AW5: FALSE | AX5: FALSE | AY5: FALSE | AZ5: FALSE | BA5: FALSE | BB5: TRUE
A6: 98 | B6: EOAN-DE | C6: E.ON SE | D6: DE000ENAG999 | E6: XETR | F6: 2641318800 | G6: 15.5 | H6: EUR | I6: 75787241 | J6: 68178826 | M6: 64558929 | N6: 16.391392 | O6: 16.318872 | P6: 59693199 | Q6: 19.656118 | R6: 59440270 | S6: 69301799 | T6: 22-Dec-25 | U6: EONGn.DE | V6: 1 | W6: 15.39 | X6: 15.5 | Y6: 0.85 | Z6: 34799375190 | AA6: 0 | AB6: 0 | AC6: 17.090985 | AD6: 2 | AE6: 0 | AF6: 0 | AG6: 0 | AH6: 0 | AI6: 0 | AJ6: 0 | AK6: 0 | AL6: 1 | AM6: 0 | AN6: 0 | AO6: FALSE | AP6: FALSE | AQ6: FALSE | AR6: FALSE | AS6: FALSE | AT6: FALSE | AU6: FALSE | AV6: FALSE | AW6: FALSE | AX6: FALSE | AY6: FALSE | AZ6: FALSE | BA6: TRUE | BB6: TRUE
A7: 100 | B7: EDP-PT | C7: EDP | D7: PTEDP0AM0009 | E7: XLIS | F7: 4184021624 | G7: 3.76 | H7: EUR | I7: 35407925 | J7: 47531076 | M7: 32116138 | N7: 22.393007 | O7: 24.202372 | P7: 32735235 | Q7: 28.072851 | R7: 35320298 | S7: 41149381 | T7: 22-Dec-25 | U7: EDP.LS | V7: 1 | W7: 3.812 | X7: 3.76 | Y7: 0.7 | Z7: 1.1012345e+10 | AA7: 0 | AB7: 0 | AC7: 19.228485 | AD7: 3 | AE7: 0 | AF7: 0 | AG7: 0 | AH7: 0 | AI7: 0 | AJ7: 0 | AK7: 0 | AL7: 1 | AM7: 0 | AN7: 0 | AO7: FALSE | AP7: FALSE | AQ7: FALSE | AR7: FALSE | AS7: FALSE | AT7: FALSE | AU7: FALSE | AV7: FALSE | AW7: FALSE | AX7: FALSE | AY7: FALSE | AZ7: FALSE | BA7: TRUE | BB7: TRUE
A8: 107 | B8: ELE-ES | C8: ENDESA | D8: ES0130670112 | E8: XMAD | F8: 1058752100 | G8: 30.88 | H8: EUR | I8: 25012838 | J8: 22131242 | M8: 22401015 | N8: 16.357222 | O8: 16.344465 | P8: 20387472 | Q8: 20.75655 | R8: 20463575 | S8: 23841930 | T8: 22-Dec-25 | U8: ELE.MC | V8: 1 | W8: 30.7 | X8: 30.88 | Y8: 0.3 | Z8: 9.8082795e+09 | AA8: 0 | AB8: 0 | AC8: 21.355281 | AD8: 2 | AE8: 0 | AF8: 0 | AG8: 0 | AH8: 0 | AI8: 0 | AJ8: 0 | AK8: 0 | AL8: 1 | AM8: 0 | AN8: 0 | AO8: FALSE | AP8: FALSE | AQ8: FALSE | AR8: FALSE | AS8: FALSE | AT8: FALSE | AU8: FALSE | AV8: FALSE | AW8: FALSE | AX8: FALSE | AY8: FALSE | AZ8: FALSE | BA8: TRUE | BB8: TRUE
A9: 108 | B9: ENEL-IT | C9: ENEL | D9: IT0003128367 | E9: MTAA | F9: 10166679946 | G9: 8.784 | H9: EUR | I9: 1.7847212e+08 | J9: 1.6654002e+08 | M9: 1.5151314e+08 | N9: 12.59181 | O9: 12.996296 | P9: 1.4983224e+08 | Q9: 17.718805 | R9: 1.4857509e+08 | S9: 1.7312563e+08 | T9: 22-Dec-25 | U9: ENEI.MI | V9: 1 | W9: 8.778 | X9: 8.784 | Y9: 0.75 | Z9: 6.6978087e+10 | AA9: 0 | AB9: 0 | AC9: 17.395155 | AD9: 3 | AE9: 0 | AF9: 0 | AG9: 0 | AH9: 0 | AI9: 0 | AJ9: 0 | AK9: 0 | AL9: 1 | AM9: 0 | AN9: 0 | AO9: FALSE | AP9: FALSE | AQ9: FALSE | AR9: FALSE | AS9: FALSE | AT9: FALSE | AU9: FALSE | AV9: FALSE | AW9: FALSE | AX9: FALSE | AY9: FALSE | AZ9: FALSE | BA9: TRUE | BB9: TRUE
