Workbook

Sheet Selected Companies
A1: Rank | B1: Ticker | C1: Company | D1: ISIN Code | E1: MIC | F1: Number of Shares | G1: Price (EUR) | H1: Currency | I1: Mcap in EUR | J1: index | K1: VOL_AV_3M | L1: Free Float | M1: FFMC_CO | N1: Close Prc | O1: FX/Index Ccy | P1: FFMC_WD | Q1: Subsector Code | R1: Supersector Code | S1: itr_scope123_target | T1: itr_scope12_trend | U1: CDP_climate_score | V1: NBR Overall Flag | W1: Tobacco - Production Maximum Percentage of Revenues (%) | X1: Tobacco - Distribution Maximum Percentage of Revenues (%) | Y1: Biological Weapons - Overall Flag | Z1: Chemical Weapons - Overall Flag | AA1: Nuclear Weapons Outside NPT - Overall Flag | AB1: Nuclear Weapons Inside NPT - Overall Flag | AC1: Cluster Munitions - Overall Flag | AD1: Depleted Uranium - Overall Flag | AE1: Anti-personnel Mines - Overall Flag | AF1: coal_mining_and_power_gen_maximum_percentage_of_revenues-values | AG1: Fossil Fuel - Total Maximum Percentage of Revenues (%) | AH1: power_generation_thermal_maximum_percentage_of_revenues-values | AI1: shale_oil_and_or_gas_involvement_tie | AJ1: arctic_drilling_share_max-values | AK1: deepwater_drilling_involvement | AL1: HydraulicFracturingInvolvement | AM1: CoalMiningExpInvolved | AN1: OilGasExtractExpInvolved | AO1: OtherFFInfraInvolved | AP1: NuclearPowerInvolvement | AQ1: NuclearPowerRevShareMax-values | AR1: NuclearPowerUraniumRevShareMax-values | AS1: CivFARevShareMax-values | AT1: MilitaryEqmtDistMaxRev-values | AU1: Social Rating (Num) | AV1: Governance Rating (Num) | AW1: Carbon Intensity (ISS) | AX1: ScoreTemperatureISS | AY1: NACE | AZ1: High_Climate_Impact | BA1: EU_Taxonomy | BB1: Country_Code | BC1: GAFI_Black_List | BD1: GAFI_Grey_List | BE1: Non_Fiscally_Cooperative | BF1: exclude_gafi_black | BG1: exclude_gafi_grey | BH1: exclude_non_fiscal_coop | BI1: exclude_subsector | BJ1: exclude_nbr_red | BK1: exclude_tobacco_prod | BL1: exclude_tobacco_dist | BM1: exclude_biological_weapons | BN1: exclude_chemical_weapons | BO1: exclude_nuclear_weapons_inside_npt | BP1: exclude_nuclear_weapons_outside_npt | BQ1: exclude_cluster_munitions | BR1: exclude_depleted_uranium | BS1: exclude_anti_personnel_mines | BT1: exclude_coal_mining | BU1: exclude_fossil_fuel | BV1: exclude_thermal_power | BW1: exclude_shale_oil_gas | BX1: exclude_arctic_drilling | BY1: exclude_deepwater_drilling | BZ1: exclude_hydraulic_fracturing | CA1: exclude_coal_mining_expansion | CB1: exclude_oil_gas_extraction_expansion | CC1: exclude_other_fossil_fuel_infra | CD1: exclude_nuclear_power | CE1: exclude_nuclear_power_revenue | CF1: exclude_nuclear_uranium | CG1: exclude_civilian_firearms | CH1: exclude_military_equipment | CI1: SG_Score | CJ1: exclude_sg_bottom_10 | CK1: Excluded | CL1: Exclusion_Reason | CM1: itr_scope123_target_filled | CN1: itr_scope12_trend_filled | CO1: cdp_temperature_score | CP1: bonus_malus | CQ1: climate_score | CR1: Median_Carbon_Intensity_Supersector | CS1: PAB_Flag | CT1: Liquidity_Cap | CU1: Liquidity_Floor
A2: 66 | B2: ALO-FR | C2: ALSTOM | D2: FR0010220475 | E2: XPAR | F2: 461510538 | G2: 20.09 | H2: EUR | I2: 9.2717467e+09 | J2: EU500 | K2: 23095735 | L2: 0.75 | M2: 6.95381e+09 | N2: 19.33 | O2: 1 | P2: 6.690749e+09 | Q2: 50202010 | R2: 5020 | S2: 1.9980521 | T2: 3.1 | U2: A | V2: Green | W2: 0 | X2: 0 | Y2: Green | Z2: Green | AA2: Green | AB2: Green | AC2: Green | AD2: Green | AE2: Green | AF2: 0 | AG2: 0 | AH2: 0 | AJ2: 0 | AK2: F | AM2: F | AN2: F | AO2: F | AQ2: 0 | AR2: 0 | AS2: 0 | AT2: 0 | AU2: 2.795 | AV2: 3.363 | AW2: 3285.23 | AX2: 1.5 | AY2: C | AZ2: 1 | BA2: 1 | BB2: FR | BC2: 0 | BD2: 0 | BE2: 0 | CI2: 3.079 | CK2: No | CM2: 1.9980521 | CN2: 3.1 | CO2: 2.5490261 | CP2: -0.3 | CQ2: 2.2490261 | CR2: 350.98887 | CS2: 0 | CT2: 0.017960925 | CU2: 0
A3: 249 | B3: CAST-SE | C3: CASTELLUM AB | D3: SE0000379190 | E3: XSTO | F3: 492601440 | G3: 10.55657 | H3: SEK | I3: 5.2001816e+09 | J3: EU500 | K3: 15217501 | L3: 0.9 | M3: 4.6801634e+09 | N3: 108.65 | O3: 0.09077334 | P3: 4.3724639e+09 | Q3: 35101010 | R3: 3510 | S3: 1.9835888 | U3: A | V3: Green | W3: 0 | X3: 0 | Y3: Green | Z3: Green | AA3: Green | AB3: Green | AC3: Green | AD3: Green | AE3: Green | AF3: 0 | AG3: 0 | AH3: 0 | AJ3: 0 | AK3: F | AM3: F | AN3: F | AO3: F | AQ3: 0 | AR3: 0 | AS3: 0 | AT3: 0 | AU3: 2.359 | AV3: 2.663 | AW3: 6.9595815 | AX3: 1.5 | AY3: L | AZ3: 1 | BA3: 1 | BB3: SE | BC3: 0 | BD3: 0 | BE3: 0 | CI3: 2.511 | CK3: No | CM3: 1.9835888 | CN3: 3.1 | CO3: 2.5417944 | CP3: -0.3 | CQ3: 2.2417944 | CR3: 23.753721 | CS3: 0 | CT3: 0.011830799 | CU3: 0
A4: 360 | B4: DSY-FR | C4: DASSAULT SYSTEMES | D4: FR0014003TT8 | E4: XPAR | F4: 1338435363 | G4: 39.72 | H4: EUR | I4: 5.3162653e+10 | J4: EU500 | K4: 57311403 | L4: 0.5 | M4: 2.6581326e+10 | N4: 32.87 | O4: 1 | P4: 2.1997185e+10 | Q4: 10101015 | R4: 1010 | S4: 1.9943237 | U4: B | V4: Green | W4: 0 | X4: 0 | Y4: Green | Z4: Green | AA4: Green | AB4: Green | AC4: Green | AD4: Green | AE4: Green | AF4: 0 | AG4: 0 | AH4: 0 | AJ4: 0 | AK4: F | AM4: F | AN4: F | AO4: F | AQ4: 0 | AR4: 0 | AS4: 0 | AT4: 0 | AU4: 2.636 | AV4: 3.304 | AW4: 10.868427 | AX4: 1.5 | AY4: J | AZ4: 0 | BA4: 1 | BB4: FR | BC4: 0 | BD4: 0 | BE4: 0 | CI4: 2.97 | CK4: No | CM4: 1.9943237 | CN4: 3.1 | CO4: 2.5471619 | CP4: -0.18 | CQ4: 2.3671619 | CR4: 33.625121 | CS4: 0 | CT4: 0.0450848 | CU4: 0
A5: 633 | B5: INPST-NL | C5: INPOST | D5: LU2290522684 | E5: XAMS | F5: 500000000 | G5: 17.46 | H5: EUR | I5: 8730000000 | J5: EU500 | K5: 7745434.2 | L5: 0.4 | M5: 3492000000 | N5: 13.32 | O5: 1 | P5: 2664000000 | Q5: 50206040 | R5: 5020 | S5: 3.3134401 | U5: A | V5: Green | W5: 0 | X5: 0 | Y5: Green | Z5: Green | AA5: Green | AB5: Green | AC5: Green | AD5: Green | AE5: Green | AF5: 0 | AG5: 0 | AH5: 0 | AJ5: 0 | AK5: F | AM5: F | AN5: F | AO5: F | AQ5: 0 | AR5: 0 | AS5: 0 | AT5: 0 | AU5: 2.05 | AV5: 3.117 | AW5: 65.872922 | AX5: 1.5 | AY5: H | AZ5: 1 | BA5: 1 | BB5: LU | BC5: 0 | BD5: 0 | BE5: 0 | CI5: 2.5835 | CK5: No | CM5: 3.3134401 | CN5: 3.1 | CO5: 3.2067201 | CP5: -0.3 | CQ5: 2.9067201 | CR5: 350.98887 | CS5: 0 | CT5: 0.0060635502 | CU5: 0
A6: 724 | B6: KRX-IE | C6: KINGSPAN GROUP PLC | D6: IE0004927939 | E6: XMSM | F6: 181964859 | G6: 75.5 | H6: EUR | I6: 1.3738347e+10 | J6: EU500 | K6: 27712784 | L6: 0.85 | M6: 1.1677595e+10 | N6: 72.6 | O6: 1 | P6: 1.1229051e+10 | Q6: 50101035 | R6: 5010 | S6: 1.9783312 | T6: 3.1 | U6: A | V6: Green | W6: 0 | X6: 0 | Y6: Green | Z6: Green | AA6: Green | AB6: Green | AC6: Green | AD6: Green | AE6: Green | AF6: 0 | AG6: 0 | AH6: 0 | AJ6: 0 | AK6: F | AM6: F | AN6: F | AO6: F | AQ6: 0 | AR6: 0 | AS6: 0 | AT6: 0 | AU6: 2.108 | AV6: 2.617 | AW6: 429.69418 | AX6: 1.5 | AY6: C | AZ6: 1 | BA6: 1 | BB6: IE | BC6: 0 | BD6: 0 | BE6: 0 | CI6: 2.3625 | CK6: No | CM6: 1.9783312 | CN6: 3.1 | CO6: 2.5391656 | CP6: -0.3 | CQ6: 2.2391656 | CR6: 644.98569 | CS6: 0 | CT6: 0.021857226 | CU6: 0
A7: 730 | B7: KBX-DE | C7: KNORR-BREMSE AG | D7: DE000KBX1006 | E7: XETR | F7: 161200000 | G7: 82.2 | H7: EUR | I7: 13250640000 | J7: EU500 | K7: 9423306.8 | L7: 0.4 | M7: 5300256000 | N7: 78.55 | O7: 1 | P7: 5064904000 | Q7: 50206025 | R7: 5020 | S7: 1.9989892 | U7: A- | V7: Green | W7: 0 | X7: 0 | Y7: Green | Z7: Green | AA7: Green | AB7: Green | AC7: Green | AD7: Green | AE7: Green | AF7: 0 | AG7: 0 | AH7: 0 | AJ7: 0 | AK7: F | AM7: F | AN7: F | AO7: F | AQ7: 0 | AR7: 0 | AS7: 0 | AT7: 0 | AU7: 2.78 | AV7: 2.888 | AW7: 3428.5625 | AX7: 1.5 | AY7: C | AZ7: 1 | BA7: 1 | BB7: DE | BC7: 0 | BD7: 0 | BE7: 0 | CI7: 2.834 | CK7: No | CM7: 1.9989892 | CN7: 3.1 | CO7: 2.5494946 | CP7: -0.24 | CQ7: 2.3094946 | CR7: 350.98887 | CS7: 0 | CT7: 0.0075512973 | CU7: 0
A8: 837 | B8: METSO-FI | C8: METSO CORPORATION | D8: FI0009014575 | E8: XHEL | F8: 828972400 | G8: 10.98 | H8: EUR | I8: 9102116952 | J8: EU500 | K8: 13202646 | L8: 0.85 | M8: 7.7367994e+09 | N8: 8.5 | O8: 1 | P8: 5989325590 | Q8: 50204020 | R8: 5020 | S8: 1.9935451 | U8: B | V8: Green | W8: 0 | X8: 0 | Y8: Green | Z8: Green | AA8: Green | AB8: Green | AC8: Green | AD8: Green | AE8: Green | AF8: 0 | AG8: 0 | AH8: 0 | AJ8: 0 | AK8: F | AM8: F | AN8: F | AO8: F | AQ8: 0 | AR8: 0 | AS8: 0 | AT8: 0 | AU8: 2.559 | AV8: 2.673 | AW8: 447.68354 | AX8: 1.5 | AY8: C | AZ8: 1 | BA8: 1 | BB8: FI | BC8: 0 | BD8: 0 | BE8: 0 | CI8: 2.616 | CK8: No | CM8: 1.9935451 | CN8: 3.1 | CO8: 2.5467726 | CP8: -0.18 | CQ8: 2.3667726 | CR8: 350.98887 | CS8: 0 | CT8: 0.010474106 | CU8: 0
A9: 941 | B9: NHY-NO | C9: NORSK HYDRO | D9: NO0005052605 | E9: XOSL | F9: 2009015998 | G9: 5.713564 | H9: NOK | I9: 1.1478641e+10 | J9: EU500 | K9: 22699024 | L9: 0.65 | M9: 7.461117e+09 | N9: 54.06 | O9: 0.08324454 | P9: 5.8766327e+09 | Q9: 55102035 | R9: 5510 | S9: 2.728329 | T9: 1.5 | U9: C | V9: Green | W9: 0 | X9: 0 | Y9: Green | Z9: Green | AA9: Green | AB9: Green | AC9: Green | AD9: Green | AE9: Green | AF9: 0 | AG9: 0 | AH9: 0 | AJ9: 0 | AK9: F | AM9: F | AN9: F | AO9: F | AQ9: 0 | AR9: 0 | AS9: 0 | AT9: 0 | AU9: 2.861 | AV9: 3.723 | AW9: 1406.9401 | AX9: 6 | AY9: C | AZ9: 1 | BA9: 1 | BB9: NO | BC9: 0 | BD9: 0 | BE9: 0 | CI9: 3.292 | CK9: No | CM9: 2.728329 | CN9: 1.5 | CO9: 2.1141645 | CP9: 0 | CQ9: 2.1141645 | CR9: 1318.4572 | CS9: 0 | CT9: 0.017585624 | CU9: 0
A10: 1062 | B10: RED-ES | C10: REDEIA CORP | D10: ES0173093024 | E10: XMAD | F10: 541080000 | G10: 16.83 | H10: EUR | I10: 9106376400 | J10: EU500 | K10: 15311685 | L10: 0.75 | M10: 6829782300 | N10: 18.67 | O10: 1 | P10: 7576472700 | Q10: 65101015 | R10: 6510 | S10: 1.5959603 | U10: A | V10: Green | W10: 0 | X10: 0 | Y10: Green | Z10: Green | AA10: Green | AB10: Green | AC10: Green | AD10: Green | AE10: Green | AF10: 0 | AG10: 0 | AH10: 0 | AJ10: 0 | AK10: F | AM10: F | AN10: F | AO10: F | AQ10: 0 | AR10: 0 | AS10: 0 | AT10: 0 | AU10: 2.938 | AV10: 2.874 | AW10: 95.988242 | AX10: 3.6 | AY10: D | AZ10: 1 | BA10: 1 | BB10: ES | BC10: 0 | BD10: 0 | BE10: 0 | CI10: 2.906 | CK10: No | CM10: 1.5959603 | CN10: 3.1 | CO10: 2.3479802 | CP10: -0.3 | CQ10: 2.0479802 | CR10: 1003.2865 | CS10: 0 | CT10: 0.012207495 | CU10: 0
A11: 1089 | B11: ROCK.B-DK | C11: ROCKWOOL B | D11: DK0063855168 | E11: XCSE | F11: 11754106 | G11: 375.3242 | H11: DKK | I11: 4.4116004e+09 | J11: EU500 | K11: 13834313 | L11: 0.85 | M11: 3.7498604e+09 | N11: 273.4 | O11: 0.13393335 | P11: 3.6584386e+08 | Q11: 50101035 | R11: 5010 | S11: 1.8363484 | T11: 3.1 | U11: B | V11: Green | W11: 0 | X11: 0 | Y11: Green | Z11: Green | AA11: Green | AB11: Green | AC11: Green | AD11: Green | AE11: Green | AF11: 0 | AG11: 0 | AH11: 0 | AJ11: 0 | AK11: F | AM11: F | AN11: F | AO11: F | AQ11: 0 | AR11: 0 | AS11: 0 | AT11: 0 | AU11: 2.152 | AV11: 2.604 | AW11: 46.694402 | AX11: 5.7 | AY11: C | AZ11: 1 | BA11: 1 | BB11: DK | BC11: 0 | BD11: 0 | BE11: 0 | CI11: 2.378 | CK11: No | CM11: 1.8363484 | CN11: 3.1 | CO11: 2.4681742 | CP11: -0.18 | CQ11: 2.2881742 | CR11: 644.98569 | CS11: 0 | CT11: 0.010410682 | CU11: 0
A12: 1159 | B12: SVT-GB | C12: SEVERN TRENT | D12: GB00B1FH8J72 | E12: XLON | F12: 300209100 | G12: 29.42568 | H12: GBX | I12: 8.8338569e+09 | J12: EU500 | K12: 14800849 | L12: 0.9 | M12: 7.9504712e+09 | N12: 2622 | O12: 0.01160026 | P12: 8.218012e+09 | Q12: 65102030 | R12: 6510 | S12: 1.7824348 | T12: 1.5 | U12: A- | V12: Green | W12: 0 | X12: 0 | Y12: Green | Z12: Green | AA12: Green | AB12: Green | AC12: Green | AD12: Green | AE12: Green | AF12: 0 | AG12: 0 | AH12: 0 | AJ12: 0 | AK12: F | AM12: F | AN12: F | AO12: F | AQ12: 0 | AR12: 0 | AS12: 0 | AT12: 0 | AU12: 2.826 | AV12: 3.137 | AW12: 59.179045 | AX12: 4.7 | AY12: E | AZ12: 1 | BA12: 1 | BB12: GB | BC12: 0 | BD12: 0 | BE12: 0 | CI12: 2.9815 | CK12: No | CM12: 1.7824348 | CN12: 1.5 | CO12: 1.6412174 | CP12: -0.24 | CQ12: 1.4012174 | CR12: 1003.2865 | CS12: 1 | CT12: 0.01188565 | CU12: 0
A13: 1321 | B13: TRN-IT | C13: TERNA | D13: IT0003242622 | E13: MTAA | F13: 2009992000 | G13: 7.826 | H13: EUR | I13: 15730197392 | J13: EU500 | K13: 30108575 | L13: 0.7 | M13: 1.1011138e+10 | N13: 8.194 | O13: 1 | P13: 1.1528912e+10 | Q13: 65101015 | R13: 6510 | S13: 1.7449211 | U13: A- | V13: Green | W13: 0 | X13: 0 | Y13: Green | Z13: Green | AA13: Green | AB13: Green | AC13: Green | AD13: Green | AE13: Green | AF13: 0 | AG13: 0 | AH13: 0 | AJ13: 0 | AK13: F | AM13: F | AN13: F | AO13: F | AQ13: 0 | AR13: 0 | AS13: 0 | AT13: 0 | AU13: 2.853 | AV13: 3.169 | AW13: 134.74022 | AX13: 5.8 | AY13: D | AZ13: 1 | BA13: 1 | BB13: IT | BC13: 0 | BD13: 0 | BE13: 0 | CI13: 3.011 | CK13: No | CM13: 1.7449211 | CN13: 3.1 | CO13: 2.4224605 | CP13: -0.24 | CQ13: 2.1824605 | CR13: 1003.2865 | CS13: 0 | CT13: 0.023682713 | CU13: 0
A14: 1421 | B14: VWS-DK | C14: VESTAS WIND SYSTEMS | D14: DK0061539921 | E14: XCSE | F14: 1009867250 | G14: 13.13903 | H14: DKK | I14: 1.3268676e+10 | J14: EU500 | K14: 50667588 | L14: 1 | M14: 1.3268676e+10 | N14: 89.9 | O14: 0.13393335 | P14: 1.2159416e+10 | Q14: 60102020 | R14: 6010 | S14: 1.9940728 | T14: 3.1 | U14: D | V14: Green | W14: 0 | X14: 0 | Y14: Green | Z14: Green | AA14: Green | AB14: Green | AC14: Green | AD14: Green | AE14: Green | AF14: 0 | AG14: 0 | AH14: 0 | AJ14: 0 | AK14: F | AM14: F | AN14: F | AO14: F | AQ14: 0 | AR14: 0 | AS14: 0 | AT14: 0 | AU14: 2.304 | AV14: 3.223 | AW14: 239.55135 | AX14: 1.5 | AY14: C | AZ14: 1 | BA14: 1 | BB14: DK | BC14: 0 | BD14: 0 | BE14: 0 | CI14: 2.7635 | CK14: No | CM14: 1.9940728 | CN14: 3.1 | CO14: 2.5470364 | CP14: 0.18 | CQ14: 2.7270364 | CR14: 2017.1154 | CS14: 0 | CT14: 0.039162201 | CU14: 0
A15: 1458 | B15: WIE-AT | C15: WIENERBERGER AG | D15: AT0000831706 | E15: WBAH | F15: 111732346 | G15: 29.66 | H15: EUR | I15: 3.3139814e+09 | J15: EU500 | K15: 6821360.8 | L15: 1 | M15: 3.3139814e+09 | N15: 29.62 | O15: 1 | P15: 3.3095121e+09 | Q15: 50101035 | R15: 5010 | U15: B | V15: Green | W15: 0 | X15: 0 | Y15: Green | Z15: Green | AA15: Green | AB15: Green | AC15: Green | AD15: Green | AE15: Green | AF15: 0 | AG15: 0 | AH15: 0 | AJ15: 0 | AK15: F | AM15: F | AN15: F | AO15: F | AQ15: 0 | AR15: 0 | AS15: 0 | AT15: 0 | AU15: 2.441 | AV15: 3.471 | AW15: 1738.1272 | AX15: 6 | AY15: C | AZ15: 1 | BA15: 1 | BB15: AT | BC15: 0 | BD15: 0 | BE15: 0 | CI15: 2.956 | CK15: No | CM15: 3.4592708 | CN15: 3.1 | CO15: 3.2796354 | CP15: -0.18 | CQ15: 3.0996354 | CR15: 644.98569 | CS15: 0 | CT15: 0.0054321567 | CU15: 0
A16: 1107 | B16: SGE-GB | C16: SAGE GROUP PLC/THE | D16: GB00B8C3BL03 | E16: XLON | F16: 995756840 | G16: 15.69208 | H16: GBX | I16: 1.5625496e+10 | J16: EU500 | K16: 29289351 | L16: 1 | M16: 1.5625496e+10 | N16: 1159 | O16: 0.01160026 | P16: 1.3387653e+10 | Q16: 10101015 | R16: 1010 | S16: 1.7465783 | T16: 1.5 | U16: A | V16: Green | W16: 0 | X16: 0 | Y16: Green | Z16: Green | AA16: Green | AB16: Green | AC16: Green | AD16: Green | AE16: Green | AF16: 0 | AG16: 0 | AH16: 0 | AJ16: 0 | AK16: F | AM16: F | AN16: F | AO16: F | AQ16: 0 | AR16: 0 | AS16: 0 | AT16: 0 | AU16: 2.41 | AV16: 3.306 | AW16: 14.625099 | AX16: 1.5 | AY16: J | AZ16: 0 | BA16: 0 | BB16: GB | BC16: 0 | BD16: 0 | BE16: 0 | CI16: 2.858 | CK16: No | CM16: 1.7465783 | CN16: 1.5 | CO16: 1.6232892 | CP16: -0.3 | CQ16: 1.3232892 | CR16: 33.625121 | CS16: 1 | CT16: 0.01006564 | CU16: 0
A17: 937 | B17: 4307-JP | C17: NOMURA RESEARCH | D17: JP3762800005 | E17: XTKS | F17: 581241500 | G17: 33.46018 | H17: JPY | I17: 1.9448445e+10 | J17: AS500 | K17: 40113347 | L17: 0.75 | M17: 1.4586334e+10 | N17: 5344 | O17: 0.00613973 | P17: 1.4303213e+10 | Q17: 10101010 | R17: 1010 | S17: 1.7260685 | T17: 1.5 | U17: A- | V17: Green | W17: 0 | X17: 0 | Y17: Green | Z17: Green | AA17: Green | AB17: Green | AC17: Green | AD17: Green | AE17: Green | AF17: 0 | AG17: 0 | AH17: 0 | AJ17: 0 | AK17: F | AM17: F | AN17: F | AO17: F | AQ17: 0 | AR17: 0 | AS17: 0 | AT17: 0 | AU17: 2.499 | AV17: 2.79 | AW17: 15.943331 | AX17: 1.5 | AY17: J | AZ17: 0 | BA17: 0 | BB17: JP | BC17: 0 | BD17: 0 | BE17: 0 | CI17: 2.6445 | CK17: No | CM17: 1.7260685 | CN17: 1.5 | CO17: 1.6130342 | CP17: -0.24 | CQ17: 1.3730342 | CR17: 33.625121 | CS17: 1 | CT17: 0.013400297 | CU17: 0
A18: 601 | B18: HPQ-US | C18: HP INC | D18: US40434L1052 | E18: XNYS | F18: 937797700 | G18: 33.12291 | H18: USD | I18: 3.1062589e+10 | J18: NA500 | K18: 2.280715e+08 | L18: 1 | M18: 3.1062589e+10 | N18: 24.04 | O18: 0.8797009 | P18: 1.9832555e+10 | Q18: 10102030 | R18: 1010 | S18: 1.7487901 | T18: 1.5 | U18: A- | V18: Green | W18: 0 | X18: 0 | Y18: Green | Z18: Green | AA18: Green | AB18: Green | AC18: Green | AD18: Green | AE18: Green | AF18: 0 | AG18: 0 | AH18: 0 | AJ18: 0 | AK18: F | AM18: F | AN18: F | AO18: F | AQ18: 0 | AR18: 0 | AS18: 0 | AT18: 0 | AU18: 2.769 | AV18: 3.447 | AW18: 682.01872 | AX18: 1.5 | AY18: C | AZ18: 1 | BA18: 0 | BB18: US | BC18: 0 | BD18: 0 | BE18: 0 | CI18: 3.108 | CK18: No | CM18: 1.7487901 | CN18: 1.5 | CO18: 1.6243951 | CP18: -0.24 | CQ18: 1.3843951 | CR18: 33.625121 | CS18: 1 | CT18: 0.070315925 | CU18: 0
A19: 508 | B19: 4901-JP | C19: FUJIFILM HOLDING | D19: JP3814000000 | E19: XTKS | F19: 1243877200 | G19: 19.2946 | H19: JPY | I19: 2.4000113e+10 | J19: AS500 | K19: 66540190 | L19: 1 | M19: 2.4000113e+10 | N19: 2648.5 | O19: 0.00613973 | P19: 2.022678e+10 | Q19: 10102035 | R19: 1010 | S19: 1.9017283 | T19: 1.5 | U19: A | V19: Green | W19: 0 | X19: 0 | Y19: Green | Z19: Green | AA19: Green | AB19: Green | AC19: Green | AD19: Green | AE19: Green | AF19: 0 | AG19: 0 | AH19: 0 | AJ19: 0 | AK19: F | AM19: F | AN19: F | AO19: F | AQ19: 0 | AR19: 0 | AS19: 0 | AT19: 0 | AU19: 2.134 | AV19: 2.707 | AW19: 131.18339 | AX19: 1.5 | AY19: C | AZ19: 1 | BA19: 0 | BB19: JP | BC19: 0 | BD19: 0 | BE19: 0 | CI19: 2.4205 | CK19: No | CM19: 1.9017283 | CN19: 1.5 | CO19: 1.7008642 | CP19: -0.3 | CQ19: 1.4008642 | CR19: 33.625121 | CS19: 1 | CT19: 0.021894189 | CU19: 0
A20: 1150 | B20: 6724-JP | C20: SEIKO EPSON | D20: JP3414750004 | E20: XTKS | F20: 384945340 | G20: 15.70364 | H20: JPY | I20: 6.045043e+09 | J20: AS500 | K20: 19629946 | L20: 0.85 | M20: 5.1382866e+09 | N20: 1909.5 | O20: 0.00613973 | P20: 3.8360736e+09 | Q20: 10102030 | R20: 1010 | S20: 1.9541852 | T20: 1.5 | U20: A | V20: Green | W20: 0 | X20: 0 | Y20: Green | Z20: Green | AA20: Green | AB20: Green | AC20: Green | AD20: Green | AE20: Green | AF20: 0 | AG20: 0 | AH20: 0 | AJ20: 0 | AK20: F | AM20: F | AN20: F | AO20: F | AQ20: 0 | AR20: 0 | AS20: 0 | AT20: 0 | AU20: 2.224 | AV20: 2.302 | AW20: 412.03624 | AX20: 1.5 | AY20: C | AZ20: 1 | BA20: 0 | BB20: JP | BC20: 0 | BD20: 0 | BE20: 0 | CI20: 2.263 | CK20: No | CM20: 1.9541852 | CN20: 1.5 | CO20: 1.7270926 | CP20: -0.3 | CQ20: 1.4270926 | CR20: 33.625121 | CS20: 1 | CT20: 0.0062554189 | CU20: 0
A21: 1070 | B21: 6723-JP | C21: RENESAS ELECTRON | D21: JP3164720009 | E21: XTKS | F21: 1870614900 | G21: 17.54549 | H21: JPY | I21: 3.2820855e+10 | J21: AS500 | K21: 1.3825327e+08 | L21: 1 | M21: 3.2820855e+10 | N21: 1660.5 | O21: 0.00613973 | P21: 1.9070959e+10 | Q21: 10102010 | R21: 1010 | S21: 1.9518801 | T21: 1.5 | U21: A- | V21: Green | W21: 0 | X21: 0 | Y21: Green | Z21: Green | AA21: Green | AB21: Green | AC21: Green | AD21: Green | AE21: Green | AF21: 0 | AG21: 0 | AH21: 0 | AJ21: 0 | AK21: F | AM21: F | AN21: F | AO21: F | AQ21: 0 | AR21: 0 | AS21: 0 | AT21: 0 | AU21: 2.474 | AV21: 3.258 | AW21: 73.555304 | AX21: 1.5 | AY21: C | AZ21: 1 | BA21: 0 | BB21: JP | BC21: 0 | BD21: 0 | BE21: 0 | CI21: 2.866 | CK21: No | CM21: 1.9518801 | CN21: 1.5 | CO21: 1.72594 | CP21: -0.24 | CQ21: 1.48594 | CR21: 33.625121 | CS21: 1 | CT21: 0.043297705 | CU21: 0
A22: 1068 | B22: REN-NL | C22: RELX | D22: GB00B2B0DG97 | E22: XAMS | F22: 1907070957 | G22: 47.26 | H22: EUR | I22: 9.0128173e+10 | J22: EU500 | K22: 34161920 | L22: 1 | M22: 9.0128173e+10 | N22: 43.84 | O22: 1 | P22: 8.3605991e+10 | Q22: 10101010 | R22: 1010 | S22: 1.9831747 | T22: 1.5 | U22: B | V22: Green | W22: 0 | X22: 0 | Y22: Green | Z22: Green | AA22: Green | AB22: Green | AC22: Green | AD22: Green | AE22: Green | AF22: 0 | AG22: 0 | AH22: 0 | AJ22: 0 | AK22: F | AM22: F | AN22: F | AO22: F | AQ22: 0 | AR22: 0 | AS22: 0 | AT22: 0 | AU22: 2.474 | AV22: 3.295 | AW22: 5.158333 | AX22: 1.5 | AY22: M | AZ22: 0 | BA22: 0 | BB22: GB | BC22: 0 | BD22: 0 | BE22: 0 | CI22: 2.8845 | CK22: No | CM22: 1.9831747 | CN22: 1.5 | CO22: 1.7415873 | CP22: -0.18 | CQ22: 1.5615873 | CR22: 33.625121 | CS22: 1 | CT22: 0.018234911 | CU22: 0
A23: 892 | B23: 6701-JP | C23: NEC CORP | D23: JP3733000008 | E23: XTKS | F23: 272849850 | G23: 96.66486 | H23: JPY | I23: 2.6374993e+10 | J23: AS500 | K23: 84508284 | L23: 1 | M23: 2.6374993e+10 | N23: 2963 | O23: 0.00613973 | P23: 4.9636899e+09 | Q23: 10102030 | R23: 1010 | S23: 1.740965 | T23: 2.08 | U23: A | V23: Green | W23: 0 | X23: 0 | Y23: Green | Z23: Green | AA23: Green | AB23: Green | AC23: Green | AD23: Green | AE23: Green | AF23: 0 | AG23: 0 | AH23: 0 | AJ23: 0 | AK23: F | AM23: F | AN23: F | AO23: F | AQ23: 0 | AR23: 0 | AS23: 0 | AT23: 0 | AU23: 2.478 | AV23: 2.811 | AW23: 110.91259 | AX23: 1.5 | AY23: J | AZ23: 0 | BA23: 0 | BB23: JP | BC23: 0 | BD23: 0 | BE23: 0 | CI23: 2.6445 | CK23: No | CM23: 1.740965 | CN23: 2.08 | CO23: 1.9104825 | CP23: -0.3 | CQ23: 1.6104825 | CR23: 33.625121 | CS23: 1 | CT23: 0.025826634 | CU23: 0
A24: 235 | B24: 7751-JP | C24: CANON INC | D24: JP3242800005 | E24: XTKS | F24: 1333763400 | G24: 32.78867 | H24: JPY | I24: 4.3732328e+10 | J24: AS500 | K24: 87704081 | L24: 0.7 | M24: 3.061263e+10 | N24: 4247 | O24: 0.00613973 | P24: 2.4344921e+10 | Q24: 10102035 | R24: 1010 | S24: 1.9387809 | T24: 1.77 | U24: A- | V24: Green | W24: 0 | X24: 0 | Y24: Green | Z24: Green | AA24: Green | AB24: Green | AC24: Green | AD24: Green | AE24: Green | AF24: 0 | AG24: 0 | AH24: 0 | AJ24: 0 | AK24: F | AM24: F | AN24: F | AO24: F | AQ24: 0 | AR24: 0 | AS24: 0 | AT24: 0 | AU24: 2.406 | AV24: 2.765 | AW24: 264.55706 | AX24: 1.5 | AY24: C | AZ24: 1 | BA24: 0 | BB24: JP | BC24: 0 | BD24: 0 | BE24: 0 | CI24: 2.5855 | CK24: No | CM24: 1.9387809 | CN24: 1.77 | CO24: 1.8543904 | CP24: -0.24 | CQ24: 1.6143904 | CR24: 33.625121 | CS24: 1 | CT24: 0.028636736 | CU24: 0
A25: 1140 | B25: 9719-JP | C25: SCSK CORP | D25: JP3400400002 | E25: XTKS | F25: 312875180 | G25: 24.06549 | H25: JPY | I25: 7.5294945e+09 | J25: AS500 | K25: 18693970 | L25: 0.5 | M25: 3.7647473e+09 | N25: 3603 | O25: 0.00613973 | P25: 3.4606259e+09 | Q25: 10101010 | R25: 1010 | S25: 1.9702873 | T25: 2.39 | U25: A | V25: Green | W25: 0 | X25: 0 | Y25: Green | Z25: Green | AA25: Green | AB25: Green | AC25: Green | AD25: Green | AE25: Green | AF25: 0 | AG25: 0 | AH25: 0 | AJ25: 0 | AK25: F | AM25: F | AN25: F | AO25: F | AQ25: 0 | AR25: 0 | AS25: 0 | AT25: 0 | AU25: 2.194 | AV25: 1.978 | AW25: 140.99185 | AX25: 1.5 | AY25: J | AZ25: 0 | BA25: 0 | BB25: JP | BC25: 0 | BD25: 0 | BE25: 0 | CI25: 2.086 | CK25: No | CM25: 1.9702873 | CN25: 2.39 | CO25: 2.1801436 | CP25: -0.3 | CQ25: 1.8801436 | CR25: 33.625121 | CS25: 0 | CT25: 0.0059387621 | CU25: 0
A26: 1449 | B26: WDC-US | C26: WESTERN DIGITAL CORP | D26: US9581021055 | E26: XNGS | F26: 347823900 | G26: 65.71497 | H26: USD | I26: 2.2857237e+10 | J26: NA500 | K26: 3.9794983e+08 | L26: 1 | M26: 2.2857237e+10 | N26: 35.82 | O26: 0.8797009 | P26: 1.0960239e+10 | Q26: 10102030 | R26: 1010 | S26: 1.9618808 | T26: 1.5 | U26: D | V26: Green | W26: 0 | X26: 0 | Y26: Green | Z26: Green | AA26: Green | AB26: Green | AC26: Green | AD26: Green | AE26: Green | AF26: 0 | AG26: 0 | AH26: 0 | AJ26: 0 | AK26: F | AM26: F | AN26: F | AO26: F | AQ26: 0 | AR26: 0 | AS26: 0 | AT26: 0 | AU26: 2.396 | AV26: 3.106 | AW26: 903.69973 | AX26: 1.5 | AY26: C | AZ26: 1 | BA26: 0 | BB26: US | BC26: 0 | BD26: 0 | BE26: 0 | CI26: 2.751 | CK26: No | CM26: 1.9618808 | CN26: 1.5 | CO26: 1.7309404 | CP26: 0.18 | CQ26: 1.9109404 | CR26: 33.625121 | CS26: 1 | CT26: 0.1 | CU26: 0
A27: 296 | B27: CTSH-US | C27: COGNIZANT TECHN SOL | D27: US1924461023 | E27: XNGS | F27: 494615500 | G27: 81.17648 | H27: USD | I27: 4.0151145e+10 | J27: NA500 | K27: 2.3407602e+08 | L27: 1 | M27: 4.0151145e+10 | N27: 70.81 | O27: 0.8797009 | P27: 3.0810401e+10 | Q27: 10101010 | R27: 1010 | S27: 1.7317486 | T27: 1.77 | U27: D | V27: Green | W27: 0 | X27: 0 | Y27: Green | Z27: Green | AA27: Green | AB27: Green | AC27: Green | AD27: Green | AE27: Green | AF27: 0 | AG27: 0 | AH27: 0 | AJ27: 0 | AK27: F | AM27: F | AN27: F | AO27: F | AQ27: 0 | AR27: 0 | AS27: 0 | AT27: 0 | AU27: 2.665 | AV27: 2.895 | AW27: 19.647787 | AX27: 1.5 | AY27: J | AZ27: 0 | BA27: 0 | BB27: US | BC27: 0 | BD27: 0 | BE27: 0 | CI27: 2.78 | CK27: No | CM27: 1.7317486 | CN27: 1.77 | CO27: 1.7508743 | CP27: 0.18 | CQ27: 1.9308743 | CR27: 33.625121 | CS27: 1 | CT27: 0.073165921 | CU27: 0
... A30: 1141 | B30: STX-US | C30: SEAGATE TECHNOLOGY | D30: IE00BKVD2N49 | E30: XNGS | F30: 211707400 | G30: 96.46102 | H30: USD | I30: 2.0421512e+10 | J30: NA500 | K30: 2.8058437e+08 | L30: 1 | M30: 2.0421512e+10 | N30: 72.67 | O30: 0.8797009 | P30: 1.3534002e+10 | Q30: 10102030 | R30: 1010 | S30: 1.9820846 | T30: 2.08 | U30: C | V30: Green | W30: 0 | X30: 0 | Y30: Green | Z30: Green | AA30: Green | AB30: Green | AC30: Green | AD30: Green | AE30: Green | AF30: 0 | AG30: 0 | AH30: 0 | AJ30: 0 | AK30: F | AM30: F | AN30: F | AO30: F | AQ30: 0 | AR30: 0 | AS30: 0 | AT30: 0 | AU30: 2.452 | AV30: 3.387 | AW30: 329.02082 | AX30: 1.8 | AY30: C | AZ30: 1 | BA30: 0 | BB30: IE | BC30: 0 | BD30: 0 | BE30: 0 | CI30: 2.9195 | CK30: No | CM30: 1.9820846 | CN30: 2.08 | CO30: 2.0310423 | CP30: 0 | CQ30: 2.0310423 | CR30: 33.625121 | CS30: 0 | CT30: 0.085468126 | CU30: 0
A31: 792 | B31: 4689-JP | C31: LY CORPORATION | D31: JP3933800009 | E31: XTKS | F31: 7152421400 | G31: 3.143927 | H31: JPY | I31: 2.2486691e+10 | J31: AS500 | K31: 31542508 | L31: 0.4 | M31: 8.9946763e+09 | N31: 517 | O31: 0.00613973 | P31: 9.081402e+09 | Q31: 10101020 | R31: 1010 | S31: 1.6174571 | U31: A | V31: Green | W31: 0 | X31: 0 | Y31: Green | Z31: Green | AA31: Green | AB31: Green | AC31: Green | AD31: Green | AE31: Green | AF31: 0 | AG31: 0 | AH31: 0 | AJ31: 0 | AK31: F | AM31: F | AN31: F | AO31: F | AQ31: 0 | AR31: 0 | AS31: 0 | AT31: 0 | AU31: 2.329 | AV31: 2.558 | AW31: 95.668827 | AX31: 1.5 | AY31: J | AZ31: 0 | BA31: 0 | BB31: JP | BC31: 0 | BD31: 0 | BE31: 0 | CI31: 2.4435 | CK31: No | CM31: 1.6174571 | CN31: 3.1 | CO31: 2.3587286 | CP31: -0.3 | CQ31: 2.0587286 | CR31: 33.625121 | CS31: 0 | CT31: 0.010330239 | CU31: 0
A32: 949 | B32: 9613-JP | C32: NTT DATA GROUP CORP | D32: JP3165700000 | E32: XTKS | F32: 1402500000 | G32: 19.04519 | H32: JPY | I32: 26710878975 | J32: AS500 | K32: 56462596 | L32: 0.4 | M32: 10684351590 | N32: 2510.5 | O32: 0.00613973 | P32: 8.6471374e+09 | Q32: 10101010 | R32: 1010 | S32: 1.7373531 | T32: 3.01 | U32: A | V32: Green | W32: 0 | X32: 0 | Y32: Green | Z32: Green | AA32: Green | AB32: Green | AC32: Green | AD32: Green | AE32: Green | AF32: 0 | AG32: 0 | AH32: 0 | AJ32: 0 | AK32: F | AM32: F | AN32: F | AO32: F | AQ32: 0 | AR32: 0 | AS32: 0 | AT32: 0 | AU32: 2.477 | AV32: 2.581 | AW32: 56.885476 | AX32: 1.5 | AY32: J | AZ32: 0 | BA32: 0 | BB32: JP | BC32: 0 | BD32: 0 | BE32: 0 | CI32: 2.529 | CK32: No | CM32: 1.7373531 | CN32: 3.01 | CO32: 2.3736766 | CP32: -0.3 | CQ32: 2.0736766 | CR32: 33.625121 | CS32: 0 | CT32: 0.017764783 | CU32: 0
A33: 1139 | B33: 7735-JP | C33: SCREEN HOLDINGS | D33: JP3494600004 | E33: XTKS | F33: 101589730 | G33: 75.08075 | H33: JPY | I33: 7.6274331e+09 | J33: AS500 | K33: 1.179789e+08 | L33: 1 | M33: 7.6274331e+09 | N33: 9487 | O33: 0.00613973 | P33: 5.9173598e+09 | Q33: 10102020 | R33: 1010 | S33: 1.9963885 | T33: 2.7 | U33: A- | V33: Green | W33: 0 | X33: 0 | Y33: Green | Z33: Green | AA33: Green | AB33: Green | AC33: Green | AD33: Green | AE33: Green | AF33: 0 | AG33: 0 | AH33: 0 | AJ33: 0 | AK33: F | AM33: F | AN33: F | AO33: F | AQ33: 0 | AR33: 0 | AS33: 0 | AT33: 0 | AU33: 1.963 | AV33: 2.131 | AW33: 393.19901 | AX33: 1.5 | AY33: C | AZ33: 1 | BA33: 0 | BB33: JP | BC33: 0 | BD33: 0 | BE33: 0 | CI33: 2.047 | CK33: No | CM33: 1.9963885 | CN33: 2.7 | CO33: 2.3481942 | CP33: -0.24 | CQ33: 2.1081942 | CR33: 33.625121 | CS33: 0 | CT33: 0.035958917 | CU33: 0
A34: 1335 | B34: 3626-JP | C34: TIS INC | D34: JP3104890003 | E34: XTKS | F34: 236233410 | G34: 24.52595 | H34: JPY | I34: 5.7938488e+09 | J34: AS500 | K34: 20044155 | L34: 1 | M34: 5.7938488e+09 | N34: 3983 | O34: 0.00613973 | P34: 5.7769805e+09 | Q34: 10101010 | R34: 1010 | S34: 1.7256042 | T34: 3.1 | U34: A | V34: Green | W34: 0 | X34: 0 | Y34: Green | Z34: Green | AA34: Green | AB34: Green | AC34: Green | AD34: Green | AE34: Green | AF34: 0 | AG34: 0 | AH34: 0 | AJ34: 0 | AK34: F | AM34: F | AN34: F | AO34: F | AQ34: 0 | AR34: 0 | AS34: 0 | AT34: 0 | AU34: 2.126 | AV34: 2.229 | AW34: 87.580417 | AX34: 1.5 | AY34: J | AZ34: 0 | BA34: 0 | BB34: JP | BC34: 0 | BD34: 0 | BE34: 0 | CI34: 2.1775 | CK34: No | CM34: 1.7256042 | CN34: 3.1 | CO34: 2.4128021 | CP34: -0.3 | CQ34: 2.1128021 | CR34: 33.625121 | CS34: 0 | CT34: 0.0065650838 | CU34: 0
A35: 118 | B35: ASM-NL | C35: ASM INTERNATIONAL | D35: NL0000334118 | E35: XAMS | F35: 49328548 | G35: 569.8 | H35: EUR | I35: 2.8107407e+10 | J35: EU500 | K35: 78679459 | L35: 0.95 | M35: 2.6702036e+10 | N35: 385.6 | O35: 1 | P35: 1.8070034e+10 | Q35: 10102020 | R35: 1010 | S35: 1.7486641 | T35: 3.1 | U35: A | V35: Green | W35: 0 | X35: 0 | Y35: Green | Z35: Green | AA35: Green | AB35: Green | AC35: Green | AD35: Green | AE35: Green | AF35: 0 | AG35: 0 | AH35: 0 | AJ35: 0 | AK35: F | AM35: F | AN35: F | AO35: F | AQ35: 0 | AR35: 0 | AS35: 0 | AT35: 0 | AU35: 2.446 | AV35: 3.219 | AW35: 51.61805 | AX35: 1.5 | AY35: C | AZ35: 1 | BA35: 0 | BB35: NL | BC35: 0 | BD35: 0 | BE35: 0 | CI35: 2.8325 | CK35: No | CM35: 1.7486641 | CN35: 3.1 | CO35: 2.4243321 | CP35: -0.3 | CQ35: 2.1243321 | CR35: 33.625121 | CS35: 0 | CT35: 0.02532995 | CU35: 0
A36: 766 | B36: 992-HK | C36: LENOVO GROUP LIMITED | D36: HK0992009065 | E36: XHKG | F36: 12404659000 | G36: 1.674363 | H36: HKD | I36: 2.0769902e+10 | J36: AS500 | K36: 1.0995044e+08 | L36: 0.65 | M36: 1.3500436e+10 | N36: 8.27 | O36: 0.11342884 | P36: 7.5635762e+09 | Q36: 10102030 | R36: 1010 | S36: 1.749664 | U36: A | V36: Green | W36: 0 | X36: 0 | Y36: Green | Z36: Green | AA36: Green | AB36: Green | AC36: Green | AD36: Green | AE36: Green | AF36: 0 | AG36: 0 | AH36: 0 | AJ36: 0 | AK36: F | AM36: F | AN36: F | AO36: F | AQ36: 0 | AR36: 0 | AS36: 0 | AT36: 0 | AU36: 2.412 | AV36: 2.657 | AW36: 871.05588 | AX36: 1.5 | AY36: C | AZ36: 1 | BA36: 0 | BB36: HK | BC36: 0 | BD36: 0 | BE36: 0 | CI36: 2.5345 | CK36: No | CM36: 1.749664 | CN36: 3.1 | CO36: 2.424832 | CP36: -0.3 | CQ36: 2.124832 | CR36: 33.625121 | CS36: 0 | CT36: 0.03370763 | CU36: 0
A37: 779 | B37: LOGN-CH | C37: LOGITECH INTL SA | D37: CH0025751329 | E37: XSWX | F37: 168994140 | G37: 99.48116 | H37: CHF | I37: 1.6811733e+10 | J37: EU500 | K37: 53427463 | L37: 0.9 | M37: 1.513056e+10 | N37: 60.7 | O37: 1.0763104 | P37: 9.936659e+09 | Q37: 10102030 | R37: 1010 | S37: 1.7497523 | U37: A | V37: Green | W37: 0 | X37: 0 | Y37: Green | Z37: Green | AA37: Green | AB37: Green | AC37: Green | AD37: Green | AE37: Green | AF37: 0 | AG37: 0 | AH37: 0 | AJ37: 0 | AK37: F | AM37: F | AN37: F | AO37: F | AQ37: 0 | AR37: 0 | AS37: 0 | AT37: 0 | AU37: 2.565 | AV37: 3.4 | AW37: 140.57785 | AX37: 1.5 | AY37: C | AZ37: 1 | BA37: 0 | BB37: CH | BC37: 0 | BD37: 0 | BE37: 0 | CI37: 2.9825 | CK37: No | CM37: 1.7497523 | CN37: 3.1 | CO37: 2.4248762 | CP37: -0.3 | CQ37: 2.1248762 | CR37: 33.625121 | CS37: 0 | CT37: 0.016977423 | CU37: 0
A38: 1497 | B38: ZS-US | C38: ZSCALER INC. | D38: US98980G1022 | E38: XNGS | F38: 153438630 | G38: 189.9187 | H38: USD | I38: 2.9140865e+10 | J38: NA500 | K38: 3.4970744e+08 | L38: 0.6 | M38: 1.7484519e+10 | N38: 199.44 | O38: 0.8797009 | P38: 1.6152259e+10 | Q38: 10101015 | R38: 1010 | S38: 1.5594323 | U38: B | V38: Green | W38: 0 | X38: 0 | Y38: Green | Z38: Green | AA38: Green | AB38: Green | AC38: Green | AD38: Green | AE38: Green | AF38: 0 | AG38: 0 | AH38: 0 | AJ38: 0 | AK38: F | AM38: F | AN38: F | AO38: F | AQ38: 0 | AR38: 0 | AS38: 0 | AT38: 0 | AU38: 2.422 | AV38: 2.761 | AW38: 0.81633985 | AX38: 1.5 | AY38: J | AZ38: 0 | BA38: 0 | BB38: US | BC38: 0 | BD38: 0 | BE38: 0 | CI38: 2.5915 | CK38: No | CM38: 1.5594323 | CN38: 3.1 | CO38: 2.3297161 | CP38: -0.18 | CQ38: 2.1497161 | CR38: 33.625121 | CS38: 0 | CT38: 0.1 | CU38: 0
A39: 100 | B39: AMAT-US | C39: APPLIED MATERIALS | D39: US0382221051 | E39: XNGS | F39: 812440860 | G39: 164.4955 | H39: USD | I39: 1.3364287e+11 | J39: NA500 | K39: 1.120737e+09 | L39: 1 | M39: 1.3364287e+11 | N39: 144.53 | O39: 0.8797009 | P39: 1.0329631e+11 | Q39: 10102020 | R39: 1010 | S39: 1.9971232 | T39: 2.7 | U39: B | V39: Green | W39: 0 | X39: 0 | Y39: Green | Z39: Green | AA39: Green | AB39: Green | AC39: Green | AD39: Green | AE39: Green | AF39: 0 | AG39: 0 | AH39: 0 | AJ39: 0 | AK39: F | AM39: F | AN39: F | AO39: F | AQ39: 0 | AR39: 0 | AS39: 0 | AT39: 0 | AU39: 2.522 | AV39: 3.158 | AW39: 202.72372 | AX39: 1.5 | AY39: C | AZ39: 1 | BA39: 0 | BB39: US | BC39: 0 | BD39: 0 | BE39: 0 | CI39: 2.84 | CK39: No | CM39: 1.9971232 | CN39: 2.7 | CO39: 2.3485616 | CP39: -0.18 | CQ39: 2.1685616 | CR39: 33.625121 | CS39: 0 | CT39: 0.1 | CU39: 0
A40: 228 | B40: CDNS-US | C40: CADENCE DESIGN SYST. | D40: US1273871087 | E40: XNGS | F40: 274108000 | G40: 247.0971 | H40: USD | I40: 6.7731292e+10 | J40: NA500 | K40: 4.9305628e+08 | L40: 1 | M40: 6.7731292e+10 | N40: 260.56 | O40: 0.8797009 | P40: 6.2829629e+10 | Q40: 10101015 | R40: 1010 | S40: 1.7199766 | T40: 3.1 | U40: A- | V40: Green | W40: 0 | X40: 0 | Y40: Green | Z40: Green | AA40: Green | AB40: Green | AC40: Green | AD40: Green | AE40: Green | AF40: 0 | AG40: 0 | AH40: 0 | AJ40: 0 | AK40: F | AM40: F | AN40: F | AO40: F | AQ40: 0 | AR40: 0 | AS40: 0 | AT40: 0 | AU40: 2.182 | AV40: 3.348 | AW40: 4.827636 | AX40: 1.5 | AY40: J | AZ40: 0 | BA40: 0 | BB40: US | BC40: 0 | BD40: 0 | BE40: 0 | CI40: 2.765 | CK40: No | CM40: 1.7199766 | CN40: 3.1 | CO40: 2.4099883 | CP40: -0.24 | CQ40: 2.1699883 | CR40: 33.625121 | CS40: 0 | CT40: 0.1 | CU40: 0
A41: 70 | B41: AMS-ES | C41: AMADEUS IT GROUP | D41: ES0109067019 | E41: XMAD | F41: 450499200 | G41: 69.46 | H41: EUR | I41: 31291674432 | J41: EU500 | K41: 42461320 | L41: 1 | M41: 31291674432 | N41: 66.52 | O41: 1 | P41: 29967206784 | Q41: 10101010 | R41: 1010 | S41: 1.7124186 | T41: 3.01 | U41: B | V41: Green | W41: 0 | X41: 0 | Y41: Green | Z41: Green | AA41: Green | AB41: Green | AC41: Green | AD41: Green | AE41: Green | AF41: 0 | AG41: 0 | AH41: 0 | AJ41: 0 | AK41: F | AM41: F | AN41: F | AO41: F | AQ41: 0 | AR41: 0 | AS41: 0 | AT41: 0 | AU41: 2.506 | AV41: 3.136 | AW41: 7.5164737 | AX41: 1.5 | AY41: N | AZ41: 0 | BA41: 0 | BB41: ES | BC41: 0 | BD41: 0 | BE41: 0 | CI41: 2.821 | CK41: No | CM41: 1.7124186 | CN41: 3.01 | CO41: 2.3612093 | CP41: -0.18 | CQ41: 2.1812093 | CR41: 33.625121 | CS41: 0 | CT41: 0.015600968 | CU41: 0
A42: 578 | B42: HEXA.B-SE | C42: HEXAGON AB-B | D42: SE0015961909 | E42: XSTO | F42: 2595227800 | G42: 11.41081 | H42: SEK | I42: 2.9613651e+10 | J42: EU500 | K42: 42986586 | L42: 0.8 | M42: 2.3690921e+10 | N42: 89.96 | O42: 0.09077334 | P42: 1.6954041e+10 | Q42: 10101015 | R42: 1010 | S42: 1.7041863 | U42: B | V42: Green | W42: 0 | X42: 0 | Y42: Green | Z42: Green | AA42: Green | AB42: Green | AC42: Green | AD42: Green | AE42: Green | AF42: 0 | AG42: 0 | AH42: 0 | AJ42: 0 | AK42: F | AM42: F | AN42: F | AO42: F | AQ42: 0 | AR42: 0 | AS42: 0 | AT42: 0 | AU42: 1.968 | AV42: 2.952 | AW42: 89.153148 | AX42: 1.5 | AY42: C | AZ42: 1 | BA42: 0 | BB42: SE | BC42: 0 | BD42: 0 | BE42: 0 | CI42: 2.46 | CK42: No | CM42: 1.7041863 | CN42: 3.1 | CO42: 2.4020931 | CP42: -0.18 | CQ42: 2.2220931 | CR42: 33.625121 | CS42: 0 | CT42: 0.014515485 | CU42: 0
...

Sheet Sheet1
A1: x | C1: x | E1: x | O1: x | P1: z
A2: AT0000730007 | B2: =_xlfn.XLOOKUP(A2,[1]Universe_World!$D$10:$D$1496,[1]Universe_World!$CK$10:$CK$1496) -> 1283.7714 | C2: AT0000730007 | D2: =_xlfn.XLOOKUP(C2,'Full Universe'!$D$3:$D$1499,'Full Universe'!$AW$3:$AW$1499) -> 1283.7714 | E2: =D2=B2 -> TRUE | J2: {=_xlfn.UNIQUE([1]!Universe_World[CI_Median])} -> 33.989273 | L2: {=_xlfn.UNIQUE('Full Universe'!$CR$2:$CR$1500)} -> 51.827488 | O2: GB00B1YW4409 | P2: 13.164173
A3: AU000000ALQ6 | B3: =_xlfn.XLOOKUP(A3,[1]Universe_World!$D$10:$D$1496,[1]Universe_World!$CK$10:$CK$1496) -> 242.61356 | C3: AU000000ALQ6 | D3: =_xlfn.XLOOKUP(C3,'Full Universe'!$D$3:$D$1499,'Full Universe'!$AW$3:$AW$1499) -> 242.61356 | E3: =D3=B3 -> TRUE | J3: 23.753721 | L3: 350.98887 | O3: US88579Y1010 | P3: 180.06968
A4: AU000000AZJ1 | B4: =_xlfn.XLOOKUP(A4,[1]Universe_World!$D$10:$D$1496,[1]Universe_World!$CK$10:$CK$1496) -> 289.30166 | C4: AU000000AZJ1 | D4: =_xlfn.XLOOKUP(C4,'Full Universe'!$D$3:$D$1499,'Full Universe'!$AW$3:$AW$1499) -> 289.30166 | E4: =D4=B4 -> TRUE | J4: 360.49567 | L4: 276.86158 | O4: JP3352000008 | P4: 1487.4985
A5: AU000000BXB1 | B5: =_xlfn.XLOOKUP(A5,[1]Universe_World!$D$10:$D$1496,[1]Universe_World!$CK$10:$CK$1496) -> 97.156371 | C5: AU000000BXB1 | D5: =_xlfn.XLOOKUP(C5,'Full Universe'!$D$3:$D$1499,'Full Universe'!$AW$3:$AW$1499) -> 97.156371 | E5: =D5=B5 -> TRUE | J5: 653.70388 | L5: 285.13539 | O5: NZATME0002S8 | P5: 474.06286
A6: AU000000QUB5 | B6: =_xlfn.XLOOKUP(A6,[1]Universe_World!$D$10:$D$1496,[1]Universe_World!$CK$10:$CK$1496) -> 432.54202 | C6: AU000000QUB5 | D6: =_xlfn.XLOOKUP(C6,'Full Universe'!$D$3:$D$1499,'Full Universe'!$AW$3:$AW$1499) -> 432.54202 | E6: =D6=B6 -> TRUE | J6: 52.62914 | L6: 1003.2865 | O6: IT0001233417 | P6: 1181.0697
A7: AU000000SEK6 | B7: =_xlfn.XLOOKUP(A7,[1]Universe_World!$D$10:$D$1496,[1]Universe_World!$CK$10:$CK$1496) -> 2.9351716 | C7: AU000000SEK6 | D7: =_xlfn.XLOOKUP(C7,'Full Universe'!$D$3:$D$1499,'Full Universe'!$AW$3:$AW$1499) -> 2.9351716 | E7: =D7=B7 -> TRUE | J7: 89.792933 | L7: 33.625121 | O7: KYG2953R1149 | P7: 556.19064
A8: AU000000TCL6 | B8: =_xlfn.XLOOKUP(A8,[1]Universe_World!$D$10:$D$1496,[1]Universe_World!$CK$10:$CK$1496) -> 10.558773 | C8: AU000000TCL6 | D8: =_xlfn.XLOOKUP(C8,'Full Universe'!$D$3:$D$1499,'Full Universe'!$AW$3:$AW$1499) -> 10.558773 | E8: =D8=B8 -> TRUE | J8: 1003.2865 | L8: 23.753721 | O8: SE0011337708 | P8: 1223.803
A9: AU0000013559 | B9: =_xlfn.XLOOKUP(A9,[1]Universe_World!$D$10:$D$1496,[1]Universe_World!$CK$10:$CK$1496) -> 381.31394 | C9: AU0000013559 | D9: =_xlfn.XLOOKUP(C9,'Full Universe'!$D$3:$D$1499,'Full Universe'!$AW$3:$AW$1499) -> 381.31394 | E9: =D9=B9 -> TRUE | J9: 414.93168 | L9: 50.951644 | O9: NL0000852564 | P9: 1619.7555
A10: AU0000364754 | B10: =_xlfn.XLOOKUP(A10,[1]Universe_World!$D$10:$D$1496,[1]Universe_World!$CK$10:$CK$1496) -> 368.92549 | C10: AU0000364754 | D10: =_xlfn.XLOOKUP(C10,'Full Universe'!$D$3:$D$1499,'Full Universe'!$AW$3:$AW$1499) -> 368.92549 | E10: =D10=B10 -> TRUE | J10: 324.26126 | L10: 201.88986 | O10: BE0974293251 | P10: 128.46807
A11: BMG507361001 | B11: =_xlfn.XLOOKUP(A11,[1]Universe_World!$D$10:$D$1496,[1]Universe_World!$CK$10:$CK$1496) -> 317.06417 | C11: BMG507361001 | D11: =_xlfn.XLOOKUP(C11,'Full Universe'!$D$3:$D$1499,'Full Universe'!$AW$3:$AW$1499) -> 317.06417 | E11: =D11=B11 -> TRUE | J11: 205.31107 | L11: 644.98569 | O11: SE0005127818 | P11: 3.5372492
A12: CA1363751027 | B12: =_xlfn.XLOOKUP(A12,[1]Universe_World!$D$10:$D$1496,[1]Universe_World!$CK$10:$CK$1496) -> 83.529122 | C12: CA1363751027 | D12: =_xlfn.XLOOKUP(C12,'Full Universe'!$D$3:$D$1499,'Full Universe'!$AW$3:$AW$1499) -> 83.529122 | E12: =D12=B12 -> TRUE | J12: 64.495465 | L12: 89.792933 | O12: CH0012221716 | P12: 5228.3624
A13: CA13646K1084 | B13: =_xlfn.XLOOKUP(A13,[1]Universe_World!$D$10:$D$1496,[1]Universe_World!$CK$10:$CK$1496) -> 81.465005 | C13: CA13646K1084 | D13: =_xlfn.XLOOKUP(C13,'Full Universe'!$D$3:$D$1499,'Full Universe'!$AW$3:$AW$1499) -> 81.465005 | E13: =D13=B13 -> TRUE | J13: 57.961718 | L13: 324.26126 | O13: US0028241000 | P13: 61.330192
A14: CH0012138605 | B14: =_xlfn.XLOOKUP(A14,[1]Universe_World!$D$10:$D$1496,[1]Universe_World!$CK$10:$CK$1496) -> 73.669675 | C14: CH0012138605 | D14: =_xlfn.XLOOKUP(C14,'Full Universe'!$D$3:$D$1499,'Full Universe'!$AW$3:$AW$1499) -> 73.669675 | E14: =D14=B14 -> TRUE | J14: 52.456211 | L14: 414.93168 | O14: US00287Y1091 | P14: 24.281901
... A21: CH0435377954 | B21: =_xlfn.XLOOKUP(A21,[1]Universe_World!$D$10:$D$1496,[1]Universe_World!$CK$10:$CK$1496) -> 184.57838 | C21: CH0435377954 | D21: =_xlfn.XLOOKUP(C21,'Full Universe'!$D$3:$D$1499,'Full Universe'!$AW$3:$AW$1499) -> 184.57838 | E21: =D21=B21 -> TRUE | J21: 687.12183 | L21: 64.495465 | O21: ES0167050915 | P21: 515.72006
A22: CH1169360919 | B22: =_xlfn.XLOOKUP(A22,[1]Universe_World!$D$10:$D$1496,[1]Universe_World!$CK$10:$CK$1496) -> 20.223472 | C22: CH1169360919 | D22: =_xlfn.XLOOKUP(C22,'Full Universe'!$D$3:$D$1499,'Full Universe'!$AW$3:$AW$1499) -> 20.223472 | E22: =D22=B22 -> TRUE | O22: SE0014781795 | P22: 135.06604
A23: CH1256740924 | B23: =_xlfn.XLOOKUP(A23,[1]Universe_World!$D$10:$D$1496,[1]Universe_World!$CK$10:$CK$1496) -> 48.003583 | C23: CH1256740924 | D23: =_xlfn.XLOOKUP(C23,'Full Universe'!$D$3:$D$1499,'Full Universe'!$AW$3:$AW$1499) -> 48.003583 | E23: =D23=B23 -> TRUE | O23: CH0012138605 | P23: 73.669675
A24: DE0005552004 | B24: =_xlfn.XLOOKUP(A24,[1]Universe_World!$D$10:$D$1496,[1]Universe_World!$CK$10:$CK$1496) -> 519.50948 | C24: DE0005552004 | D24: =_xlfn.XLOOKUP(C24,'Full Universe'!$D$3:$D$1499,'Full Universe'!$AW$3:$AW$1499) -> 519.50948 | E24: =D24=B24 -> TRUE | O24: DE000A1EWWW0 | P24: 156.19655
A25: DE0006602006 | B25: =_xlfn.XLOOKUP(A25,[1]Universe_World!$D$10:$D$1496,[1]Universe_World!$CK$10:$CK$1496) -> 4346.5658 | C25: DE0006602006 | D25: =_xlfn.XLOOKUP(C25,'Full Universe'!$D$3:$D$1499,'Full Universe'!$AW$3:$AW$1499) -> 4346.5658 | E25: =D25=B25 -> TRUE | O25: GB00B02J6398 | P25: 0.37512065
A26: DE0007010803 | B26: =_xlfn.XLOOKUP(A26,[1]Universe_World!$D$10:$D$1496,[1]Universe_World!$CK$10:$CK$1496) -> 162.61099 | C26: DE0007010803 | D26: =_xlfn.XLOOKUP(C26,'Full Universe'!$D$3:$D$1499,'Full Universe'!$AW$3:$AW$1499) -> 162.61099 | E26: =D26=B26 -> TRUE | O26: US00724F1012 | P26: 2.4645519
A27: DE0007030009 | B27: =_xlfn.XLOOKUP(A27,[1]Universe_World!$D$10:$D$1496,[1]Universe_World!$CK$10:$CK$1496) -> 586.35118 | C27: DE0007030009 | D27: =_xlfn.XLOOKUP(C27,'Full Universe'!$D$3:$D$1499,'Full Universe'!$AW$3:$AW$1499) -> 586.35118 | E27: =D27=B27 -> TRUE | O27: FR0010340141 | P27: 1046.2147
A28: DE0007236101 | B28: =_xlfn.XLOOKUP(A28,[1]Universe_World!$D$10:$D$1496,[1]Universe_World!$CK$10:$CK$1496) -> 3012.5164 | C28: DE0007236101 | D28: =_xlfn.XLOOKUP(C28,'Full Universe'!$D$3:$D$1499,'Full Universe'!$AW$3:$AW$1499) -> 3012.5164 | E28: =D28=B28 -> TRUE | O28: JP3047160001 | P28: 6.8662207
A29: DE0007500001 | B29: =_xlfn.XLOOKUP(A29,[1]Universe_World!$D$10:$D$1496,[1]Universe_World!$CK$10:$CK$1496) -> 55273.618 | C29: DE0007500001 | D29: =_xlfn.XLOOKUP(C29,'Full Universe'!$D$3:$D$1499,'Full Universe'!$AW$3:$AW$1499) -> 55273.618 | E29: =D29=B29 -> TRUE | O29: US0079031078 | P29: 99.328746
A30: DE000A0D9PT0 | B30: =_xlfn.XLOOKUP(A30,[1]Universe_World!$D$10:$D$1496,[1]Universe_World!$CK$10:$CK$1496) -> 740.68014 | C30: DE000A0D9PT0 | D30: =_xlfn.XLOOKUP(C30,'Full Universe'!$D$3:$D$1499,'Full Universe'!$AW$3:$AW$1499) -> 740.68014 | E30: =D30=B30 -> TRUE | O30: JP3122400009 | P30: 39.208876
A31: DE000DTR0CK8 | B31: =_xlfn.XLOOKUP(A31,[1]Universe_World!$D$10:$D$1496,[1]Universe_World!$CK$10:$CK$1496) -> 2250.9008 | C31: DE000DTR0CK8 | D31: =_xlfn.XLOOKUP(C31,'Full Universe'!$D$3:$D$1499,'Full Universe'!$AW$3:$AW$1499) -> 2250.9008 | E31: =D31=B31 -> TRUE | O31: NL0012969182 | P31: 8.867792
A32: DE000KBX1006 | B32: =_xlfn.XLOOKUP(A32,[1]Universe_World!$D$10:$D$1496,[1]Universe_World!$CK$10:$CK$1496) -> 3428.5625 | C32: DE000KBX1006 | D32: =_xlfn.XLOOKUP(C32,'Full Universe'!$D$3:$D$1499,'Full Universe'!$AW$3:$AW$1499) -> 3428.5625 | E32: =D32=B32 -> TRUE | O32: BE0003851681 | P32: 9.2750313
A33: DK0010244508 | B33: =_xlfn.XLOOKUP(A33,[1]Universe_World!$D$10:$D$1496,[1]Universe_World!$CK$10:$CK$1496) -> 1897.7701 | C33: DK0010244508 | D33: =_xlfn.XLOOKUP(C33,'Full Universe'!$D$3:$D$1499,'Full Universe'!$AW$3:$AW$1499) -> 1897.7701 | E33: =D33=B33 -> TRUE | O33: BMG0112X1056 | P33: 205.29609
... A260: US98419M1009 | B260: =_xlfn.XLOOKUP(A260,[1]Universe_World!$D$10:$D$1496,[1]Universe_World!$CK$10:$CK$1496) -> 2529.1874 | C260: US98419M1009 | D260: =_xlfn.XLOOKUP(C260,'Full Universe'!$D$3:$D$1499,'Full Universe'!$AW$3:$AW$1499) -> 2529.1874 | E260: =D260=B260 -> TRUE | O260: JP3566800003 | P260: 28.355979
O261: GB00B033F229 | P261: 1597.0072
O262: CA12532H1047 | P262: 72.26846
O263: US8085131055 | P263: 27.088612
O264: US16119P1084 | P264: 172.22133
O265: AU000000CHC0 | P265: 126.20468
O266: IL0010824113 | P266: 24.460998
O267: US16411R2085 | P267: 1348.5978
O268: US1667641005 | P268: 4003.7103
O269: JP3511800009 | P269: 604.46634
O270: US1696561059 | P270: 1.4991416
O271: CH0044328745 | P271: 253.49704
O272: JP3526600006 | P272: 3644.7207
...

Sheet Full Universe
A1: Rank | B1: Ticker | C1: Company | D1: ISIN Code | E1: MIC | F1: Number of Shares | G1: Price (EUR) | H1: Currency | I1: Mcap in EUR | J1: index | K1: VOL_AV_3M | L1: Free Float | M1: FFMC_CO | N1: Close Prc | O1: FX/Index Ccy | P1: FFMC_WD | Q1: Subsector Code | R1: Supersector Code | S1: itr_scope123_target | T1: itr_scope12_trend | U1: CDP_climate_score | V1: NBR Overall Flag | W1: Tobacco - Production Maximum Percentage of Revenues (%) | X1: Tobacco - Distribution Maximum Percentage of Revenues (%) | Y1: Biological Weapons - Overall Flag | Z1: Chemical Weapons - Overall Flag | AA1: Nuclear Weapons Outside NPT - Overall Flag | AB1: Nuclear Weapons Inside NPT - Overall Flag | AC1: Cluster Munitions - Overall Flag | AD1: Depleted Uranium - Overall Flag | AE1: Anti-personnel Mines - Overall Flag | AF1: coal_mining_and_power_gen_maximum_percentage_of_revenues-values | AG1: Fossil Fuel - Total Maximum Percentage of Revenues (%) | AH1: power_generation_thermal_maximum_percentage_of_revenues-values | AI1: shale_oil_and_or_gas_involvement_tie | AJ1: arctic_drilling_share_max-values | AK1: deepwater_drilling_involvement | AL1: HydraulicFracturingInvolvement | AM1: CoalMiningExpInvolved | AN1: OilGasExtractExpInvolved | AO1: OtherFFInfraInvolved | AP1: NuclearPowerInvolvement | AQ1: NuclearPowerRevShareMax-values | AR1: NuclearPowerUraniumRevShareMax-values | AS1: CivFARevShareMax-values | AT1: MilitaryEqmtDistMaxRev-values | AU1: Social Rating (Num) | AV1: Governance Rating (Num) | AW1: Carbon Intensity (ISS) | AX1: ScoreTemperatureISS | AY1: NACE | AZ1: High_Climate_Impact | BA1: EU_Taxonomy | BB1: Country_Code | BC1: GAFI_Black_List | BD1: GAFI_Grey_List | BE1: Non_Fiscally_Cooperative | BF1: exclude_gafi_black | BG1: exclude_gafi_grey | BH1: exclude_non_fiscal_coop | BI1: exclude_subsector | BJ1: exclude_nbr_red | BK1: exclude_tobacco_prod | BL1: exclude_tobacco_dist | BM1: exclude_biological_weapons | BN1: exclude_chemical_weapons | BO1: exclude_nuclear_weapons_inside_npt | BP1: exclude_nuclear_weapons_outside_npt | BQ1: exclude_cluster_munitions | BR1: exclude_depleted_uranium | BS1: exclude_anti_personnel_mines | BT1: exclude_coal_mining | BU1: exclude_fossil_fuel | BV1: exclude_thermal_power | BW1: exclude_shale_oil_gas | BX1: exclude_arctic_drilling | BY1: exclude_deepwater_drilling | BZ1: exclude_hydraulic_fracturing | CA1: exclude_coal_mining_expansion | CB1: exclude_oil_gas_extraction_expansion | CC1: exclude_other_fossil_fuel_infra | CD1: exclude_nuclear_power | CE1: exclude_nuclear_power_revenue | CF1: exclude_nuclear_uranium | CG1: exclude_civilian_firearms | CH1: exclude_military_equipment | CI1: SG_Score | CJ1: exclude_sg_bottom_10 | CK1: Excluded | CL1: Exclusion_Reason | CM1: itr_scope123_target_filled | CN1: itr_scope12_trend_filled | CO1: cdp_temperature_score | CP1: bonus_malus | CQ1: climate_score | CR1: Median_Carbon_Intensity_Supersector
A2: 1 | B2: III-GB | C2: 3I GROUP PLC | D2: GB00B1YW4409 | E2: XLON | F2: 973396500 | G2: 49.60294 | H2: GBX | I2: 4.8283328e+10 | J2: EU500 | K2: 39423545 | L2: 1 | M2: 4.8283328e+10 | N2: 3904 | O2: 0.01160026 | P2: 4.4082611e+10 | Q2: 30202010 | R2: 3020 | S2: 1.994079 | T2: 1.5 | U2: D | V2: Green | W2: 0 | X2: 0 | Y2: Green | Z2: Green | AA2: Green | AB2: Green | AC2: Green | AD2: Green | AE2: Green | AG2: 0.05 | AJ2: 0 | AK2: F | AM2: F | AN2: F | AO2: F | AQ2: 0 | AR2: 0 | AS2: 0 | AT2: 0 | AU2: 2.406 | AV2: 3.006 | AW2: 13.164173 | AX2: 1.5 | AY2: K | AZ2: 0 | BA2: 0 | BB2: GB | BC2: 0 | BD2: 0 | BE2: 0 | BU2: exclude_fossil_fuel | CI2: 2.706 | CK2: Yes | CL2: exclude_fossil_fuel | CM2: 1.994079 | CN2: 1.5 | CO2: 1.7470395 | CP2: 0.18 | CQ2: 1.9270395 | CR2: 51.827488
A3: 2 | B3: MMM-US | C3: 3M CO | D3: US88579Y1010 | E3: XNYS | F3: 542900000 | G3: 138.6705 | H3: USD | I3: 75284214450 | J3: NA500 | K3: 4.6977667e+08 | L3: 1 | M3: 75284214450 | N3: 136.01 | O3: 0.8797009 | P3: 6.4956964e+10 | Q3: 50203000 | R3: 5020 | U3: D | V3: Green | W3: 0 | X3: 0 | Y3: Green | Z3: Green | AA3: Green | AB3: Green | AC3: Green | AD3: Green | AE3: Green | AF3: 0 | AG3: 0.05 | AH3: 0 | AI3: Services | AJ3: 0 | AK3: F | AL3: Services | AM3: F | AN3: F | AO3: F | AP3: Services | AQ3: 0.01 | AR3: 0 | AS3: 0 | AT3: 0 | AU3: 2.564 | AV3: 3.384 | AW3: 180.06968 | AX3: 2.1 | AY3: C | AZ3: 1 | BA3: 0 | BB3: US | BC3: 0 | BD3: 0 | BE3: 0 | BU3: exclude_fossil_fuel | BW3: exclude_shale_oil_gas | BZ3: exclude_hydraulic_fracturing | CD3: exclude_nuclear_power | CI3: 2.974 | CK3: Yes | CL3: exclude_fossil_fuel; exclude_shale_oil_gas; exclude_hydraulic_fracturing; exclude_nuclear_power | CM3: 3.4592708 | CN3: 3.1 | CO3: 3.2796354 | CP3: 0.18 | CQ3: 3.4596354 | CR3: 350.98887
A4: 3 | B4: 8341-JP | C4: 77 BANK LTD. | D4: JP3352000008 | E4: XTKS | F4: 76655750 | G4: 29.43114 | H4: JPY | I4: 2.2560661e+09 | J4: AS500 | K4: 5232903.1 | L4: 1 | M4: 2.2560661e+09 | N4: 3934 | O4: 0.00613973 | P4: 1.8515198e+09 | Q4: 30101010 | R4: 3010 | S4: 3.4 | U4: C | V4: Green | W4: 0 | X4: 0 | Y4: Green | Z4: Green | AA4: Green | AB4: Green | AC4: Green | AD4: Green | AE4: Green | AF4: 0 | AG4: 0 | AH4: 0 | AJ4: 0 | AK4: F | AM4: F | AN4: F | AO4: F | AQ4: 0 | AR4: 0 | AS4: 0 | AT4: 0 | AU4: 1.73 | AV4: 1.698 | AW4: 1487.4985 | AX4: 2.9 | AY4: K | AZ4: 0 | BA4: 0 | BB4: JP | BC4: 0 | BD4: 0 | BE4: 0 | CI4: 1.714 | CJ4: exclude_sg_bottom_10 | CK4: Yes | CL4: exclude_sg_bottom_10 | CM4: 3.4 | CN4: 3.1 | CO4: 3.25 | CP4: 0 | CQ4: 3.25 | CR4: 276.86158
A5: 4 | B5: A2M-AU | C5: A2 MILK CO LTD | D5: NZATME0002S8 | E5: XASX | F5: 724019100 | G5: 4.737804 | H5: AUD | I5: 3.4302606e+09 | J5: AS500 | K5: 8193130.8 | L5: 0.9 | M5: 3.0872345e+09 | N5: 8.06 | O5: 0.55671538 | P5: 2.9238884e+09 | Q5: 45102020 | R5: 4510 | S5: 3.4 | U5: F | V5: Green | W5: 0 | X5: 0 | Y5: Green | Z5: Green | AA5: Green | AB5: Green | AC5: Green | AD5: Green | AE5: Green | AF5: 0 | AG5: 0 | AH5: 0 | AJ5: 0 | AK5: F | AM5: F | AN5: F | AO5: F | AQ5: 0 | AR5: 0 | AS5: 0 | AT5: 0 | AU5: 2.013 | AV5: 3.066 | AW5: 474.06286 | AX5: 1.5 | AY5: A | AZ5: 1 | BA5: 0 | BB5: NZ | BC5: 0 | BD5: 0 | BE5: 0 | CI5: 2.5395 | CK5: No | CM5: 3.4 | CN5: 3.1 | CO5: 3.25 | CP5: 0.3 | CQ5: 3.55 | CR5: 285.13539
A6: 5 | B6: A2A-IT | C6: A2A | D6: IT0001233417 | E6: MTAA | F6: 3132905277 | G6: 2.145 | H6: EUR | I6: 6.7200818e+09 | J6: EU500 | K6: 19527443 | L6: 0.5 | M6: 3.3600409e+09 | N6: 2.036 | O6: 1 | P6: 3.1892976e+09 | Q6: 65101015 | R6: 6510 | S6: 2 | T6: 2.93 | U6: A- | V6: Green | W6: 0 | X6: 0 | Y6: Green | Z6: Green | AA6: Green | AB6: Green | AC6: Green | AD6: Green | AE6: Green | AF6: 0.0029 | AG6: 0.369 | AH6: 0.0893 | AJ6: 0 | AK6: F | AM6: F | AN6: F | AO6: T | AQ6: 0 | AR6: 0 | AS6: 0 | AT6: 0 | AU6: 2.448 | AV6: 2.942 | AW6: 1181.0697 | AX6: 2.3 | AY6: D | AZ6: 1 | BA6: 0 | BB6: IT | BC6: 0 | BD6: 0 | BE6: 0 | BT6: exclude_coal_mining | BU6: exclude_fossil_fuel | BV6: exclude_thermal_power | CC6: exclude_other_fossil_fuel_infra | CI6: 2.695 | CK6: Yes | CL6: exclude_coal_mining; exclude_fossil_fuel; exclude_thermal_power; exclude_other_fossil_fuel_infra | CM6: 2 | CN6: 2.93 | CO6: 2.465 | CP6: -0.24 | CQ6: 2.225 | CR6: 1003.2865
A7: 6 | B7: 2018-HK | C7: AAC TECHNOLOGIES | D7: KYG2953R1149 | E7: XHKG | F7: 1198500000 | G7: 6.155748 | H7: HKD | I7: 7377663978 | J7: AS500 | K7: 32843617 | L7: 0.7 | M7: 5.1643648e+09 | N7: 36.65 | O7: 0.11342884 | P7: 3.4876552e+09 | Q7: 10102015 | R7: 1010 | S7: 3.4 | U7: C | V7: Green | W7: 0 | X7: 0 | Y7: Green | Z7: Green | AA7: Green | AB7: Green | AC7: Green | AD7: Green | AE7: Green | AF7: 0 | AG7: 0 | AH7: 0 | AJ7: 0 | AK7: F | AM7: F | AN7: F | AO7: F | AQ7: 0 | AR7: 0 | AS7: 0 | AT7: 0 | AU7: 1.906 | AV7: 2.317 | AW7: 556.19064 | AX7: 6 | AY7: C | AZ7: 1 | BA7: 0 | BB7: KY | BC7: 0 | BD7: 0 | BE7: 0 | CI7: 2.1115 | CK7: No | CM7: 3.4 | CN7: 3.1 | CO7: 3.25 | CP7: 0 | CQ7: 3.25 | CR7: 33.625121
A8: 7 | B8: AAK-SE | C8: AAK AB | D8: SE0011337708 | E8: XSTO | F8: 259559200 | G8: 27.4255 | H8: SEK | I8: 7.1185408e+09 | J8: EU500 | K8: 10069959 | L8: 0.7 | M8: 4.9829786e+09 | N8: 268 | O8: 0.09077334 | P8: 4.420054e+09 | Q8: 45102020 | R8: 4510 | S8: 1.9643056 | U8: C | V8: Green | W8: 0 | X8: 0 | Y8: Green | Z8: Green | AA8: Green | AB8: Green | AC8: Green | AD8: Green | AE8: Green | AF8: 0 | AG8: 0 | AH8: 0 | AJ8: 0 | AK8: F | AM8: F | AN8: F | AO8: F | AQ8: 0 | AR8: 0 | AS8: 0 | AT8: 0 | AU8: 2.42 | AV8: 3.154 | AW8: 1223.803 | AX8: 1.5 | AY8: C | AZ8: 1 | BA8: 0 | BB8: SE | BC8: 0 | BD8: 0 | BE8: 0 | CI8: 2.787 | CK8: No | CM8: 1.9643056 | CN8: 3.1 | CO8: 2.5321528 | CP8: 0 | CQ8: 2.5321528 | CR8: 285.13539
A9: 8 | B9: AALB-NL | C9: AALBERTS NV | D9: NL0000852564 | E9: XAMS | F9: 110580102 | G9: 36.3 | H9: EUR | I9: 4.0140577e+09 | J9: EU500 | K9: 4806266.6 | L9: 0.9 | M9: 3.6126519e+09 | N9: 26.96 | O9: 1 | P9: 2.6831156e+09 | Q9: 50202020 | R9: 5020 | U9: C | V9: Green | W9: 0 | X9: 0 | Y9: Green | Z9: Green | AA9: Green | AB9: Green | AC9: Green | AD9: Green | AE9: Green | AF9: 0 | AG9: 0.1 | AH9: 0 | AJ9: 0 | AK9: F | AM9: F | AN9: F | AO9: F | AP9: Services | AQ9: 0.01 | AR9: 0 | AS9: 0 | AT9: 0 | AU9: 1.998 | AV9: 3.25 | AW9: 1619.7555 | AX9: 1.7 | AY9: C | AZ9: 1 | BA9: 0 | BB9: NL | BC9: 0 | BD9: 0 | BE9: 0 | BU9: exclude_fossil_fuel | CD9: exclude_nuclear_power | CI9: 2.624 | CK9: Yes | CL9: exclude_fossil_fuel; exclude_nuclear_power | CM9: 3.4592708 | CN9: 3.1 | CO9: 3.2796354 | CP9: 0 | CQ9: 3.2796354 | CR9: 350.98887
A10: 9 | B10: ABI-BE | C10: AB INBEV | D10: BE0974293251 | E10: XBRU | F10: 1797198523 | G10: 51.62 | H10: EUR | I10: 9.2771388e+10 | J10: EU500 | K10: 98018859 | L10: 0.55 | M10: 5.1024263e+10 | N10: 55.4 | O10: 1 | P10: 5.4760639e+10 | Q10: 45101010 | R10: 4510 | S10: 2.101079 | T10: 2.7 | U10: Score not available | V10: Amber | W10: 0 | X10: 0 | Y10: Green | Z10: Green | AA10: Green | AB10: Green | AC10: Green | AD10: Green | AE10: Green | AF10: 0 | AG10: 0 | AH10: 0 | AJ10: 0 | AK10: F | AM10: F | AN10: F | AO10: F | AQ10: 0 | AR10: 0 | AS10: 0 | AT10: 0 | AU10: 1.867 | AV10: 2.352 | AW10: 128.46807 | AX10: 1.8 | AY10: C | AZ10: 1 | BA10: 0 | BB10: BE | BC10: 0 | BD10: 0 | BE10: 0 | CI10: 2.1095 | CK10: No | CM10: 2.101079 | CN10: 2.7 | CO10: 2.4005395 | CP10: 0.3 | CQ10: 2.7005395 | CR10: 285.13539
A11: 10 | B11: SAGA.B-SE | C11: AB SAGAX CLASS B | D11: SE0005127818 | E11: XSTO | F11: 313943020 | G11: 19.72838 | H11: SEK | I11: 6.1935872e+09 | J11: EU500 | K11: 7671301.9 | L11: 0.7 | M11: 4.335511e+09 | N11: 201.4 | O11: 0.09077334 | P11: 4.0175996e+09 | Q11: 35101010 | R11: 3510 | S11: 3.2721025 | U11: F | V11: Green | W11: 0 | X11: 0 | Y11: Green | Z11: Green | AA11: Green | AB11: Green | AC11: Green | AD11: Green | AE11: Green | AF11: 0 | AG11: 0 | AH11: 0 | AJ11: 0 | AK11: F | AM11: F | AN11: F | AO11: F | AQ11: 0 | AR11: 0 | AS11: 0 | AT11: 0 | AU11: 1.961 | AV11: 2.119 | AW11: 3.5372492 | AX11: 1.5 | AY11: L | AZ11: 1 | BA11: 0 | BB11: SE | BC11: 0 | BD11: 0 | BE11: 0 | CI11: 2.04 | CK11: No | CM11: 3.2721025 | CN11: 3.1 | CO11: 3.1860513 | CP11: 0.3 | CQ11: 3.4860513 | CR11: 23.753721
A12: 11 | B12: ABBN-CH | C12: ABB LTD | D12: CH0012221716 | E12: XSWX | F12: 1860614900 | G12: 55.5674 | H12: CHF | I12: 1.0338953e+11 | J12: EU500 | K12: 1.4023889e+08 | L12: 0.85 | M12: 8.7881103e+10 | N12: 41.37 | O12: 1.0763104 | P12: 7.0420399e+10 | Q12: 50202010 | R12: 5020 | S12: 1.7491009 | T12: 1.5 | U12: A | V12: Amber | W12: 0 | X12: 0 | Y12: Green | Z12: Green | AA12: Green | AB12: Green | AC12: Green | AD12: Green | AE12: Green | AF12: 0.01 | AG12: 0.15 | AH12: 0 | AJ12: 0 | AK12: T | AM12: F | AN12: F | AO12: F | AP12: Services | AQ12: 0.04 | AR12: 0 | AS12: 0 | AT12: 0 | AU12: 2.887 | AV12: 2.502 | AW12: 5228.3624 | AX12: 1.5 | AY12: C | AZ12: 1 | BA12: 0 | BB12: CH | BC12: 0 | BD12: 0 | BE12: 0 | BT12: exclude_coal_mining | BU12: exclude_fossil_fuel | BY12: exclude_deepwater_drilling | CD12: exclude_nuclear_power | CI12: 2.6945 | CK12: Yes | CL12: exclude_coal_mining; exclude_fossil_fuel; exclude_deepwater_drilling; exclude_nuclear_power | CM12: 1.7491009 | CN12: 1.5 | CO12: 1.6245504 | CP12: -0.3 | CQ12: 1.3245504 | CR12: 350.98887
A13: 12 | B13: ABT-US | C13: ABBOTT LABORATORIES | D13: US0028241000 | E13: XNYS | F13: 1734323400 | G13: 129.0483 | H13: USD | I13: 2.2381149e+11 | J13: NA500 | K13: 6.6899105e+08 | L13: 1 | M13: 2.2381149e+11 | N13: 127.96 | O13: 0.8797009 | P13: 1.9522676e+11 | Q13: 20102010 | R13: 2010 | S13: 1.9835941 | T13: 2.08 | U13: B | V13: Green | W13: 0 | X13: 0 | Y13: Green | Z13: Green | AA13: Green | AB13: Green | AC13: Green | AD13: Green | AE13: Green | AF13: 0 | AG13: 0 | AH13: 0 | AJ13: 0 | AK13: F | AM13: F | AN13: F | AO13: F | AQ13: 0 | AR13: 0 | AS13: 0 | AT13: 0 | AU13: 2.693 | AV13: 3.678 | AW13: 61.330192 | AX13: 1.5 | AY13: C | AZ13: 1 | BA13: 0 | BB13: US | BC13: 0 | BD13: 0 | BE13: 0 | CI13: 3.1855 | CK13: No | CM13: 1.9835941 | CN13: 2.08 | CO13: 2.0317971 | CP13: -0.18 | CQ13: 1.8517971 | CR13: 50.951644
A14: 13 | B14: ABBV-US | C14: ABBVIE INC. | D14: US00287Y1091 | E14: XNYS | F14: 1765354900 | G14: 193.2855 | H14: USD | I14: 3.412175e+11 | J14: NA500 | K14: 1.0309011e+09 | L14: 1 | M14: 3.412175e+11 | N14: 179.1 | O14: 0.8797009 | P14: 2.7813949e+11 | Q14: 20103015 | R14: 2010 | S14: 1.969737 | T14: 2.08 | U14: B | V14: Green | W14: 0 | X14: 0 | Y14: Green | Z14: Green | AA14: Green | AB14: Green | AC14: Green | AD14: Green | AE14: Green | AF14: 0 | AG14: 0 | AH14: 0 | AJ14: 0 | AK14: F | AM14: F | AN14: F | AO14: F | AQ14: 0 | AR14: 0 | AS14: 0 | AT14: 0 | AU14: 2.616 | AV14: 2.953 | AW14: 24.281901 | AX14: 1.5 | AY14: C | AZ14: 1 | BA14: 0 | BB14: US | BC14: 0 | BD14: 0 | BE14: 0 | CI14: 2.7845 | CK14: No | CM14: 1.969737 | CN14: 2.08 | CO14: 2.0248685 | CP14: -0.18 | CQ14: 1.8448685 | CR14: 50.951644
A15: 14 | B15: ABN-NL | C15: ABN AMRO BANK N.V. | D15: NL0011540547 | E15: XAMS | F15: 539163896 | G15: 17.8 | H15: EUR | I15: 9.5971173e+09 | J15: EU500 | K15: 48401045 | L15: 1 | M15: 9.5971173e+09 | N15: 17.56 | O15: 1 | P15: 9.467718e+09 | Q15: 30101010 | R15: 3010 | S15: 3.2733333 | U15: C | V15: Green | W15: 0 | X15: 0 | Y15: Green | Z15: Green | AA15: Green | AB15: Green | AC15: Green | AD15: Green | AE15: Green | AF15: 0 | AG15: 0 | AH15: 0 | AJ15: 0 | AK15: F | AM15: F | AN15: F | AO15: F | AQ15: 0 | AR15: 0 | AS15: 0 | AT15: 0 | AU15: 2.394 | AV15: 2.779 | AW15: 397.99801 | AX15: 1.5 | AY15: K | AZ15: 0 | BA15: 0 | BB15: NL | BC15: 0 | BD15: 0 | BE15: 0 | CI15: 2.5865 | CK15: No | CM15: 3.2733333 | CN15: 3.1 | CO15: 3.1866667 | CP15: 0 | CQ15: 3.1866667 | CR15: 276.86158
