Workbook

Sheet Index Composition
A1: Company | B1: ISIN Code | C1: MIC | D1: Number of Shares | E1: Free Float | F1: Capping Factor | G1: Effective Date of Review | H1: Currency
A2: ALPHABET CLASS A | B2: US02079K3059 | C2: XNGS | D2: 973106 | E2: 1 | F2: 1 | G2: 22-Sep-25 | H2: USD
A3: AMAZON | B3: US0231351067 | C3: XNGS | D3: 1044244 | E3: 1 | F3: 1 | G3: 22-Sep-25 | H3: USD
A4: APPLE | B4: US0378331005 | C4: XNGS | D4: 1026266 | E4: 1 | F4: 1 | G4: 22-Sep-25 | H4: USD
A5: BANK OF AMERICA | B5: US0605051046 | C5: XNYS | D5: 4824423 | E5: 1 | F5: 1 | G5: 22-Sep-25 | H5: USD
A6: BROADCOM INC. | B6: US11135F1012 | C6: XNGS | D6: 678903 | E6: 1 | F6: 1 | G6: 22-Sep-25 | H6: USD
A7: CISCO SYSTEMS INC | B7: US17275R1023 | C7: XNGS | D7: 3651655 | E7: 1 | F7: 1 | G7: 22-Sep-25 | H7: USD
A8: COCA-COLA CO | B8: US1912161007 | C8: XNYS | D8: 3689693 | E8: 1 | F8: 1 | G8: 22-Sep-25 | H8: USD
A9: ELI LILLY AND CO | B9: US5324571083 | C9: XNYS | D9: 319605 | E9: 1 | F9: 1 | G9: 22-Sep-25 | H9: USD
A10: GE AEROSPACE | B10: US3696043013 | C10: XNYS | D10: 834233 | E10: 1 | F10: 1 | G10: 22-Sep-25 | H10: USD
A11: HOME DEPOT INC | B11: US4370761029 | C11: XNYS | D11: 579915 | E11: 1 | F11: 1 | G11: 22-Sep-25 | H11: USD
A12: JOHNSON & JOHNSON | B12: US4781601046 | C12: XNYS | D12: 1385046 | E12: 1 | F12: 1 | G12: 22-Sep-25 | H12: USD
A13: JP MORGAN CHASE & CO | B13: US46625H1005 | C13: XNYS | D13: 790469 | E13: 1 | F13: 1 | G13: 22-Sep-25 | H13: USD
... A26: WALMART INC | B26: US9311421039 | C26: XNYS | D26: 2363230 | E26: 1 | F26: 1 | G26: 22-Sep-25 | H26: USD

Sheet Inclusion
A1: Company | B1: ISIN Code | C1: MIC
A2: ALPHABET CLASS A | B2: US02079K3059 | C2: XNGS
A3: AMAZON | B3: US0231351067 | C3: XNGS
A4: TESLA INC | B4: US88160R1014 | C4: XNGS

Sheet Exclusion
A1: Company | B1: ISIN code | C1: MIC
A2: ABBVIE INC. | B2: US00287Y1091 | C2: XNYS
A3: IBM CORP | B3: US4592001014 | C3: XNYS
A4: NVIDIA CORP | B4: US67066G1040 | C4: XNGS

Sheet Full Universe
A1: Rank | B1: Company | C1: Ticker | D1: ISIN | E1: Currency (Local) | F1: Price (EUR) | G1: NOSH | H1: Exchange Name (VND) | I1: Sec Market Value (EUR) | J1: 20 days aver. turn EUR | K1: 6 month aver. turnover EUR | L1: 3 month average turnover EUR | M1: 3 months aver. Turnover USD | N1: 12 month aver. turnover EUR | O1: MIC | P1: Free Float | Q1: #Symbol | R1: FX/Index Ccy | S1: ClimateCuAlignIEANZTgt2050-values | T1: ESG Performance Score | U1: Reported Emissions - Emissions Trust Metric | V1: NBR Overall Flag | W1: Anti-personnel Mines - Overall Flag | X1: Biological Weapons - Overall Flag | Y1: Chemical Weapons - Overall Flag | Z1: Cluster Munitions - Overall Flag | AA1: Depleted Uranium - Overall Flag | AB1: Incendiary Weapons - Overall Flag | AC1: Nuclear Weapons Outside NPT - Overall Flag | AD1: White Phosphorous Weapons - Overall Flag | AE1: Thermal Coal Mining - Maximum Percentage of Revenues (%) | AF1: Power Generation - Thermal Maximum Percentage of Revenues (%) | AG1: Shale Oil and/or Gas - Involvement tie | AH1: Trust Metric Numeric | AI1: Coal Mining Numeric | AJ1: Thermal Power Numeric | AK1: Carbon Budget Rank | AL1: exclusion_1_TrustMetric | AM1: exclusion_2_NBROverallFlag | AN1: exclusion_3_APMines | AO1: exclusion_4_BiologicalWeapons | AP1: exclusion_5_ChemicalWeapons | AQ1: exclusion_6_ClusterMunitions | AR1: exclusion_7_DepletedUranium | AS1: exclusion_8_IncendiaryWeapons | AT1: exclusion_9_NuclearWeaponsNonNPT | AU1: exclusion_10_WhitePhosphorus | AV1: exclusion_11_CoalMining | AW1: exclusion_12_ThermalPower | AX1: exclusion_13_ShaleOilGas | AY1: exclusion_14_CarbonBudget | AZ1: Exclusion Summary | BA1: Excluded | BB1: ESG Performance Rank
A2: 1 | B2: 3M CO | C2: MMM-US | D2: US88579Y1010 | E2: USD | F2: 135.4497 | G2: 532629700 | H2: NYSE | I2: 72144.55 | J2: 4.0894509e+08 | K2: 4.9663707e+08 | L2: 4.4055249e+08 | M2: 5.1103236e+08 | N2: 4.7372284e+08 | O2: XNYS | P2: 1 | Q2: MMM.N | R2: 0.84373945 | S2: 2.06 | T2: 62.06 | U2: 0.99 | V2: Green | W2: Green | X2: Green | Y2: Green | Z2: Green | AA2: Green | AB2: Green | AC2: Green | AD2: Green | AE2: 0 | AF2: 0 | AG2: Services | AH2: 0.99 | AI2: 0 | AJ2: 0 | AK2: 233 | AZ2: Included | BA2: No | BB2: 34
A3: 2 | B3: ABBOTT LABORATORIES | C3: ABT-US | D3: US0028241000 | E3: USD | F3: 113.1507 | G3: 1740459000 | H3: NYSE | I3: 196934.2 | J3: 6.1682532e+08 | K3: 7.9636219e+08 | L3: 7.2641161e+08 | M3: 8.421529e+08 | N3: 6.9617688e+08 | O3: XNYS | P3: 1 | Q3: ABT.N | R3: 0.84373945 | S3: 2.02 | T3: 59.53 | U3: 1 | V3: Green | W3: Green | X3: Green | Y3: Green | Z3: Green | AA3: Green | AB3: Green | AC3: Green | AD3: Green | AE3: 0 | AF3: 0 | AH3: 1 | AI3: 0 | AJ3: 0 | AK3: 228 | AZ3: Included | BA3: No | BB3: 54
A4: 3 | B4: ABBVIE INC. | C4: ABBV-US | D4: US00287Y1091 | E4: USD | F4: 179.7235 | G4: 1766558200 | H4: NYSE | I4: 317492.1 | J4: 8.0936205e+08 | K4: 1.1783614e+09 | L4: 9.342367e+08 | M4: 1.0832805e+09 | N4: 1.0849966e+09 | O4: XNYS | P4: 1 | Q4: ABBV.N | R4: 0.84373945 | S4: 7.07 | T4: 59.51 | U4: 0.95 | V4: Green | W4: Green | X4: Green | Y4: Green | Z4: Green | AA4: Green | AB4: Green | AC4: Green | AD4: Green | AE4: 0 | AF4: 0 | AH4: 0.95 | AI4: 0 | AJ4: 0 | AK4: 435 | AY4: exclude_CarbonBudget | AZ4: CarbonBudget | BA4: Yes
A5: 4 | B5: ACCENTURE PLC-A | C5: ACN-US | D5: IE00B4BNMY34 | E5: USD | F5: 221.2152 | G5: 622852700 | H5: NYSE | I5: 137784.5 | J5: 1.0767012e+09 | K5: 9.8915591e+08 | L5: 9.5671143e+08 | M5: 1.1087687e+09 | N5: 9.152817e+08 | O5: XNYS | P5: 1 | Q5: ACN.N | R5: 0.84373945 | S5: 0.69 | T5: 63.16 | U5: 0.99 | V5: Amber | W5: Green | X5: Green | Y5: Green | Z5: Green | AA5: Green | AB5: Green | AC5: Green | AD5: Green | AE5: 0 | AF5: 0 | AH5: 0.99 | AI5: 0 | AJ5: 0 | AK5: 62 | AZ5: Included | BA5: No | BB5: 29
A6: 5 | B6: ADOBE INC | C6: ADBE-US | D6: US00724F1012 | E6: USD | F6: 309.0032 | G6: 424200000 | H6: NASDAQ | I6: 131079.2 | J6: 1.1209776e+09 | K6: 1.2945546e+09 | L6: 1.2387585e+09 | M6: 1.4359691e+09 | N6: 1.4229173e+09 | O6: XNGS | P6: 1 | Q6: ADBE.O | R6: 0.84373945 | S6: 0.62 | T6: 69.03 | U6: 0.92 | V6: Green | W6: Green | X6: Green | Y6: Green | Z6: Green | AA6: Green | AB6: Green | AC6: Green | AD6: Green | AE6: 0 | AF6: 0 | AH6: 0.92 | AI6: 0 | AJ6: 0 | AK6: 52 | AZ6: Included | BA6: No | BB6: 8
A7: 6 | B7: ADVANCED MICRO DEV. | C7: AMD-US | D7: US0079031078 | E7: USD | F7: 143.1644 | G7: 1622843800 | H7: NASDAQ | I7: 232333.4 | J7: 1.0180694e+10 | K7: 5.5215137e+09 | L7: 7.308069e+09 | M7: 8.4823675e+09 | N7: 5.1385126e+09 | O7: XNGS | P7: 1 | Q7: AMD.O | R7: 0.84373945 | S7: 7.58 | T7: 63.93 | U7: 0.93 | V7: Green | W7: Green | X7: Green | Y7: Green | Z7: Green | AA7: Green | AB7: Green | AC7: Green | AD7: Green | AE7: 0 | AF7: 0 | AH7: 0.93 | AI7: 0 | AJ7: 0 | AK7: 443 | AY7: exclude_CarbonBudget | AZ7: CarbonBudget | BA7: Yes
A8: 7 | B8: AERCAP HOLDINGS NV | C8: AER-US | D8: NL0000687663 | E8: USD | F8: 101.9287 | G8: 176566560 | H8: NYSE | I8: 17997.19 | J8: 1.4667501e+08 | K8: 1.4845408e+08 | L8: 1.2816052e+08 | M8: 1.484442e+08 | N8: 1.2325096e+08 | O8: XNYS | P8: 1 | Q8: AER.N | R8: 0.84373945 | S8: 0.19 | T8: 42.09 | U8: 0.5 | V8: Green | W8: Green | X8: Green | Y8: Green | Z8: Green | AA8: Green | AB8: Green | AC8: Green | AD8: Green | AE8: 0 | AF8: 0 | AH8: 0.5 | AI8: 0 | AJ8: 0 | AK8: 3 | AL8: exclude_TrustMetric | AZ8: TrustMetric | BA8: Yes
A9: 8 | B9: AFFIRM HLDNG CLASS A | C9: AFRM-US | D9: US00827B1061 | E9: USD | F9: 67.83581 | G9: 281825620 | H9: NASDAQ | I9: 19117.87 | J9: 3.7984228e+08 | K9: 3.4939164e+08 | L9: 3.1330658e+08 | M9: 3.6334448e+08 | N9: 4.0808896e+08 | O9: XNGS | P9: 1 | Q9: AFRM.O | R9: 0.84373945 | S9: 3.03 | T9: 36.1 | U9: 0.5 | V9: Green | W9: Green | X9: Green | Y9: Green | Z9: Green | AA9: Green | AB9: Green | AC9: Green | AD9: Green | AE9: 0 | AF9: 0 | AH9: 0.5 | AI9: 0 | AJ9: 0 | AK9: 356 | AL9: exclude_TrustMetric | AZ9: TrustMetric | BA9: Yes
A10: 9 | B10: AFLAC INCORPORATED | C10: AFL-US | D10: US0010551028 | E10: USD | F10: 92.55846 | G10: 534831500 | H10: NYSE | I10: 49503.18 | J10: 2.3656445e+08 | K10: 2.1079298e+08 | L10: 2.1836058e+08 | M10: 2.5326599e+08 | N10: 2.0951413e+08 | O10: XNYS | P10: 0.9 | Q10: AFL.N | R10: 0.84373945 | S10: 0.81 | T10: 47.44 | U10: 0.95 | V10: Green | W10: Green | X10: Green | Y10: Green | Z10: Green | AA10: Green | AB10: Green | AC10: Green | AD10: Green | AE10: 0 | AF10: 0 | AH10: 0.95 | AI10: 0 | AJ10: 0 | AK10: 80 | AZ10: Included | BA10: No | BB10: 197
A11: 10 | B11: AGILENT TECHNOLOGIES | C11: A-US | D11: US00846U1016 | E11: USD | F11: 103.7976 | G11: 284064730 | H11: NYSE | I11: 29485.23 | J11: 1.1335849e+08 | K11: 2.0771335e+08 | L11: 1.7971705e+08 | M11: 2.0790079e+08 | N11: 2.1068761e+08 | O11: XNYS | P11: 1 | Q11: A.N | R11: 0.84373945 | S11: 0.58 | T11: 54.94 | U11: 0.98 | V11: Green | W11: Green | X11: Green | Y11: Green | Z11: Green | AA11: Green | AB11: Green | AC11: Green | AD11: Green | AE11: 0 | AF11: 0 | AH11: 0.98 | AI11: 0 | AJ11: 0 | AK11: 45 | AZ11: Included | BA11: No | BB11: 108
A12: 12 | B12: AIR PROD & CHEMICALS | C12: APD-US | D12: US0091581068 | E12: USD | F12: 255.419 | G12: 222553630 | H12: NYSE | I12: 56844.43 | J12: 2.19176e+08 | K12: 2.9626585e+08 | L12: 2.6904217e+08 | M12: 3.1152427e+08 | N12: 3.583009e+08 | O12: XNYS | P12: 1 | Q12: APD.N | R12: 0.84373945 | S12: 2.75 | T12: 58.25 | U12: 0.99 | V12: Green | W12: Green | X12: Green | Y12: Green | Z12: Green | AA12: Green | AB12: Green | AC12: Green | AD12: Green | AE12: 0 | AF12: 0.01 | AG12: Services | AH12: 0.99 | AI12: 0 | AJ12: 0.01 | AK12: 328 | AZ12: Included | BA12: No | BB12: 68
A13: 13 | B13: AIRBNB INC. CLASS A | C13: ABNB-US | D13: US0090661010 | E13: USD | F13: 110.8722 | G13: 429079560 | H13: NASDAQ | I13: 47572.98 | J13: 6.8107911e+08 | K13: 6.0294661e+08 | L13: 5.4679516e+08 | M13: 6.3286068e+08 | N13: 5.9084316e+08 | O13: XNGS | P13: 1 | Q13: ABNB.O | R13: 0.84373945 | S13: 0.62 | T13: 34.92 | U13: 0.84 | V13: Green | W13: Green | X13: Green | Y13: Green | Z13: Green | AA13: Green | AB13: Green | AC13: Green | AD13: Green | AE13: 0 | AF13: 0 | AH13: 0.84 | AI13: 0 | AJ13: 0 | AK13: 52 | AZ13: Included | BA13: No | BB13: 290
A14: 15 | B14: ALLSTATE CORPORATION | C14: ALL-US | D14: US0200021014 | E14: USD | F14: 175.3883 | G14: 263505340 | H14: NYSE | I14: 46215.75 | J14: 2.3016961e+08 | K14: 3.0072871e+08 | L14: 2.7287305e+08 | M14: 3.1614098e+08 | N14: 2.9194916e+08 | O14: XNYS | P14: 1 | Q14: ALL.N | R14: 0.84373945 | S14: 0.48 | T14: 52.89 | U14: 0.99 | V14: Green | W14: Green | X14: Green | Y14: Green | Z14: Green | AA14: Green | AB14: Green | AC14: Green | AD14: Green | AE14: 0 | AF14: 0 | AH14: 0.99 | AI14: 0 | AJ14: 0 | AK14: 26 | AZ14: Included | BA14: No | BB14: 139
A15: 16 | B15: ALNYLAM PHARMA | C15: ALNY-US | D15: US02043Q1076 | E15: USD | F15: 387.7624 | G15: 131079010 | H15: NASDAQ | I15: 50827.52 | J15: 4.7851202e+08 | K15: 2.7916715e+08 | L15: 3.2744825e+08 | M15: 3.7957111e+08 | N15: 2.3400888e+08 | O15: XNGS | P15: 1 | Q15: ALNY.O | R15: 0.84373945 | S15: 6.53 | T15: 56 | U15: 0.71 | V15: Green | W15: Green | X15: Green | Y15: Green | Z15: Green | AA15: Green | AB15: Green | AC15: Green | AD15: Green | AE15: 0 | AF15: 0 | AH15: 0.71 | AI15: 0 | AJ15: 0 | AK15: 433 | AY15: exclude_CarbonBudget | AZ15: CarbonBudget | BA15: Yes
A16: 17 | B16: ALPHABET CLASS A | C16: GOOGL-US | D16: US02079K3059 | E16: USD | F16: 175.8747 | G16: 5817000000 | H16: NASDAQ | I16: 1023063 | J16: 4.9248801e+09 | K16: 5.8717197e+09 | L16: 5.9033678e+09 | M16: 6.8459395e+09 | N16: 5.1699677e+09 | O16: XNGS | P16: 1 | Q16: GOOGL.O | R16: 0.84373945 | S16: 0.65 | T16: 57.27 | U16: 0.84 | V16: Amber | W16: Green | X16: Green | Y16: Green | Z16: Green | AA16: Green | AB16: Green | AC16: Green | AD16: Green | AE16: 0 | AF16: 0 | AH16: 0.84 | AI16: 0 | AJ16: 0 | AK16: 58 | AZ16: Included | BA16: No | BB16: 79
A17: 18 | B17: ALTRIA GROUP INC | C17: MO-US | D17: US02209S1033 | E17: USD | F17: 57.74876 | G17: 1679891000 | H17: NYSE | I17: 97011.62 | J17: 4.328411e+08 | K17: 5.0524081e+08 | L17: 4.5528886e+08 | M17: 5.2787621e+08 | N17: 4.4449354e+08 | O17: XNYS | P17: 1 | Q17: MO.N | R17: 0.84373945 | S17: 0.79 | T17: 43.06 | U17: 0.99 | V17: Green | W17: Green | X17: Green | Y17: Green | Z17: Green | AA17: Green | AB17: Green | AC17: Green | AD17: Green | AE17: 0 | AF17: 0 | AH17: 0.99 | AI17: 0 | AJ17: 0 | AK17: 77 | AZ17: Included | BA17: No | BB17: 242
A18: 19 | B18: AMAZON | C18: AMZN-US | D18: US0231351067 | E18: USD | F18: 195.2893 | G18: 10664912000 | H18: NASDAQ | I18: 2082743 | J18: 7.9772001e+09 | K18: 8.5104795e+09 | L18: 7.9912963e+09 | M18: 9.2643579e+09 | N18: 7.8246173e+09 | O18: XNGS | P18: 0.9 | Q18: AMZN.O | R18: 0.84373945 | S18: 1.36 | T18: 43.66 | U18: 0.93 | V18: Amber | W18: Green | X18: Green | Y18: Green | Z18: Green | AA18: Green | AB18: Green | AC18: Green | AD18: Green | AE18: 0 | AF18: 0 | AH18: 0.93 | AI18: 0 | AJ18: 0 | AK18: 145 | AZ18: Included | BA18: No | BB18: 232
A19: 20 | B19: AMCOR PLC | C19: AMCR-US | D19: JE00BJ1F3079 | E19: USD | F19: 7.433009 | G19: 2305359900 | H19: NYSE | I19: 17135.76 | J19: 2.3413273e+08 | K19: 2.6565502e+08 | L19: 2.0831158e+08 | M19: 2.4131198e+08 | N19: 1.9659698e+08 | O19: XNYS | P19: 1 | Q19: AMCR.N | R19: 0.84373945 | S19: 1.44 | T19: 58.26 | U19: 0.99 | V19: Green | W19: Green | X19: Green | Y19: Green | Z19: Green | AA19: Green | AB19: Green | AC19: Green | AD19: Green | AE19: 0 | AF19: 0 | AH19: 0.99 | AI19: 0 | AJ19: 0 | AK19: 154 | AZ19: Included | BA19: No | BB19: 67
A20: 21 | B20: AMEREN CORPORATION | C20: AEE-US | D20: US0236081024 | E20: USD | F20: 87.0029 | G20: 270409900 | H20: NYSE | I20: 23526.45 | J20: 1.2245225e+08 | K20: 1.5137013e+08 | L20: 1.3361704e+08 | M20: 1.548029e+08 | N20: 1.3799348e+08 | O20: XNYS | P20: 1 | Q20: AEE.N | R20: 0.84373945 | S20: 2.65 | T20: 34.93 | U20: 0.93 | V20: Green | W20: Green | X20: Green | Y20: Green | Z20: Green | AA20: Green | AB20: Green | AC20: Green | AD20: Green | AE20: 0 | AF20: 0.2326 | AH20: 0.93 | AI20: 0 | AJ20: 0.2326 | AK20: 316 | AW20: exclude_ThermalPower | AZ20: ThermalPower | BA20: Yes
A21: 22 | B21: AMERICAN ELECT. PWR. | C21: AEP-US | D21: US0255371017 | E21: USD | F21: 97.30329 | G21: 534794740 | H21: NASDAQ | I21: 52037.29 | J21: 3.0197537e+08 | K21: 3.4255525e+08 | L21: 2.7478319e+08 | M21: 3.1851057e+08 | N21: 3.0528238e+08 | O21: XNGS | P21: 1 | Q21: AEP.O | R21: 0.84373945 | S21: 2.37 | T21: 43 | U21: 0.73 | V21: Green | W21: Green | X21: Green | Y21: Green | Z21: Green | AA21: Green | AB21: Green | AC21: Green | AD21: Green | AE21: 0 | AF21: 0.2509 | AH21: 0.73 | AI21: 0 | AJ21: 0.2509 | AK21: 276 | AW21: exclude_ThermalPower | AZ21: ThermalPower | BA21: Yes
A22: 23 | B22: AMERICAN EXPRESS | C22: AXP-US | D22: US0258161092 | E22: USD | F22: 272.3673 | G22: 695882200 | H22: NYSE | I22: 189535.6 | J22: 6.1478665e+08 | K22: 7.6537691e+08 | L22: 6.8852872e+08 | M22: 7.9844639e+08 | N22: 7.2732359e+08 | O22: XNYS | P22: 0.8 | Q22: AXP.N | R22: 0.84373945 | S22: 0.71 | T22: 48.25 | U22: 0.86 | V22: Green | W22: Green | X22: Green | Y22: Green | Z22: Green | AA22: Green | AB22: Green | AC22: Green | AD22: Green | AE22: 0 | AF22: 0 | AH22: 0.86 | AI22: 0 | AJ22: 0 | AK22: 64 | AZ22: Included | BA22: No | BB22: 192
A23: 24 | B23: AMERICAN INTERN. | C23: AIG-US | D23: US0268747849 | E23: USD | F23: 71.15549 | G23: 554003850 | H23: NYSE | I23: 39420.41 | J23: 2.6003803e+08 | K23: 3.3994544e+08 | L23: 2.9556747e+08 | M23: 3.4259511e+08 | N23: 3.1062969e+08 | O23: XNYS | P23: 1 | Q23: AIG.N | R23: 0.84373945 | S23: 1.04 | T23: 41.74 | U23: 0.76 | V23: Green | W23: Green | X23: Green | Y23: Green | Z23: Green | AA23: Green | AB23: Green | AC23: Green | AD23: Green | AE23: 0 | AF23: 0 | AH23: 0.76 | AI23: 0 | AJ23: 0 | AK23: 111 | AZ23: Included | BA23: No | BB23: 252
A24: 25 | B24: AMERICAN TOWER CORP | C24: AMT-US | D24: US03027X1000 | E24: USD | F24: 180.8158 | G24: 468251220 | H24: NYSE | I24: 84667.24 | J24: 3.9275888e+08 | K24: 5.158913e+08 | L24: 3.9996884e+08 | M24: 4.6319874e+08 | N24: 4.7697854e+08 | O24: XNYS | P24: 1 | Q24: AMT.N | R24: 0.84373945 | S24: 4 | T24: 51.93 | U24: 0.5 | V24: Green | W24: Green | X24: Green | Y24: Green | Z24: Green | AA24: Green | AB24: Green | AC24: Green | AD24: Green | AE24: 0 | AF24: 0 | AH24: 0.5 | AI24: 0 | AJ24: 0 | AK24: 401 | AL24: exclude_TrustMetric | AY24: exclude_CarbonBudget | AZ24: TrustMetric; CarbonBudget | BA24: Yes
A25: 26 | B25: AMERICAN WATER WORKS | C25: AWK-US | D25: US0304201033 | E25: USD | F25: 124.7653 | G25: 202140820 | H25: NYSE | I25: 25220.16 | J25: 2.0283616e+08 | K25: 1.8588778e+08 | L25: 1.5908726e+08 | M25: 1.8429776e+08 | N25: 1.6540337e+08 | O25: XNYS | P25: 1 | Q25: AWK.N | R25: 0.84373945 | S25: 2.16 | T25: 69.08 | U25: 0.96 | V25: Green | W25: Green | X25: Green | Y25: Green | Z25: Green | AA25: Green | AB25: Green | AC25: Green | AD25: Green | AE25: 0 | AF25: 0 | AH25: 0.96 | AI25: 0 | AJ25: 0 | AK25: 247 | AZ25: Included | BA25: No | BB25: 7
A26: 27 | B26: AMERIPRISE FINANCIAL | C26: AMP-US | D26: US03076C1062 | E26: USD | F26: 441.1333 | G26: 94271570 | H26: NYSE | I26: 41586.33 | J26: 1.6819253e+08 | K26: 2.1774123e+08 | L26: 2.0042298e+08 | M26: 2.3224784e+08 | N26: 2.2542364e+08 | O26: XNYS | P26: 1 | Q26: AMP.N | R26: 0.84373945 | S26: 2.6 | T26: 51.83 | U26: 0.74 | V26: Green | W26: Green | X26: Green | Y26: Green | Z26: Green | AA26: Green | AB26: Green | AC26: Green | AD26: Green | AE26: 0 | AF26: 0 | AH26: 0.74 | AI26: 0 | AJ26: 0 | AK26: 308 | AZ26: Included | BA26: No | BB26: 157
A27: 28 | B27: AMETEK INC. | C27: AME-US | D27: US0311001004 | E27: USD | F27: 159.5409 | G27: 230953960 | H27: NYSE | I27: 36846.6 | J27: 1.9023048e+08 | K27: 2.1611398e+08 | L27: 2.1095942e+08 | M27: 2.443305e+08 | N27: 2.1001555e+08 | O27: XNYS | P27: 1 | Q27: AME.N | R27: 0.84373945 | S27: 2.18 | T27: 35.76 | U27: 0.66 | V27: Green | W27: Green | X27: Green | Y27: Green | Z27: Green | AA27: Green | AB27: Green | AC27: Green | AD27: Green | AE27: 0 | AF27: 0 | AG27: Services | AH27: 0.66 | AI27: 0 | AJ27: 0 | AK27: 251 | AZ27: Included | BA27: No | BB27: 288
A28: 29 | B28: AMGEN INC | C28: AMGN-US | D28: US0311621009 | E28: USD | F28: 250.6571 | G28: 538361900 | H28: NASDAQ | I28: 134944.2 | J28: 5.4594013e+08 | K28: 7.2116114e+08 | L28: 5.9994509e+08 | M28: 6.9446391e+08 | N28: 7.6237189e+08 | O28: XNGS | P28: 1 | Q28: AMGN.O | R28: 0.84373945 | S28: 1.06 | T28: 60.78 | U28: 0.99 | V28: Amber | W28: Green | X28: Green | Y28: Green | Z28: Green | AA28: Green | AB28: Green | AC28: Green | AD28: Green | AE28: 0 | AF28: 0 | AH28: 0.99 | AI28: 0 | AJ28: 0 | AK28: 113 | AZ28: Included | BA28: No | BB28: 43
A29: 30 | B29: AMPHENOL COR CLASS A | C29: APH-US | D29: US0320951017 | E29: USD | F29: 93.32651 | G29: 1220921100 | H29: NYSE | I29: 113944.3 | J29: 6.8199416e+08 | K29: 6.456871e+08 | L29: 7.4146339e+08 | M29: 8.5991509e+08 | N29: 5.4344609e+08 | O29: XNYS | P29: 1 | Q29: APH.N | R29: 0.84373945 | S29: 1.2 | T29: 47.59 | U29: 0.67 | V29: Green | W29: Green | X29: Green | Y29: Green | Z29: Green | AA29: Green | AB29: Green | AC29: Green | AD29: Green | AE29: 0 | AF29: 0 | AH29: 0.67 | AI29: 0 | AJ29: 0 | AK29: 126 | AZ29: Included | BA29: No | BB29: 196
A30: 31 | B30: AMRIZE | C30: AMRZ-US | D30: CH1430134226 | E30: USD | F30: 43.7276 | G30: 552735960 | H30: NYSE | I30: 24169.82 | J30: 1.2421026e+08 | K30: 1.4078713e+08 | L30: 1.4078713e+08 | M30: 1.6396716e+08 | N30: 1.4078713e+08 | O30: XNYS | P30: 0.95 | Q30: AMRZ.S | R30: 1.0711799 | U30: Not Collected | V30: Green | W30: Green | X30: Green | Y30: Green | Z30: Green | AA30: Green | AB30: Green | AC30: Green | AD30: Green | AE30: 0 | AF30: 0 | AI30: 0 | AJ30: 0 | AK30: 454 | AL30: exclude_TrustMetric | AY30: exclude_CarbonBudget | AZ30: TrustMetric; CarbonBudget | BA30: Yes
A31: 32 | B31: ANALOG DEVICES INC | C31: ADI-US | D31: US0326541051 | E31: USD | F31: 215.2244 | G31: 491955440 | H31: NASDAQ | I31: 105880.8 | J31: 7.8648679e+08 | K31: 7.6823978e+08 | L31: 7.3965538e+08 | M31: 8.5692957e+08 | N31: 7.1141108e+08 | O31: XNGS | P31: 1 | Q31: ADI.O | R31: 0.84373945 | S31: 0.29 | T31: 54.21 | U31: 0.94 | V31: Green | W31: Green | X31: Green | Y31: Green | Z31: Green | AA31: Green | AB31: Green | AC31: Green | AD31: Green | AE31: 0 | AF31: 0 | AH31: 0.94 | AI31: 0 | AJ31: 0 | AK31: 6 | AZ31: Included | BA31: No | BB31: 118
A32: 33 | B32: ANGLOGOLD ASHANTI | C32: AU-US | D32: GB00BRXH2664 | E32: USD | F32: 46.60352 | G32: 503527040 | H32: NYSE | I32: 23466.13 | J32: 1.2527038e+08 | K32: 1.2487429e+08 | L32: 1.4007955e+08 | M32: 1.62562e+08 | N32: 97503699 | O32: XNYS | P32: 1 | Q32: AU.N | R32: 0.84373945 | S32: 0.98 | T32: 49.63 | U32: 0.98 | V32: Amber | W32: Green | X32: Green | Y32: Green | Z32: Green | AA32: Green | AB32: Green | AC32: Green | AD32: Green | AE32: 0 | AF32: 0 | AH32: 0.98 | AI32: 0 | AJ32: 0 | AK32: 105 | AZ32: Included | BA32: No | BB32: 177
A33: 34 | B33: AON PLC CLASS A | C33: AON-US | D33: IE00BLP1HW54 | E33: USD | F33: 320.1058 | G33: 215626600 | H33: NYSE | I33: 69023.33 | J33: 4.2284411e+08 | K33: 4.5989012e+08 | L33: 4.2189028e+08 | M33: 4.8925184e+08 | N33: 3.9723105e+08 | O33: XNYS | P33: 1 | Q33: AON.N | R33: 0.84373945 | S33: 0.47 | T33: 38.22 | U33: 0.62 | V33: Green | W33: Green | X33: Green | Y33: Green | Z33: Green | AA33: Green | AB33: Green | AC33: Green | AD33: Green | AE33: 0 | AF33: 0 | AH33: 0.62 | AI33: 0 | AJ33: 0 | AK33: 24 | AZ33: Included | BA33: No | BB33: 279
A34: 35 | B34: APOLLO GLOBAL MNGMNT | C34: APO-US | D34: US03769M1062 | E34: USD | F34: 114.5247 | G34: 572026730 | H34: NYSE | I34: 65511.17 | J34: 4.2196472e+08 | K34: 4.4437613e+08 | L34: 3.5284316e+08 | M34: 4.0916264e+08 | N34: 5.3542697e+08 | O34: XNYS | P34: 0.7 | Q34: APO.N | R34: 0.84373945 | S34: 4.39 | T34: 45.46 | U34: 0.75 | V34: Green | W34: Green | X34: Green | Y34: Green | Z34: Green | AA34: Green | AB34: Green | AC34: Green | AD34: Green | AE34: 0 | AF34: 0 | AH34: 0.75 | AI34: 0 | AJ34: 0 | AK34: 414 | AY34: exclude_CarbonBudget | AZ34: CarbonBudget | BA34: Yes
A35: 36 | B35: APPLE | C35: AAPL-US | D35: US0378331005 | E35: USD | F35: 194.3676 | G35: 14840390000 | H35: NASDAQ | I35: 2884492 | J35: 1.1742442e+10 | K35: 1.0834249e+10 | L35: 1.0078044e+10 | M35: 1.1681697e+10 | N35: 1.0788743e+10 | O35: XNGS | P35: 1 | Q35: AAPL.O | R35: 0.84373945 | S35: 0.42 | T35: 64.95 | U35: 0.93 | V35: Amber | W35: Green | X35: Green | Y35: Green | Z35: Green | AA35: Green | AB35: Green | AC35: Green | AD35: Green | AE35: 0 | AF35: 0 | AH35: 0.93 | AI35: 0 | AJ35: 0 | AK35: 18 | AZ35: Included | BA35: No | BB35: 25
A36: 37 | B36: APPLIED MATERIALS | C36: AMAT-US | D36: US0382221051 | E36: USD | F36: 138.667 | G36: 796642460 | H36: NASDAQ | I36: 110468 | J36: 1.30406e+09 | K36: 1.1013615e+09 | L36: 1.1110164e+09 | M36: 1.2883422e+09 | N36: 1.1167945e+09 | O36: XNGS | P36: 1 | Q36: AMAT.O | R36: 0.84373945 | S36: 1.06 | T36: 58.08 | U36: 0.99 | V36: Green | W36: Green | X36: Green | Y36: Green | Z36: Green | AA36: Green | AB36: Green | AC36: Green | AD36: Green | AE36: 0 | AF36: 0 | AH36: 0.99 | AI36: 0 | AJ36: 0 | AK36: 113 | AZ36: Included | BA36: No | BB36: 70
A37: 38 | B37: APPLOVIN CORP CLSS A | C37: APP-US | D37: US03831W1080 | E37: USD | F37: 376.9244 | G37: 307636380 | H37: NASDAQ | I37: 115955.6 | J37: 2.5656797e+09 | K37: 2.212126e+09 | L37: 1.8714938e+09 | M37: 2.1680133e+09 | N37: 1.8150301e+09 | O37: XNGS | P37: 0.75 | Q37: APP.O | R37: 0.84373945 | S37: 2.53 | T37: 40.67 | U37: Not Applicable | V37: Green | W37: Green | X37: Green | Y37: Green | Z37: Green | AA37: Green | AB37: Green | AC37: Green | AD37: Green | AE37: 0 | AF37: 0 | AI37: 0 | AJ37: 0 | AK37: 299 | AZ37: Included | BA37: No | BB37: 258
A38: 39 | B38: ARCH CAPITAL GROUP | C38: ACGL-US | D38: BMG0450A1053 | E38: USD | F38: 79.71497 | G38: 373220300 | H38: NASDAQ | I38: 29751.24 | J38: 1.5319338e+08 | K38: 1.5430351e+08 | L38: 1.6897503e+08 | M38: 1.9614616e+08 | N38: 1.6335796e+08 | O38: XNGS | P38: 1 | Q38: ACGL.O | R38: 0.84373945 | S38: 3 | T38: 49.52 | U38: 0.66 | V38: Green | W38: Green | X38: Green | Y38: Green | Z38: Green | AA38: Green | AB38: Green | AC38: Green | AD38: Green | AE38: 0 | AF38: 0 | AH38: 0.66 | AI38: 0 | AJ38: 0 | AK38: 352 | AZ38: Included | BA38: No | BB38: 179
A39: 40 | B39: ARCHER-DANIELS-MID. | C39: ADM-US | D39: US0394831020 | E39: USD | F39: 53.69517 | G39: 480464480 | H39: NYSE | I39: 25798.62 | J39: 1.9756694e+08 | K39: 1.8162581e+08 | L39: 1.684143e+08 | M39: 1.9536449e+08 | N39: 1.6836819e+08 | O39: XNYS | P39: 1 | Q39: ADM.N | R39: 0.84373945 | S39: 2.7 | T39: 52.37 | U39: 0.94 | V39: Green | W39: Green | X39: Green | Y39: Green | Z39: Green | AA39: Green | AB39: Green | AC39: Green | AD39: Green | AE39: 0 | AF39: 0 | AH39: 0.94 | AI39: 0 | AJ39: 0 | AK39: 326 | AZ39: Included | BA39: No | BB39: 147
A40: 41 | B40: ARES MANAGEMENT CORP | C40: ARES-US | D40: US03990B1017 | E40: USD | F40: 154.523 | G40: 215934700 | H40: NYSE | I40: 33366.87 | J40: 2.0952462e+08 | K40: 2.5273597e+08 | L40: 2.1508802e+08 | M40: 2.4926242e+08 | N40: 2.1781916e+08 | O40: XNYS | P40: 0.9 | Q40: ARES.N | R40: 0.84373945 | S40: 2.51 | T40: 27.77 | U40: 0.57 | V40: Green | W40: Green | X40: Green | Y40: Green | Z40: Green | AA40: Green | AB40: Green | AC40: Green | AD40: Green | AE40: 0 | AF40: 0 | AH40: 0.57 | AI40: 0 | AJ40: 0 | AK40: 296 | AL40: exclude_TrustMetric | AZ40: TrustMetric | BA40: Yes
...

Sheet Top 250
A1: Rank | B1: Company | C1: Ticker | D1: ISIN | E1: Currency (Local) | F1: Price (EUR) | G1: NOSH | H1: Exchange Name (VND) | I1: Sec Market Value (EUR) | J1: 20 days aver. turn EUR | K1: 6 month aver. turnover EUR | L1: 3 month average turnover EUR | M1: 3 months aver. Turnover USD | N1: 12 month aver. turnover EUR | O1: MIC | P1: Free Float | Q1: #Symbol | R1: FX/Index Ccy | S1: ClimateCuAlignIEANZTgt2050-values | T1: ESG Performance Score | U1: Reported Emissions - Emissions Trust Metric | V1: NBR Overall Flag | W1: Anti-personnel Mines - Overall Flag | X1: Biological Weapons - Overall Flag | Y1: Chemical Weapons - Overall Flag | Z1: Cluster Munitions - Overall Flag | AA1: Depleted Uranium - Overall Flag | AB1: Incendiary Weapons - Overall Flag | AC1: Nuclear Weapons Outside NPT - Overall Flag | AD1: White Phosphorous Weapons - Overall Flag | AE1: Thermal Coal Mining - Maximum Percentage of Revenues (%) | AF1: Power Generation - Thermal Maximum Percentage of Revenues (%) | AG1: Shale Oil and/or Gas - Involvement tie | AH1: Trust Metric Numeric | AI1: Coal Mining Numeric | AJ1: Thermal Power Numeric | AK1: Carbon Budget Rank | AL1: exclusion_1_TrustMetric | AM1: exclusion_2_NBROverallFlag | AN1: exclusion_3_APMines | AO1: exclusion_4_BiologicalWeapons | AP1: exclusion_5_ChemicalWeapons | AQ1: exclusion_6_ClusterMunitions | AR1: exclusion_7_DepletedUranium | AS1: exclusion_8_IncendiaryWeapons | AT1: exclusion_9_NuclearWeaponsNonNPT | AU1: exclusion_10_WhitePhosphorus | AV1: exclusion_11_CoalMining | AW1: exclusion_12_ThermalPower | AX1: exclusion_13_ShaleOilGas | AY1: exclusion_14_CarbonBudget | AZ1: Exclusion Summary | BA1: Excluded | BB1: ESG Performance Rank | BC1: Symbol | BD1: Close Prc_EOD | BE1: Price in Index Currency | BF1: FFMC | BG1: FFMC Rank
A2: 305 | B2: MICROSOFT CORP | C2: MSFT-US | D2: US5949181045 | E2: USD | F2: 432.864 | G2: 7433166500 | H2: NASDAQ | I2: 3217550 | J2: 9.4369412e+09 | K2: 8.7216266e+09 | L2: 8.529722e+09 | M2: 9.8852136e+09 | N2: 8.4822591e+09 | O2: XNGS | P2: 1 | Q2: MSFT.O | R2: 0.84373945 | S2: 0.47 | T2: 65.25 | U2: 0.91 | V2: Amber | W2: Green | X2: Green | Y2: Green | Z2: Green | AA2: Green | AB2: Green | AC2: Green | AD2: Green | AE2: 0 | AF2: 0 | AH2: 0.91 | AI2: 0 | AJ2: 0 | AK2: 24 | AZ2: Included | BA2: No | BB2: 21 | BC2: MSFT.O | BD2: 509.04 | BE2: 429.49713 | BF2: 2.714774e+12 | BG2: 1
A3: 36 | B3: APPLE | C3: AAPL-US | D3: US0378331005 | E3: USD | F3: 194.3676 | G3: 14840390000 | H3: NASDAQ | I3: 2884492 | J3: 1.1742442e+10 | K3: 1.0834249e+10 | L3: 1.0078044e+10 | M3: 1.1681697e+10 | N3: 1.0788743e+10 | O3: XNGS | P3: 1 | Q3: AAPL.O | R3: 0.84373945 | S3: 0.42 | T3: 64.95 | U3: 0.93 | V3: Amber | W3: Green | X3: Green | Y3: Green | Z3: Green | AA3: Green | AB3: Green | AC3: Green | AD3: Green | AE3: 0 | AF3: 0 | AH3: 0.93 | AI3: 0 | AJ3: 0 | AK3: 18 | AZ3: Included | BA3: No | BB3: 25 | BC3: AAPL.O | BD3: 238.15 | BE3: 200.93655 | BF3: 2.4337588e+12 | BG3: 2
A4: 19 | B4: AMAZON | C4: AMZN-US | D4: US0231351067 | E4: USD | F4: 195.2893 | G4: 10664912000 | H4: NASDAQ | I4: 2082743 | J4: 7.9772001e+09 | K4: 8.5104795e+09 | L4: 7.9912963e+09 | M4: 9.2643579e+09 | N4: 7.8246173e+09 | O4: XNGS | P4: 0.9 | Q4: AMZN.O | R4: 0.84373945 | S4: 1.36 | T4: 43.66 | U4: 0.93 | V4: Amber | W4: Green | X4: Green | Y4: Green | Z4: Green | AA4: Green | AB4: Green | AC4: Green | AD4: Green | AE4: 0 | AF4: 0 | AH4: 0.93 | AI4: 0 | AJ4: 0 | AK4: 145 | AZ4: Included | BA4: No | BB4: 232 | BC4: AMZN.O | BD4: 234.05 | BE4: 197.47722 | BF4: 1.5815633e+12 | BG4: 3
A5: 300 | B5: META PLTFORM ORD | C5: META-US | D5: US30303M1027 | E5: USD | F5: 644.1287 | G5: 2168962400 | H5: NASDAQ | I5: 1397091 | J5: 7.2998813e+09 | K5: 8.553469e+09 | L5: 7.5540757e+09 | M5: 8.7499585e+09 | N5: 7.956731e+09 | O5: XNGS | P5: 1 | Q5: META.O | R5: 0.84373945 | S5: 0.84 | T5: 44.17 | U5: 0.91 | V5: Amber | W5: Green | X5: Green | Y5: Green | Z5: Green | AA5: Green | AB5: Green | AC5: Green | AD5: Green | AE5: 0 | AF5: 0 | AH5: 0.91 | AI5: 0 | AJ5: 0 | AK5: 85 | AZ5: Included | BA5: No | BB5: 226 | BC5: META.O | BD5: 779 | BE5: 657.27303 | BF5: 1.1787807e+12 | BG5: 4
A6: 70 | B6: BROADCOM INC. | C6: AVGO-US | D6: US11135F1012 | E6: USD | F6: 250.8961 | G6: 4703471000 | H6: NASDAQ | I6: 1180082 | J6: 4.4284572e+09 | K6: 5.0063213e+09 | L6: 4.833545e+09 | M6: 5.5971754e+09 | N6: 5.1125496e+09 | O6: XNGS | P6: 1 | Q6: AVGO.O | R6: 0.84373945 | S6: 3.02 | T6: 44.8 | U6: 0.63 | V6: Green | W6: Green | X6: Green | Y6: Green | Z6: Green | AA6: Green | AB6: Green | AC6: Green | AD6: Green | AE6: 0 | AF6: 0 | AH6: 0.63 | AI6: 0 | AJ6: 0 | AK6: 355 | AZ6: Included | BA6: No | BB6: 221 | BC6: AVGO.O | BD6: 360 | BE6: 303.7462 | BF6: 9.9568219e+11 | BG6: 5
A7: 17 | B7: ALPHABET CLASS A | C7: GOOGL-US | D7: US02079K3059 | E7: USD | F7: 175.8747 | G7: 5817000000 | H7: NASDAQ | I7: 1023063 | J7: 4.9248801e+09 | K7: 5.8717197e+09 | L7: 5.9033678e+09 | M7: 6.8459395e+09 | N7: 5.1699677e+09 | O7: XNGS | P7: 1 | Q7: GOOGL.O | R7: 0.84373945 | S7: 0.65 | T7: 57.27 | U7: 0.84 | V7: Amber | W7: Green | X7: Green | Y7: Green | Z7: Green | AA7: Green | AB7: Green | AC7: Green | AD7: Green | AE7: 0 | AF7: 0 | AH7: 0.84 | AI7: 0 | AJ7: 0 | AK7: 58 | AZ7: Included | BA7: No | BB7: 79 | BC7: GOOGL.O | BD7: 251.16 | BE7: 211.9136 | BF7: 8.6319872e+11 | BG7: 6
A8: 433 | B8: TESLA INC | C8: TSLA-US | D8: US88160R1014 | E8: USD | F8: 290.1604 | G8: 3225449000 | H8: NASDAQ | I8: 935897.7 | J8: 2.1367951e+10 | K8: 2.9445717e+10 | L8: 2.7999684e+10 | M8: 3.241537e+10 | N8: 2.7610006e+10 | O8: XNGS | P8: 0.85 | Q8: TSLA.O | R8: 0.84373945 | S8: 2.89 | T8: 60.66 | U8: 0.91 | V8: Amber | W8: Green | X8: Green | Y8: Green | Z8: Green | AA8: Green | AB8: Green | AC8: Green | AD8: Green | AE8: 0 | AF8: 0 | AH8: 0.91 | AI8: 0 | AJ8: 0 | AK8: 342 | AZ8: Included | BA8: No | BB8: 45 | BC8: TSLA.O | BD8: 421.62 | BE8: 355.73743 | BF8: 6.7120565e+11 | BG8: 7
A9: 258 | B9: JP MORGAN CHASE & CO | C9: JPM-US | D9: US46625H1005 | E9: USD | F9: 252.8076 | G9: 2749754000 | H9: NYSE | I9: 695158.8 | J9: 1.7506895e+09 | K9: 2.2815889e+09 | L9: 2.0406602e+09 | M9: 2.3670612e+09 | N9: 2.1415283e+09 | O9: XNYS | P9: 1 | Q9: JPM.N | R9: 0.84373945 | S9: 1.76 | T9: 47.38 | U9: 0.94 | V9: Green | W9: Green | X9: Green | Y9: Green | Z9: Green | AA9: Green | AB9: Green | AC9: Green | AD9: Green | AE9: 0 | AF9: 0 | AH9: 0.94 | AI9: 0 | AJ9: 0 | AK9: 191 | AZ9: Included | BA9: No | BB9: 199 | BC9: JPM.N | BD9: 309.19 | BE9: 260.8758 | BF9: 5.8653283e+11 | BG9: 8
A10: 471 | B10: VISA INC | C10: V-US | D10: US92826C8394 | E10: USD | F10: 298.7199 | G10: 1698682500 | H10: NYSE | I10: 507430.3 | J10: 1.7368346e+09 | K10: 2.083355e+09 | L10: 1.9676343e+09 | M10: 2.2791641e+09 | N10: 1.929801e+09 | O10: XNYS | P10: 1 | Q10: V.N | R10: 0.84373945 | S10: 0.82 | T10: 55.33 | U10: 0.87 | V10: Green | W10: Green | X10: Green | Y10: Green | Z10: Green | AA10: Green | AB10: Green | AC10: Green | AD10: Green | AE10: 0 | AF10: 0 | AH10: 0.87 | AI10: 0 | AJ10: 0 | AK10: 82 | AZ10: Included | BA10: No | BB10: 100 | BC10: V.N | BD10: 340.03 | BE10: 286.89673 | BF10: 4.2813893e+11 | BG10: 9
A11: 172 | B11: ELI LILLY AND CO | C11: LLY-US | D11: US5324571083 | E11: USD | F11: 607.3391 | G11: 946456800 | H11: NYSE | I11: 574820.2 | J11: 4.4289558e+09 | K11: 2.9085759e+09 | L11: 2.7474037e+09 | M11: 3.1851577e+09 | N11: 2.816072e+09 | O11: XNYS | P11: 0.85 | Q11: LLY.N | R11: 0.84373945 | S11: 2.55 | T11: 59.02 | U11: 1 | V11: Green | W11: Green | X11: Green | Y11: Green | Z11: Green | AA11: Green | AB11: Green | AC11: Green | AD11: Green | AE11: 0 | AF11: 0 | AH11: 1 | AI11: 0 | AJ11: 0 | AK11: 302 | AZ11: Included | BA11: No | BB11: 57 | BC11: LLY.N | BD11: 764.71 | BE11: 645.21599 | BF11: 4.1224872e+11 | BG11: 10
A12: 319 | B12: NETFLIX INC. | C12: NFLX-US | D12: US64110L1061 | E12: USD | F12: 1028.034 | G12: 424926360 | H12: NASDAQ | I12: 436838.7 | J12: 2.9174361e+09 | K12: 3.9762351e+09 | L12: 3.4028095e+09 | M12: 3.9478521e+09 | N12: 3.3245206e+09 | O12: XNGS | P12: 1 | Q12: NFLX.O | R12: 0.84373945 | S12: 1.85 | T12: 44.05 | U12: 0.8 | V12: Green | W12: Green | X12: Green | Y12: Green | Z12: Green | AA12: Green | AB12: Green | AC12: Green | AD12: Green | AE12: 0 | AF12: 0 | AH12: 0.8 | AI12: 0 | AJ12: 0 | AK12: 203 | AZ12: Included | BA12: No | BB12: 227 | BC12: NFLX.O | BD12: 1200.51 | BE12: 1012.9176 | BF12: 3.6857808e+11 | BG12: 11
A13: 293 | B13: MASTERCARD INC | C13: MA-US | D13: US57636Q1040 | E13: USD | F13: 511.1453 | G13: 897274200 | H13: NYSE | I13: 458637.4 | J13: 1.2482194e+09 | K13: 1.3987234e+09 | L13: 1.3689725e+09 | M13: 1.5866785e+09 | N13: 1.3074093e+09 | O13: XNYS | P13: 0.9 | Q13: MA.N | R13: 0.84373945 | S13: 0.57 | T13: 58.24 | U13: 0.86 | V13: Green | W13: Green | X13: Green | Y13: Green | Z13: Green | AA13: Green | AB13: Green | AC13: Green | AD13: Green | AE13: 0 | AF13: 0 | AH13: 0.86 | AI13: 0 | AJ13: 0 | AK13: 43 | AZ13: Included | BA13: No | BB13: 69 | BC13: MA.N | BD13: 586.42 | BE13: 494.78569 | BF13: 3.4827349e+11 | BG13: 12
... A52: 220 | B52: GILEAD SCIENCES INC. | C52: GILD-US | D52: US3755581036 | E52: USD | F52: 97.94333 | G52: 1240806900 | H52: NASDAQ | I52: 121528.8 | J52: 6.8788614e+08 | K52: 8.2666118e+08 | L52: 6.9104648e+08 | M52: 8.0031528e+08 | N52: 7.0710623e+08 | O52: XNGS | P52: 1 | Q52: GILD.O | R52: 0.84373945 | S52: 0.57 | T52: 55.84 | U52: 0.89 | V52: Green | W52: Green | X52: Green | Y52: Green | Z52: Green | AA52: Green | AB52: Green | AC52: Green | AD52: Green | AE52: 0 | AF52: 0 | AH52: 0.89 | AI52: 0 | AJ52: 0 | AK52: 43 | AZ52: Included | BA52: No | BB52: 96 | BC52: GILD.O | BD52: 110.86 | BE52: 93.536955 | BF52: 1.0253861e+11 | BG52: 51
A53: 232 | B53: HONEYWELL INTER. INC | C53: HON-US | D53: US4385161066 | E53: USD | F53: 190.1604 | G53: 634896550 | H53: NASDAQ | I53: 120732.2 | J53: 5.9014427e+08 | K53: 7.6908309e+08 | L53: 6.6576827e+08 | M53: 7.7195475e+08 | N53: 7.7663867e+08 | O53: XNGS | P53: 1 | Q53: HON.O | R53: 0.84373945 | S53: 0.56 | T53: 53.96 | U53: 0.89 | V53: Green | W53: Green | X53: Green | Y53: Green | Z53: Green | AA53: Green | AB53: Green | AC53: Green | AD53: Green | AE53: 0 | AF53: 0 | AG53: Services | AH53: 0.89 | AI53: 0 | AJ53: 0 | AK53: 39 | AZ53: Included | BA53: No | BB53: 120 | BC53: HON.O | BD53: 210.95 | BE53: 177.98684 | BF53: 1.018665e+11 | BG53: 52
A54: 144 | B54: DANAHER CORPORATION | C54: DHR-US | D54: US2358511028 | E54: USD | F54: 180.7476 | G54: 716051600 | H54: NYSE | I54: 129424.6 | J54: 5.8575044e+08 | K54: 7.272495e+08 | L54: 6.7680308e+08 | M54: 7.8485664e+08 | N54: 7.3025046e+08 | O54: XNYS | P54: 0.9 | Q54: DHR.N | R54: 0.84373945 | S54: 1.57 | T54: 57.15 | U54: 0.63 | V54: Green | W54: Green | X54: Green | Y54: Green | Z54: Green | AA54: Green | AB54: Green | AC54: Green | AD54: Green | AE54: 0 | AF54: 0 | AH54: 0.63 | AI54: 0 | AJ54: 0 | AK54: 166 | AZ54: Included | BA54: No | BB54: 80 | BC54: DHR.N | BD54: 190.47 | BE54: 160.70705 | BF54: 9.8280583e+10 | BG54: 53
A55: 165 | B55: EATON CORP. PLC | C55: ETN-US | D55: IE00B8KQN827 | E55: USD | F55: 296.6462 | G55: 389300000 | H55: NYSE | I55: 115484.4 | J55: 8.2685783e+08 | K55: 8.1398401e+08 | L55: 6.9814216e+08 | M55: 8.0936852e+08 | N55: 7.6758201e+08 | O55: XNYS | P55: 1 | Q55: ETN.N | R55: 0.84373945 | S55: 2.6 | T55: 54.76 | U55: 0.99 | V55: Green | W55: Green | X55: Green | Y55: Green | Z55: Green | AA55: Green | AB55: Green | AC55: Green | AD55: Green | AE55: 0 | AF55: 0 | AG55: Services | AH55: 0.99 | AI55: 0 | AJ55: 0 | AK55: 308 | AZ55: Included | BA55: No | BB55: 110 | BC55: ETN.N | BD55: 371.19 | BE55: 313.18765 | BF55: 9.7438715e+10 | BG55: 54
A56: 455 | B56: UNION PACIFIC CORP | C56: UNP-US | D56: US9078181081 | E56: USD | F56: 194.4444 | G56: 593039860 | H56: NYSE | I56: 115313.3 | J56: 7.3027253e+08 | K56: 7.103976e+08 | L56: 7.71268e+08 | M56: 8.9392519e+08 | N56: 6.43011e+08 | O56: XNYS | P56: 1 | Q56: UNP.N | R56: 0.84373945 | S56: 1.44 | T56: 54.72 | U56: 0.97 | V56: Green | W56: Green | X56: Green | Y56: Green | Z56: Green | AA56: Green | AB56: Green | AC56: Green | AD56: Amber | AE56: 0 | AF56: 0 | AG56: Services | AH56: 0.97 | AI56: 0 | AJ56: 0 | AK56: 154 | AZ56: Included | BA56: No | BB56: 111 | BC56: UNP.N | BD56: 216 | BE56: 182.24772 | BF56: 9.7294363e+10 | BG56: 55
A57: 30 | B57: AMPHENOL COR CLASS A | C57: APH-US | D57: US0320951017 | E57: USD | F57: 93.32651 | G57: 1220921100 | H57: NYSE | I57: 113944.3 | J57: 6.8199416e+08 | K57: 6.456871e+08 | L57: 7.4146339e+08 | M57: 8.5991509e+08 | N57: 5.4344609e+08 | O57: XNYS | P57: 1 | Q57: APH.N | R57: 0.84373945 | S57: 1.2 | T57: 47.59 | U57: 0.67 | V57: Green | W57: Green | X57: Green | Y57: Green | Z57: Green | AA57: Green | AB57: Green | AC57: Green | AD57: Green | AE57: 0 | AF57: 0 | AH57: 0.67 | AI57: 0 | AJ57: 0 | AK57: 126 | AZ57: Included | BA57: No | BB57: 196 | BC57: APH.N | BD57: 119.04 | BE57: 100.43874 | BF57: 9.6139305e+10 | BG57: 56
A58: 304 | B58: MICRON TECHNOLOGY | C58: MU-US | D58: US5951121038 | E58: USD | F58: 100.4267 | G58: 1119125100 | H58: NASDAQ | I58: 112390 | J58: 1.9268302e+09 | K58: 2.0156003e+09 | L58: 2.1964685e+09 | M58: 2.54895e+09 | N58: 2.0712965e+09 | O58: XNGS | P58: 1 | Q58: MU.O | R58: 0.84373945 | S58: 2.35 | T58: 52.37 | U58: 0.85 | V58: Green | W58: Green | X58: Green | Y58: Green | Z58: Green | AA58: Green | AB58: Green | AC58: Green | AD58: Green | AE58: 0 | AF58: 0 | AH58: 0.85 | AI58: 0 | AJ58: 0 | AK58: 273 | AZ58: Included | BA58: No | BB58: 147 | BC58: MU.O | BD58: 158.82 | BE58: 134.0027 | BF58: 9.4827911e+10 | BG58: 57
A59: 37 | B59: APPLIED MATERIALS | C59: AMAT-US | D59: US0382221051 | E59: USD | F59: 138.667 | G59: 796642460 | H59: NASDAQ | I59: 110468 | J59: 1.30406e+09 | K59: 1.1013615e+09 | L59: 1.1110164e+09 | M59: 1.2883422e+09 | N59: 1.1167945e+09 | O59: XNGS | P59: 1 | Q59: AMAT.O | R59: 0.84373945 | S59: 1.06 | T59: 58.08 | U59: 0.99 | V59: Green | W59: Green | X59: Green | Y59: Green | Z59: Green | AA59: Green | AB59: Green | AC59: Green | AD59: Green | AE59: 0 | AF59: 0 | AH59: 0.99 | AI59: 0 | AJ59: 0 | AK59: 113 | AZ59: Included | BA59: No | BB59: 70 | BC59: AMAT.O | BD59: 173.54 | BE59: 146.42254 | BF59: 9.3206226e+10 | BG59: 58
A60: 147 | B60: DEERE & CO | C60: DE-US | D60: US2441991054 | E60: USD | F60: 423.2719 | G60: 270827060 | H60: NYSE | I60: 114633.5 | J60: 6.5746806e+08 | K60: 5.7939163e+08 | L60: 5.409376e+08 | M60: 6.2728905e+08 | N60: 5.4904284e+08 | O60: XNYS | P60: 0.95 | Q60: DE.N | R60: 0.84373945 | S60: 1.65 | T60: 58.74 | U60: 0.99 | V60: Green | W60: Green | X60: Green | Y60: Green | Z60: Green | AA60: Green | AB60: Green | AC60: Green | AD60: Green | AE60: 0 | AF60: 0 | AH60: 0.99 | AI60: 0 | AJ60: 0 | AK60: 178 | AZ60: Included | BA60: No | BB60: 60 | BC60: DE.N | BD60: 468.7 | BE60: 395.46068 | BF60: 9.1884753e+10 | BG60: 59
A61: 118 | B61: COMCAST | C61: CMCSA-US | D61: US20030N1019 | E61: USD | F61: 29.1432 | G61: 3682762200 | H61: NASDAQ | I61: 107327.5 | J61: 6.1617247e+08 | K61: 7.2922211e+08 | L61: 6.1986807e+08 | M61: 7.1795622e+08 | N61: 7.5155177e+08 | O61: XNGS | P61: 1 | Q61: CMCSA.O | R61: 0.84373945 | S61: 1.76 | T61: 51.68 | U61: 0.92 | V61: Green | W61: Green | X61: Green | Y61: Green | Z61: Green | AA61: Green | AB61: Green | AC61: Green | AD61: Green | AE61: 0 | AF61: 0 | AH61: 0.92 | AI61: 0 | AJ61: 0 | AK61: 191 | AZ61: Included | BA61: No | BB61: 159 | BC61: CMCSA.O | BD61: 32.29 | BE61: 27.244347 | BF61: 9.0556425e+10 | BG61: 60
A62: 49 | B62: AUTOM. DATA PROCESSI | C62: ADP-US | D62: US0530151036 | E62: USD | F62: 262.8008 | G62: 405043150 | H62: NASDAQ | I62: 106445.7 | J62: 3.7148242e+08 | K62: 4.7709362e+08 | L62: 4.2288049e+08 | M62: 4.8969548e+08 | N62: 4.6326217e+08 | O62: XNGS | P62: 1 | Q62: ADP.O | R62: 0.84373945 | S62: 1.86 | T62: 59.95 | U62: 0.89 | V62: Green | W62: Green | X62: Green | Y62: Green | Z62: Green | AA62: Green | AB62: Green | AC62: Green | AD62: Green | AE62: 0 | AF62: 0 | AH62: 0.89 | AI62: 0 | AJ62: 0 | AK62: 204 | AZ62: Included | BA62: No | BB62: 50 | BC62: ADP.O | BD62: 288.69 | BE62: 243.57914 | BF62: 8.9812406e+10 | BG62: 61
A63: 32 | B63: ANALOG DEVICES INC | C63: ADI-US | D63: US0326541051 | E63: USD | F63: 215.2244 | G63: 491955440 | H63: NASDAQ | I63: 105880.8 | J63: 7.8648679e+08 | K63: 7.6823978e+08 | L63: 7.3965538e+08 | M63: 8.5692957e+08 | N63: 7.1141108e+08 | O63: XNGS | P63: 1 | Q63: ADI.O | R63: 0.84373945 | S63: 0.29 | T63: 54.21 | U63: 0.94 | V63: Green | W63: Green | X63: Green | Y63: Green | Z63: Green | AA63: Green | AB63: Green | AC63: Green | AD63: Green | AE63: 0 | AF63: 0 | AH63: 0.94 | AI63: 0 | AJ63: 0 | AK63: 6 | AZ63: Included | BA63: No | BB63: 118 | BC63: ADI.O | BD63: 244.1 | BE63: 205.9568 | BF63: 8.933582e+10 | BG63: 62
A64: 297 | B64: MEDTRONIC PLC | C64: MDT-US | D64: IE00BTN1Y115 | E64: USD | F64: 79.1176 | G64: 1281264600 | H64: NYSE | I64: 101483 | J64: 6.4158453e+08 | K64: 6.0478856e+08 | L64: 6.0217139e+08 | M64: 6.9785897e+08 | N64: 5.6903676e+08 | O64: XNYS | P64: 1 | Q64: MDT.N | R64: 0.84373945 | S64: 1.33 | T64: 63.53 | U64: 0.96 | V64: Green | W64: Green | X64: Green | Y64: Green | Z64: Green | AA64: Green | AB64: Green | AC64: Green | AD64: Green | AE64: 0 | AF64: 0 | AH64: 0.96 | AI64: 0 | AJ64: 0 | AK64: 143 | AZ64: Included | BA64: No | BB64: 28 | BC64: MDT.N | BD64: 94.19 | BE64: 79.471819 | BF64: 8.5530358e+10 | BG64: 63
A65: 268 | B65: KLA CORPORATION | C65: KLAC-US | D65: US4824801009 | E65: USD | F65: 742.6865 | G65: 131961360 | H65: NASDAQ | I65: 98005.91 | J65: 7.6879403e+08 | K65: 7.9744869e+08 | L65: 8.2526447e+08 | M65: 9.5556304e+08 | N65: 7.5777953e+08 | O65: XNGS | P65: 1 | Q65: KLAC.O | R65: 0.84373945 | S65: 1.51 | T65: 50.03 | U65: 0.91 | V65: Green | W65: Green | X65: Green | Y65: Green | Z65: Green | AA65: Green | AB65: Green | AC65: Green | AD65: Green | AE65: 0 | AF65: 0 | AH65: 0.91 | AI65: 0 | AJ65: 0 | AK65: 160 | AZ65: Included | BA65: No | BB65: 174 | BC65: KLAC.O | BD65: 990.57 | BE65: 835.78299 | BF65: 8.2691462e+10 | BG65: 64
A66: 18 | B66: ALTRIA GROUP INC | C66: MO-US | D66: US02209S1033 | E66: USD | F66: 57.74876 | G66: 1679891000 | H66: NYSE | I66: 97011.62 | J66: 4.328411e+08 | K66: 5.0524081e+08 | L66: 4.5528886e+08 | M66: 5.2787621e+08 | N66: 4.4449354e+08 | O66: XNYS | P66: 1 | Q66: MO.N | R66: 0.84373945 | S66: 0.79 | T66: 43.06 | U66: 0.99 | V66: Green | W66: Green | X66: Green | Y66: Green | Z66: Green | AA66: Green | AB66: Green | AC66: Green | AD66: Green | AE66: 0 | AF66: 0 | AH66: 0.99 | AI66: 0 | AJ66: 0 | AK66: 77 | AZ66: Included | BA66: No | BB66: 242 | BC66: MO.N | BD66: 64.81 | BE66: 54.682754 | BF66: 8.1852533e+10 | BG66: 65
A67: 421 | B67: SYNOPSYS INC. | C67: SNPS-US | D67: US8716071076 | E67: USD | F67: 517.5969 | G67: 185043640 | H67: NASDAQ | I67: 95778 | J67: 5.5977571e+08 | K67: 6.7536349e+08 | L67: 8.2125405e+08 | M67: 9.5168815e+08 | N67: 5.9997564e+08 | O67: XNGS | P67: 1 | Q67: SNPS.O | R67: 0.84373945 | S67: 1.75 | T67: 58 | U67: 0.9 | V67: Green | W67: Green | X67: Green | Y67: Green | Z67: Green | AA67: Green | AB67: Green | AC67: Green | AD67: Green | AE67: 0 | AF67: 0 | AH67: 0.9 | AI67: 0 | AJ67: 0 | AK67: 189 | AZ67: Included | BA67: No | BB67: 71 | BC67: SNPS.O | BD67: 425.97 | BE67: 359.40769 | BF67: 8.0811689e+10 | BG67: 66
A68: 483 | B68: WELLTOWER INC | C68: WELL-US | D68: US95040Q1040 | E68: USD | F68: 140.3226 | G68: 667943900 | H68: NYSE | I68: 93727.6 | J68: 3.4774103e+08 | K68: 4.0724809e+08 | L68: 3.8523147e+08 | M68: 4.4602975e+08 | N68: 3.7334679e+08 | O68: XNYS | P68: 1 | Q68: WELL.N | R68: 0.84373945 | S68: 2.04 | T68: 58.28 | U68: 0.84 | V68: Green | W68: Green | X68: Green | Y68: Green | Z68: Green | AA68: Green | AB68: Green | AC68: Green | AD68: Green | AE68: 0 | AF68: 0 | AH68: 0.84 | AI68: 0 | AJ68: 0 | AK68: 230 | AZ68: Included | BA68: No | BB68: 66 | BC68: WELL.N | BD68: 165.21 | BE68: 139.39419 | BF68: 7.9081695e+10 | BG68: 67
... A81: 445 | B81: TRANE TECHNOLOGIES | C81: TT-US | D81: IE00BK9ZQ967 | E81: USD | F81: 361.9304 | G81: 222515370 | H81: NYSE | I81: 80535.06 | J81: 3.7250815e+08 | K81: 5.011852e+08 | L81: 4.5667544e+08 | M81: 5.2905725e+08 | N81: 4.6765553e+08 | O81: XNYS | P81: 1 | Q81: TT.N | R81: 0.84373945 | S81: 1.65 | T81: 61.74 | U81: 0.98 | V81: Green | W81: Green | X81: Green | Y81: Green | Z81: Green | AA81: Green | AB81: Green | AC81: Green | AD81: Green | AE81: 0 | AF81: 0 | AH81: 0.98 | AI81: 0 | AJ81: 0 | AK81: 178 | AZ81: Included | BA81: No | BB81: 35 | BC81: TT.N | BD81: 399.99 | BE81: 337.48734 | BF81: 6.7950621e+10 | BG81: 80
A82: 322 | B82: NIKE INC | C82: NKE-US | D82: US6541061031 | E82: USD | F82: 66.88854 | G82: 1188015700 | H82: NYSE | I82: 79464.64 | J82: 5.370476e+08 | K82: 1.0234951e+09 | L82: 9.0130919e+08 | M82: 1.0473027e+09 | N82: 9.622578e+08 | O82: XNYS | P82: 1 | Q82: NKE.N | R82: 0.84373945 | S82: 0.42 | T82: 56.09 | U82: Not Applicable | V82: Green | W82: Green | X82: Green | Y82: Green | Z82: Green | AA82: Green | AB82: Green | AC82: Green | AD82: Green | AE82: 0 | AF82: 0 | AI82: 0 | AJ82: 0 | AK82: 18 | AZ82: Included | BA82: No | BB82: 91 | BC82: NKE.N | BD82: 72.75 | BE82: 61.382045 | BF82: 6.7047448e+10 | BG82: 81
A83: 141 | B83: CVS HEALTH CORP. | C83: CVS-US | D83: US1266501006 | E83: USD | F83: 60.84657 | G83: 1268326400 | H83: NYSE | I83: 77173.3 | J83: 3.7150935e+08 | K83: 5.2036635e+08 | L83: 4.2818274e+08 | M83: 4.958411e+08 | N83: 5.8738684e+08 | O83: XNYS | P83: 1 | Q83: CVS.N | R83: 0.84373945 | S83: 0.46 | T83: 61.35 | U83: 0.99 | V83: Amber | W83: Green | X83: Green | Y83: Green | Z83: Green | AA83: Green | AB83: Green | AC83: Green | AD83: Green | AE83: 0 | AF83: 0 | AH83: 0.99 | AI83: 0 | AJ83: 0 | AK83: 23 | AZ83: Included | BA83: No | BB83: 38 | BC83: CVS.N | BD83: 73.48 | BE83: 61.997975 | BF83: 6.5114167e+10 | BG83: 82
A84: 391 | B84: ROYAL CARIBBEAN | C84: RCL-US | D84: LR0008862868 | E84: USD | F84: 294.1372 | G84: 271627660 | H84: NYSE | I84: 79895.8 | J84: 5.255555e+08 | K84: 5.7522895e+08 | L84: 6.2235401e+08 | M84: 7.2238473e+08 | N84: 4.9708978e+08 | O84: XNYS | P84: 0.95 | Q84: RCL.N | R84: 0.84373945 | S84: 1.06 | T84: 51.2 | U84: 0.93 | V84: Green | W84: Green | X84: Green | Y84: Green | Z84: Green | AA84: Green | AB84: Green | AC84: Green | AD84: Green | AE84: 0 | AF84: 0 | AH84: 0.93 | AI84: 0 | AJ84: 0 | AK84: 113 | AZ84: Included | BA84: No | BB84: 162 | BC84: RCL.N | BD84: 321.7 | BE84: 271.43098 | BF84: 6.4040676e+10 | BG84: 83
A85: 1 | B85: 3M CO | C85: MMM-US | D85: US88579Y1010 | E85: USD | F85: 135.4497 | G85: 532629700 | H85: NYSE | I85: 72144.55 | J85: 4.0894509e+08 | K85: 4.9663707e+08 | L85: 4.4055249e+08 | M85: 5.1103236e+08 | N85: 4.7372284e+08 | O85: XNYS | P85: 1 | Q85: MMM.N | R85: 0.84373945 | S85: 2.06 | T85: 62.06 | U85: 0.99 | V85: Green | W85: Green | X85: Green | Y85: Green | Z85: Green | AA85: Green | AB85: Green | AC85: Green | AD85: Green | AE85: 0 | AF85: 0 | AG85: Services | AH85: 0.99 | AI85: 0 | AJ85: 0 | AK85: 233 | AZ85: Included | BA85: No | BB85: 34 | BC85: MMM.N | BD85: 156.5 | BE85: 132.04522 | BF85: 6.0871189e+10 | BG85: 84
A86: 479 | B86: WASTE MANAGEMENT | C86: WM-US | D86: US94106L1098 | E86: USD | F86: 193.7361 | G86: 402830320 | H86: NYSE | I86: 78042.77 | J86: 3.4990151e+08 | K86: 3.5546445e+08 | L86: 3.3357195e+08 | M86: 3.8671755e+08 | N86: 3.3180569e+08 | O86: XNYS | P86: 0.9 | Q86: WM.N | R86: 0.84373945 | S86: 2.13 | T86: 57.3 | U86: 0.95 | V86: Green | W86: Green | X86: Green | Y86: Green | Z86: Green | AA86: Green | AB86: Green | AC86: Green | AD86: Green | AE86: 0 | AF86: 0 | AH86: 0.95 | AI86: 0 | AJ86: 0 | AK86: 243 | AZ86: Included | BA86: No | BB86: 78 | BC86: WM.N | BD86: 213.88 | BE86: 180.45899 | BF86: 5.9262991e+10 | BG86: 85
A87: 306 | B87: MONDELEZ INT CLASS A | C87: MDLZ-US | D87: US6092071058 | E87: USD | F87: 54.11333 | G87: 1293945400 | H87: NASDAQ | I87: 70019.7 | J87: 3.8302632e+08 | K87: 4.9191745e+08 | L87: 4.2270167e+08 | M87: 4.8984579e+08 | N87: 4.9200633e+08 | O87: XNGS | P87: 1 | Q87: MDLZ.O | R87: 0.84373945 | S87: 0.78 | T87: 49.02 | U87: 0.96 | V87: Green | W87: Green | X87: Green | Y87: Green | Z87: Green | AA87: Green | AB87: Green | AC87: Green | AD87: Green | AE87: 0 | AF87: 0 | AH87: 0.96 | AI87: 0 | AJ87: 0 | AK87: 74 | AZ87: Included | BA87: No | BB87: 184 | BC87: MDLZ.O | BD87: 62.7 | BE87: 52.902464 | BF87: 5.9078378e+10 | BG87: 86
A88: 103 | B88: CIGNA GROUP | C88: CI-US | D88: US1255231003 | E88: USD | F88: 259.7286 | G88: 266928070 | H88: NYSE | I88: 69328.87 | J88: 4.5528226e+08 | K88: 5.1334735e+08 | L88: 4.9067012e+08 | M88: 5.6858536e+08 | N88: 5.1729069e+08 | O88: XNYS | P88: 1 | Q88: CI.N | R88: 0.84373945 | S88: 2.22 | T88: 67.99 | U88: 0.93 | V88: Green | W88: Green | X88: Green | Y88: Green | Z88: Green | AA88: Green | AB88: Green | AC88: Green | AD88: Green | AE88: 0 | AF88: 0 | AH88: 0.93 | AI88: 0 | AJ88: 0 | AK88: 254 | AZ88: Included | BA88: No | BB88: 11 | BC88: CI.N | BD88: 294.21 | BE88: 248.23658 | BF88: 5.8495489e+10 | BG88: 87
A89: 357 | B89: PNC FINANCIAL SERV. | C89: PNC-US | D89: US6934751057 | E89: USD | F89: 172.1198 | G89: 393807370 | H89: NYSE | I89: 67782.05 | J89: 2.4355779e+08 | K89: 3.6918784e+08 | L89: 3.4360391e+08 | M89: 3.9881033e+08 | N89: 3.5815657e+08 | O89: XNYS | P89: 1 | Q89: PNC.N | R89: 0.84373945 | S89: 2.32 | T89: 41.84 | U89: 0.97 | V89: Green | W89: Green | X89: Green | Y89: Green | Z89: Green | AA89: Green | AB89: Green | AC89: Green | AD89: Green | AE89: 0 | AF89: 0 | AH89: 0.97 | AI89: 0 | AJ89: 0 | AK89: 266 | AZ89: Included | BA89: No | BB89: 250 | BC89: PNC.N | BD89: 200.94 | BE89: 169.54101 | BF89: 5.7190386e+10 | BG89: 88
A90: 310 | B90: MOODY'S CORPORATION | C90: MCO-US | D90: US6153691059 | E90: USD | F90: 440.3567 | G90: 179400000 | H90: NYSE | I90: 78999.99 | J90: 2.6250783e+08 | K90: 3.341081e+08 | L90: 2.952486e+08 | M90: 3.4235821e+08 | N90: 3.2711697e+08 | O90: XNYS | P90: 0.85 | Q90: MCO.N | R90: 0.84373945 | S90: 0.71 | T90: 65.7 | U90: 0.88 | V90: Green | W90: Green | X90: Green | Y90: Green | Z90: Green | AA90: Green | AB90: Green | AC90: Green | AD90: Green | AE90: 0 | AF90: 0 | AH90: 0.88 | AI90: 0 | AJ90: 0 | AK90: 64 | AZ90: Included | BA90: No | BB90: 17 | BC90: MCO.N | BD90: 508 | BE90: 428.61964 | BF90: 5.6657098e+10 | BG90: 89
...

Sheet Final Selection
A1: Rank | B1: Company | C1: Ticker | D1: ISIN | E1: Currency (Local) | F1: Price (EUR) | G1: NOSH | H1: Exchange Name (VND) | I1: Sec Market Value (EUR) | J1: 20 days aver. turn EUR | K1: 6 month aver. turnover EUR | L1: 3 month average turnover EUR | M1: 3 months aver. Turnover USD | N1: 12 month aver. turnover EUR | O1: MIC | P1: Free Float | R1: #Symbol | S1: FX/Index Ccy | T1: ClimateCuAlignIEANZTgt2050-values | U1: ESG Performance Score | V1: Reported Emissions - Emissions Trust Metric | W1: NBR Overall Flag | X1: Anti-personnel Mines - Overall Flag | Y1: Biological Weapons - Overall Flag | Z1: Chemical Weapons - Overall Flag | AA1: Cluster Munitions - Overall Flag | AB1: Depleted Uranium - Overall Flag | AC1: Incendiary Weapons - Overall Flag | AD1: Nuclear Weapons Outside NPT - Overall Flag | AE1: White Phosphorous Weapons - Overall Flag | AF1: Thermal Coal Mining - Maximum Percentage of Revenues (%) | AG1: Power Generation - Thermal Maximum Percentage of Revenues (%) | AH1: Shale Oil and/or Gas - Involvement tie | AI1: Trust Metric Numeric | AJ1: Coal Mining Numeric | AK1: Thermal Power Numeric | AL1: Carbon Budget Rank | AM1: exclusion_1_TrustMetric | AN1: exclusion_2_NBROverallFlag | AO1: exclusion_3_APMines | AP1: exclusion_4_BiologicalWeapons | AQ1: exclusion_5_ChemicalWeapons | AR1: exclusion_6_ClusterMunitions | AS1: exclusion_7_DepletedUranium | AT1: exclusion_8_IncendiaryWeapons | AU1: exclusion_9_NuclearWeaponsNonNPT | AV1: exclusion_10_WhitePhosphorus | AW1: exclusion_11_CoalMining | AX1: exclusion_12_ThermalPower | AY1: exclusion_13_ShaleOilGas | AZ1: exclusion_14_CarbonBudget | BA1: Exclusion Summary | BB1: Excluded | BC1: ESG Performance Rank | BD1: Symbol | BE1: Close Prc_EOD | BF1: Price in Index Currency | BH1: FFMC | BI1: FFMC Rank | BJ1: Unrounded NOSH | BK1: Rounded NOSH | BL1: Capping Factor | BM1: Effective Date of Review
A2: 17 | B2: ALPHABET CLASS A | C2: GOOGL-US | D2: US02079K3059 | E2: USD | F2: 175.8747 | G2: 5817000000 | H2: NASDAQ | I2: 1023063 | J2: 4.9248801e+09 | K2: 5.8717197e+09 | L2: 5.9033678e+09 | M2: 6.8459395e+09 | N2: 5.1699677e+09 | O2: XNGS | P2: 1 | Q2: =_xlfn.XLOOKUP(D2,'Top 250'!$D$2:$D$251,'Top 250'!$P$2:$P$251) -> 1 | R2: GOOGL.O | S2: 0.84373945 | T2: 0.65 | U2: 57.27 | V2: 0.84 | W2: Amber | X2: Green | Y2: Green | Z2: Green | AA2: Green | AB2: Green | AC2: Green | AD2: Green | AE2: Green | AF2: 0 | AG2: 0 | AI2: 0.84 | AJ2: 0 | AK2: 0 | AL2: 58 | BA2: Included | BB2: No | BC2: 79 | BD2: GOOGL.O | BE2: 251.16 | BF2: 211.9136 | BG2: =F2*G2*Q2*S2 -> 8.6319872e+11 | BH2: 8.6319872e+11 | BI2: 6 | BJ2: 973105.81 | BK2: 973106 | BL2: 1 | BM2: 22-Sep-25
A3: 19 | B3: AMAZON | C3: AMZN-US | D3: US0231351067 | E3: USD | F3: 195.2893 | G3: 10664912000 | H3: NASDAQ | I3: 2082743 | J3: 7.9772001e+09 | K3: 8.5104795e+09 | L3: 7.9912963e+09 | M3: 9.2643579e+09 | N3: 7.8246173e+09 | O3: XNGS | P3: 1 | Q3: =_xlfn.XLOOKUP(D3,'Top 250'!$D$2:$D$251,'Top 250'!$P$2:$P$251) -> 0.9 | R3: AMZN.O | S3: 0.84373945 | T3: 1.36 | U3: 43.66 | V3: 0.93 | W3: Amber | X3: Green | Y3: Green | Z3: Green | AA3: Green | AB3: Green | AC3: Green | AD3: Green | AE3: Green | AF3: 0 | AG3: 0 | AI3: 0.93 | AJ3: 0 | AK3: 0 | AL3: 145 | BA3: Included | BB3: No | BC3: 232 | BD3: AMZN.O | BE3: 234.05 | BF3: 197.47722 | BG3: =F3*G3*Q3*S3 -> 1.5815633e+12 | BH3: 1.5815633e+12 | BI3: 3 | BJ3: 1044243.8 | BK3: 1044244 | BL3: 1 | BM3: 22-Sep-25
A4: 36 | B4: APPLE | C4: AAPL-US | D4: US0378331005 | E4: USD | F4: 194.3676 | G4: 14840390000 | H4: NASDAQ | I4: 2884492 | J4: 1.1742442e+10 | K4: 1.0834249e+10 | L4: 1.0078044e+10 | M4: 1.1681697e+10 | N4: 1.0788743e+10 | O4: XNGS | P4: 1 | Q4: =_xlfn.XLOOKUP(D4,'Top 250'!$D$2:$D$251,'Top 250'!$P$2:$P$251) -> 1 | R4: AAPL.O | S4: 0.84373945 | T4: 0.42 | U4: 64.95 | V4: 0.93 | W4: Amber | X4: Green | Y4: Green | Z4: Green | AA4: Green | AB4: Green | AC4: Green | AD4: Green | AE4: Green | AF4: 0 | AG4: 0 | AI4: 0.93 | AJ4: 0 | AK4: 0 | AL4: 18 | BA4: Included | BB4: No | BC4: 25 | BD4: AAPL.O | BE4: 238.15 | BF4: 200.93655 | BG4: =F4*G4*Q4*S4 -> 2.4337588e+12 | BH4: 2.4337588e+12 | BI4: 2 | BJ4: 1026266 | BK4: 1026266 | BL4: 1 | BM4: 22-Sep-25
A5: 55 | B5: BANK OF AMERICA | C5: BAC-US | D5: US0605051046 | E5: USD | F5: 42.22564 | G5: 7406947300 | H5: NYSE | I5: 312763.1 | J5: 1.3268499e+09 | K5: 1.6718114e+09 | L5: 1.5432748e+09 | M5: 1.7896074e+09 | N5: 1.5611002e+09 | O5: XNYS | P5: 1 | Q5: =_xlfn.XLOOKUP(D5,'Top 250'!$D$2:$D$251,'Top 250'!$P$2:$P$251) -> 0.9 | R5: BAC.N | S5: 0.84373945 | T5: 1.8 | U5: 45.4 | V5: 0.96 | W5: Amber | X5: Green | Y5: Green | Z5: Green | AA5: Green | AB5: Green | AC5: Green | AD5: Green | AE5: Green | AF5: 0 | AG5: 0 | AI5: 0.96 | AJ5: 0 | AK5: 0 | AL5: 197 | BA5: Included | BB5: No | BC5: 217 | BD5: BAC.N | BE5: 50.66 | BF5: 42.743841 | BG5: =F5*G5*Q5*S5 -> 2.375015e+11 | BH5: 2.375015e+11 | BI5: 19 | BJ5: 4824422.7 | BK5: 4824423 | BL5: 1 | BM5: 22-Sep-25
A6: 70 | B6: BROADCOM INC. | C6: AVGO-US | D6: US11135F1012 | E6: USD | F6: 250.8961 | G6: 4703471000 | H6: NASDAQ | I6: 1180082 | J6: 4.4284572e+09 | K6: 5.0063213e+09 | L6: 4.833545e+09 | M6: 5.5971754e+09 | N6: 5.1125496e+09 | O6: XNGS | P6: 1 | Q6: =_xlfn.XLOOKUP(D6,'Top 250'!$D$2:$D$251,'Top 250'!$P$2:$P$251) -> 1 | R6: AVGO.O | S6: 0.84373945 | T6: 3.02 | U6: 44.8 | V6: 0.63 | W6: Green | X6: Green | Y6: Green | Z6: Green | AA6: Green | AB6: Green | AC6: Green | AD6: Green | AE6: Green | AF6: 0 | AG6: 0 | AI6: 0.63 | AJ6: 0 | AK6: 0 | AL6: 355 | BA6: Included | BB6: No | BC6: 221 | BD6: AVGO.O | BE6: 360 | BF6: 303.7462 | BG6: =F6*G6*Q6*S6 -> 9.9568219e+11 | BH6: 9.9568219e+11 | BI6: 5 | BJ6: 678903.49 | BK6: 678903 | BL6: 1 | BM6: 22-Sep-25
A7: 107 | B7: CISCO SYSTEMS INC | C7: CSCO-US | D7: US17275R1023 | E7: USD | F7: 57.45008 | G7: 3959998300 | H7: NASDAQ | I7: 227502.2 | J7: 1.4308107e+09 | K7: 1.2342565e+09 | L7: 1.1800785e+09 | M7: 1.3689942e+09 | N7: 1.1150463e+09 | O7: XNGS | P7: 1 | Q7: =_xlfn.XLOOKUP(D7,'Top 250'!$D$2:$D$251,'Top 250'!$P$2:$P$251) -> 1 | R7: CSCO.O | S7: 0.84373945 | T7: 0.25 | U7: 65.66 | V7: 0.99 | W7: Green | X7: Green | Y7: Green | Z7: Green | AA7: Green | AB7: Green | AC7: Green | AD7: Green | AE7: Green | AF7: 0 | AG7: 0 | AI7: 0.99 | AJ7: 0 | AK7: 0 | AL7: 5 | BA7: Included | BB7: No | BC7: 18 | BD7: CSCO.O | BE7: 66.93 | BF7: 56.471481 | BG7: =F7*G7*Q7*S7 -> 1.919526e+11 | BH7: 1.919526e+11 | BI7: 24 | BJ7: 3651654.8 | BK7: 3651655 | BL7: 1 | BM7: 22-Sep-25
A8: 113 | B8: COCA-COLA CO | C8: KO-US | D8: US1912161007 | E8: USD | F8: 59.84809 | G8: 4303667500 | H8: NYSE | I8: 257566.3 | J8: 7.2645929e+08 | K8: 1.051613e+09 | L8: 9.1423038e+08 | M8: 1.0599458e+09 | N8: 1.0225264e+09 | O8: XNYS | P8: 1 | Q8: =_xlfn.XLOOKUP(D8,'Top 250'!$D$2:$D$251,'Top 250'!$P$2:$P$251) -> 0.9 | R8: KO.N | S8: 0.84373945 | T8: 0.67 | U8: 44.27 | V8: 0.93 | W8: Amber | X8: Green | Y8: Green | Z8: Green | AA8: Green | AB8: Green | AC8: Green | AD8: Green | AE8: Green | AF8: 0 | AG8: 0 | AI8: 0.93 | AJ8: 0 | AK8: 0 | AL8: 61 | BA8: Included | BB8: No | BC8: 224 | BD8: KO.N | BE8: 66.24 | BF8: 55.889301 | BG8: =F8*G8*Q8*S8 -> 1.9558695e+11 | BH8: 1.9558695e+11 | BI8: 22 | BJ8: 3689692.9 | BK8: 3689693 | BL8: 1 | BM8: 22-Sep-25
A9: 172 | B9: ELI LILLY AND CO | C9: LLY-US | D9: US5324571083 | E9: USD | F9: 607.3391 | G9: 946456800 | H9: NYSE | I9: 574820.2 | J9: 4.4289558e+09 | K9: 2.9085759e+09 | L9: 2.7474037e+09 | M9: 3.1851577e+09 | N9: 2.816072e+09 | O9: XNYS | P9: 1 | Q9: =_xlfn.XLOOKUP(D9,'Top 250'!$D$2:$D$251,'Top 250'!$P$2:$P$251) -> 0.85 | R9: LLY.N | S9: 0.84373945 | T9: 2.55 | U9: 59.02 | V9: 1 | W9: Green | X9: Green | Y9: Green | Z9: Green | AA9: Green | AB9: Green | AC9: Green | AD9: Green | AE9: Green | AF9: 0 | AG9: 0 | AI9: 1 | AJ9: 0 | AK9: 0 | AL9: 302 | BA9: Included | BB9: No | BC9: 57 | BD9: LLY.N | BE9: 764.71 | BF9: 645.21599 | BG9: =F9*G9*Q9*S9 -> 4.1224872e+11 | BH9: 4.1224872e+11 | BI9: 10 | BJ9: 319605.15 | BK9: 319605 | BL9: 1 | BM9: 22-Sep-25
